Workbook

Sheet Pai
A1: string[64] | B1: dword | C1: qword | D1: dword | E1: float | F1: float | G1: dword | H1: dword | I1: dword | J1: dword | K1: dword | L1: dword | M1: float | N1: dword | O1: float | P1: float | Q1: dword | R1: dword | S1: dword | T1: dword | U1: dword | V1: dword | W1: dword | X1: string[64] | Y1: dword | Z1: dword | AA1: string[64] | AB1: dword | AC1: string[64] | AD1: dword | AE1: dword | AF1: dword | AG1: dword | AH1: dword | AI1: dword | AJ1: dword | AK1: dword | AL1: dword | AM1: dword | AN1: dword | AO1: dword | AP1: dword | AQ1: dword | AR1: dword | AS1: dword | AT1: dword | AU1: dword | AV1: dword | AW1: END
A2: Code | B2: Level | C2: NeedExp | D2: UseFP | E2: Penalty | F2: AttGap | G2: Attack_DP | H2: AttFcStd | I2: MinAfSelProb | J2: MaxAFSelProb | K2: AttSklUnit | L2: DefSklUnit | M2: WeakPart | N2: StdDefFc | O2: DefGap | P2: DefFacing | Q2: fire | R2: water | S2: soil | T2: wind | U2: ForceLv | V2: ForceMast | W2: ForceAttStd | X2: AttTechID1 | Y2: AttTech1Prob | Z2: AttTech1MotionTime | AA2: PSecTechID | AB2: PSecTechMotionTime | AC2: MSecTechID | AD2: MSeacTechMotionTime | AE2: MaxHP | AF2: HPRecDelay | AG2: HPRecUnit | AH2: MaxFP | AI2: FPRecDelay | AJ2: FPRecUnit | AK2: AttSpd | AL2: AttMoTime1 | AM2: AttMoTime2 | AN2: CrtMoTime | AO2: ViewExt | AP2: RefExt | AQ2: AttExt | AR2: MovSpd | AS2: ScaleRate | AT2: Width | AU2: AttEffType | AV2: DefEffType
A3: 0 | B3: 1 | C3: 200 | D3: 0 | E3: 0.02 | F3: 1 | G3: 0 | H3: 34 | I3: 30 | J3: 50 | K3: 135 | L3: 1 | M3: -1 | N3: 14 | O3: 0.69999999 | P3: 0.078273997 | Q3: 0 | R3: 0 | S3: 0 | T3: 0 | U3: 1 | V3: 1 | W3: 16 | X3: 0 | Y3: 0 | Z3: 1000 | AA3: 0 | AB3: 1000 | AC3: 0 | AD3: 1000 | AE3: 28 | AF3: 2000 | AG3: 5 | AH3: 50 | AI3: 2000 | AJ3: 4 | AK3: 2000 | AL3: 1575 | AM3: 1575 | AN3: 0 | AO3: 340 | AP3: 340 | AQ3: 45 | AR3: 6 | AS3: 100 | AT3: 20 | AU3: 1 | AV3: 512
A4: 0 | B4: 2 | C4: 600 | D4: 0 | E4: 0.02 | F4: 1 | G4: 0 | H4: 35 | I4: 30 | J4: 50 | K4: 137 | L4: 1 | M4: -1 | N4: 21 | O4: 0.69999999 | P4: 0.079306997 | Q4: 0 | R4: 0 | S4: 0 | T4: 0 | U4: 1 | V4: 1 | W4: 16 | X4: 0 | Y4: 0 | Z4: 1000 | AA4: 0 | AB4: 1000 | AC4: 0 | AD4: 1000 | AE4: 36 | AF4: 2000 | AG4: 5 | AH4: 50 | AI4: 2000 | AJ4: 4 | AK4: 2000 | AL4: 1575 | AM4: 1575 | AN4: 0 | AO4: 340 | AP4: 340 | AQ4: 45 | AR4: 6 | AS4: 102 | AT4: 20 | AU4: 1 | AV4: 512
A5: 0 | B5: 3 | C5: 1200 | D5: 0 | E5: 0.02 | F5: 1 | G5: 0 | H5: 37 | I5: 30 | J5: 50 | K5: 139 | L5: 1 | M5: -1 | N5: 23 | O5: 0.69999999 | P5: 0.082814001 | Q5: 0 | R5: 0 | S5: 0 | T5: 0 | U5: 1 | V5: 1 | W5: 16 | X5: 0 | Y5: 0 | Z5: 1000 | AA5: 0 | AB5: 1000 | AC5: 0 | AD5: 1000 | AE5: 48 | AF5: 2000 | AG5: 6 | AH5: 50 | AI5: 2000 | AJ5: 4 | AK5: 2000 | AL5: 1575 | AM5: 1575 | AN5: 0 | AO5: 340 | AP5: 340 | AQ5: 45 | AR5: 6 | AS5: 104 | AT5: 20 | AU5: 1 | AV5: 512
A6: 0 | B6: 4 | C6: 2000 | D6: 0 | E6: 0.02 | F6: 1 | G6: 0 | H6: 42 | I6: 30 | J6: 50 | K6: 141 | L6: 1 | M6: -1 | N6: 23 | O6: 0.69999999 | P6: 0.082640998 | Q6: 0 | R6: 0 | S6: 0 | T6: 0 | U6: 1 | V6: 1 | W6: 16 | X6: 0 | Y6: 0 | Z6: 1000 | AA6: 0 | AB6: 1000 | AC6: 0 | AD6: 1000 | AE6: 52 | AF6: 2000 | AG6: 6 | AH6: 50 | AI6: 2000 | AJ6: 4 | AK6: 2000 | AL6: 1575 | AM6: 1575 | AN6: 0 | AO6: 340 | AP6: 340 | AQ6: 45 | AR6: 6 | AS6: 106 | AT6: 20 | AU6: 1 | AV6: 512
A7: 0 | B7: 5 | C7: 3000 | D7: 0 | E7: 0.02 | F7: 1 | G7: 0 | H7: 50 | I7: 30 | J7: 50 | K7: 160 | L7: 1 | M7: -1 | N7: 28 | O7: 0.69999999 | P7: 0.082736999 | Q7: 0 | R7: 0 | S7: 0 | T7: 0 | U7: 1 | V7: 1 | W7: 16 | X7: 0 | Y7: 0 | Z7: 1000 | AA7: 0 | AB7: 1000 | AC7: 0 | AD7: 1000 | AE7: 68 | AF7: 2000 | AG7: 6 | AH7: 50 | AI7: 2000 | AJ7: 4 | AK7: 2000 | AL7: 1575 | AM7: 1575 | AN7: 0 | AO7: 340 | AP7: 340 | AQ7: 45 | AR7: 6 | AS7: 108 | AT7: 20 | AU7: 1 | AV7: 512
A8: 0 | B8: 6 | C8: 4201 | D8: 0 | E8: 0.02 | F8: 1 | G8: 0 | H8: 53 | I8: 30 | J8: 50 | K8: 162 | L8: 1 | M8: -1 | N8: 31 | O8: 0.69999999 | P8: 0.081169002 | Q8: 0 | R8: 0 | S8: 0 | T8: 0 | U8: 1 | V8: 1 | W8: 16 | X8: 0 | Y8: 0 | Z8: 1000 | AA8: 0 | AB8: 1000 | AC8: 0 | AD8: 1000 | AE8: 80 | AF8: 2000 | AG8: 6 | AH8: 50 | AI8: 2000 | AJ8: 4 | AK8: 2000 | AL8: 1575 | AM8: 1575 | AN8: 0 | AO8: 340 | AP8: 340 | AQ8: 45 | AR8: 6 | AS8: 110 | AT8: 20 | AU8: 1 | AV8: 512
A9: 0 | B9: 7 | C9: 5602 | D9: 0 | E9: 0.02 | F9: 1 | G9: 0 | H9: 59 | I9: 30 | J9: 50 | K9: 164 | L9: 1 | M9: -1 | N9: 35 | O9: 0.69999999 | P9: 0.080023997 | Q9: 0 | R9: 0 | S9: 0 | T9: 0 | U9: 1 | V9: 1 | W9: 16 | X9: 0 | Y9: 0 | Z9: 1000 | AA9: 0 | AB9: 1000 | AC9: 0 | AD9: 1000 | AE9: 84 | AF9: 2000 | AG9: 7 | AH9: 50 | AI9: 2000 | AJ9: 4 | AK9: 2000 | AL9: 1575 | AM9: 1575 | AN9: 0 | AO9: 340 | AP9: 340 | AQ9: 45 | AR9: 6 | AS9: 112 | AT9: 20 | AU9: 1 | AV9: 512
A10: 0 | B10: 8 | C10: 7204 | D10: 0 | E10: 0.02 | F10: 1 | G10: 0 | H10: 66 | I10: 30 | J10: 50 | K10: 166 | L10: 1 | M10: -1 | N10: 43 | O10: 0.69999999 | P10: 0.07784 | Q10: 0 | R10: 0 | S10: 0 | T10: 0 | U10: 1 | V10: 1 | W10: 16 | X10: 0 | Y10: 0 | Z10: 1000 | AA10: 0 | AB10: 1000 | AC10: 0 | AD10: 1000 | AE10: 100 | AF10: 2000 | AG10: 7 | AH10: 50 | AI10: 2000 | AJ10: 4 | AK10: 2000 | AL10: 1575 | AM10: 1575 | AN10: 0 | AO10: 340 | AP10: 340 | AQ10: 45 | AR10: 6 | AS10: 114 | AT10: 20 | AU10: 1 | AV10: 512
A11: 0 | B11: 9 | C11: 9008 | D11: 0 | E11: 0.02 | F11: 1 | G11: 0 | H11: 76 | I11: 30 | J11: 50 | K11: 168 | L11: 1 | M11: -1 | N11: 50 | O11: 0.69999999 | P11: 0.075383998 | Q11: 0 | R11: 0 | S11: 0 | T11: 0 | U11: 1 | V11: 1 | W11: 16 | X11: 0 | Y11: 0 | Z11: 1000 | AA11: 0 | AB11: 1000 | AC11: 0 | AD11: 1000 | AE11: 112 | AF11: 2000 | AG11: 8 | AH11: 50 | AI11: 2000 | AJ11: 4 | AK11: 2000 | AL11: 1575 | AM11: 1575 | AN11: 0 | AO11: 340 | AP11: 340 | AQ11: 45 | AR11: 6 | AS11: 116 | AT11: 20 | AU11: 1 | AV11: 512
A12: 0 | B12: 10 | C12: 11014 | D12: 0 | E12: 0.02 | F12: 1 | G12: 0 | H12: 86 | I12: 30 | J12: 50 | K12: 185 | L12: 1 | M12: -1 | N12: 61 | O12: 0.69999999 | P12: 0.073120996 | Q12: 0 | R12: 0 | S12: 0 | T12: 0 | U12: 1 | V12: 1 | W12: 16 | X12: 0 | Y12: 0 | Z12: 1000 | AA12: 0 | AB12: 1000 | AC12: 0 | AD12: 1000 | AE12: 124 | AF12: 2000 | AG12: 8 | AH12: 50 | AI12: 2000 | AJ12: 4 | AK12: 2000 | AL12: 1575 | AM12: 1575 | AN12: 0 | AO12: 340 | AP12: 340 | AQ12: 45 | AR12: 6 | AS12: 118 | AT12: 20 | AU12: 1 | AV12: 512
A13: 0 | B13: 11 | C13: 13223 | D13: 0 | E13: 0.02 | F13: 1 | G13: 0 | H13: 97 | I13: 30 | J13: 50 | K13: 187 | L13: 1 | M13: -1 | N13: 70 | O13: 0.69999999 | P13: 0.070991002 | Q13: 0 | R13: 0 | S13: 0 | T13: 0 | U13: 1 | V13: 1 | W13: 16 | X13: 0 | Y13: 0 | Z13: 1000 | AA13: 0 | AB13: 1000 | AC13: 0 | AD13: 1000 | AE13: 132 | AF13: 2000 | AG13: 9 | AH13: 50 | AI13: 2000 | AJ13: 4 | AK13: 2000 | AL13: 1575 | AM13: 1575 | AN13: 0 | AO13: 340 | AP13: 340 | AQ13: 45 | AR13: 6 | AS13: 120 | AT13: 20 | AU13: 1 | AV13: 512
A14: 0 | B14: 12 | C14: 15638 | D14: 0 | E14: 0.02 | F14: 1 | G14: 0 | H14: 108 | I14: 30 | J14: 50 | K14: 189 | L14: 1 | M14: -1 | N14: 84 | O14: 0.69999999 | P14: 0.069271997 | Q14: 0 | R14: 0 | S14: 0 | T14: 0 | U14: 1 | V14: 1 | W14: 16 | X14: 0 | Y14: 0 | Z14: 1000 | AA14: 0 | AB14: 1000 | AC14: 0 | AD14: 1000 | AE14: 160 | AF14: 2000 | AG14: 9 | AH14: 50 | AI14: 2000 | AJ14: 4 | AK14: 2000 | AL14: 1575 | AM14: 1575 | AN14: 0 | AO14: 340 | AP14: 340 | AQ14: 45 | AR14: 6 | AS14: 122 | AT14: 20 | AU14: 1 | AV14: 512
... A77: 0 | B77: 75 | C77: 7.0665409e+15 | D77: 134 | E77: 0.02 | F77: 1 | G77: 0 | H77: 13152 | I77: 30 | J77: 50 | K77: 255 | L77: 1 | M77: -1 | N77: 80000 | O77: 0.69999999 | P77: 0.0035610001 | Q77: 0 | R77: 0 | S77: 0 | T77: 0 | U77: 1 | V77: 1 | W77: 16 | X77: 0 | Y77: 0 | Z77: 1000 | AA77: 0 | AB77: 1000 | AC77: 0 | AD77: 1000 | AE77: 60000 | AF77: 2000 | AG77: 111 | AH77: 50 | AI77: 2000 | AJ77: 4 | AK77: 2000 | AL77: 1575 | AM77: 1575 | AN77: 0 | AO77: 340 | AP77: 340 | AQ77: 45 | AR77: 6 | AS77: 270 | AT77: 20 | AU77: 1 | AV77: 512

Sheet Hec
A1: string[64] | B1: dword | C1: qword | D1: dword | E1: float | F1: float | G1: dword | H1: dword | I1: dword | J1: dword | K1: dword | L1: dword | M1: float | N1: dword | O1: float | P1: float | Q1: dword | R1: dword | S1: dword | T1: dword | U1: dword | V1: dword | W1: dword | X1: string[64] | Y1: dword | Z1: dword | AA1: string[64] | AB1: dword | AC1: string[64] | AD1: dword | AE1: dword | AF1: dword | AG1: dword | AH1: dword | AI1: dword | AJ1: dword | AK1: dword | AL1: dword | AM1: dword | AN1: dword | AO1: dword | AP1: dword | AQ1: dword | AR1: dword | AS1: dword | AT1: dword | AU1: dword | AV1: dword | AW1: END
A2: Code | B2: Level | C2: NeedExp | D2: UseFP | E2: Penalty | F2: AttGap | G2: Attack_DP | H2: AttFcStd | I2: MinAfSelProb | J2: MaxAFSelProb | K2: AttSklUnit | L2: DefSklUnit | M2: WeakPart | N2: StdDefFc | O2: DefGap | P2: DefFacing | Q2: fire | R2: water | S2: soil | T2: wind | U2: ForceLv | V2: ForceMast | W2: ForceAttStd | X2: AttTechID1 | Y2: AttTech1Prob | Z2: AttTech1MotionTime | AA2: PSecTechID | AB2: PSecTechMotionTime | AC2: MSecTechID | AD2: MSeacTechMotionTime | AE2: MaxHP | AF2: HPRecDelay | AG2: HPRecUnit | AH2: MaxFP | AI2: FPRecDelay | AJ2: FPRecUnit | AK2: AttSpd | AL2: AttMoTime1 | AM2: AttMoTime2 | AN2: CrtMoTime | AO2: ViewExt | AP2: RefExt | AQ2: AttExt | AR2: MovSpd | AS2: ScaleRate | AT2: Width | AU2: AttEffType | AV2: DefEffType
A3: 0 | B3: 1 | C3: 200 | D3: 0 | E3: 0.02 | F3: 1 | G3: 0 | H3: 1 | I3: 37 | J3: 50 | K3: 95 | L3: 3 | M3: -1 | N3: 10 | O3: 0.57499999 | P3: 0.74255002 | Q3: 10 | R3: 10 | S3: 10 | T3: 10 | U3: 1 | V3: 1 | W3: 16 | X3: 0 | Y3: 0 | Z3: 1000 | AA3: 0 | AB3: 1000 | AC3: 0 | AD3: 1000 | AE3: 70 | AF3: 2000 | AG3: 12 | AH3: 50 | AI3: 2000 | AJ3: 4 | AK3: 900 | AL3: 900 | AM3: 900 | AN3: 0 | AO3: 340 | AP3: 340 | AQ3: 225 | AR3: 6 | AS3: 100 | AT3: 20 | AU3: 10 | AV3: 273
A4: 0 | B4: 2 | C4: 600 | D4: 0 | E4: 0.02 | F4: 1 | G4: 0 | H4: 1 | I4: 34 | J4: 45 | K4: 97 | L4: 3 | M4: -1 | N4: 12 | O4: 0.57499999 | P4: 0.79121798 | Q4: 10 | R4: 10 | S4: 10 | T4: 10 | U4: 1 | V4: 1 | W4: 16 | X4: 0 | Y4: 0 | Z4: 1000 | AA4: 0 | AB4: 1000 | AC4: 0 | AD4: 1000 | AE4: 90 | AF4: 2000 | AG4: 12 | AH4: 50 | AI4: 2000 | AJ4: 4 | AK4: 900 | AL4: 900 | AM4: 900 | AN4: 0 | AO4: 340 | AP4: 340 | AQ4: 225 | AR4: 6 | AS4: 100 | AT4: 20 | AU4: 10 | AV4: 273
A5: 0 | B5: 3 | C5: 1200 | D5: 0 | E5: 0.02 | F5: 1 | G5: 0 | H5: 1 | I5: 32 | J5: 43 | K5: 99 | L5: 3 | M5: -1 | N5: 16 | O5: 0.57499999 | P5: 0.773498 | Q5: 10 | R5: 10 | S5: 10 | T5: 10 | U5: 1 | V5: 1 | W5: 16 | X5: 0 | Y5: 0 | Z5: 1000 | AA5: 0 | AB5: 1000 | AC5: 0 | AD5: 1000 | AE5: 120 | AF5: 2000 | AG5: 14 | AH5: 50 | AI5: 2000 | AJ5: 4 | AK5: 900 | AL5: 900 | AM5: 900 | AN5: 0 | AO5: 340 | AP5: 340 | AQ5: 225 | AR5: 6 | AS5: 100 | AT5: 20 | AU5: 10 | AV5: 273
A6: 0 | B6: 4 | C6: 2000 | D6: 0 | E6: 0.02 | F6: 1 | G6: 0 | H6: 1 | I6: 30 | J6: 41 | K6: 101 | L6: 6 | M6: -1 | N6: 18 | O6: 0.57499999 | P6: 0.80910701 | Q6: 10 | R6: 10 | S6: 10 | T6: 10 | U6: 1 | V6: 1 | W6: 16 | X6: 0 | Y6: 0 | Z6: 1000 | AA6: 0 | AB6: 1000 | AC6: 0 | AD6: 1000 | AE6: 130 | AF6: 2000 | AG6: 14 | AH6: 50 | AI6: 2000 | AJ6: 4 | AK6: 900 | AL6: 900 | AM6: 900 | AN6: 0 | AO6: 340 | AP6: 340 | AQ6: 225 | AR6: 6 | AS6: 100 | AT6: 20 | AU6: 10 | AV6: 273
A7: 0 | B7: 5 | C7: 3000 | D7: 0 | E7: 0.02 | F7: 1 | G7: 0 | H7: 1 | I7: 30 | J7: 40 | K7: 120 | L7: 9 | M7: -1 | N7: 22 | O7: 0.57499999 | P7: 0.81847501 | Q7: 10 | R7: 10 | S7: 10 | T7: 10 | U7: 1 | V7: 1 | W7: 16 | X7: 0 | Y7: 0 | Z7: 1000 | AA7: 0 | AB7: 1000 | AC7: 0 | AD7: 1000 | AE7: 170 | AF7: 2000 | AG7: 16 | AH7: 50 | AI7: 2000 | AJ7: 4 | AK7: 900 | AL7: 900 | AM7: 900 | AN7: 0 | AO7: 340 | AP7: 340 | AQ7: 225 | AR7: 6 | AS7: 100 | AT7: 20 | AU7: 10 | AV7: 273
A8: 0 | B8: 6 | C8: 4201 | D8: 0 | E8: 0.02 | F8: 1 | G8: 0 | H8: 1 | I8: 29 | J8: 38 | K8: 122 | L8: 9 | M8: -1 | N8: 22 | O8: 0.57499999 | P8: 0.85005099 | Q8: 10 | R8: 10 | S8: 10 | T8: 10 | U8: 1 | V8: 1 | W8: 16 | X8: 0 | Y8: 0 | Z8: 1000 | AA8: 0 | AB8: 1000 | AC8: 0 | AD8: 1000 | AE8: 200 | AF8: 2000 | AG8: 16 | AH8: 50 | AI8: 2000 | AJ8: 4 | AK8: 900 | AL8: 900 | AM8: 900 | AN8: 0 | AO8: 340 | AP8: 340 | AQ8: 225 | AR8: 6 | AS8: 100 | AT8: 20 | AU8: 10 | AV8: 273
A9: 0 | B9: 7 | C9: 5602 | D9: 0 | E9: 0.02 | F9: 1 | G9: 0 | H9: 1 | I9: 28 | J9: 38 | K9: 124 | L9: 12 | M9: -1 | N9: 26 | O9: 0.57499999 | P9: 0.84850597 | Q9: 10 | R9: 10 | S9: 10 | T9: 10 | U9: 1 | V9: 1 | W9: 16 | X9: 0 | Y9: 0 | Z9: 1000 | AA9: 0 | AB9: 1000 | AC9: 0 | AD9: 1000 | AE9: 210 | AF9: 2000 | AG9: 18 | AH9: 50 | AI9: 2000 | AJ9: 4 | AK9: 900 | AL9: 900 | AM9: 900 | AN9: 0 | AO9: 340 | AP9: 340 | AQ9: 225 | AR9: 6 | AS9: 100 | AT9: 20 | AU9: 10 | AV9: 273
A10: 0 | B10: 8 | C10: 7204 | D10: 0 | E10: 0.02 | F10: 1 | G10: 0 | H10: 1 | I10: 28 | J10: 37 | K10: 126 | L10: 12 | M10: -1 | N10: 30 | O10: 0.57499999 | P10: 0.84936303 | Q10: 10 | R10: 10 | S10: 10 | T10: 10 | U10: 1 | V10: 1 | W10: 16 | X10: 0 | Y10: 0 | Z10: 1000 | AA10: 0 | AB10: 1000 | AC10: 0 | AD10: 1000 | AE10: 250 | AF10: 2000 | AG10: 18 | AH10: 50 | AI10: 2000 | AJ10: 4 | AK10: 900 | AL10: 900 | AM10: 900 | AN10: 0 | AO10: 340 | AP10: 340 | AQ10: 225 | AR10: 6 | AS10: 100 | AT10: 20 | AU10: 10 | AV10: 273
A11: 0 | B11: 9 | C11: 9008 | D11: 0 | E11: 0.02 | F11: 1 | G11: 0 | H11: 1 | I11: 27 | J11: 36 | K11: 128 | L11: 12 | M11: -1 | N11: 38 | O11: 0.57499999 | P11: 0.83528602 | Q11: 10 | R11: 10 | S11: 10 | T11: 10 | U11: 1 | V11: 1 | W11: 16 | X11: 0 | Y11: 0 | Z11: 1000 | AA11: 0 | AB11: 1000 | AC11: 0 | AD11: 1000 | AE11: 280 | AF11: 2000 | AG11: 20 | AH11: 50 | AI11: 2000 | AJ11: 4 | AK11: 900 | AL11: 900 | AM11: 900 | AN11: 0 | AO11: 340 | AP11: 340 | AQ11: 225 | AR11: 6 | AS11: 100 | AT11: 20 | AU11: 10 | AV11: 273
A12: 0 | B12: 10 | C12: 11014 | D12: 0 | E12: 0.02 | F12: 1 | G12: 0 | H12: 1 | I12: 27 | J12: 36 | K12: 145 | L12: 15 | M12: -1 | N12: 46 | O12: 0.57499999 | P12: 0.82496297 | Q12: 10 | R12: 10 | S12: 10 | T12: 10 | U12: 1 | V12: 1 | W12: 16 | X12: 0 | Y12: 0 | Z12: 1000 | AA12: 0 | AB12: 1000 | AC12: 0 | AD12: 1000 | AE12: 310 | AF12: 2000 | AG12: 20 | AH12: 50 | AI12: 2000 | AJ12: 4 | AK12: 900 | AL12: 900 | AM12: 900 | AN12: 0 | AO12: 340 | AP12: 340 | AQ12: 225 | AR12: 6 | AS12: 100 | AT12: 20 | AU12: 10 | AV12: 273
A13: 0 | B13: 11 | C13: 13223 | D13: 0 | E13: 0.02 | F13: 1 | G13: 0 | H13: 1 | I13: 26 | J13: 35 | K13: 147 | L13: 15 | M13: -1 | N13: 58 | O13: 0.57499999 | P13: 0.80516201 | Q13: 10 | R13: 10 | S13: 10 | T13: 10 | U13: 1 | V13: 1 | W13: 16 | X13: 0 | Y13: 0 | Z13: 1000 | AA13: 0 | AB13: 1000 | AC13: 0 | AD13: 1000 | AE13: 330 | AF13: 2000 | AG13: 22 | AH13: 50 | AI13: 2000 | AJ13: 4 | AK13: 900 | AL13: 900 | AM13: 900 | AN13: 0 | AO13: 340 | AP13: 340 | AQ13: 225 | AR13: 6 | AS13: 100 | AT13: 20 | AU13: 10 | AV13: 273
A14: 0 | B14: 12 | C14: 15638 | D14: 0 | E14: 0.02 | F14: 1 | G14: 0 | H14: 1 | I14: 26 | J14: 35 | K14: 149 | L14: 18 | M14: -1 | N14: 72 | O14: 0.57499999 | P14: 0.78274101 | Q14: 10 | R14: 10 | S14: 10 | T14: 10 | U14: 1 | V14: 1 | W14: 16 | X14: 0 | Y14: 0 | Z14: 1000 | AA14: 0 | AB14: 1000 | AC14: 0 | AD14: 1000 | AE14: 400 | AF14: 2000 | AG14: 22 | AH14: 50 | AI14: 2000 | AJ14: 4 | AK14: 900 | AL14: 900 | AM14: 900 | AN14: 0 | AO14: 340 | AP14: 340 | AQ14: 225 | AR14: 6 | AS14: 100 | AT14: 20 | AU14: 10 | AV14: 273
... A77: 0 | B77: 75 | C77: 7.0006654e+17 | D77: 134 | E77: 0.02 | F77: 1 | G77: 0 | H77: 1 | I77: 4 | J77: 6 | K77: 255 | L77: 743 | M77: -1 | N77: 7883 | O77: 0.57499999 | P77: 0.048413999 | Q77: 10 | R77: 10 | S77: 10 | T77: 10 | U77: 1 | V77: 1 | W77: 16 | X77: 0 | Y77: 0 | Z77: 1000 | AA77: 0 | AB77: 1000 | AC77: 0 | AD77: 1000 | AE77: 60000 | AF77: 2000 | AG77: 74 | AH77: 50 | AI77: 2000 | AJ77: 4 | AK77: 900 | AL77: 900 | AM77: 900 | AN77: 0 | AO77: 340 | AP77: 340 | AQ77: 230 | AR77: 6 | AS77: 100 | AT77: 20 | AU77: 10 | AV77: 273

Sheet Ina
A1: string[64] | B1: dword | C1: qword | D1: dword | E1: float | F1: float | G1: dword | H1: dword | I1: dword | J1: dword | K1: dword | L1: dword | M1: float | N1: dword | O1: float | P1: float | Q1: dword | R1: dword | S1: dword | T1: dword | U1: dword | V1: dword | W1: dword | X1: string[64] | Y1: dword | Z1: dword | AA1: string[64] | AB1: dword | AC1: string[64] | AD1: dword | AE1: dword | AF1: dword | AG1: dword | AH1: dword | AI1: dword | AJ1: dword | AK1: dword | AL1: dword | AM1: dword | AN1: dword | AO1: dword | AP1: dword | AQ1: dword | AR1: dword | AS1: dword | AT1: dword | AU1: dword | AV1: dword | AW1: END
A2: Code | B2: Level | C2: NeedExp | D2: UseFP | E2: Penalty | F2: AttGap | G2: Attack_DP | H2: AttFcStd | I2: MinAfSelProb | J2: MaxAFSelProb | K2: AttSklUnit | L2: DefSklUnit | M2: WeakPart | N2: StdDefFc | O2: DefGap | P2: DefFacing | Q2: fire | R2: water | S2: soil | T2: wind | U2: ForceLv | V2: ForceMast | W2: ForceAttStd | X2: AttTechID1 | Y2: AttTech1Prob | Z2: AttTech1MotionTime | AA2: PSecTechID | AB2: PSecTechMotionTime | AC2: MSecTechID | AD2: MSeacTechMotionTime | AE2: MaxHP | AF2: HPRecDelay | AG2: HPRecUnit | AH2: MaxFP | AI2: FPRecDelay | AJ2: FPRecUnit | AK2: AttSpd | AL2: AttMoTime1 | AM2: AttMoTime2 | AN2: CrtMoTime | AO2: ViewExt | AP2: RefExt | AQ2: AttExt | AR2: MovSpd | AS2: ScaleRate | AT2: Width | AU2: AttEffType | AV2: DefEffType
A3: 0 | B3: 1 | C3: 2160 | D3: 0 | E3: 0.02 | F3: 1 | G3: 0 | H3: 27 | I3: 50 | J3: 50 | K3: 1 | L3: 1 | M3: -1 | N3: 10 | O3: 0.57499999 | P3: 0.74255002 | Q3: 0 | R3: 0 | S3: 0 | T3: 0 | U3: 1 | V3: 1 | W3: 16 | X3: 0 | Y3: 0 | Z3: 1000 | AA3: 0 | AB3: 1000 | AC3: 0 | AD3: 1000 | AE3: 70 | AF3: 2000 | AG3: 12 | AH3: 50 | AI3: 2000 | AJ3: 4 | AK3: 1575 | AL3: 1575 | AM3: 1575 | AN3: 0 | AO3: 340 | AP3: 340 | AQ3: 225 | AR3: 6 | AS3: 70 | AT3: 20 | AU3: 0 | AV3: 1041
A4: 0 | B4: 2 | C4: 4752 | D4: 0 | E4: 0.02 | F4: 1 | G4: 0 | H4: 32 | I4: 50 | J4: 50 | K4: 1 | L4: 2 | M4: -1 | N4: 12 | O4: 0.57499999 | P4: 0.79121798 | Q4: 0 | R4: 0 | S4: 0 | T4: 0 | U4: 1 | V4: 1 | W4: 16 | X4: 0 | Y4: 0 | Z4: 1000 | AA4: 0 | AB4: 1000 | AC4: 0 | AD4: 1000 | AE4: 90 | AF4: 2000 | AG4: 12 | AH4: 50 | AI4: 2000 | AJ4: 4 | AK4: 1575 | AL4: 1575 | AM4: 1575 | AN4: 0 | AO4: 340 | AP4: 340 | AQ4: 225 | AR4: 6 | AS4: 70 | AT4: 20 | AU4: 0 | AV4: 1041
A5: 0 | B5: 3 | C5: 8682 | D5: 0 | E5: 0.02 | F5: 1 | G5: 0 | H5: 39 | I5: 50 | J5: 50 | K5: 1 | L5: 3 | M5: -1 | N5: 16 | O5: 0.57499999 | P5: 0.773498 | Q5: 0 | R5: 0 | S5: 0 | T5: 0 | U5: 1 | V5: 1 | W5: 16 | X5: 0 | Y5: 0 | Z5: 1000 | AA5: 0 | AB5: 1000 | AC5: 0 | AD5: 1000 | AE5: 120 | AF5: 2000 | AG5: 14 | AH5: 50 | AI5: 2000 | AJ5: 4 | AK5: 1575 | AL5: 1575 | AM5: 1575 | AN5: 0 | AO5: 340 | AP5: 340 | AQ5: 225 | AR5: 6 | AS5: 70 | AT5: 20 | AU5: 0 | AV5: 1041
A6: 0 | B6: 4 | C6: 14046 | D6: 0 | E6: 0.02 | F6: 1 | G6: 0 | H6: 45 | I6: 50 | J6: 50 | K6: 2 | L6: 4 | M6: -1 | N6: 18 | O6: 0.57499999 | P6: 0.80910701 | Q6: 0 | R6: 0 | S6: 0 | T6: 0 | U6: 1 | V6: 1 | W6: 16 | X6: 0 | Y6: 0 | Z6: 1000 | AA6: 0 | AB6: 1000 | AC6: 0 | AD6: 1000 | AE6: 130 | AF6: 2000 | AG6: 14 | AH6: 50 | AI6: 2000 | AJ6: 4 | AK6: 1575 | AL6: 1575 | AM6: 1575 | AN6: 0 | AO6: 340 | AP6: 340 | AQ6: 225 | AR6: 6 | AS6: 70 | AT6: 20 | AU6: 0 | AV6: 1041
A7: 0 | B7: 5 | C7: 21606 | D7: 0 | E7: 0.02 | F7: 1 | G7: 0 | H7: 54 | I7: 50 | J7: 50 | K7: 3 | L7: 10 | M7: -1 | N7: 22 | O7: 0.57499999 | P7: 0.81847501 | Q7: 0 | R7: 0 | S7: 0 | T7: 0 | U7: 1 | V7: 1 | W7: 16 | X7: 0 | Y7: 0 | Z7: 1000 | AA7: 0 | AB7: 1000 | AC7: 0 | AD7: 1000 | AE7: 170 | AF7: 2000 | AG7: 16 | AH7: 50 | AI7: 2000 | AJ7: 4 | AK7: 1575 | AL7: 1575 | AM7: 1575 | AN7: 0 | AO7: 340 | AP7: 340 | AQ7: 225 | AR7: 6 | AS7: 70 | AT7: 20 | AU7: 0 | AV7: 1041
A8: 0 | B8: 6 | C8: 31214 | D8: 0 | E8: 0.02 | F8: 1 | G8: 0 | H8: 60 | I8: 50 | J8: 50 | K8: 4 | L8: 11 | M8: -1 | N8: 22 | O8: 0.57499999 | P8: 0.85005099 | Q8: 0 | R8: 0 | S8: 0 | T8: 0 | U8: 1 | V8: 1 | W8: 16 | X8: 0 | Y8: 0 | Z8: 1000 | AA8: 0 | AB8: 1000 | AC8: 0 | AD8: 1000 | AE8: 200 | AF8: 2000 | AG8: 16 | AH8: 50 | AI8: 2000 | AJ8: 4 | AK8: 1575 | AL8: 1575 | AM8: 1575 | AN8: 0 | AO8: 340 | AP8: 340 | AQ8: 225 | AR8: 6 | AS8: 70 | AT8: 20 | AU8: 0 | AV8: 1041
A9: 0 | B9: 7 | C9: 43102 | D9: 0 | E9: 0.02 | F9: 1 | G9: 0 | H9: 66 | I9: 50 | J9: 50 | K9: 4 | L9: 12 | M9: -1 | N9: 26 | O9: 0.57499999 | P9: 0.84850597 | Q9: 0 | R9: 0 | S9: 0 | T9: 0 | U9: 1 | V9: 1 | W9: 16 | X9: 0 | Y9: 0 | Z9: 1000 | AA9: 0 | AB9: 1000 | AC9: 0 | AD9: 1000 | AE9: 210 | AF9: 2000 | AG9: 18 | AH9: 50 | AI9: 2000 | AJ9: 4 | AK9: 1575 | AL9: 1575 | AM9: 1575 | AN9: 0 | AO9: 340 | AP9: 340 | AQ9: 225 | AR9: 6 | AS9: 70 | AT9: 20 | AU9: 0 | AV9: 1041
A10: 0 | B10: 8 | C10: 58601 | D10: 0 | E10: 0.02 | F10: 1 | G10: 0 | H10: 77 | I10: 50 | J10: 50 | K10: 4 | L10: 13 | M10: -1 | N10: 30 | O10: 0.57499999 | P10: 0.84936303 | Q10: 0 | R10: 0 | S10: 0 | T10: 0 | U10: 1 | V10: 1 | W10: 16 | X10: 0 | Y10: 0 | Z10: 1000 | AA10: 0 | AB10: 1000 | AC10: 0 | AD10: 1000 | AE10: 250 | AF10: 2000 | AG10: 18 | AH10: 50 | AI10: 2000 | AJ10: 4 | AK10: 1575 | AL10: 1575 | AM10: 1575 | AN10: 0 | AO10: 340 | AP10: 340 | AQ10: 225 | AR10: 6 | AS10: 70 | AT10: 20 | AU10: 0 | AV10: 1041
A11: 0 | B11: 9 | C11: 77188 | D11: 0 | E11: 0.02 | F11: 1 | G11: 0 | H11: 84 | I11: 50 | J11: 50 | K11: 5 | L11: 14 | M11: -1 | N11: 38 | O11: 0.57499999 | P11: 0.83528602 | Q11: 0 | R11: 0 | S11: 0 | T11: 0 | U11: 1 | V11: 1 | W11: 16 | X11: 0 | Y11: 0 | Z11: 1000 | AA11: 0 | AB11: 1000 | AC11: 0 | AD11: 1000 | AE11: 280 | AF11: 2000 | AG11: 20 | AH11: 50 | AI11: 2000 | AJ11: 4 | AK11: 1575 | AL11: 1575 | AM11: 1575 | AN11: 0 | AO11: 340 | AP11: 340 | AQ11: 225 | AR11: 6 | AS11: 70 | AT11: 20 | AU11: 0 | AV11: 1041
A12: 0 | B12: 10 | C12: 100585 | D12: 0 | E12: 0.02 | F12: 1 | G12: 0 | H12: 97 | I12: 50 | J12: 50 | K12: 5 | L12: 20 | M12: -1 | N12: 46 | O12: 0.57499999 | P12: 0.82496297 | Q12: 0 | R12: 0 | S12: 0 | T12: 0 | U12: 1 | V12: 1 | W12: 16 | X12: 0 | Y12: 0 | Z12: 1000 | AA12: 0 | AB12: 1000 | AC12: 0 | AD12: 1000 | AE12: 310 | AF12: 2000 | AG12: 20 | AH12: 50 | AI12: 2000 | AJ12: 4 | AK12: 1575 | AL12: 1575 | AM12: 1575 | AN12: 0 | AO12: 340 | AP12: 340 | AQ12: 225 | AR12: 6 | AS12: 70 | AT12: 20 | AU12: 0 | AV12: 1041
A13: 0 | B13: 11 | C13: 127918 | D13: 0 | E13: 0.02 | F13: 1 | G13: 0 | H13: 105 | I13: 50 | J13: 50 | K13: 6 | L13: 21 | M13: -1 | N13: 58 | O13: 0.57499999 | P13: 0.80516201 | Q13: 0 | R13: 0 | S13: 0 | T13: 0 | U13: 1 | V13: 1 | W13: 16 | X13: 0 | Y13: 0 | Z13: 1000 | AA13: 0 | AB13: 1000 | AC13: 0 | AD13: 1000 | AE13: 330 | AF13: 2000 | AG13: 22 | AH13: 50 | AI13: 2000 | AJ13: 4 | AK13: 1575 | AL13: 1575 | AM13: 1575 | AN13: 0 | AO13: 340 | AP13: 340 | AQ13: 225 | AR13: 6 | AS13: 70 | AT13: 20 | AU13: 0 | AV13: 1041
A14: 0 | B14: 12 | C14: 161474 | D14: 0 | E14: 0.02 | F14: 1 | G14: 0 | H14: 119 | I14: 50 | J14: 50 | K14: 6 | L14: 22 | M14: -1 | N14: 72 | O14: 0.57499999 | P14: 0.78274101 | Q14: 0 | R14: 0 | S14: 0 | T14: 0 | U14: 1 | V14: 1 | W14: 16 | X14: 0 | Y14: 0 | Z14: 1000 | AA14: 0 | AB14: 1000 | AC14: 0 | AD14: 1000 | AE14: 400 | AF14: 2000 | AG14: 22 | AH14: 50 | AI14: 2000 | AJ14: 4 | AK14: 1575 | AL14: 1575 | AM14: 1575 | AN14: 0 | AO14: 340 | AP14: 340 | AQ14: 225 | AR14: 6 | AS14: 70 | AT14: 20 | AU14: 0 | AV14: 1041
... A77: 0 | B77: 75 | C77: 7.0665409e+15 | D77: 134 | E77: 0.02 | F77: 1 | G77: 0 | H77: 4500 | I77: 50 | J77: 50 | K77: 99 | L77: 150 | M77: -1 | N77: 7883 | O77: 0.57499999 | P77: 0.048413999 | Q77: 0 | R77: 0 | S77: 0 | T77: 0 | U77: 1 | V77: 1 | W77: 16 | X77: 0 | Y77: 0 | Z77: 1000 | AA77: 0 | AB77: 1000 | AC77: 0 | AD77: 1000 | AE77: 60000 | AF77: 2000 | AG77: 74 | AH77: 50 | AI77: 2000 | AJ77: 4 | AK77: 1400 | AL77: 1575 | AM77: 1575 | AN77: 0 | AO77: 340 | AP77: 340 | AQ77: 225 | AR77: 6 | AS77: 70 | AT77: 20 | AU77: 0 | AV77: 1041

Sheet Isi
A1: string[64] | B1: dword | C1: qword | D1: dword | E1: float | F1: float | G1: dword | H1: dword | I1: dword | J1: dword | K1: dword | L1: dword | M1: float | N1: dword | O1: float | P1: float | Q1: dword | R1: dword | S1: dword | T1: dword | U1: dword | V1: dword | W1: dword | X1: string[64] | Y1: dword | Z1: dword | AA1: string[64] | AB1: dword | AC1: string[64] | AD1: dword | AE1: dword | AF1: dword | AG1: dword | AH1: dword | AI1: dword | AJ1: dword | AK1: dword | AL1: dword | AM1: dword | AN1: dword | AO1: dword | AP1: dword | AQ1: dword | AR1: dword | AS1: dword | AT1: dword | AU1: dword | AV1: dword | AW1: END
A2: Code | B2: Level | C2: NeedExp | D2: UseFP | E2: Penalty | F2: AttGap | G2: Attack_DP | H2: AttFcStd | I2: MinAfSelProb | J2: MaxAFSelProb | K2: AttSklUnit | L2: DefSklUnit | M2: WeakPart | N2: StdDefFc | O2: DefGap | P2: DefFacing | Q2: fire | R2: water | S2: soil | T2: wind | U2: ForceLv | V2: ForceMast | W2: ForceAttStd | X2: AttTechID1 | Y2: AttTech1Prob | Z2: AttTech1MotionTime | AA2: PSecTechID | AB2: PSecTechMotionTime | AC2: MSecTechID | AD2: MSeacTechMotionTime | AE2: MaxHP | AF2: HPRecDelay | AG2: HPRecUnit | AH2: MaxFP | AI2: FPRecDelay | AJ2: FPRecUnit | AK2: AttSpd | AL2: AttMoTime1 | AM2: AttMoTime2 | AN2: CrtMoTime | AO2: ViewExt | AP2: RefExt | AQ2: AttExt | AR2: MovSpd | AS2: ScaleRate | AT2: Width | AU2: AttEffType | AV2: DefEffType
A3: 0 | B3: 1 | C3: 200 | D3: 0 | E3: 0.02 | F3: 0.5 | G3: 0 | H3: 150 | I3: 40 | J3: 60 | K3: 175 | L3: 1 | M3: -1 | N3: 5 | O3: 0.5 | P3: 0.71028 | Q3: 50 | R3: 50 | S3: 50 | T3: 50 | U3: 1 | V3: 1 | W3: 16 | X3: 0 | Y3: 0 | Z3: 1000 | AA3: 0 | AB3: 1000 | AC3: 0 | AD3: 1000 | AE3: 70 | AF3: 2000 | AG3: 12 | AH3: 50 | AI3: 2000 | AJ3: 4 | AK3: 1800 | AL3: 1575 | AM3: 1575 | AN3: 0 | AO3: 300 | AP3: 300 | AQ3: 300 | AR3: 6 | AS3: 100 | AT3: 20 | AU3: 1 | AV3: 7
A4: 0 | B4: 2 | C4: 600 | D4: 0 | E4: 0.02 | F4: 0.5 | G4: 0 | H4: 172 | I4: 40 | J4: 60 | K4: 177 | L4: 1 | M4: -1 | N4: 6 | O4: 0.5 | P4: 0.76310301 | Q4: 50 | R4: 50 | S4: 50 | T4: 50 | U4: 1 | V4: 1 | W4: 16 | X4: 0 | Y4: 0 | Z4: 1000 | AA4: 0 | AB4: 1000 | AC4: 0 | AD4: 1000 | AE4: 90 | AF4: 2000 | AG4: 12 | AH4: 50 | AI4: 2000 | AJ4: 4 | AK4: 1800 | AL4: 1575 | AM4: 1575 | AN4: 0 | AO4: 300 | AP4: 300 | AQ4: 300 | AR4: 6 | AS4: 100 | AT4: 20 | AU4: 1 | AV4: 7
A5: 0 | B5: 3 | C5: 1200 | D5: 0 | E5: 0.02 | F5: 0.5 | G5: 0 | H5: 199 | I5: 40 | J5: 60 | K5: 179 | L5: 1 | M5: -1 | N5: 8 | O5: 0.5 | P5: 0.74376899 | Q5: 50 | R5: 50 | S5: 50 | T5: 50 | U5: 1 | V5: 1 | W5: 16 | X5: 0 | Y5: 0 | Z5: 1000 | AA5: 0 | AB5: 1000 | AC5: 0 | AD5: 1000 | AE5: 120 | AF5: 2000 | AG5: 14 | AH5: 50 | AI5: 2000 | AJ5: 4 | AK5: 1800 | AL5: 1575 | AM5: 1575 | AN5: 0 | AO5: 300 | AP5: 300 | AQ5: 300 | AR5: 6 | AS5: 100 | AT5: 20 | AU5: 1 | AV5: 7
A6: 0 | B6: 4 | C6: 2000 | D6: 0 | E6: 0.02 | F6: 0.5 | G6: 0 | H6: 241 | I6: 40 | J6: 60 | K6: 181 | L6: 2 | M6: -1 | N6: 9 | O6: 0.5 | P6: 0.78273898 | Q6: 50 | R6: 50 | S6: 50 | T6: 50 | U6: 1 | V6: 1 | W6: 16 | X6: 0 | Y6: 0 | Z6: 1000 | AA6: 0 | AB6: 1000 | AC6: 0 | AD6: 1000 | AE6: 130 | AF6: 2000 | AG6: 14 | AH6: 50 | AI6: 2000 | AJ6: 4 | AK6: 1800 | AL6: 1575 | AM6: 1575 | AN6: 0 | AO6: 300 | AP6: 300 | AQ6: 300 | AR6: 6 | AS6: 100 | AT6: 20 | AU6: 1 | AV6: 7
A7: 0 | B7: 5 | C7: 3000 | D7: 0 | E7: 0.02 | F7: 0.5 | G7: 0 | H7: 298 | I7: 40 | J7: 60 | K7: 200 | L7: 3 | M7: -1 | N7: 11 | O7: 0.5 | P7: 0.79307002 | Q7: 50 | R7: 50 | S7: 50 | T7: 50 | U7: 1 | V7: 1 | W7: 16 | X7: 0 | Y7: 0 | Z7: 1000 | AA7: 0 | AB7: 1000 | AC7: 0 | AD7: 1000 | AE7: 170 | AF7: 2000 | AG7: 16 | AH7: 50 | AI7: 2000 | AJ7: 4 | AK7: 1800 | AL7: 1575 | AM7: 1575 | AN7: 0 | AO7: 300 | AP7: 300 | AQ7: 300 | AR7: 6 | AS7: 100 | AT7: 20 | AU7: 1 | AV7: 7
A8: 0 | B8: 6 | C8: 4201 | D8: 0 | E8: 0.02 | F8: 0.5 | G8: 0 | H8: 328 | I8: 40 | J8: 60 | K8: 202 | L8: 3 | M8: -1 | N8: 11 | O8: 0.5 | P8: 0.82813698 | Q8: 50 | R8: 50 | S8: 50 | T8: 50 | U8: 1 | V8: 1 | W8: 16 | X8: 0 | Y8: 0 | Z8: 1000 | AA8: 0 | AB8: 1000 | AC8: 0 | AD8: 1000 | AE8: 200 | AF8: 2000 | AG8: 16 | AH8: 50 | AI8: 2000 | AJ8: 4 | AK8: 1800 | AL8: 1575 | AM8: 1575 | AN8: 0 | AO8: 300 | AP8: 300 | AQ8: 300 | AR8: 6 | AS8: 100 | AT8: 20 | AU8: 1 | AV8: 7
A9: 0 | B9: 7 | C9: 5602 | D9: 0 | E9: 0.02 | F9: 0.5 | G9: 0 | H9: 378 | I9: 40 | J9: 60 | K9: 204 | L9: 4 | M9: -1 | N9: 13 | O9: 0.5 | P9: 0.82641298 | Q9: 50 | R9: 50 | S9: 50 | T9: 50 | U9: 1 | V9: 1 | W9: 16 | X9: 0 | Y9: 0 | Z9: 1000 | AA9: 0 | AB9: 1000 | AC9: 0 | AD9: 1000 | AE9: 210 | AF9: 2000 | AG9: 18 | AH9: 50 | AI9: 2000 | AJ9: 4 | AK9: 1800 | AL9: 1575 | AM9: 1575 | AN9: 0 | AO9: 300 | AP9: 300 | AQ9: 300 | AR9: 6 | AS9: 100 | AT9: 20 | AU9: 1 | AV9: 7
A10: 0 | B10: 8 | C10: 7204 | D10: 0 | E10: 0.02 | F10: 0.5 | G10: 0 | H10: 436 | I10: 40 | J10: 60 | K10: 206 | L10: 4 | M10: -1 | N10: 15 | O10: 0.5 | P10: 0.82736897 | Q10: 50 | R10: 50 | S10: 50 | T10: 50 | U10: 1 | V10: 1 | W10: 16 | X10: 0 | Y10: 0 | Z10: 1000 | AA10: 0 | AB10: 1000 | AC10: 0 | AD10: 1000 | AE10: 250 | AF10: 2000 | AG10: 18 | AH10: 50 | AI10: 2000 | AJ10: 4 | AK10: 1800 | AL10: 1575 | AM10: 1575 | AN10: 0 | AO10: 300 | AP10: 300 | AQ10: 300 | AR10: 6 | AS10: 100 | AT10: 20 | AU10: 1 | AV10: 7
A11: 0 | B11: 9 | C11: 9008 | D11: 0 | E11: 0.02 | F11: 0.5 | G11: 0 | H11: 516 | I11: 40 | J11: 60 | K11: 208 | L11: 4 | M11: -1 | N11: 19 | O11: 0.5 | P11: 0.81169301 | Q11: 50 | R11: 50 | S11: 50 | T11: 50 | U11: 1 | V11: 1 | W11: 16 | X11: 0 | Y11: 0 | Z11: 1000 | AA11: 0 | AB11: 1000 | AC11: 0 | AD11: 1000 | AE11: 280 | AF11: 2000 | AG11: 20 | AH11: 50 | AI11: 2000 | AJ11: 4 | AK11: 1800 | AL11: 1575 | AM11: 1575 | AN11: 0 | AO11: 300 | AP11: 300 | AQ11: 300 | AR11: 6 | AS11: 100 | AT11: 20 | AU11: 1 | AV11: 7
A12: 0 | B12: 10 | C12: 11014 | D12: 0 | E12: 0.02 | F12: 0.5 | G12: 0 | H12: 591 | I12: 40 | J12: 60 | K12: 225 | L12: 5 | M12: -1 | N12: 23 | O12: 0.5 | P12: 0.80024397 | Q12: 50 | R12: 50 | S12: 50 | T12: 50 | U12: 1 | V12: 1 | W12: 16 | X12: 0 | Y12: 0 | Z12: 1000 | AA12: 0 | AB12: 1000 | AC12: 0 | AD12: 1000 | AE12: 310 | AF12: 2000 | AG12: 20 | AH12: 50 | AI12: 2000 | AJ12: 4 | AK12: 1800 | AL12: 1575 | AM12: 1575 | AN12: 0 | AO12: 300 | AP12: 300 | AQ12: 300 | AR12: 6 | AS12: 100 | AT12: 20 | AU12: 1 | AV12: 7
A13: 0 | B13: 11 | C13: 13223 | D13: 0 | E13: 0.02 | F13: 0.5 | G13: 0 | H13: 683 | I13: 40 | J13: 60 | K13: 227 | L13: 5 | M13: -1 | N13: 29 | O13: 0.5 | P13: 0.77839798 | Q13: 50 | R13: 50 | S13: 50 | T13: 50 | U13: 1 | V13: 1 | W13: 16 | X13: 0 | Y13: 0 | Z13: 1000 | AA13: 0 | AB13: 1000 | AC13: 0 | AD13: 1000 | AE13: 330 | AF13: 2000 | AG13: 22 | AH13: 50 | AI13: 2000 | AJ13: 4 | AK13: 1800 | AL13: 1575 | AM13: 1575 | AN13: 0 | AO13: 300 | AP13: 300 | AQ13: 300 | AR13: 6 | AS13: 100 | AT13: 20 | AU13: 1 | AV13: 7
A14: 0 | B14: 12 | C14: 15638 | D14: 0 | E14: 0.02 | F14: 0.5 | G14: 0 | H14: 771 | I14: 40 | J14: 60 | K14: 229 | L14: 6 | M14: -1 | N14: 36 | O14: 0.5 | P14: 0.75383902 | Q14: 50 | R14: 50 | S14: 50 | T14: 50 | U14: 1 | V14: 1 | W14: 16 | X14: 0 | Y14: 0 | Z14: 1000 | AA14: 0 | AB14: 1000 | AC14: 0 | AD14: 1000 | AE14: 400 | AF14: 2000 | AG14: 22 | AH14: 50 | AI14: 2000 | AJ14: 4 | AK14: 1800 | AL14: 1575 | AM14: 1575 | AN14: 0 | AO14: 300 | AP14: 300 | AQ14: 300 | AR14: 6 | AS14: 100 | AT14: 20 | AU14: 1 | AV14: 7
... A77: 0 | B77: 75 | C77: 7.0006654e+17 | D77: 134 | E77: 0.02 | F77: 0.30000001 | G77: 0 | H77: 80000 | I77: 40 | J77: 60 | K77: 255 | L77: 99 | M77: -1 | N77: 5129 | O77: 0.5 | P77: 0.041453 | Q77: 50 | R77: 50 | S77: 50 | T77: 50 | U77: 1 | V77: 1 | W77: 16 | X77: 0 | Y77: 0 | Z77: 1000 | AA77: 0 | AB77: 1000 | AC77: 0 | AD77: 1000 | AE77: 60000 | AF77: 2000 | AG77: 74 | AH77: 50 | AI77: 2000 | AJ77: 4 | AK77: 1500 | AL77: 1575 | AM77: 1575 | AN77: 0 | AO77: 300 | AP77: 300 | AQ77: 300 | AR77: 6 | AS77: 100 | AT77: 20 | AU77: 1 | AV77: 7

Sheet SPai
A1: string[64] | B1: dword | C1: qword | D1: dword | E1: float | F1: float | G1: dword | H1: dword | I1: dword | J1: dword | K1: dword | L1: dword | M1: float | N1: dword | O1: float | P1: float | Q1: dword | R1: dword | S1: dword | T1: dword | U1: dword | V1: dword | W1: dword | X1: string[64] | Y1: dword | Z1: dword | AA1: string[64] | AB1: dword | AC1: string[64] | AD1: dword | AE1: dword | AF1: dword | AG1: dword | AH1: dword | AI1: dword | AJ1: dword | AK1: dword | AL1: dword | AM1: dword | AN1: dword | AO1: dword | AP1: dword | AQ1: dword | AR1: dword | AS1: dword | AT1: dword | AU1: dword | AV1: dword | AW1: END
A2: Code | B2: Level | C2: NeedExp | D2: UseFP | E2: Penalty | F2: AttGap | G2: Attack_DP | H2: AttFcStd | I2: MinAfSelProb | J2: MaxAFSelProb | K2: AttSklUnit | L2: DefSklUnit | M2: WeakPart | N2: StdDefFc | O2: DefGap | P2: DefFacing | Q2: fire | R2: water | S2: soil | T2: wind | U2: ForceLv | V2: ForceMast | W2: ForceAttStd | X2: AttTechID1 | Y2: AttTech1Prob | Z2: AttTech1MotionTime | AA2: PSecTechID | AB2: PSecTechMotionTime | AC2: MSecTechID | AD2: MSeacTechMotionTime | AE2: MaxHP | AF2: HPRecDelay | AG2: HPRecUnit | AH2: MaxFP | AI2: FPRecDelay | AJ2: FPRecUnit | AK2: AttSpd | AL2: AttMoTime1 | AM2: AttMoTime2 | AN2: CrtMoTime | AO2: ViewExt | AP2: RefExt | AQ2: AttExt | AR2: MovSpd | AS2: ScaleRate | AT2: Width | AU2: AttEffType | AV2: DefEffType
A3: 0 | B3: 1 | C3: 200 | D3: 0 | E3: 0.02 | F3: 1 | G3: 0 | H3: 34 | I3: 30 | J3: 50 | K3: 135 | L3: 1 | M3: -1 | N3: 14 | O3: 0.69999999 | P3: 0.078273997 | Q3: 0 | R3: 0 | S3: 0 | T3: 0 | U3: 1 | V3: 1 | W3: 16 | X3: 0 | Y3: 0 | Z3: 1000 | AA3: 0 | AB3: 1000 | AC3: 0 | AD3: 1000 | AE3: 28 | AF3: 2000 | AG3: 5 | AH3: 50 | AI3: 2000 | AJ3: 4 | AK3: 2000 | AL3: 1575 | AM3: 1575 | AN3: 0 | AO3: 340 | AP3: 340 | AQ3: 45 | AR3: 6 | AS3: 60 | AT3: 20 | AU3: 1 | AV3: 512
A4: 0 | B4: 2 | C4: 600 | D4: 0 | E4: 0.02 | F4: 1 | G4: 0 | H4: 35 | I4: 30 | J4: 50 | K4: 137 | L4: 1 | M4: -1 | N4: 21 | O4: 0.69999999 | P4: 0.079306997 | Q4: 0 | R4: 0 | S4: 0 | T4: 0 | U4: 1 | V4: 1 | W4: 16 | X4: 0 | Y4: 0 | Z4: 1000 | AA4: 0 | AB4: 1000 | AC4: 0 | AD4: 1000 | AE4: 36 | AF4: 2000 | AG4: 5 | AH4: 50 | AI4: 2000 | AJ4: 4 | AK4: 2000 | AL4: 1575 | AM4: 1575 | AN4: 0 | AO4: 340 | AP4: 340 | AQ4: 45 | AR4: 6 | AS4: 61 | AT4: 20 | AU4: 1 | AV4: 512
A5: 0 | B5: 3 | C5: 1200 | D5: 0 | E5: 0.02 | F5: 1 | G5: 0 | H5: 37 | I5: 30 | J5: 50 | K5: 139 | L5: 1 | M5: -1 | N5: 23 | O5: 0.69999999 | P5: 0.082814001 | Q5: 0 | R5: 0 | S5: 0 | T5: 0 | U5: 1 | V5: 1 | W5: 16 | X5: 0 | Y5: 0 | Z5: 1000 | AA5: 0 | AB5: 1000 | AC5: 0 | AD5: 1000 | AE5: 48 | AF5: 2000 | AG5: 6 | AH5: 50 | AI5: 2000 | AJ5: 4 | AK5: 2000 | AL5: 1575 | AM5: 1575 | AN5: 0 | AO5: 340 | AP5: 340 | AQ5: 45 | AR5: 6 | AS5: 62 | AT5: 20 | AU5: 1 | AV5: 512
A6: 0 | B6: 4 | C6: 2000 | D6: 0 | E6: 0.02 | F6: 1 | G6: 0 | H6: 42 | I6: 30 | J6: 50 | K6: 141 | L6: 1 | M6: -1 | N6: 23 | O6: 0.69999999 | P6: 0.082640998 | Q6: 0 | R6: 0 | S6: 0 | T6: 0 | U6: 1 | V6: 1 | W6: 16 | X6: 0 | Y6: 0 | Z6: 1000 | AA6: 0 | AB6: 1000 | AC6: 0 | AD6: 1000 | AE6: 52 | AF6: 2000 | AG6: 6 | AH6: 50 | AI6: 2000 | AJ6: 4 | AK6: 2000 | AL6: 1575 | AM6: 1575 | AN6: 0 | AO6: 340 | AP6: 340 | AQ6: 45 | AR6: 6 | AS6: 63 | AT6: 20 | AU6: 1 | AV6: 512
A7: 0 | B7: 5 | C7: 3000 | D7: 0 | E7: 0.02 | F7: 1 | G7: 0 | H7: 50 | I7: 30 | J7: 50 | K7: 160 | L7: 1 | M7: -1 | N7: 28 | O7: 0.69999999 | P7: 0.082736999 | Q7: 0 | R7: 0 | S7: 0 | T7: 0 | U7: 1 | V7: 1 | W7: 16 | X7: 0 | Y7: 0 | Z7: 1000 | AA7: 0 | AB7: 1000 | AC7: 0 | AD7: 1000 | AE7: 68 | AF7: 2000 | AG7: 6 | AH7: 50 | AI7: 2000 | AJ7: 4 | AK7: 2000 | AL7: 1575 | AM7: 1575 | AN7: 0 | AO7: 340 | AP7: 340 | AQ7: 45 | AR7: 6 | AS7: 64 | AT7: 20 | AU7: 1 | AV7: 512
A8: 0 | B8: 6 | C8: 4201 | D8: 0 | E8: 0.02 | F8: 1 | G8: 0 | H8: 53 | I8: 30 | J8: 50 | K8: 162 | L8: 1 | M8: -1 | N8: 31 | O8: 0.69999999 | P8: 0.081169002 | Q8: 0 | R8: 0 | S8: 0 | T8: 0 | U8: 1 | V8: 1 | W8: 16 | X8: 0 | Y8: 0 | Z8: 1000 | AA8: 0 | AB8: 1000 | AC8: 0 | AD8: 1000 | AE8: 80 | AF8: 2000 | AG8: 6 | AH8: 50 | AI8: 2000 | AJ8: 4 | AK8: 2000 | AL8: 1575 | AM8: 1575 | AN8: 0 | AO8: 340 | AP8: 340 | AQ8: 45 | AR8: 6 | AS8: 66 | AT8: 20 | AU8: 1 | AV8: 512
A9: 0 | B9: 7 | C9: 5602 | D9: 0 | E9: 0.02 | F9: 1 | G9: 0 | H9: 59 | I9: 30 | J9: 50 | K9: 164 | L9: 1 | M9: -1 | N9: 35 | O9: 0.69999999 | P9: 0.080023997 | Q9: 0 | R9: 0 | S9: 0 | T9: 0 | U9: 1 | V9: 1 | W9: 16 | X9: 0 | Y9: 0 | Z9: 1000 | AA9: 0 | AB9: 1000 | AC9: 0 | AD9: 1000 | AE9: 84 | AF9: 2000 | AG9: 7 | AH9: 50 | AI9: 2000 | AJ9: 4 | AK9: 2000 | AL9: 1575 | AM9: 1575 | AN9: 0 | AO9: 340 | AP9: 340 | AQ9: 45 | AR9: 6 | AS9: 67 | AT9: 20 | AU9: 1 | AV9: 512
A10: 0 | B10: 8 | C10: 7204 | D10: 0 | E10: 0.02 | F10: 1 | G10: 0 | H10: 66 | I10: 30 | J10: 50 | K10: 166 | L10: 1 | M10: -1 | N10: 43 | O10: 0.69999999 | P10: 0.07784 | Q10: 0 | R10: 0 | S10: 0 | T10: 0 | U10: 1 | V10: 1 | W10: 16 | X10: 0 | Y10: 0 | Z10: 1000 | AA10: 0 | AB10: 1000 | AC10: 0 | AD10: 1000 | AE10: 100 | AF10: 2000 | AG10: 7 | AH10: 50 | AI10: 2000 | AJ10: 4 | AK10: 2000 | AL10: 1575 | AM10: 1575 | AN10: 0 | AO10: 340 | AP10: 340 | AQ10: 45 | AR10: 6 | AS10: 68 | AT10: 20 | AU10: 1 | AV10: 512
A11: 0 | B11: 9 | C11: 9008 | D11: 0 | E11: 0.02 | F11: 1 | G11: 0 | H11: 76 | I11: 30 | J11: 50 | K11: 168 | L11: 1 | M11: -1 | N11: 50 | O11: 0.69999999 | P11: 0.075383998 | Q11: 0 | R11: 0 | S11: 0 | T11: 0 | U11: 1 | V11: 1 | W11: 16 | X11: 0 | Y11: 0 | Z11: 1000 | AA11: 0 | AB11: 1000 | AC11: 0 | AD11: 1000 | AE11: 112 | AF11: 2000 | AG11: 8 | AH11: 50 | AI11: 2000 | AJ11: 4 | AK11: 2000 | AL11: 1575 | AM11: 1575 | AN11: 0 | AO11: 340 | AP11: 340 | AQ11: 45 | AR11: 6 | AS11: 69 | AT11: 20 | AU11: 1 | AV11: 512
A12: 0 | B12: 10 | C12: 11014 | D12: 0 | E12: 0.02 | F12: 1 | G12: 0 | H12: 86 | I12: 30 | J12: 50 | K12: 185 | L12: 1 | M12: -1 | N12: 61 | O12: 0.69999999 | P12: 0.073120996 | Q12: 0 | R12: 0 | S12: 0 | T12: 0 | U12: 1 | V12: 1 | W12: 16 | X12: 0 | Y12: 0 | Z12: 1000 | AA12: 0 | AB12: 1000 | AC12: 0 | AD12: 1000 | AE12: 124 | AF12: 2000 | AG12: 8 | AH12: 50 | AI12: 2000 | AJ12: 4 | AK12: 2000 | AL12: 1575 | AM12: 1575 | AN12: 0 | AO12: 340 | AP12: 340 | AQ12: 45 | AR12: 6 | AS12: 70 | AT12: 20 | AU12: 1 | AV12: 512
A13: 0 | B13: 11 | C13: 13223 | D13: 0 | E13: 0.02 | F13: 1 | G13: 0 | H13: 97 | I13: 30 | J13: 50 | K13: 187 | L13: 1 | M13: -1 | N13: 70 | O13: 0.69999999 | P13: 0.070991002 | Q13: 0 | R13: 0 | S13: 0 | T13: 0 | U13: 1 | V13: 1 | W13: 16 | X13: 0 | Y13: 0 | Z13: 1000 | AA13: 0 | AB13: 1000 | AC13: 0 | AD13: 1000 | AE13: 132 | AF13: 2000 | AG13: 9 | AH13: 50 | AI13: 2000 | AJ13: 4 | AK13: 2000 | AL13: 1575 | AM13: 1575 | AN13: 0 | AO13: 340 | AP13: 340 | AQ13: 45 | AR13: 6 | AS13: 72 | AT13: 20 | AU13: 1 | AV13: 512
A14: 0 | B14: 12 | C14: 15638 | D14: 0 | E14: 0.02 | F14: 1 | G14: 0 | H14: 108 | I14: 30 | J14: 50 | K14: 189 | L14: 1 | M14: -1 | N14: 84 | O14: 0.69999999 | P14: 0.069271997 | Q14: 0 | R14: 0 | S14: 0 | T14: 0 | U14: 1 | V14: 1 | W14: 16 | X14: 0 | Y14: 0 | Z14: 1000 | AA14: 0 | AB14: 1000 | AC14: 0 | AD14: 1000 | AE14: 160 | AF14: 2000 | AG14: 9 | AH14: 50 | AI14: 2000 | AJ14: 4 | AK14: 2000 | AL14: 1575 | AM14: 1575 | AN14: 0 | AO14: 340 | AP14: 340 | AQ14: 45 | AR14: 6 | AS14: 73 | AT14: 20 | AU14: 1 | AV14: 512
... A77: 0 | B77: 75 | C77: 7.0665409e+15 | D77: 134 | E77: 0.02 | F77: 1 | G77: 0 | H77: 13152 | I77: 30 | J77: 50 | K77: 255 | L77: 1 | M77: -1 | N77: 80000 | O77: 0.69999999 | P77: 0.0035610001 | Q77: 0 | R77: 0 | S77: 0 | T77: 0 | U77: 1 | V77: 1 | W77: 16 | X77: 0 | Y77: 0 | Z77: 1000 | AA77: 0 | AB77: 1000 | AC77: 0 | AD77: 1000 | AE77: 60000 | AF77: 2000 | AG77: 111 | AH77: 50 | AI77: 2000 | AJ77: 4 | AK77: 2000 | AL77: 1575 | AM77: 1575 | AN77: 0 | AO77: 340 | AP77: 340 | AQ77: 45 | AR77: 6 | AS77: 133 | AT77: 20 | AU77: 1 | AV77: 512

Sheet SHec
A1: string[64] | B1: dword | C1: qword | D1: dword | E1: float | F1: float | G1: dword | H1: dword | I1: dword | J1: dword | K1: dword | L1: dword | M1: float | N1: dword | O1: float | P1: float | Q1: dword | R1: dword | S1: dword | T1: dword | U1: dword | V1: dword | W1: dword | X1: string[64] | Y1: dword | Z1: dword | AA1: string[64] | AB1: dword | AC1: string[64] | AD1: dword | AE1: dword | AF1: dword | AG1: dword | AH1: dword | AI1: dword | AJ1: dword | AK1: dword | AL1: dword | AM1: dword | AN1: dword | AO1: dword | AP1: dword | AQ1: dword | AR1: dword | AS1: dword | AT1: dword | AU1: dword | AV1: dword | AW1: END
A2: Code | B2: Level | C2: NeedExp | D2: UseFP | E2: Penalty | F2: AttGap | G2: Attack_DP | H2: AttFcStd | I2: MinAfSelProb | J2: MaxAFSelProb | K2: AttSklUnit | L2: DefSklUnit | M2: WeakPart | N2: StdDefFc | O2: DefGap | P2: DefFacing | Q2: fire | R2: water | S2: soil | T2: wind | U2: ForceLv | V2: ForceMast | W2: ForceAttStd | X2: AttTechID1 | Y2: AttTech1Prob | Z2: AttTech1MotionTime | AA2: PSecTechID | AB2: PSecTechMotionTime | AC2: MSecTechID | AD2: MSeacTechMotionTime | AE2: MaxHP | AF2: HPRecDelay | AG2: HPRecUnit | AH2: MaxFP | AI2: FPRecDelay | AJ2: FPRecUnit | AK2: AttSpd | AL2: AttMoTime1 | AM2: AttMoTime2 | AN2: CrtMoTime | AO2: ViewExt | AP2: RefExt | AQ2: AttExt | AR2: MovSpd | AS2: ScaleRate | AT2: Width | AU2: AttEffType | AV2: DefEffType
A3: 0 | B3: 1 | C3: 200 | D3: 0 | E3: 0.02 | F3: 1 | G3: 0 | H3: 60 | I3: 37 | J3: 50 | K3: 95 | L3: 3 | M3: -1 | N3: 10 | O3: 0.57499999 | P3: 0.74255002 | Q3: 10 | R3: 10 | S3: 10 | T3: 10 | U3: 1 | V3: 1 | W3: 16 | X3: 0 | Y3: 0 | Z3: 1000 | AA3: 0 | AB3: 1000 | AC3: 0 | AD3: 1000 | AE3: 70 | AF3: 2000 | AG3: 12 | AH3: 50 | AI3: 2000 | AJ3: 4 | AK3: 900 | AL3: 900 | AM3: 900 | AN3: 0 | AO3: 340 | AP3: 340 | AQ3: 225 | AR3: 6 | AS3: 60 | AT3: 20 | AU3: 10 | AV3: 273
A4: 0 | B4: 2 | C4: 600 | D4: 0 | E4: 0.02 | F4: 1 | G4: 0 | H4: 70 | I4: 34 | J4: 45 | K4: 97 | L4: 3 | M4: -1 | N4: 12 | O4: 0.57499999 | P4: 0.79121798 | Q4: 10 | R4: 10 | S4: 10 | T4: 10 | U4: 1 | V4: 1 | W4: 16 | X4: 0 | Y4: 0 | Z4: 1000 | AA4: 0 | AB4: 1000 | AC4: 0 | AD4: 1000 | AE4: 90 | AF4: 2000 | AG4: 12 | AH4: 50 | AI4: 2000 | AJ4: 4 | AK4: 900 | AL4: 900 | AM4: 900 | AN4: 0 | AO4: 340 | AP4: 340 | AQ4: 225 | AR4: 6 | AS4: 60 | AT4: 20 | AU4: 10 | AV4: 273
A5: 0 | B5: 3 | C5: 1200 | D5: 0 | E5: 0.02 | F5: 1 | G5: 0 | H5: 84 | I5: 32 | J5: 43 | K5: 99 | L5: 3 | M5: -1 | N5: 16 | O5: 0.57499999 | P5: 0.773498 | Q5: 10 | R5: 10 | S5: 10 | T5: 10 | U5: 1 | V5: 1 | W5: 16 | X5: 0 | Y5: 0 | Z5: 1000 | AA5: 0 | AB5: 1000 | AC5: 0 | AD5: 1000 | AE5: 120 | AF5: 2000 | AG5: 14 | AH5: 50 | AI5: 2000 | AJ5: 4 | AK5: 900 | AL5: 900 | AM5: 900 | AN5: 0 | AO5: 340 | AP5: 340 | AQ5: 225 | AR5: 6 | AS5: 60 | AT5: 20 | AU5: 10 | AV5: 273
A6: 0 | B6: 4 | C6: 2000 | D6: 0 | E6: 0.02 | F6: 1 | G6: 0 | H6: 101 | I6: 30 | J6: 41 | K6: 101 | L6: 6 | M6: -1 | N6: 18 | O6: 0.57499999 | P6: 0.80910701 | Q6: 10 | R6: 10 | S6: 10 | T6: 10 | U6: 1 | V6: 1 | W6: 16 | X6: 0 | Y6: 0 | Z6: 1000 | AA6: 0 | AB6: 1000 | AC6: 0 | AD6: 1000 | AE6: 130 | AF6: 2000 | AG6: 14 | AH6: 50 | AI6: 2000 | AJ6: 4 | AK6: 900 | AL6: 900 | AM6: 900 | AN6: 0 | AO6: 340 | AP6: 340 | AQ6: 225 | AR6: 6 | AS6: 60 | AT6: 20 | AU6: 10 | AV6: 273
A7: 0 | B7: 5 | C7: 3000 | D7: 0 | E7: 0.02 | F7: 1 | G7: 0 | H7: 122 | I7: 30 | J7: 40 | K7: 120 | L7: 9 | M7: -1 | N7: 22 | O7: 0.57499999 | P7: 0.81847501 | Q7: 10 | R7: 10 | S7: 10 | T7: 10 | U7: 1 | V7: 1 | W7: 16 | X7: 0 | Y7: 0 | Z7: 1000 | AA7: 0 | AB7: 1000 | AC7: 0 | AD7: 1000 | AE7: 170 | AF7: 2000 | AG7: 16 | AH7: 50 | AI7: 2000 | AJ7: 4 | AK7: 900 | AL7: 900 | AM7: 900 | AN7: 0 | AO7: 340 | AP7: 340 | AQ7: 225 | AR7: 6 | AS7: 60 | AT7: 20 | AU7: 10 | AV7: 273
A8: 0 | B8: 6 | C8: 4201 | D8: 0 | E8: 0.02 | F8: 1 | G8: 0 | H8: 137 | I8: 29 | J8: 38 | K8: 122 | L8: 9 | M8: -1 | N8: 22 | O8: 0.57499999 | P8: 0.85005099 | Q8: 10 | R8: 10 | S8: 10 | T8: 10 | U8: 1 | V8: 1 | W8: 16 | X8: 0 | Y8: 0 | Z8: 1000 | AA8: 0 | AB8: 1000 | AC8: 0 | AD8: 1000 | AE8: 200 | AF8: 2000 | AG8: 16 | AH8: 50 | AI8: 2000 | AJ8: 4 | AK8: 900 | AL8: 900 | AM8: 900 | AN8: 0 | AO8: 340 | AP8: 340 | AQ8: 225 | AR8: 6 | AS8: 60 | AT8: 20 | AU8: 10 | AV8: 273
A9: 0 | B9: 7 | C9: 5602 | D9: 0 | E9: 0.02 | F9: 1 | G9: 0 | H9: 156 | I9: 28 | J9: 38 | K9: 124 | L9: 12 | M9: -1 | N9: 26 | O9: 0.57499999 | P9: 0.84850597 | Q9: 10 | R9: 10 | S9: 10 | T9: 10 | U9: 1 | V9: 1 | W9: 16 | X9: 0 | Y9: 0 | Z9: 1000 | AA9: 0 | AB9: 1000 | AC9: 0 | AD9: 1000 | AE9: 210 | AF9: 2000 | AG9: 18 | AH9: 50 | AI9: 2000 | AJ9: 4 | AK9: 900 | AL9: 900 | AM9: 900 | AN9: 0 | AO9: 340 | AP9: 340 | AQ9: 225 | AR9: 6 | AS9: 60 | AT9: 20 | AU9: 10 | AV9: 273
A10: 0 | B10: 8 | C10: 7204 | D10: 0 | E10: 0.02 | F10: 1 | G10: 0 | H10: 176 | I10: 28 | J10: 37 | K10: 126 | L10: 12 | M10: -1 | N10: 30 | O10: 0.57499999 | P10: 0.84936303 | Q10: 10 | R10: 10 | S10: 10 | T10: 10 | U10: 1 | V10: 1 | W10: 16 | X10: 0 | Y10: 0 | Z10: 1000 | AA10: 0 | AB10: 1000 | AC10: 0 | AD10: 1000 | AE10: 250 | AF10: 2000 | AG10: 18 | AH10: 50 | AI10: 2000 | AJ10: 4 | AK10: 900 | AL10: 900 | AM10: 900 | AN10: 0 | AO10: 340 | AP10: 340 | AQ10: 225 | AR10: 6 | AS10: 60 | AT10: 20 | AU10: 10 | AV10: 273
A11: 0 | B11: 9 | C11: 9008 | D11: 0 | E11: 0.02 | F11: 1 | G11: 0 | H11: 201 | I11: 27 | J11: 36 | K11: 128 | L11: 12 | M11: -1 | N11: 38 | O11: 0.57499999 | P11: 0.83528602 | Q11: 10 | R11: 10 | S11: 10 | T11: 10 | U11: 1 | V11: 1 | W11: 16 | X11: 0 | Y11: 0 | Z11: 1000 | AA11: 0 | AB11: 1000 | AC11: 0 | AD11: 1000 | AE11: 280 | AF11: 2000 | AG11: 20 | AH11: 50 | AI11: 2000 | AJ11: 4 | AK11: 900 | AL11: 900 | AM11: 900 | AN11: 0 | AO11: 340 | AP11: 340 | AQ11: 225 | AR11: 6 | AS11: 60 | AT11: 20 | AU11: 10 | AV11: 273
A12: 0 | B12: 10 | C12: 11014 | D12: 0 | E12: 0.02 | F12: 1 | G12: 0 | H12: 225 | I12: 27 | J12: 36 | K12: 145 | L12: 15 | M12: -1 | N12: 46 | O12: 0.57499999 | P12: 0.82496297 | Q12: 10 | R12: 10 | S12: 10 | T12: 10 | U12: 1 | V12: 1 | W12: 16 | X12: 0 | Y12: 0 | Z12: 1000 | AA12: 0 | AB12: 1000 | AC12: 0 | AD12: 1000 | AE12: 310 | AF12: 2000 | AG12: 20 | AH12: 50 | AI12: 2000 | AJ12: 4 | AK12: 900 | AL12: 900 | AM12: 900 | AN12: 0 | AO12: 340 | AP12: 340 | AQ12: 225 | AR12: 6 | AS12: 60 | AT12: 20 | AU12: 10 | AV12: 273
A13: 0 | B13: 11 | C13: 13223 | D13: 0 | E13: 0.02 | F13: 1 | G13: 0 | H13: 251 | I13: 26 | J13: 35 | K13: 147 | L13: 15 | M13: -1 | N13: 58 | O13: 0.57499999 | P13: 0.80516201 | Q13: 10 | R13: 10 | S13: 10 | T13: 10 | U13: 1 | V13: 1 | W13: 16 | X13: 0 | Y13: 0 | Z13: 1000 | AA13: 0 | AB13: 1000 | AC13: 0 | AD13: 1000 | AE13: 330 | AF13: 2000 | AG13: 22 | AH13: 50 | AI13: 2000 | AJ13: 4 | AK13: 900 | AL13: 900 | AM13: 900 | AN13: 0 | AO13: 340 | AP13: 340 | AQ13: 225 | AR13: 6 | AS13: 60 | AT13: 20 | AU13: 10 | AV13: 273
A14: 0 | B14: 12 | C14: 15638 | D14: 0 | E14: 0.02 | F14: 1 | G14: 0 | H14: 277 | I14: 26 | J14: 35 | K14: 149 | L14: 18 | M14: -1 | N14: 72 | O14: 0.57499999 | P14: 0.78274101 | Q14: 10 | R14: 10 | S14: 10 | T14: 10 | U14: 1 | V14: 1 | W14: 16 | X14: 0 | Y14: 0 | Z14: 1000 | AA14: 0 | AB14: 1000 | AC14: 0 | AD14: 1000 | AE14: 400 | AF14: 2000 | AG14: 22 | AH14: 50 | AI14: 2000 | AJ14: 4 | AK14: 900 | AL14: 900 | AM14: 900 | AN14: 0 | AO14: 340 | AP14: 340 | AQ14: 225 | AR14: 6 | AS14: 60 | AT14: 20 | AU14: 10 | AV14: 273
... A77: 0 | B77: 75 | C77: 7.0006654e+17 | D77: 134 | E77: 0.02 | F77: 1 | G77: 0 | H77: 8538 | I77: 4 | J77: 6 | K77: 255 | L77: 743 | M77: -1 | N77: 7883 | O77: 0.57499999 | P77: 0.048413999 | Q77: 10 | R77: 10 | S77: 10 | T77: 10 | U77: 1 | V77: 1 | W77: 16 | X77: 0 | Y77: 0 | Z77: 1000 | AA77: 0 | AB77: 1000 | AC77: 0 | AD77: 1000 | AE77: 60000 | AF77: 2000 | AG77: 74 | AH77: 50 | AI77: 2000 | AJ77: 4 | AK77: 900 | AL77: 900 | AM77: 900 | AN77: 0 | AO77: 340 | AP77: 340 | AQ77: 230 | AR77: 6 | AS77: 60 | AT77: 20 | AU77: 10 | AV77: 273

Sheet SIna
A1: string[64] | B1: dword | C1: qword | D1: dword | E1: float | F1: float | G1: dword | H1: dword | I1: dword | J1: dword | K1: dword | L1: dword | M1: float | N1: dword | O1: float | P1: float | Q1: dword | R1: dword | S1: dword | T1: dword | U1: dword | V1: dword | W1: dword | X1: string[64] | Y1: dword | Z1: dword | AA1: string[64] | AB1: dword | AC1: string[64] | AD1: dword | AE1: dword | AF1: dword | AG1: dword | AH1: dword | AI1: dword | AJ1: dword | AK1: dword | AL1: dword | AM1: dword | AN1: dword | AO1: dword | AP1: dword | AQ1: dword | AR1: dword | AS1: dword | AT1: dword | AU1: dword | AV1: dword | AW1: END
A2: Code | B2: Level | C2: NeedExp | D2: UseFP | E2: Penalty | F2: AttGap | G2: Attack_DP | H2: AttFcStd | I2: MinAfSelProb | J2: MaxAFSelProb | K2: AttSklUnit | L2: DefSklUnit | M2: WeakPart | N2: StdDefFc | O2: DefGap | P2: DefFacing | Q2: fire | R2: water | S2: soil | T2: wind | U2: ForceLv | V2: ForceMast | W2: ForceAttStd | X2: AttTechID1 | Y2: AttTech1Prob | Z2: AttTech1MotionTime | AA2: PSecTechID | AB2: PSecTechMotionTime | AC2: MSecTechID | AD2: MSeacTechMotionTime | AE2: MaxHP | AF2: HPRecDelay | AG2: HPRecUnit | AH2: MaxFP | AI2: FPRecDelay | AJ2: FPRecUnit | AK2: AttSpd | AL2: AttMoTime1 | AM2: AttMoTime2 | AN2: CrtMoTime | AO2: ViewExt | AP2: RefExt | AQ2: AttExt | AR2: MovSpd | AS2: ScaleRate | AT2: Width | AU2: AttEffType | AV2: DefEffType
A3: 0 | B3: 1 | C3: 2160 | D3: 0 | E3: 0.02 | F3: 1 | G3: 0 | H3: 27 | I3: 50 | J3: 50 | K3: 1 | L3: 1 | M3: -1 | N3: 10 | O3: 0.57499999 | P3: 0.74255002 | Q3: 0 | R3: 0 | S3: 0 | T3: 0 | U3: 1 | V3: 1 | W3: 16 | X3: 0 | Y3: 0 | Z3: 1000 | AA3: 0 | AB3: 1000 | AC3: 0 | AD3: 1000 | AE3: 70 | AF3: 2000 | AG3: 12 | AH3: 50 | AI3: 2000 | AJ3: 4 | AK3: 1575 | AL3: 1575 | AM3: 1575 | AN3: 0 | AO3: 340 | AP3: 340 | AQ3: 225 | AR3: 6 | AS3: 42 | AT3: 20 | AU3: 0 | AV3: 1041
A4: 0 | B4: 2 | C4: 4752 | D4: 0 | E4: 0.02 | F4: 1 | G4: 0 | H4: 32 | I4: 50 | J4: 50 | K4: 1 | L4: 2 | M4: -1 | N4: 12 | O4: 0.57499999 | P4: 0.79121798 | Q4: 0 | R4: 0 | S4: 0 | T4: 0 | U4: 1 | V4: 1 | W4: 16 | X4: 0 | Y4: 0 | Z4: 1000 | AA4: 0 | AB4: 1000 | AC4: 0 | AD4: 1000 | AE4: 90 | AF4: 2000 | AG4: 12 | AH4: 50 | AI4: 2000 | AJ4: 4 | AK4: 1575 | AL4: 1575 | AM4: 1575 | AN4: 0 | AO4: 340 | AP4: 340 | AQ4: 225 | AR4: 6 | AS4: 42 | AT4: 20 | AU4: 0 | AV4: 1041
A5: 0 | B5: 3 | C5: 8682 | D5: 0 | E5: 0.02 | F5: 1 | G5: 0 | H5: 39 | I5: 50 | J5: 50 | K5: 1 | L5: 3 | M5: -1 | N5: 16 | O5: 0.57499999 | P5: 0.773498 | Q5: 0 | R5: 0 | S5: 0 | T5: 0 | U5: 1 | V5: 1 | W5: 16 | X5: 0 | Y5: 0 | Z5: 1000 | AA5: 0 | AB5: 1000 | AC5: 0 | AD5: 1000 | AE5: 120 | AF5: 2000 | AG5: 14 | AH5: 50 | AI5: 2000 | AJ5: 4 | AK5: 1575 | AL5: 1575 | AM5: 1575 | AN5: 0 | AO5: 340 | AP5: 340 | AQ5: 225 | AR5: 6 | AS5: 42 | AT5: 20 | AU5: 0 | AV5: 1041
A6: 0 | B6: 4 | C6: 14046 | D6: 0 | E6: 0.02 | F6: 1 | G6: 0 | H6: 45 | I6: 50 | J6: 50 | K6: 2 | L6: 4 | M6: -1 | N6: 18 | O6: 0.57499999 | P6: 0.80910701 | Q6: 0 | R6: 0 | S6: 0 | T6: 0 | U6: 1 | V6: 1 | W6: 16 | X6: 0 | Y6: 0 | Z6: 1000 | AA6: 0 | AB6: 1000 | AC6: 0 | AD6: 1000 | AE6: 130 | AF6: 2000 | AG6: 14 | AH6: 50 | AI6: 2000 | AJ6: 4 | AK6: 1575 | AL6: 1575 | AM6: 1575 | AN6: 0 | AO6: 340 | AP6: 340 | AQ6: 225 | AR6: 6 | AS6: 42 | AT6: 20 | AU6: 0 | AV6: 1041
A7: 0 | B7: 5 | C7: 21606 | D7: 0 | E7: 0.02 | F7: 1 | G7: 0 | H7: 54 | I7: 50 | J7: 50 | K7: 3 | L7: 10 | M7: -1 | N7: 22 | O7: 0.57499999 | P7: 0.81847501 | Q7: 0 | R7: 0 | S7: 0 | T7: 0 | U7: 1 | V7: 1 | W7: 16 | X7: 0 | Y7: 0 | Z7: 1000 | AA7: 0 | AB7: 1000 | AC7: 0 | AD7: 1000 | AE7: 170 | AF7: 2000 | AG7: 16 | AH7: 50 | AI7: 2000 | AJ7: 4 | AK7: 1575 | AL7: 1575 | AM7: 1575 | AN7: 0 | AO7: 340 | AP7: 340 | AQ7: 225 | AR7: 6 | AS7: 42 | AT7: 20 | AU7: 0 | AV7: 1041
A8: 0 | B8: 6 | C8: 31214 | D8: 0 | E8: 0.02 | F8: 1 | G8: 0 | H8: 60 | I8: 50 | J8: 50 | K8: 4 | L8: 11 | M8: -1 | N8: 22 | O8: 0.57499999 | P8: 0.85005099 | Q8: 0 | R8: 0 | S8: 0 | T8: 0 | U8: 1 | V8: 1 | W8: 16 | X8: 0 | Y8: 0 | Z8: 1000 | AA8: 0 | AB8: 1000 | AC8: 0 | AD8: 1000 | AE8: 200 | AF8: 2000 | AG8: 16 | AH8: 50 | AI8: 2000 | AJ8: 4 | AK8: 1575 | AL8: 1575 | AM8: 1575 | AN8: 0 | AO8: 340 | AP8: 340 | AQ8: 225 | AR8: 6 | AS8: 42 | AT8: 20 | AU8: 0 | AV8: 1041
A9: 0 | B9: 7 | C9: 43102 | D9: 0 | E9: 0.02 | F9: 1 | G9: 0 | H9: 66 | I9: 50 | J9: 50 | K9: 4 | L9: 12 | M9: -1 | N9: 26 | O9: 0.57499999 | P9: 0.84850597 | Q9: 0 | R9: 0 | S9: 0 | T9: 0 | U9: 1 | V9: 1 | W9: 16 | X9: 0 | Y9: 0 | Z9: 1000 | AA9: 0 | AB9: 1000 | AC9: 0 | AD9: 1000 | AE9: 210 | AF9: 2000 | AG9: 18 | AH9: 50 | AI9: 2000 | AJ9: 4 | AK9: 1575 | AL9: 1575 | AM9: 1575 | AN9: 0 | AO9: 340 | AP9: 340 | AQ9: 225 | AR9: 6 | AS9: 42 | AT9: 20 | AU9: 0 | AV9: 1041
A10: 0 | B10: 8 | C10: 58601 | D10: 0 | E10: 0.02 | F10: 1 | G10: 0 | H10: 77 | I10: 50 | J10: 50 | K10: 4 | L10: 13 | M10: -1 | N10: 30 | O10: 0.57499999 | P10: 0.84936303 | Q10: 0 | R10: 0 | S10: 0 | T10: 0 | U10: 1 | V10: 1 | W10: 16 | X10: 0 | Y10: 0 | Z10: 1000 | AA10: 0 | AB10: 1000 | AC10: 0 | AD10: 1000 | AE10: 250 | AF10: 2000 | AG10: 18 | AH10: 50 | AI10: 2000 | AJ10: 4 | AK10: 1575 | AL10: 1575 | AM10: 1575 | AN10: 0 | AO10: 340 | AP10: 340 | AQ10: 225 | AR10: 6 | AS10: 42 | AT10: 20 | AU10: 0 | AV10: 1041
A11: 0 | B11: 9 | C11: 77188 | D11: 0 | E11: 0.02 | F11: 1 | G11: 0 | H11: 84 | I11: 50 | J11: 50 | K11: 5 | L11: 14 | M11: -1 | N11: 38 | O11: 0.57499999 | P11: 0.83528602 | Q11: 0 | R11: 0 | S11: 0 | T11: 0 | U11: 1 | V11: 1 | W11: 16 | X11: 0 | Y11: 0 | Z11: 1000 | AA11: 0 | AB11: 1000 | AC11: 0 | AD11: 1000 | AE11: 280 | AF11: 2000 | AG11: 20 | AH11: 50 | AI11: 2000 | AJ11: 4 | AK11: 1575 | AL11: 1575 | AM11: 1575 | AN11: 0 | AO11: 340 | AP11: 340 | AQ11: 225 | AR11: 6 | AS11: 42 | AT11: 20 | AU11: 0 | AV11: 1041
A12: 0 | B12: 10 | C12: 100585 | D12: 0 | E12: 0.02 | F12: 1 | G12: 0 | H12: 97 | I12: 50 | J12: 50 | K12: 5 | L12: 20 | M12: -1 | N12: 46 | O12: 0.57499999 | P12: 0.82496297 | Q12: 0 | R12: 0 | S12: 0 | T12: 0 | U12: 1 | V12: 1 | W12: 16 | X12: 0 | Y12: 0 | Z12: 1000 | AA12: 0 | AB12: 1000 | AC12: 0 | AD12: 1000 | AE12: 310 | AF12: 2000 | AG12: 20 | AH12: 50 | AI12: 2000 | AJ12: 4 | AK12: 1575 | AL12: 1575 | AM12: 1575 | AN12: 0 | AO12: 340 | AP12: 340 | AQ12: 225 | AR12: 6 | AS12: 42 | AT12: 20 | AU12: 0 | AV12: 1041
A13: 0 | B13: 11 | C13: 127918 | D13: 0 | E13: 0.02 | F13: 1 | G13: 0 | H13: 105 | I13: 50 | J13: 50 | K13: 6 | L13: 21 | M13: -1 | N13: 58 | O13: 0.57499999 | P13: 0.80516201 | Q13: 0 | R13: 0 | S13: 0 | T13: 0 | U13: 1 | V13: 1 | W13: 16 | X13: 0 | Y13: 0 | Z13: 1000 | AA13: 0 | AB13: 1000 | AC13: 0 | AD13: 1000 | AE13: 330 | AF13: 2000 | AG13: 22 | AH13: 50 | AI13: 2000 | AJ13: 4 | AK13: 1575 | AL13: 1575 | AM13: 1575 | AN13: 0 | AO13: 340 | AP13: 340 | AQ13: 225 | AR13: 6 | AS13: 42 | AT13: 20 | AU13: 0 | AV13: 1041
A14: 0 | B14: 12 | C14: 161474 | D14: 0 | E14: 0.02 | F14: 1 | G14: 0 | H14: 119 | I14: 50 | J14: 50 | K14: 6 | L14: 22 | M14: -1 | N14: 72 | O14: 0.57499999 | P14: 0.78274101 | Q14: 0 | R14: 0 | S14: 0 | T14: 0 | U14: 1 | V14: 1 | W14: 16 | X14: 0 | Y14: 0 | Z14: 1000 | AA14: 0 | AB14: 1000 | AC14: 0 | AD14: 1000 | AE14: 400 | AF14: 2000 | AG14: 22 | AH14: 50 | AI14: 2000 | AJ14: 4 | AK14: 1575 | AL14: 1575 | AM14: 1575 | AN14: 0 | AO14: 340 | AP14: 340 | AQ14: 225 | AR14: 6 | AS14: 42 | AT14: 20 | AU14: 0 | AV14: 1041
... A77: 0 | B77: 75 | C77: 7.0665409e+15 | D77: 134 | E77: 0.02 | F77: 1 | G77: 0 | H77: 4500 | I77: 50 | J77: 50 | K77: 99 | L77: 150 | M77: -1 | N77: 7883 | O77: 0.57499999 | P77: 0.048413999 | Q77: 0 | R77: 0 | S77: 0 | T77: 0 | U77: 1 | V77: 1 | W77: 16 | X77: 0 | Y77: 0 | Z77: 1000 | AA77: 0 | AB77: 1000 | AC77: 0 | AD77: 1000 | AE77: 60000 | AF77: 2000 | AG77: 74 | AH77: 50 | AI77: 2000 | AJ77: 4 | AK77: 1400 | AL77: 1575 | AM77: 1575 | AN77: 0 | AO77: 340 | AP77: 340 | AQ77: 225 | AR77: 6 | AS77: 42 | AT77: 20 | AU77: 0 | AV77: 1041

Sheet SIsi
A1: string[64] | B1: dword | C1: qword | D1: dword | E1: float | F1: float | G1: dword | H1: dword | I1: dword | J1: dword | K1: dword | L1: dword | M1: float | N1: dword | O1: float | P1: float | Q1: dword | R1: dword | S1: dword | T1: dword | U1: dword | V1: dword | W1: dword | X1: string[64] | Y1: dword | Z1: dword | AA1: string[64] | AB1: dword | AC1: string[64] | AD1: dword | AE1: dword | AF1: dword | AG1: dword | AH1: dword | AI1: dword | AJ1: dword | AK1: dword | AL1: dword | AM1: dword | AN1: dword | AO1: dword | AP1: dword | AQ1: dword | AR1: dword | AS1: dword | AT1: dword | AU1: dword | AV1: dword | AW1: END
A2: Code | B2: Level | C2: NeedExp | D2: UseFP | E2: Penalty | F2: AttGap | G2: Attack_DP | H2: AttFcStd | I2: MinAfSelProb | J2: MaxAFSelProb | K2: AttSklUnit | L2: DefSklUnit | M2: WeakPart | N2: StdDefFc | O2: DefGap | P2: DefFacing | Q2: fire | R2: water | S2: soil | T2: wind | U2: ForceLv | V2: ForceMast | W2: ForceAttStd | X2: AttTechID1 | Y2: AttTech1Prob | Z2: AttTech1MotionTime | AA2: PSecTechID | AB2: PSecTechMotionTime | AC2: MSecTechID | AD2: MSeacTechMotionTime | AE2: MaxHP | AF2: HPRecDelay | AG2: HPRecUnit | AH2: MaxFP | AI2: FPRecDelay | AJ2: FPRecUnit | AK2: AttSpd | AL2: AttMoTime1 | AM2: AttMoTime2 | AN2: CrtMoTime | AO2: ViewExt | AP2: RefExt | AQ2: AttExt | AR2: MovSpd | AS2: ScaleRate | AT2: Width | AU2: AttEffType | AV2: DefEffType
A3: 0 | B3: 1 | C3: 200 | D3: 0 | E3: 0.02 | F3: 0.5 | G3: 0 | H3: 150 | I3: 40 | J3: 60 | K3: 175 | L3: 1 | M3: -1 | N3: 5 | O3: 0.5 | P3: 0.71028 | Q3: 50 | R3: 50 | S3: 50 | T3: 50 | U3: 1 | V3: 1 | W3: 16 | X3: 0 | Y3: 0 | Z3: 1000 | AA3: 0 | AB3: 1000 | AC3: 0 | AD3: 1000 | AE3: 70 | AF3: 2000 | AG3: 12 | AH3: 50 | AI3: 2000 | AJ3: 4 | AK3: 1800 | AL3: 1575 | AM3: 1575 | AN3: 0 | AO3: 300 | AP3: 300 | AQ3: 300 | AR3: 6 | AS3: 60 | AT3: 20 | AU3: 1 | AV3: 7
A4: 0 | B4: 2 | C4: 600 | D4: 0 | E4: 0.02 | F4: 0.5 | G4: 0 | H4: 172 | I4: 40 | J4: 60 | K4: 177 | L4: 1 | M4: -1 | N4: 6 | O4: 0.5 | P4: 0.76310301 | Q4: 50 | R4: 50 | S4: 50 | T4: 50 | U4: 1 | V4: 1 | W4: 16 | X4: 0 | Y4: 0 | Z4: 1000 | AA4: 0 | AB4: 1000 | AC4: 0 | AD4: 1000 | AE4: 90 | AF4: 2000 | AG4: 12 | AH4: 50 | AI4: 2000 | AJ4: 4 | AK4: 1800 | AL4: 1575 | AM4: 1575 | AN4: 0 | AO4: 300 | AP4: 300 | AQ4: 300 | AR4: 6 | AS4: 60 | AT4: 20 | AU4: 1 | AV4: 7
A5: 0 | B5: 3 | C5: 1200 | D5: 0 | E5: 0.02 | F5: 0.5 | G5: 0 | H5: 199 | I5: 40 | J5: 60 | K5: 179 | L5: 1 | M5: -1 | N5: 8 | O5: 0.5 | P5: 0.74376899 | Q5: 50 | R5: 50 | S5: 50 | T5: 50 | U5: 1 | V5: 1 | W5: 16 | X5: 0 | Y5: 0 | Z5: 1000 | AA5: 0 | AB5: 1000 | AC5: 0 | AD5: 1000 | AE5: 120 | AF5: 2000 | AG5: 14 | AH5: 50 | AI5: 2000 | AJ5: 4 | AK5: 1800 | AL5: 1575 | AM5: 1575 | AN5: 0 | AO5: 300 | AP5: 300 | AQ5: 300 | AR5: 6 | AS5: 60 | AT5: 20 | AU5: 1 | AV5: 7
A6: 0 | B6: 4 | C6: 2000 | D6: 0 | E6: 0.02 | F6: 0.5 | G6: 0 | H6: 241 | I6: 40 | J6: 60 | K6: 181 | L6: 2 | M6: -1 | N6: 9 | O6: 0.5 | P6: 0.78273898 | Q6: 50 | R6: 50 | S6: 50 | T6: 50 | U6: 1 | V6: 1 | W6: 16 | X6: 0 | Y6: 0 | Z6: 1000 | AA6: 0 | AB6: 1000 | AC6: 0 | AD6: 1000 | AE6: 130 | AF6: 2000 | AG6: 14 | AH6: 50 | AI6: 2000 | AJ6: 4 | AK6: 1800 | AL6: 1575 | AM6: 1575 | AN6: 0 | AO6: 300 | AP6: 300 | AQ6: 300 | AR6: 6 | AS6: 60 | AT6: 20 | AU6: 1 | AV6: 7
A7: 0 | B7: 5 | C7: 3000 | D7: 0 | E7: 0.02 | F7: 0.5 | G7: 0 | H7: 298 | I7: 40 | J7: 60 | K7: 200 | L7: 3 | M7: -1 | N7: 11 | O7: 0.5 | P7: 0.79307002 | Q7: 50 | R7: 50 | S7: 50 | T7: 50 | U7: 1 | V7: 1 | W7: 16 | X7: 0 | Y7: 0 | Z7: 1000 | AA7: 0 | AB7: 1000 | AC7: 0 | AD7: 1000 | AE7: 170 | AF7: 2000 | AG7: 16 | AH7: 50 | AI7: 2000 | AJ7: 4 | AK7: 1800 | AL7: 1575 | AM7: 1575 | AN7: 0 | AO7: 300 | AP7: 300 | AQ7: 300 | AR7: 6 | AS7: 60 | AT7: 20 | AU7: 1 | AV7: 7
A8: 0 | B8: 6 | C8: 4201 | D8: 0 | E8: 0.02 | F8: 0.5 | G8: 0 | H8: 328 | I8: 40 | J8: 60 | K8: 202 | L8: 3 | M8: -1 | N8: 11 | O8: 0.5 | P8: 0.82813698 | Q8: 50 | R8: 50 | S8: 50 | T8: 50 | U8: 1 | V8: 1 | W8: 16 | X8: 0 | Y8: 0 | Z8: 1000 | AA8: 0 | AB8: 1000 | AC8: 0 | AD8: 1000 | AE8: 200 | AF8: 2000 | AG8: 16 | AH8: 50 | AI8: 2000 | AJ8: 4 | AK8: 1800 | AL8: 1575 | AM8: 1575 | AN8: 0 | AO8: 300 | AP8: 300 | AQ8: 300 | AR8: 6 | AS8: 60 | AT8: 20 | AU8: 1 | AV8: 7
A9: 0 | B9: 7 | C9: 5602 | D9: 0 | E9: 0.02 | F9: 0.5 | G9: 0 | H9: 378 | I9: 40 | J9: 60 | K9: 204 | L9: 4 | M9: -1 | N9: 13 | O9: 0.5 | P9: 0.82641298 | Q9: 50 | R9: 50 | S9: 50 | T9: 50 | U9: 1 | V9: 1 | W9: 16 | X9: 0 | Y9: 0 | Z9: 1000 | AA9: 0 | AB9: 1000 | AC9: 0 | AD9: 1000 | AE9: 210 | AF9: 2000 | AG9: 18 | AH9: 50 | AI9: 2000 | AJ9: 4 | AK9: 1800 | AL9: 1575 | AM9: 1575 | AN9: 0 | AO9: 300 | AP9: 300 | AQ9: 300 | AR9: 6 | AS9: 60 | AT9: 20 | AU9: 1 | AV9: 7
