Workbook

Sheet MonsterCharacter
A1: string[64] | B1: string[64] | C1: string[64] | D1: dword | E1: dword | F1: dword | G1: dword | H1: dword | I1: dword | J1: dword | K1: dword | L1: dword | M1: dword | N1: dword | O1: dword | P1: dword | Q1: dword | R1: float | S1: dword | T1: dword | U1: dword | V1: float | W1: dword | X1: dword | Y1: dword | Z1: dword | AA1: dword | AB1: float | AC1: float | AD1: dword | AE1: dword | AF1: float | AG1: dword | AH1: dword | AI1: float | AJ1: float | AK1: float | AL1: float | AM1: float | AN1: dword | AO1: float | AP1: float | AQ1: float | AR1: dword | AS1: dword | AT1: float | AU1: float | AV1: float | AW1: float | AX1: string[64] | AY1: string[64] | AZ1: string[64] | BA1: string[64] | BB1: string[64] | BC1: string[64] | BD1: string[64] | BE1: string[64] | BF1: string[64] | BG1: string[64] | BH1: string[64] | BI1: string[64] | BJ1: string[64] | BK1: string[64] | BL1: string[64] | BM1: float | BN1: float | BO1: float | BP1: string[64] | BQ1: float | BR1: float | BS1: string[64] | BT1: float | BU1: float | BV1: string[64] | BW1: float | BX1: float | BY1: string[64] | BZ1: float | CA1: string[64] | CB1: float | CC1: dword | CD1: float | CE1: float | CF1: float | CG1: float | CH1: float | CI1: float | CJ1: float | CK1: dword | CL1: dword | CM1: dword | CN1: float | CO1: float | CP1: float | CQ1: float | CR1: float | CS1: float | CT1: float | CU1: dword | CV1: float | CW1: float | CX1: dword | CY1: dword | CZ1: dword | DA1: string[64] | DB1: dword | DC1: string[64] | DD1: dword | DE1: string[64] | DF1: dword | DG1: float | DH1: float | DI1: dword | DJ1: float | DK1: float | DL1: float | DM1: float | DN1: float | DO1: float | DP1: float | DQ1: float | DR1: float | DS1: float | DT1: float | DU1: float | DV1: float | DW1: float | DX1: float | DY1: float | DZ1: float | EA1: float | EB1: float | EC1: float | ED1: float | EE1: float | EF1: float | EG1: float | EH1: float | EI1: dword | EJ1: dword | EK1: string[64] | EL1: dword | EM1: dword | EN1: string[64] | EO1: dword | EP1: dword | EQ1: string[64] | ER1: dword | ES1: dword | ET1: string[64] | EU1: dword | EV1: dword | EW1: string[64] | EX1: dword | EY1: dword | EZ1: END
A2: Code | B2: Name | C2: EffectCode | D2: MobGrade | E2: RaceCode | F2: MobRace | G2: KillPoint | H2: ToCombatTime | I2: PincerCnt | J2: PreAttRange | K2: MinMoveDist | L2: MaxMoveDist | M2: MobAlienation | N2: MinMoveArea | O2: MaxMoveArea | P2: GuardRecallTimeMS | Q2: GuardingArea | R2: TarDecType | S2: APTime | T2: APReset | U2: UglierType | V2: Level | W2: bMonsterCond | X2: CriticalTol | Y2: bExpDown | Z2: UpLooting | AA2: DnLooting | AB2: Exp | AC2: AttFcStd | AD2: Attack_DP | AE2: Property | AF2: AttGap | AG2: bAttRangeType | AH2: AttType | AI2: MinAFSelProb | AJ2: MaxAFSelProb | AK2: AttSklUnit | AL2: SefSklUnit | AM2: WeakPart | AN2: bUseDefence | AO2: StdDefFc | AP2: DefGap | AQ2: DefFacing | AR2: ShieldBlock | AS2: BlockPer | AT2: fire | AU2: water | AV2: soil | AW2: wind | AX2: SPCode_1 | AY2: SPCode_2 | AZ2: SPCode_3 | BA2: SPCode_4 | BB2: SPCode_5 | BC2: SPCode_6 | BD2: SPCode_7 | BE2: SPCode_8 | BF2: SPCode_9 | BG2: SPCode_10 | BH2: SPCode_11 | BI2: SPCode_12 | BJ2: SPCode_13 | BK2: SPCode_14 | BL2: SPCode_15 | BM2: ForceLevel | BN2: ForceMastery | BO2: ForceAttStd | BP2: AttTechID_1 | BQ2: AttTechUseProb_1 | BR2: AttTechMotionTime_1 | BS2: AttTechID_2 | BT2: AttTechUseProb_2 | BU2: AttTechMotionTime_2 | BV2: AttTechID_3 | BW2: AttTechUseProb_3 | BX2: AttTechMotionTime_3 | BY2: PSecTechID | BZ2: PSecTechIDMotionTime | CA2: MSecTechID | CB2: MSecTechIDMotionTime | CC2: InjuryLimit | CD2: MaxHP | CE2: HPRecDelay | CF2: HPRecUnit | CG2: AttSpd | CH2: AttMoTime1 | CI2: AttMoTime2 | CJ2: CrtMoTime | CK2: ViewAngle | CL2: ViewAngleCap | CM2: CapacityValue | CN2: ViewExt | CO2: AttExt | CP2: MRefExt | CQ2: CopTime | CR2: MovSpd | CS2: WarMovSpd | CT2: ScaleRate | CU2: bScaleChange | CV2: Width | CW2: WaitTime | CX2: AsitReqRate | CY2: AsitAptRate | CZ2: AsitType | DA2: ChildMon_1 | DB2: MonNum_1 | DC2: ChildMon_2 | DD2: MonNum_2 | DE2: ChildMon_3 | DF2: MonNum_3 | DG2: EmoType | DH2: OffensiveRate | DI2: OffensiveType | DJ2: DamHPStd | DK2: EmoImpStdTime | DL2: GoodToOrdHPPer | DM2: OrdToBadHPPer | DN2: BadToWorseHPPer | DO2: EspTFProb | DP2: TypeCompTerms | DQ2: PSecTechChat | DR2: PAttTechChat | DS2: EmoChat_0 | DT2: EmoChatProb_0 | DU2: EmoChat_1 | DV2: EmoChatProb_1 | DW2: EmoChat_2 | DX2: EmoChatProb_2 | DY2: EmoChat_3 | DZ2: EmoChatProb_3 | EA2: EmoChat_4 | EB2: EmoChatProb_4 | EC2: AsitReqSteEspChat | ED2: AsitReqSteEspChatProb | EE2: AsitReqSteHelpChat | EF2: AsitReqSteHelpChatProb | EG2: AsitReqSteCopChat | EH2: AsitReqSteCopChatProb | EI2: EmotionCon_1 | EJ2: EmotionClass_1 | EK2: EmotionCode_1 | EL2: EmotionCon_2 | EM2: EmotionClass_2 | EN2: EmotionCode_2 | EO2: EmotionCon_3 | EP2: EmotionClass_3 | EQ2: EmotionCode_3 | ER2: EmotionCon_4 | ES2: EmotionClass_4 | ET2: EmotionCode_4 | EU2: EmotionCon_5 | EV2: EmotionClass_5 | EW2: EmotionCode_5 | EX2: AttEffType | EY2: DefEffType
A3: 00000 | B3: Young Flym | C3: 00000 | D3: 0 | E3: -1 | F3: 7 | G3: 1 | H3: 10000 | I3: 1 | J3: 50 | K3: 30 | L3: 100 | M3: 1 | N3: 0 | O3: 0 | P3: 0 | Q3: 0 | R3: 0 | S3: 5 | T3: 10 | U3: -1 | V3: 1 | W3: 0 | X3: 0 | Y3: 1 | Z3: 2 | AA3: 1 | AB3: 11 | AC3: 28 | AD3: 0 | AE3: -1 | AF3: 1 | AG3: 0 | AH3: 0 | AI3: 30 | AJ3: 65 | AK3: 2 | AL3: 2 | AM3: -1 | AN3: 0 | AO3: 8 | AP3: 0.5 | AQ3: 0.73154402 | AR3: 0 | AS3: 0 | AT3: 0 | AU3: 0 | AV3: 0 | AW3: 0 | AX3: -1 | AY3: -1 | AZ3: -1 | BA3: -1 | BB3: -1 | BC3: -1 | BD3: -1 | BE3: -1 | BF3: -1 | BG3: -1 | BH3: -1 | BI3: -1 | BJ3: -1 | BK3: -1 | BL3: -1 | BM3: 1 | BN3: 1 | BO3: 1 | BP3: 1 | BQ3: 1 | BR3: 1 | BS3: 1 | BT3: 1 | BU3: 1 | BV3: 1 | BW3: 1 | BX3: 1 | BY3: 1 | BZ3: 1 | CA3: 1 | CB3: 1 | CC3: 3 | CD3: 22 | CE3: 0 | CF3: 0 | CG3: 2034 | CH3: 2034 | CI3: 2034 | CJ3: 608 | CK3: 270 | CL3: 4 | CM3: 30 | CN3: 100 | CO3: 25 | CP3: 100 | CQ3: 5000 | CR3: 2 | CS3: 4 | CT3: 100 | CU3: 0 | CV3: 40 | CW3: 8000 | CX3: 0 | CY3: 0 | CZ3: 0 | DA3: -1 | DB3: 0 | DC3: -1 | DD3: 0 | DE3: -1 | DF3: 0 | DG3: 5 | DH3: 0 | DI3: 0 | DJ3: 1 | DK3: 20000 | DL3: 50 | DM3: 30 | DN3: 10 | DO3: 50 | DP3: 0 | DQ3: 1 | DR3: 1 | DS3: 1 | DT3: 1 | DU3: 1 | DV3: 1 | DW3: 1 | DX3: 1 | DY3: 1 | DZ3: 1 | EA3: 1 | EB3: 1 | EC3: 1 | ED3: 1 | EE3: 1 | EF3: 1 | EG3: 1 | EH3: 1 | EI3: 1 | EJ3: 1 | EK3: 0 | EL3: 7 | EM3: 1 | EN3: 1 | EO3: 9 | EP3: 0 | EQ3: 7 | ER3: 0 | ES3: -1 | ET3: -1 | EU3: 0 | EV3: -1 | EW3: -1 | EX3: 21 | EY3: 1
A4: 00001 | B4: Young Flym | C4: 00000 | D4: 0 | E4: -1 | F4: 7 | G4: 1 | H4: 10000 | I4: 1 | J4: 50 | K4: 30 | L4: 100 | M4: 1 | N4: 0 | O4: 0 | P4: 0 | Q4: 0 | R4: 0 | S4: 5 | T4: 10 | U4: -1 | V4: 1 | W4: 0 | X4: 0 | Y4: 1 | Z4: 2 | AA4: 1 | AB4: 11 | AC4: 28 | AD4: 0 | AE4: -1 | AF4: 1 | AG4: 0 | AH4: 0 | AI4: 30 | AJ4: 65 | AK4: 2 | AL4: 2 | AM4: -1 | AN4: 0 | AO4: 8 | AP4: 0.5 | AQ4: 0.73154402 | AR4: 0 | AS4: 0 | AT4: 0 | AU4: 0 | AV4: 0 | AW4: 0 | AX4: -1 | AY4: -1 | AZ4: -1 | BA4: -1 | BB4: -1 | BC4: -1 | BD4: -1 | BE4: -1 | BF4: -1 | BG4: -1 | BH4: -1 | BI4: -1 | BJ4: -1 | BK4: -1 | BL4: -1 | BM4: 1 | BN4: 1 | BO4: 1 | BP4: 1 | BQ4: 1 | BR4: 1 | BS4: 1 | BT4: 1 | BU4: 1 | BV4: 1 | BW4: 1 | BX4: 1 | BY4: 1 | BZ4: 1 | CA4: 1 | CB4: 1 | CC4: 3 | CD4: 22 | CE4: 0 | CF4: 0 | CG4: 2034 | CH4: 2034 | CI4: 2034 | CJ4: 608 | CK4: 270 | CL4: 4 | CM4: 30 | CN4: 100 | CO4: 25 | CP4: 100 | CQ4: 5000 | CR4: 2 | CS4: 4 | CT4: 100 | CU4: 0 | CV4: 40 | CW4: 8000 | CX4: 0 | CY4: 0 | CZ4: 0 | DA4: -1 | DB4: 0 | DC4: -1 | DD4: 0 | DE4: -1 | DF4: 0 | DG4: 5 | DH4: 0 | DI4: 0 | DJ4: 1 | DK4: 20000 | DL4: 50 | DM4: 30 | DN4: 10 | DO4: 50 | DP4: 0 | DQ4: 1 | DR4: 1 | DS4: 1 | DT4: 1 | DU4: 1 | DV4: 1 | DW4: 1 | DX4: 1 | DY4: 1 | DZ4: 1 | EA4: 1 | EB4: 1 | EC4: 1 | ED4: 1 | EE4: 1 | EF4: 1 | EG4: 1 | EH4: 1 | EI4: 1 | EJ4: 1 | EK4: 0 | EL4: 7 | EM4: 1 | EN4: 1 | EO4: 9 | EP4: 0 | EQ4: 7 | ER4: 0 | ES4: -1 | ET4: -1 | EU4: 0 | EV4: -1 | EW4: -1 | EX4: 21 | EY4: 1
A5: 00002 | B5: Young Flym | C5: 00000 | D5: 0 | E5: -1 | F5: 7 | G5: 1 | H5: 10000 | I5: 1 | J5: 50 | K5: 30 | L5: 100 | M5: 1 | N5: 0 | O5: 0 | P5: 0 | Q5: 0 | R5: 0 | S5: 5 | T5: 10 | U5: -1 | V5: 1 | W5: 0 | X5: 0 | Y5: 1 | Z5: 2 | AA5: 1 | AB5: 11 | AC5: 28 | AD5: 0 | AE5: -1 | AF5: 1 | AG5: 0 | AH5: 0 | AI5: 30 | AJ5: 65 | AK5: 2 | AL5: 2 | AM5: -1 | AN5: 0 | AO5: 8 | AP5: 0.5 | AQ5: 0.73154402 | AR5: 0 | AS5: 0 | AT5: 0 | AU5: 0 | AV5: 0 | AW5: 0 | AX5: -1 | AY5: -1 | AZ5: -1 | BA5: -1 | BB5: -1 | BC5: -1 | BD5: -1 | BE5: -1 | BF5: -1 | BG5: -1 | BH5: -1 | BI5: -1 | BJ5: -1 | BK5: -1 | BL5: -1 | BM5: 1 | BN5: 1 | BO5: 1 | BP5: 1 | BQ5: 1 | BR5: 1 | BS5: 1 | BT5: 1 | BU5: 1 | BV5: 1 | BW5: 1 | BX5: 1 | BY5: 1 | BZ5: 1 | CA5: 1 | CB5: 1 | CC5: 3 | CD5: 22 | CE5: 0 | CF5: 0 | CG5: 2034 | CH5: 2034 | CI5: 2034 | CJ5: 608 | CK5: 270 | CL5: 4 | CM5: 30 | CN5: 100 | CO5: 25 | CP5: 100 | CQ5: 5000 | CR5: 2 | CS5: 4 | CT5: 100 | CU5: 0 | CV5: 40 | CW5: 8000 | CX5: 0 | CY5: 0 | CZ5: 0 | DA5: -1 | DB5: 0 | DC5: -1 | DD5: 0 | DE5: -1 | DF5: 0 | DG5: 5 | DH5: 0 | DI5: 0 | DJ5: 1 | DK5: 20000 | DL5: 50 | DM5: 30 | DN5: 10 | DO5: 50 | DP5: 0 | DQ5: 1 | DR5: 1 | DS5: 1 | DT5: 1 | DU5: 1 | DV5: 1 | DW5: 1 | DX5: 1 | DY5: 1 | DZ5: 1 | EA5: 1 | EB5: 1 | EC5: 1 | ED5: 1 | EE5: 1 | EF5: 1 | EG5: 1 | EH5: 1 | EI5: 1 | EJ5: 1 | EK5: 0 | EL5: 7 | EM5: 1 | EN5: 1 | EO5: 9 | EP5: 0 | EQ5: 7 | ER5: 0 | ES5: -1 | ET5: -1 | EU5: 0 | EV5: -1 | EW5: -1 | EX5: 21 | EY5: 1
A6: 00100 | B6: Wing | C6: 00080 | D6: 0 | E6: -1 | F6: 5 | G6: 2 | H6: 10000 | I6: 1 | J6: 50 | K6: 30 | L6: 100 | M6: 1 | N6: 0 | O6: 0 | P6: 0 | Q6: 0 | R6: 0 | S6: 5 | T6: 10 | U6: -1 | V6: 2 | W6: 0 | X6: 1 | Y6: 1 | Z6: 2 | AA6: 1 | AB6: 14 | AC6: 35 | AD6: 0 | AE6: -1 | AF6: 1 | AG6: 0 | AH6: 0 | AI6: 30 | AJ6: 65 | AK6: 5 | AL6: 4 | AM6: -1 | AN6: 0 | AO6: 9 | AP6: 0.5 | AQ6: 0.77386898 | AR6: 0 | AS6: 0 | AT6: 0 | AU6: 0 | AV6: 0 | AW6: 0 | AX6: -1 | AY6: -1 | AZ6: -1 | BA6: -1 | BB6: -1 | BC6: -1 | BD6: -1 | BE6: -1 | BF6: -1 | BG6: -1 | BH6: -1 | BI6: -1 | BJ6: -1 | BK6: -1 | BL6: -1 | BM6: 1 | BN6: 1 | BO6: 1 | BP6: 1 | BQ6: 1 | BR6: 1 | BS6: 1 | BT6: 1 | BU6: 1 | BV6: 1 | BW6: 1 | BX6: 1 | BY6: 1 | BZ6: 1 | CA6: 1 | CB6: 1 | CC6: 3 | CD6: 31 | CE6: 0 | CF6: 0 | CG6: 2034 | CH6: 2034 | CI6: 2034 | CJ6: 1000 | CK6: 270 | CL6: 4 | CM6: 30 | CN6: 100 | CO6: 37.5 | CP6: 100 | CQ6: 5000 | CR6: 4 | CS6: 6 | CT6: 150 | CU6: 0 | CV6: 60 | CW6: 8000 | CX6: 0 | CY6: 0 | CZ6: 0 | DA6: -1 | DB6: 0 | DC6: -1 | DD6: 0 | DE6: -1 | DF6: 0 | DG6: 5 | DH6: 0 | DI6: 0 | DJ6: 1 | DK6: 20000 | DL6: 50 | DM6: 30 | DN6: 10 | DO6: 75 | DP6: 0 | DQ6: 1 | DR6: 1 | DS6: 1 | DT6: 1 | DU6: 1 | DV6: 1 | DW6: 1 | DX6: 1 | DY6: 1 | DZ6: 1 | EA6: 1 | EB6: 1 | EC6: 1 | ED6: 1 | EE6: 1 | EF6: 1 | EG6: 1 | EH6: 1 | EI6: 1 | EJ6: 1 | EK6: 0 | EL6: 7 | EM6: 1 | EN6: 1 | EO6: 0 | EP6: -1 | EQ6: -1 | ER6: 0 | ES6: -1 | ET6: -1 | EU6: 0 | EV6: -1 | EW6: -1 | EX6: 13 | EY6: 2
A7: 00101 | B7: Wing | C7: 00080 | D7: 0 | E7: -1 | F7: 5 | G7: 2 | H7: 10000 | I7: 1 | J7: 50 | K7: 30 | L7: 100 | M7: 1 | N7: 0 | O7: 0 | P7: 0 | Q7: 0 | R7: 0 | S7: 5 | T7: 10 | U7: -1 | V7: 2 | W7: 0 | X7: 1 | Y7: 1 | Z7: 2 | AA7: 1 | AB7: 14 | AC7: 35 | AD7: 0 | AE7: -1 | AF7: 1 | AG7: 0 | AH7: 0 | AI7: 30 | AJ7: 65 | AK7: 5 | AL7: 4 | AM7: -1 | AN7: 0 | AO7: 9 | AP7: 0.5 | AQ7: 0.77386898 | AR7: 0 | AS7: 0 | AT7: 0 | AU7: 0 | AV7: 0 | AW7: 0 | AX7: -1 | AY7: -1 | AZ7: -1 | BA7: -1 | BB7: -1 | BC7: -1 | BD7: -1 | BE7: -1 | BF7: -1 | BG7: -1 | BH7: -1 | BI7: -1 | BJ7: -1 | BK7: -1 | BL7: -1 | BM7: 1 | BN7: 1 | BO7: 1 | BP7: 1 | BQ7: 1 | BR7: 1 | BS7: 1 | BT7: 1 | BU7: 1 | BV7: 1 | BW7: 1 | BX7: 1 | BY7: 1 | BZ7: 1 | CA7: 1 | CB7: 1 | CC7: 3 | CD7: 31 | CE7: 0 | CF7: 0 | CG7: 2034 | CH7: 2034 | CI7: 2034 | CJ7: 1000 | CK7: 270 | CL7: 4 | CM7: 30 | CN7: 100 | CO7: 37.5 | CP7: 100 | CQ7: 5000 | CR7: 4 | CS7: 6 | CT7: 150 | CU7: 0 | CV7: 60 | CW7: 8000 | CX7: 0 | CY7: 0 | CZ7: 0 | DA7: -1 | DB7: 0 | DC7: -1 | DD7: 0 | DE7: -1 | DF7: 0 | DG7: 5 | DH7: 0 | DI7: 0 | DJ7: 1 | DK7: 20000 | DL7: 50 | DM7: 30 | DN7: 10 | DO7: 75 | DP7: 0 | DQ7: 1 | DR7: 1 | DS7: 1 | DT7: 1 | DU7: 1 | DV7: 1 | DW7: 1 | DX7: 1 | DY7: 1 | DZ7: 1 | EA7: 1 | EB7: 1 | EC7: 1 | ED7: 1 | EE7: 1 | EF7: 1 | EG7: 1 | EH7: 1 | EI7: 1 | EJ7: 1 | EK7: 0 | EL7: 7 | EM7: 1 | EN7: 1 | EO7: 0 | EP7: -1 | EQ7: -1 | ER7: 0 | ES7: -1 | ET7: -1 | EU7: 0 | EV7: -1 | EW7: -1 | EX7: 13 | EY7: 2
A8: 00102 | B8: Wing | C8: 00080 | D8: 0 | E8: -1 | F8: 5 | G8: 2 | H8: 10000 | I8: 1 | J8: 50 | K8: 30 | L8: 100 | M8: 1 | N8: 0 | O8: 0 | P8: 0 | Q8: 0 | R8: 0 | S8: 5 | T8: 10 | U8: -1 | V8: 2 | W8: 0 | X8: 1 | Y8: 1 | Z8: 2 | AA8: 1 | AB8: 14 | AC8: 35 | AD8: 0 | AE8: -1 | AF8: 1 | AG8: 0 | AH8: 0 | AI8: 30 | AJ8: 65 | AK8: 5 | AL8: 4 | AM8: -1 | AN8: 0 | AO8: 9 | AP8: 0.5 | AQ8: 0.77386898 | AR8: 0 | AS8: 0 | AT8: 0 | AU8: 0 | AV8: 0 | AW8: 0 | AX8: -1 | AY8: -1 | AZ8: -1 | BA8: -1 | BB8: -1 | BC8: -1 | BD8: -1 | BE8: -1 | BF8: -1 | BG8: -1 | BH8: -1 | BI8: -1 | BJ8: -1 | BK8: -1 | BL8: -1 | BM8: 1 | BN8: 1 | BO8: 1 | BP8: 1 | BQ8: 1 | BR8: 1 | BS8: 1 | BT8: 1 | BU8: 1 | BV8: 1 | BW8: 1 | BX8: 1 | BY8: 1 | BZ8: 1 | CA8: 1 | CB8: 1 | CC8: 3 | CD8: 31 | CE8: 0 | CF8: 0 | CG8: 2034 | CH8: 2034 | CI8: 2034 | CJ8: 1000 | CK8: 270 | CL8: 4 | CM8: 30 | CN8: 100 | CO8: 37.5 | CP8: 100 | CQ8: 5000 | CR8: 4 | CS8: 6 | CT8: 150 | CU8: 0 | CV8: 60 | CW8: 8000 | CX8: 0 | CY8: 0 | CZ8: 0 | DA8: -1 | DB8: 0 | DC8: -1 | DD8: 0 | DE8: -1 | DF8: 0 | DG8: 5 | DH8: 0 | DI8: 0 | DJ8: 1 | DK8: 20000 | DL8: 50 | DM8: 30 | DN8: 10 | DO8: 75 | DP8: 0 | DQ8: 1 | DR8: 1 | DS8: 1 | DT8: 1 | DU8: 1 | DV8: 1 | DW8: 1 | DX8: 1 | DY8: 1 | DZ8: 1 | EA8: 1 | EB8: 1 | EC8: 1 | ED8: 1 | EE8: 1 | EF8: 1 | EG8: 1 | EH8: 1 | EI8: 1 | EJ8: 1 | EK8: 0 | EL8: 7 | EM8: 1 | EN8: 1 | EO8: 0 | EP8: -1 | EQ8: -1 | ER8: 0 | ES8: -1 | ET8: -1 | EU8: 0 | EV8: -1 | EW8: -1 | EX8: 13 | EY8: 2
A9: 00300 | B9: Digger Clan | C9: 00082 | D9: 0 | E9: -1 | F9: 2 | G9: 3 | H9: 10000 | I9: 1 | J9: 50 | K9: 30 | L9: 100 | M9: 1 | N9: 0 | O9: 0 | P9: 0 | Q9: 0 | R9: 0 | S9: 5 | T9: 10 | U9: -1 | V9: 3 | W9: 0 | X9: 2 | Y9: 1 | Z9: 2 | AA9: 1 | AB9: 18 | AC9: 37 | AD9: 0 | AE9: -1 | AF9: 1 | AG9: 0 | AH9: 0 | AI9: 30 | AJ9: 65 | AK9: 7 | AL9: 6 | AM9: -1 | AN9: 0 | AO9: 11 | AP9: 0.5 | AQ9: 0.78723401 | AR9: 0 | AS9: 0 | AT9: 0 | AU9: 0 | AV9: 0 | AW9: 0 | AX9: -1 | AY9: -1 | AZ9: -1 | BA9: -1 | BB9: -1 | BC9: -1 | BD9: -1 | BE9: -1 | BF9: -1 | BG9: -1 | BH9: -1 | BI9: -1 | BJ9: -1 | BK9: -1 | BL9: -1 | BM9: 1 | BN9: 1 | BO9: 1 | BP9: 1 | BQ9: 1 | BR9: 1 | BS9: 1 | BT9: 1 | BU9: 1 | BV9: 1 | BW9: 1 | BX9: 1 | BY9: 1 | BZ9: 1 | CA9: 1 | CB9: 1 | CC9: 3 | CD9: 51 | CE9: 0 | CF9: 0 | CG9: 2034 | CH9: 2034 | CI9: 2034 | CJ9: 1184 | CK9: 270 | CL9: 4 | CM9: 30 | CN9: 100 | CO9: 37.5 | CP9: 100 | CQ9: 5000 | CR9: 3 | CS9: 5 | CT9: 150 | CU9: 0 | CV9: 60 | CW9: 8000 | CX9: 0 | CY9: 0 | CZ9: 1 | DA9: -1 | DB9: 0 | DC9: -1 | DD9: 0 | DE9: -1 | DF9: 0 | DG9: 5 | DH9: 0 | DI9: 0 | DJ9: 1 | DK9: 20000 | DL9: 50 | DM9: 30 | DN9: 10 | DO9: 75 | DP9: 0 | DQ9: 1 | DR9: 1 | DS9: 1 | DT9: 1 | DU9: 1 | DV9: 1 | DW9: 1 | DX9: 1 | DY9: 1 | DZ9: 1 | EA9: 1 | EB9: 1 | EC9: 1 | ED9: 1 | EE9: 1 | EF9: 1 | EG9: 1 | EH9: 1 | EI9: 1 | EJ9: 1 | EK9: 0 | EL9: 7 | EM9: 1 | EN9: 1 | EO9: 0 | EP9: -1 | EQ9: -1 | ER9: 0 | ES9: -1 | ET9: -1 | EU9: 0 | EV9: -1 | EW9: -1 | EX9: 21 | EY9: 256
A10: 00301 | B10: Digger Clan | C10: 00082 | D10: 0 | E10: -1 | F10: 2 | G10: 3 | H10: 10000 | I10: 1 | J10: 50 | K10: 30 | L10: 100 | M10: 1 | N10: 0 | O10: 0 | P10: 0 | Q10: 0 | R10: 0 | S10: 5 | T10: 10 | U10: -1 | V10: 3 | W10: 0 | X10: 2 | Y10: 1 | Z10: 2 | AA10: 1 | AB10: 18 | AC10: 37 | AD10: 0 | AE10: -1 | AF10: 1 | AG10: 0 | AH10: 0 | AI10: 30 | AJ10: 65 | AK10: 7 | AL10: 6 | AM10: -1 | AN10: 0 | AO10: 11 | AP10: 0.5 | AQ10: 0.78723401 | AR10: 0 | AS10: 0 | AT10: 35 | AU10: 0 | AV10: 0 | AW10: 0 | AX10: -1 | AY10: -1 | AZ10: -1 | BA10: -1 | BB10: -1 | BC10: -1 | BD10: -1 | BE10: -1 | BF10: -1 | BG10: -1 | BH10: -1 | BI10: -1 | BJ10: -1 | BK10: -1 | BL10: -1 | BM10: 1 | BN10: 1 | BO10: 1 | BP10: 1 | BQ10: 1 | BR10: 1 | BS10: 1 | BT10: 1 | BU10: 1 | BV10: 1 | BW10: 1 | BX10: 1 | BY10: 1 | BZ10: 1 | CA10: 1 | CB10: 1 | CC10: 3 | CD10: 51 | CE10: 0 | CF10: 0 | CG10: 2034 | CH10: 2034 | CI10: 2034 | CJ10: 1184 | CK10: 270 | CL10: 4 | CM10: 30 | CN10: 100 | CO10: 37.5 | CP10: 100 | CQ10: 5000 | CR10: 3 | CS10: 5 | CT10: 150 | CU10: 0 | CV10: 60 | CW10: 8000 | CX10: 0 | CY10: 0 | CZ10: 1 | DA10: -1 | DB10: 0 | DC10: -1 | DD10: 0 | DE10: -1 | DF10: 0 | DG10: 5 | DH10: 0 | DI10: 0 | DJ10: 1 | DK10: 20000 | DL10: 50 | DM10: 30 | DN10: 10 | DO10: 75 | DP10: 0 | DQ10: 1 | DR10: 1 | DS10: 1 | DT10: 1 | DU10: 1 | DV10: 1 | DW10: 1 | DX10: 1 | DY10: 1 | DZ10: 1 | EA10: 1 | EB10: 1 | EC10: 1 | ED10: 1 | EE10: 1 | EF10: 1 | EG10: 1 | EH10: 1 | EI10: 1 | EJ10: 1 | EK10: 0 | EL10: 7 | EM10: 1 | EN10: 1 | EO10: 0 | EP10: -1 | EQ10: -1 | ER10: 0 | ES10: -1 | ET10: -1 | EU10: 0 | EV10: -1 | EW10: -1 | EX10: 21 | EY10: 256
A11: 00201 | B11: Flym | C11: 00009 | D11: 0 | E11: -1 | F11: 7 | G11: 3 | H11: 10000 | I11: 1 | J11: 50 | K11: 30 | L11: 100 | M11: 1 | N11: 0 | O11: 0 | P11: 0 | Q11: 0 | R11: 0 | S11: 5 | T11: 10 | U11: -1 | V11: 3 | W11: 0 | X11: 2 | Y11: 1 | Z11: 2 | AA11: 1 | AB11: 18 | AC11: 37 | AD11: 0 | AE11: -1 | AF11: 1 | AG11: 0 | AH11: 0 | AI11: 30 | AJ11: 65 | AK11: 7 | AL11: 6 | AM11: -1 | AN11: 0 | AO11: 11 | AP11: 0.5 | AQ11: 0.78723401 | AR11: 0 | AS11: 0 | AT11: 0 | AU11: 0 | AV11: 35 | AW11: 0 | AX11: -1 | AY11: -1 | AZ11: -1 | BA11: -1 | BB11: -1 | BC11: -1 | BD11: -1 | BE11: -1 | BF11: -1 | BG11: -1 | BH11: -1 | BI11: -1 | BJ11: -1 | BK11: -1 | BL11: -1 | BM11: 1 | BN11: 1 | BO11: 1 | BP11: 1 | BQ11: 1 | BR11: 1 | BS11: 1 | BT11: 1 | BU11: 1 | BV11: 1 | BW11: 1 | BX11: 1 | BY11: 1 | BZ11: 1 | CA11: 1 | CB11: 1 | CC11: 3 | CD11: 51 | CE11: 0 | CF11: 0 | CG11: 2034 | CH11: 2034 | CI11: 2034 | CJ11: 608 | CK11: 270 | CL11: 4 | CM11: 30 | CN11: 100 | CO11: 25 | CP11: 100 | CQ11: 5000 | CR11: 2 | CS11: 4 | CT11: 100 | CU11: 0 | CV11: 40 | CW11: 8000 | CX11: 0 | CY11: 0 | CZ11: 0 | DA11: -1 | DB11: 0 | DC11: -1 | DD11: 0 | DE11: -1 | DF11: 0 | DG11: 5 | DH11: 0 | DI11: 0 | DJ11: 1 | DK11: 20000 | DL11: 50 | DM11: 30 | DN11: 10 | DO11: 50 | DP11: 0 | DQ11: 1 | DR11: 1 | DS11: 1 | DT11: 1 | DU11: 1 | DV11: 1 | DW11: 1 | DX11: 1 | DY11: 1 | DZ11: 1 | EA11: 1 | EB11: 1 | EC11: 1 | ED11: 1 | EE11: 1 | EF11: 1 | EG11: 1 | EH11: 1 | EI11: 1 | EJ11: 1 | EK11: 0 | EL11: 7 | EM11: 1 | EN11: 1 | EO11: 0 | EP11: -1 | EQ11: -1 | ER11: 0 | ES11: -1 | ET11: -1 | EU11: 0 | EV11: -1 | EW11: -1 | EX11: 21 | EY11: 1
A12: 00202 | B12: Flym | C12: 00009 | D12: 0 | E12: -1 | F12: 7 | G12: 3 | H12: 10000 | I12: 1 | J12: 50 | K12: 30 | L12: 100 | M12: 1 | N12: 0 | O12: 0 | P12: 0 | Q12: 0 | R12: 0 | S12: 5 | T12: 10 | U12: -1 | V12: 3 | W12: 0 | X12: 2 | Y12: 1 | Z12: 2 | AA12: 1 | AB12: 18 | AC12: 37 | AD12: 0 | AE12: -1 | AF12: 1 | AG12: 0 | AH12: 0 | AI12: 30 | AJ12: 65 | AK12: 7 | AL12: 6 | AM12: -1 | AN12: 0 | AO12: 11 | AP12: 0.5 | AQ12: 0.78723401 | AR12: 0 | AS12: 0 | AT12: 0 | AU12: 0 | AV12: 35 | AW12: 0 | AX12: -1 | AY12: -1 | AZ12: -1 | BA12: -1 | BB12: -1 | BC12: -1 | BD12: -1 | BE12: -1 | BF12: -1 | BG12: -1 | BH12: -1 | BI12: -1 | BJ12: -1 | BK12: -1 | BL12: -1 | BM12: 1 | BN12: 1 | BO12: 1 | BP12: 1 | BQ12: 1 | BR12: 1 | BS12: 1 | BT12: 1 | BU12: 1 | BV12: 1 | BW12: 1 | BX12: 1 | BY12: 1 | BZ12: 1 | CA12: 1 | CB12: 1 | CC12: 3 | CD12: 51 | CE12: 0 | CF12: 0 | CG12: 2034 | CH12: 2034 | CI12: 2034 | CJ12: 608 | CK12: 270 | CL12: 4 | CM12: 30 | CN12: 100 | CO12: 25 | CP12: 100 | CQ12: 5000 | CR12: 2 | CS12: 4 | CT12: 100 | CU12: 0 | CV12: 40 | CW12: 8000 | CX12: 0 | CY12: 0 | CZ12: 0 | DA12: -1 | DB12: 0 | DC12: -1 | DD12: 0 | DE12: -1 | DF12: 0 | DG12: 5 | DH12: 0 | DI12: 0 | DJ12: 1 | DK12: 20000 | DL12: 50 | DM12: 30 | DN12: 10 | DO12: 50 | DP12: 0 | DQ12: 1 | DR12: 1 | DS12: 1 | DT12: 1 | DU12: 1 | DV12: 1 | DW12: 1 | DX12: 1 | DY12: 1 | DZ12: 1 | EA12: 1 | EB12: 1 | EC12: 1 | ED12: 1 | EE12: 1 | EF12: 1 | EG12: 1 | EH12: 1 | EI12: 1 | EJ12: 1 | EK12: 0 | EL12: 7 | EM12: 1 | EN12: 1 | EO12: 0 | EP12: -1 | EQ12: -1 | ER12: 0 | ES12: -1 | ET12: -1 | EU12: 0 | EV12: -1 | EW12: -1 | EX12: 21 | EY12: 1
A13: 00200 | B13: Flym | C13: 00009 | D13: 0 | E13: -1 | F13: 7 | G13: 4 | H13: 10000 | I13: 1 | J13: 50 | K13: 30 | L13: 100 | M13: 1 | N13: 0 | O13: 0 | P13: 0 | Q13: 0 | R13: 0 | S13: 5 | T13: 10 | U13: -1 | V13: 4 | W13: 0 | X13: 3 | Y13: 1 | Z13: 2 | AA13: 1 | AB13: 22 | AC13: 37 | AD13: 0 | AE13: -1 | AF13: 1 | AG13: 0 | AH13: 0 | AI13: 30 | AJ13: 65 | AK13: 9 | AL13: 8 | AM13: -1 | AN13: 0 | AO13: 11 | AP13: 0.5 | AQ13: 0.82343501 | AR13: 0 | AS13: 0 | AT13: 0 | AU13: 0 | AV13: 35 | AW13: 0 | AX13: -1 | AY13: -1 | AZ13: -1 | BA13: -1 | BB13: -1 | BC13: -1 | BD13: -1 | BE13: -1 | BF13: -1 | BG13: -1 | BH13: -1 | BI13: -1 | BJ13: -1 | BK13: -1 | BL13: -1 | BM13: 1 | BN13: 1 | BO13: 1 | BP13: 1 | BQ13: 1 | BR13: 1 | BS13: 1 | BT13: 1 | BU13: 1 | BV13: 1 | BW13: 1 | BX13: 1 | BY13: 1 | BZ13: 1 | CA13: 1 | CB13: 1 | CC13: 3 | CD13: 77 | CE13: 0 | CF13: 0 | CG13: 2034 | CH13: 2034 | CI13: 2034 | CJ13: 608 | CK13: 270 | CL13: 4 | CM13: 30 | CN13: 100 | CO13: 25 | CP13: 100 | CQ13: 5000 | CR13: 2 | CS13: 4 | CT13: 100 | CU13: 0 | CV13: 40 | CW13: 8000 | CX13: 0 | CY13: 0 | CZ13: 0 | DA13: -1 | DB13: 0 | DC13: -1 | DD13: 0 | DE13: -1 | DF13: 0 | DG13: 5 | DH13: 0 | DI13: 0 | DJ13: 1 | DK13: 20000 | DL13: 50 | DM13: 30 | DN13: 10 | DO13: 50 | DP13: 0 | DQ13: 1 | DR13: 1 | DS13: 1 | DT13: 1 | DU13: 1 | DV13: 1 | DW13: 1 | DX13: 1 | DY13: 1 | DZ13: 1 | EA13: 1 | EB13: 1 | EC13: 1 | ED13: 1 | EE13: 1 | EF13: 1 | EG13: 1 | EH13: 1 | EI13: 1 | EJ13: 1 | EK13: 0 | EL13: 7 | EM13: 1 | EN13: 1 | EO13: 0 | EP13: -1 | EQ13: -1 | ER13: 0 | ES13: -1 | ET13: -1 | EU13: 0 | EV13: -1 | EW13: -1 | EX13: 21 | EY13: 1
A14: 00500 | B14: Stingbug | C14: 00003 | D14: 0 | E14: -1 | F14: 4 | G14: 4 | H14: 10000 | I14: 1 | J14: 50 | K14: 30 | L14: 100 | M14: 1 | N14: 0 | O14: 0 | P14: 0 | Q14: 0 | R14: 0 | S14: 5 | T14: 10 | U14: -1 | V14: 4 | W14: 0 | X14: 3 | Y14: 1 | Z14: 2 | AA14: 1 | AB14: 22 | AC14: 37 | AD14: 0 | AE14: -1 | AF14: 1 | AG14: 0 | AH14: 0 | AI14: 30 | AJ14: 65 | AK14: 9 | AL14: 8 | AM14: -1 | AN14: 0 | AO14: 11 | AP14: 0.5 | AQ14: 0.82343501 | AR14: 0 | AS14: 0 | AT14: 0 | AU14: 30 | AV14: 0 | AW14: 0 | AX14: -1 | AY14: -1 | AZ14: -1 | BA14: -1 | BB14: -1 | BC14: -1 | BD14: -1 | BE14: -1 | BF14: -1 | BG14: -1 | BH14: -1 | BI14: -1 | BJ14: -1 | BK14: -1 | BL14: -1 | BM14: 1 | BN14: 1 | BO14: 1 | BP14: 1 | BQ14: 1 | BR14: 1 | BS14: 1 | BT14: 1 | BU14: 1 | BV14: 1 | BW14: 1 | BX14: 1 | BY14: 1 | BZ14: 1 | CA14: 1 | CB14: 1 | CC14: 3 | CD14: 77 | CE14: 0 | CF14: 0 | CG14: 2034 | CH14: 2034 | CI14: 2034 | CJ14: 608 | CK14: 270 | CL14: 4 | CM14: 30 | CN14: 100 | CO14: 25 | CP14: 100 | CQ14: 5000 | CR14: 2 | CS14: 4 | CT14: 100 | CU14: 0 | CV14: 40 | CW14: 8000 | CX14: 0 | CY14: 0 | CZ14: 1 | DA14: -1 | DB14: 0 | DC14: -1 | DD14: 0 | DE14: -1 | DF14: 0 | DG14: 5 | DH14: 0 | DI14: 0 | DJ14: 1 | DK14: 20000 | DL14: 50 | DM14: 30 | DN14: 10 | DO14: 25 | DP14: 0 | DQ14: 1 | DR14: 1 | DS14: 1 | DT14: 1 | DU14: 1 | DV14: 1 | DW14: 1 | DX14: 1 | DY14: 1 | DZ14: 1 | EA14: 1 | EB14: 1 | EC14: 1 | ED14: 1 | EE14: 1 | EF14: 1 | EG14: 1 | EH14: 1 | EI14: 1 | EJ14: 1 | EK14: 0 | EL14: 7 | EM14: 1 | EN14: 1 | EO14: 0 | EP14: -1 | EQ14: -1 | ER14: 0 | ES14: -1 | ET14: -1 | EU14: 0 | EV14: -1 | EW14: -1 | EX14: 21 | EY14: 2048
... A941: 0A503 | B941: Jewerly Cube | C941: 00107 | D941: 0 | E941: -1 | F941: 7 | G941: 40 | H941: 10000 | I941: 1 | J941: 50 | K941: 0 | L941: 0 | M941: 1 | N941: 0 | O941: 0 | P941: 0 | Q941: 0 | R941: 0 | S941: 5 | T941: 10 | U941: -1 | V941: 40 | W941: 0 | X941: 36 | Y941: 1 | Z941: -1 | AA941: -1 | AB941: 1033683 | AC941: 0 | AD941: 0 | AE941: -1 | AF941: 1 | AG941: 0 | AH941: 0 | AI941: 30 | AJ941: 65 | AK941: 104 | AL941: 91 | AM941: -1 | AN941: 0 | AO941: 842 | AP941: 0.5 | AQ941: 0.193409 | AR941: 0 | AS941: 0 | AT941: 20 | AU941: 20 | AV941: 20 | AW941: 20 | AX941: -1 | AY941: -1 | AZ941: -1 | BA941: -1 | BB941: -1 | BC941: -1 | BD941: -1 | BE941: -1 | BF941: -1 | BG941: -1 | BH941: -1 | BI941: -1 | BJ941: -1 | BK941: -1 | BL941: -1 | BM941: 1 | BN941: 1 | BO941: 1 | BP941: 1 | BQ941: 1 | BR941: 1 | BS941: 1 | BT941: 1 | BU941: 1 | BV941: 1 | BW941: 1 | BX941: 1 | BY941: 1 | BZ941: 1 | CA941: 1 | CB941: 1 | CC941: 3 | CD941: 560000 | CE941: 0 | CF941: 0 | CG941: 2034 | CH941: 2034 | CI941: 2034 | CJ941: 1000 | CK941: 270 | CL941: 4 | CM941: 30 | CN941: 100 | CO941: 0 | CP941: 150 | CQ941: 5000 | CR941: 0 | CS941: 0 | CT941: 50 | CU941: 0 | CV941: 10 | CW941: 8000 | CX941: 100 | CY941: 0 | CZ941: 0 | DA941: -1 | DB941: 0 | DC941: -1 | DD941: 0 | DE941: -1 | DF941: 0 | DG941: 1 | DH941: 0 | DI941: 0 | DJ941: 1 | DK941: 20000 | DL941: 50 | DM941: 30 | DN941: 10 | DO941: 0 | DP941: 0 | DQ941: 1 | DR941: 1 | DS941: 1 | DT941: 1 | DU941: 1 | DV941: 1 | DW941: 1 | DX941: 1 | DY941: 1 | DZ941: 1 | EA941: 1 | EB941: 1 | EC941: 1 | ED941: 1 | EE941: 1 | EF941: 1 | EG941: 1 | EH941: 1 | EI941: 1 | EJ941: 1 | EK941: 0 | EL941: 7 | EM941: 1 | EN941: 1 | EO941: 0 | EP941: -1 | EQ941: -1 | ER941: 0 | ES941: -1 | ET941: -1 | EU941: 0 | EV941: -1 | EW941: -1 | EX941: -1 | EY941: 514
A942: 16407 | B942: Golden Pig | C942: 00229 | D942: 2 | E942: -1 | F942: 0 | G942: 924 | H942: 10000 | I942: 11 | J942: 50 | K942: 30 | L942: 50 | M942: 1 | N942: 500 | O942: 800 | P942: 10000 | Q942: 0 | R942: 0 | S942: 5 | T942: 10 | U942: -1 | V942: 66 | W942: 1 | X942: 59 | Y942: 1 | Z942: -1 | AA942: -1 | AB942: 287075598336 | AC942: 106827.7 | AD942: 0 | AE942: -1 | AF942: 1 | AG942: 0 | AH942: 6 | AI942: 30 | AJ942: 30 | AK942: 830 | AL942: 565 | AM942: -1 | AN942: 0 | AO942: 5112 | AP942: 0.5 | AQ942: 0.059409 | AR942: 0 | AS942: 0 | AT942: 0 | AU942: 0 | AV942: 0 | AW942: 0 | AX942: -1 | AY942: -1 | AZ942: -1 | BA942: -1 | BB942: -1 | BC942: -1 | BD942: -1 | BE942: -1 | BF942: -1 | BG942: -1 | BH942: -1 | BI942: -1 | BJ942: -1 | BK942: -1 | BL942: -1 | BM942: 1 | BN942: 1 | BO942: 1 | BP942: 1 | BQ942: 1 | BR942: 1 | BS942: 1 | BT942: 1 | BU942: 1 | BV942: 1 | BW942: 1 | BX942: 1 | BY942: 1 | BZ942: 1 | CA942: 1 | CB942: 1 | CC942: 3 | CD942: 3029300 | CE942: 26 | CF942: 475200 | CG942: 2034 | CH942: 2034 | CI942: 2034 | CJ942: 1000 | CK942: 270 | CL942: 4 | CM942: 30 | CN942: 100 | CO942: 250 | CP942: 100 | CQ942: 5000 | CR942: 5 | CS942: 8 | CT942: 500 | CU942: 0 | CV942: 200 | CW942: 13000 | CX942: 100 | CY942: 100 | CZ942: 0 | DA942: -1 | DB942: 0 | DC942: -1 | DD942: 0 | DE942: -1 | DF942: 0 | DG942: 1 | DH942: 0 | DI942: 0 | DJ942: 1 | DK942: 5000 | DL942: 99.900002 | DM942: 60 | DN942: 45 | DO942: 0 | DP942: 0 | DQ942: 1 | DR942: 1 | DS942: 1 | DT942: 1 | DU942: 1 | DV942: 1 | DW942: 1 | DX942: 1 | DY942: 1 | DZ942: 1 | EA942: 1 | EB942: 1 | EC942: 1 | ED942: 1 | EE942: 1 | EF942: 1 | EG942: 1 | EH942: 1 | EI942: 1 | EJ942: 1 | EK942: 0 | EL942: 7 | EM942: 1 | EN942: 1 | EO942: 0 | EP942: -1 | EQ942: -1 | ER942: 0 | ES942: -1 | ET942: -1 | EU942: 0 | EV942: -1 | EW942: -1 | EX942: 4 | EY942: 513
A943: 00903 | B943: Hive Marr | C943: 0000D | D943: 0 | E943: -1 | F943: 4 | G943: 0 | H943: 10000 | I943: 1 | J943: 50 | K943: 30 | L943: 50 | M943: 1 | N943: 0 | O943: 0 | P943: 0 | Q943: 0 | R943: 0 | S943: 5 | T943: 10 | U943: -1 | V943: 57 | W943: 0 | X943: 51 | Y943: 1 | Z943: -1 | AA943: -1 | AB943: 0 | AC943: 35104 | AD943: 0 | AE943: -1 | AF943: 1 | AG943: 0 | AH943: 0 | AI943: 30 | AJ943: 65 | AK943: 306 | AL943: 260 | AM943: -1 | AN943: 0 | AO943: 2273 | AP943: 0.5 | AQ943: 0.081170999 | AR943: 0 | AS943: 0 | AT943: 0 | AU943: 0 | AV943: 0 | AW943: 40 | AX943: -1 | AY943: -1 | AZ943: -1 | BA943: -1 | BB943: -1 | BC943: -1 | BD943: -1 | BE943: -1 | BF943: -1 | BG943: -1 | BH943: -1 | BI943: -1 | BJ943: -1 | BK943: -1 | BL943: -1 | BM943: 1 | BN943: 1 | BO943: 1 | BP943: 1 | BQ943: 1 | BR943: 1 | BS943: 1 | BT943: 1 | BU943: 1 | BV943: 1 | BW943: 1 | BX943: 1 | BY943: 1 | BZ943: 1 | CA943: 1 | CB943: 1 | CC943: 3 | CD943: 2073 | CE943: 26 | CF943: 51300 | CG943: 2034 | CH943: 2034 | CI943: 2034 | CJ943: 736 | CK943: 270 | CL943: 4 | CM943: 30 | CN943: 150 | CO943: 21.25 | CP943: 150 | CQ943: 5000 | CR943: 7 | CS943: 9 | CT943: 85 | CU943: 0 | CV943: 34 | CW943: 13000 | CX943: 100 | CY943: 100 | CZ943: 1 | DA943: -1 | DB943: 0 | DC943: -1 | DD943: 0 | DE943: -1 | DF943: 0 | DG943: 9 | DH943: 0.082431003 | DI943: 0 | DJ943: 1 | DK943: 20000 | DL943: 50 | DM943: 30 | DN943: 10 | DO943: 0 | DP943: 0 | DQ943: 1 | DR943: 1 | DS943: 1 | DT943: 1 | DU943: 1 | DV943: 1 | DW943: 1 | DX943: 1 | DY943: 1 | DZ943: 1 | EA943: 1 | EB943: 1 | EC943: 1 | ED943: 1 | EE943: 1 | EF943: 1 | EG943: 1 | EH943: 1 | EI943: 1 | EJ943: 1 | EK943: 0 | EL943: 7 | EM943: 1 | EN943: 1 | EO943: 0 | EP943: -1 | EQ943: -1 | ER943: 0 | ES943: -1 | ET943: -1 | EU943: 0 | EV943: -1 | EW943: -1 | EX943: 21 | EY943: 768
A944: 0231B | B944: Lizard Guardian | C944: 00045 | D944: 1 | E944: -1 | F944: 7 | G944: 124 | H944: 10000 | I944: 1 | J944: 50 | K944: 0 | L944: 0 | M944: 1 | N944: 0 | O944: 0 | P944: 0 | Q944: 0 | R944: 0 | S944: 5 | T944: 10 | U944: -1 | V944: 61 | W944: 0 | X944: 55 | Y944: 1 | Z944: -1 | AA944: -1 | AB944: 1143409664 | AC944: 74644.203 | AD944: 0 | AE944: -1 | AF944: 1 | AG944: 0 | AH944: 0 | AI944: 30 | AJ944: 45 | AK944: 642 | AL944: 481 | AM944: -1 | AN944: 0 | AO944: 3063.5 | AP944: 0 | AQ944: 0.067564003 | AR944: 0 | AS944: 0 | AT944: 0 | AU944: 0 | AV944: 60 | AW944: 0 | AX944: -1 | AY944: -1 | AZ944: -1 | BA944: -1 | BB944: -1 | BC944: -1 | BD944: -1 | BE944: -1 | BF944: -1 | BG944: -1 | BH944: -1 | BI944: -1 | BJ944: -1 | BK944: -1 | BL944: -1 | BM944: 1 | BN944: 1 | BO944: 1 | BP944: 1 | BQ944: 1 | BR944: 1 | BS944: 1 | BT944: 1 | BU944: 1 | BV944: 1 | BW944: 1 | BX944: 1 | BY944: 1 | BZ944: 1 | CA944: 1 | CB944: 1 | CC944: 3 | CD944: 40363 | CE944: 26 | CF944: 55800 | CG944: 2034 | CH944: 2034 | CI944: 2034 | CJ944: 1000 | CK944: 270 | CL944: 4 | CM944: 30 | CN944: 250 | CO944: 25 | CP944: 250 | CQ944: 5000 | CR944: 4 | CS944: 6 | CT944: 150 | CU944: 0 | CV944: 60 | CW944: 13000 | CX944: 100 | CY944: 0 | CZ944: 0 | DA944: -1 | DB944: 0 | DC944: -1 | DD944: 0 | DE944: -1 | DF944: 0 | DG944: 9 | DH944: 0.084182002 | DI944: 0 | DJ944: 1 | DK944: 20000 | DL944: 30 | DM944: 20 | DN944: 10 | DO944: 0 | DP944: 0 | DQ944: 1 | DR944: 1 | DS944: 1 | DT944: 1 | DU944: 1 | DV944: 1 | DW944: 1 | DX944: 1 | DY944: 1 | DZ944: 1 | EA944: 1 | EB944: 1 | EC944: 1 | ED944: 1 | EE944: 1 | EF944: 1 | EG944: 1 | EH944: 1 | EI944: 1 | EJ944: 1 | EK944: 0 | EL944: 7 | EM944: 1 | EN944: 1 | EO944: 0 | EP944: -1 | EQ944: -1 | ER944: 0 | ES944: -1 | ET944: -1 | EU944: 0 | EV944: -1 | EW944: -1 | EX944: 21 | EY944: 2049
A945: 0DC1B | B945: Cremul Patrol | C945: 0013F | D945: 1 | E945: -1 | F945: 6 | G945: 124 | H945: 10000 | I945: 1 | J945: 50 | K945: 0 | L945: 0 | M945: 1 | N945: 0 | O945: 0 | P945: 0 | Q945: 0 | R945: 0 | S945: 5 | T945: 10 | U945: -1 | V945: 61 | W945: 0 | X945: 55 | Y945: 1 | Z945: -1 | AA945: -1 | AB945: 418320640 | AC945: 62203.5 | AD945: 0 | AE945: -1 | AF945: 1 | AG945: 0 | AH945: 0 | AI945: 30 | AJ945: 45 | AK945: 622 | AL945: 461 | AM945: -1 | AN945: 0 | AO945: 2367.25 | AP945: 0 | AQ945: 0.067564003 | AR945: 0 | AS945: 0 | AT945: 0 | AU945: 0 | AV945: 0 | AW945: 70 | AX945: -1 | AY945: -1 | AZ945: -1 | BA945: -1 | BB945: -1 | BC945: -1 | BD945: -1 | BE945: -1 | BF945: -1 | BG945: -1 | BH945: -1 | BI945: -1 | BJ945: -1 | BK945: -1 | BL945: -1 | BM945: 1 | BN945: 1 | BO945: 1 | BP945: 1 | BQ945: 1 | BR945: 1 | BS945: 1 | BT945: 1 | BU945: 1 | BV945: 1 | BW945: 1 | BX945: 1 | BY945: 1 | BZ945: 1 | CA945: 1 | CB945: 1 | CC945: 3 | CD945: 20989 | CE945: 26 | CF945: 55800 | CG945: 2034 | CH945: 2034 | CI945: 2034 | CJ945: 1000 | CK945: 270 | CL945: 4 | CM945: 30 | CN945: 250 | CO945: 25 | CP945: 500 | CQ945: 5000 | CR945: 4 | CS945: 6 | CT945: 180 | CU945: 0 | CV945: 72 | CW945: 13000 | CX945: 100 | CY945: 100 | CZ945: 0 | DA945: -1 | DB945: 0 | DC945: -1 | DD945: 0 | DE945: -1 | DF945: 0 | DG945: 9 | DH945: 0.084182002 | DI945: 0 | DJ945: 1 | DK945: 20000 | DL945: 30 | DM945: 20 | DN945: 10 | DO945: 0 | DP945: 0 | DQ945: 1 | DR945: 1 | DS945: 1 | DT945: 1 | DU945: 1 | DV945: 1 | DW945: 1 | DX945: 1 | DY945: 1 | DZ945: 1 | EA945: 1 | EB945: 1 | EC945: 1 | ED945: 1 | EE945: 1 | EF945: 1 | EG945: 1 | EH945: 1 | EI945: 1 | EJ945: 1 | EK945: 0 | EL945: 7 | EM945: 1 | EN945: 1 | EO945: 0 | EP945: -1 | EQ945: -1 | ER945: 0 | ES945: -1 | ET945: -1 | EU945: 0 | EV945: -1 | EW945: -1 | EX945: 21 | EY945: 513
A946: 0301B | B946: Naroom Patrol | C946: 00063 | D946: 1 | E946: -1 | F946: 6 | G946: 128 | H946: 10000 | I946: 1 | J946: 50 | K946: 0 | L946: 0 | M946: 1 | N946: 0 | O946: 0 | P946: 0 | Q946: 0 | R946: 0 | S946: 5 | T946: 10 | U946: -1 | V946: 61 | W946: 0 | X946: 57 | Y946: 1 | Z946: -1 | AA946: -1 | AB946: 353480928 | AC946: 58470.5 | AD946: 0 | AE946: -1 | AF946: 1 | AG946: 0 | AH946: 0 | AI946: 30 | AJ946: 45 | AK946: 726 | AL946: 563 | AM946: -1 | AN946: 0 | AO946: 2541.5 | AP946: 0 | AQ946: 0.063225001 | AR946: 0 | AS946: 0 | AT946: 0 | AU946: 70 | AV946: 0 | AW946: 0 | AX946: -1 | AY946: -1 | AZ946: -1 | BA946: -1 | BB946: -1 | BC946: -1 | BD946: -1 | BE946: -1 | BF946: -1 | BG946: -1 | BH946: -1 | BI946: -1 | BJ946: -1 | BK946: -1 | BL946: -1 | BM946: 1 | BN946: 1 | BO946: 1 | BP946: 1 | BQ946: 1 | BR946: 1 | BS946: 1 | BT946: 1 | BU946: 1 | BV946: 1 | BW946: 1 | BX946: 1 | BY946: 1 | BZ946: 1 | CA946: 1 | CB946: 1 | CC946: 3 | CD946: 21645 | CE946: 26 | CF946: 57600 | CG946: 2034 | CH946: 2034 | CI946: 2034 | CJ946: 1000 | CK946: 270 | CL946: 4 | CM946: 30 | CN946: 250 | CO946: 25 | CP946: 500 | CQ946: 5000 | CR946: 4 | CS946: 6 | CT946: 130 | CU946: 0 | CV946: 52 | CW946: 13000 | CX946: 100 | CY946: 100 | CZ946: 0 | DA946: -1 | DB946: 0 | DC946: -1 | DD946: 0 | DE946: -1 | DF946: 0 | DG946: 9 | DH946: 0.084853001 | DI946: 0 | DJ946: 1 | DK946: 20000 | DL946: 30 | DM946: 20 | DN946: 10 | DO946: 0 | DP946: 0 | DQ946: 1 | DR946: 1 | DS946: 1 | DT946: 1 | DU946: 1 | DV946: 1 | DW946: 1 | DX946: 1 | DY946: 1 | DZ946: 1 | EA946: 1 | EB946: 1 | EC946: 1 | ED946: 1 | EE946: 1 | EF946: 1 | EG946: 1 | EH946: 1 | EI946: 1 | EJ946: 1 | EK946: 0 | EL946: 7 | EM946: 1 | EN946: 1 | EO946: 0 | EP946: -1 | EQ946: -1 | ER946: 0 | ES946: -1 | ET946: -1 | EU946: 0 | EV946: -1 | EW946: -1 | EX946: 19 | EY946: 513
A947: 0E60B | B947: Kukra Patrol | C947: 00073 | D947: 1 | E947: -1 | F947: 6 | G947: 130 | H947: 10000 | I947: 1 | J947: 50 | K947: 0 | L947: 0 | M947: 1 | N947: 0 | O947: 0 | P947: 0 | Q947: 0 | R947: 0 | S947: 5 | T947: 10 | U947: -1 | V947: 61 | W947: 0 | X947: 58 | Y947: 1 | Z947: -1 | AA947: -1 | AB947: 459525184 | AC947: 65841.047 | AD947: 0 | AE947: -1 | AF947: 1 | AG947: 0 | AH947: 0 | AI947: 30 | AJ947: 45 | AK947: 728 | AL947: 564 | AM947: -1 | AN947: 0 | AO947: 2629.05 | AP947: 0 | AQ947: 0.060963001 | AR947: 0 | AS947: 0 | AT947: 70 | AU947: 0 | AV947: 0 | AW947: 0 | AX947: -1 | AY947: -1 | AZ947: -1 | BA947: -1 | BB947: -1 | BC947: -1 | BD947: -1 | BE947: -1 | BF947: -1 | BG947: -1 | BH947: -1 | BI947: -1 | BJ947: -1 | BK947: -1 | BL947: -1 | BM947: 1 | BN947: 1 | BO947: 1 | BP947: 1 | BQ947: 1 | BR947: 1 | BS947: 1 | BT947: 1 | BU947: 1 | BV947: 1 | BW947: 1 | BX947: 1 | BY947: 1 | BZ947: 1 | CA947: 1 | CB947: 1 | CC947: 3 | CD947: 21860 | CE947: 26 | CF947: 58500 | CG947: 2034 | CH947: 2034 | CI947: 2034 | CJ947: 1000 | CK947: 270 | CL947: 4 | CM947: 30 | CN947: 250 | CO947: 168 | CP947: 500 | CQ947: 5000 | CR947: 4 | CS947: 6 | CT947: 140 | CU947: 0 | CV947: 56 | CW947: 13000 | CX947: 100 | CY947: 100 | CZ947: 0 | DA947: -1 | DB947: 0 | DC947: -1 | DD947: 0 | DE947: -1 | DF947: 0 | DG947: 9 | DH947: 0.085182004 | DI947: 0 | DJ947: 1 | DK947: 20000 | DL947: 30 | DM947: 20 | DN947: 10 | DO947: 0 | DP947: 0 | DQ947: 1 | DR947: 1 | DS947: 1 | DT947: 1 | DU947: 1 | DV947: 1 | DW947: 1 | DX947: 1 | DY947: 1 | DZ947: 1 | EA947: 1 | EB947: 1 | EC947: 1 | ED947: 1 | EE947: 1 | EF947: 1 | EG947: 1 | EH947: 1 | EI947: 1 | EJ947: 1 | EK947: 0 | EL947: 7 | EM947: 1 | EN947: 1 | EO947: 0 | EP947: -1 | EQ947: -1 | ER947: 0 | ES947: -1 | ET947: -1 | EU947: 0 | EV947: -1 | EW947: -1 | EX947: 11 | EY947: 513
A948: 00F0B | B948: Infected Ratmoth | C948: 0001B | D948: 1 | E948: -1 | F948: 2 | G948: 120 | H948: 10000 | I948: 1 | J948: 50 | K948: 30 | L948: 50 | M948: 1 | N948: 0 | O948: 0 | P948: 0 | Q948: 0 | R948: 0 | S948: 5 | T948: 10 | U948: -1 | V948: 60 | W948: 0 | X948: 54 | Y948: 1 | Z948: -1 | AA948: -1 | AB948: 577563008 | AC948: 58067.102 | AD948: 0 | AE948: -1 | AF948: 1 | AG948: 0 | AH948: 0 | AI948: 30 | AJ948: 45 | AK948: 518 | AL948: 359 | AM948: -1 | AN948: 0 | AO948: 2838 | AP948: 0.5 | AQ948: 0.072543003 | AR948: 0 | AS948: 0 | AT948: 0 | AU948: 0 | AV948: 0 | AW948: 60 | AX948: -1 | AY948: -1 | AZ948: -1 | BA948: -1 | BB948: -1 | BC948: -1 | BD948: -1 | BE948: -1 | BF948: -1 | BG948: -1 | BH948: -1 | BI948: -1 | BJ948: -1 | BK948: -1 | BL948: -1 | BM948: 1 | BN948: 1 | BO948: 1 | BP948: 1 | BQ948: 1 | BR948: 1 | BS948: 1 | BT948: 1 | BU948: 1 | BV948: 1 | BW948: 1 | BX948: 1 | BY948: 1 | BZ948: 1 | CA948: 1 | CB948: 1 | CC948: 3 | CD948: 39100 | CE948: 26 | CF948: 54000 | CG948: 2034 | CH948: 2034 | CI948: 2034 | CJ948: 640 | CK948: 270 | CL948: 4 | CM948: 30 | CN948: 100 | CO948: 37.5 | CP948: 150 | CQ948: 5000 | CR948: 4 | CS948: 6 | CT948: 120 | CU948: 0 | CV948: 48 | CW948: 13000 | CX948: 0 | CY948: 0 | CZ948: 1 | DA948: -1 | DB948: 0 | DC948: -1 | DD948: 0 | DE948: -1 | DF948: 0 | DG948: 8 | DH948: 0.083494999 | DI948: 0 | DJ948: 1 | DK948: 20000 | DL948: 30 | DM948: 20 | DN948: 10 | DO948: 25 | DP948: 0 | DQ948: 1 | DR948: 1 | DS948: 1 | DT948: 1 | DU948: 1 | DV948: 1 | DW948: 1 | DX948: 1 | DY948: 1 | DZ948: 1 | EA948: 1 | EB948: 1 | EC948: 1 | ED948: 1 | EE948: 1 | EF948: 1 | EG948: 1 | EH948: 1 | EI948: 1 | EJ948: 1 | EK948: 0 | EL948: 7 | EM948: 1 | EN948: 1 | EO948: 0 | EP948: -1 | EQ948: -1 | ER948: 0 | ES948: -1 | ET948: -1 | EU948: 0 | EV948: -1 | EW948: -1 | EX948: 21 | EY948: 1
A949: 01503 | B949: Infected Big Ratmoth | C949: 0002D | D949: 4 | E949: -1 | F949: 2 | G949: 305 | H949: 10000 | I949: 11 | J949: 50 | K949: 30 | L949: 50 | M949: 1 | N949: 0 | O949: 0 | P949: 0 | Q949: 0 | R949: 0 | S949: 5 | T949: 10 | U949: -1 | V949: 61 | W949: 0 | X949: 54 | Y949: 1 | Z949: -1 | AA949: -1 | AB949: 5363084800 | AC949: 73069 | AD949: 0 | AE949: -1 | AF949: 1 | AG949: 0 | AH949: 0 | AI949: 30 | AJ949: 45 | AK949: 320 | AL949: 160 | AM949: -1 | AN949: 0 | AO949: 3219.6001 | AP949: 0.5 | AQ949: 0.069629997 | AR949: 0 | AS949: 0 | AT949: 0 | AU949: 0 | AV949: 0 | AW949: 60 | AX949: -1 | AY949: -1 | AZ949: -1 | BA949: -1 | BB949: -1 | BC949: -1 | BD949: -1 | BE949: -1 | BF949: -1 | BG949: -1 | BH949: -1 | BI949: -1 | BJ949: -1 | BK949: -1 | BL949: -1 | BM949: 1 | BN949: 1 | BO949: 1 | BP949: 1 | BQ949: 1 | BR949: 1 | BS949: 1 | BT949: 1 | BU949: 1 | BV949: 1 | BW949: 1 | BX949: 1 | BY949: 1 | BZ949: 1 | CA949: 1 | CB949: 1 | CC949: 3 | CD949: 63260 | CE949: 26 | CF949: 54900 | CG949: 2034 | CH949: 2034 | CI949: 2034 | CJ949: 640 | CK949: 270 | CL949: 4 | CM949: 30 | CN949: 170 | CO949: 53.125 | CP949: 100 | CQ949: 5000 | CR949: 4 | CS949: 6 | CT949: 170 | CU949: 0 | CV949: 68 | CW949: 13000 | CX949: 0 | CY949: 0 | CZ949: 1 | DA949: -1 | DB949: 0 | DC949: -1 | DD949: 0 | DE949: -1 | DF949: 0 | DG949: 9 | DH949: 0.083839998 | DI949: 0 | DJ949: 1 | DK949: 20000 | DL949: 0 | DM949: 0 | DN949: 0 | DO949: 25 | DP949: 0 | DQ949: 1 | DR949: 1 | DS949: 1 | DT949: 1 | DU949: 1 | DV949: 1 | DW949: 1 | DX949: 1 | DY949: 1 | DZ949: 1 | EA949: 1 | EB949: 1 | EC949: 1 | ED949: 1 | EE949: 1 | EF949: 1 | EG949: 1 | EH949: 1 | EI949: 1 | EJ949: 1 | EK949: 0 | EL949: 7 | EM949: 1 | EN949: 1 | EO949: 0 | EP949: -1 | EQ949: -1 | ER949: 0 | ES949: -1 | ET949: -1 | EU949: 0 | EV949: -1 | EW949: -1 | EX949: 21 | EY949: 1
A950: 04E13 | B950: Rake Foot Draco | C950: 000A1 | D950: 3 | E950: -1 | F950: 2 | G950: 244 | H950: 10000 | I950: 11 | J950: 50 | K950: 30 | L950: 50 | M950: 1 | N950: 0 | O950: 0 | P950: 0 | Q950: 0 | R950: 0 | S950: 5 | T950: 10 | U950: -1 | V950: 61 | W950: 0 | X950: 54 | Y950: 1 | Z950: -1 | AA950: -1 | AB950: 5720624128 | AC950: 65762.102 | AD950: 0 | AE950: -1 | AF950: 1 | AG950: 0 | AH950: 0 | AI950: 30 | AJ950: 45 | AK950: 520 | AL950: 360 | AM950: -1 | AN950: 0 | AO950: 2951.3 | AP950: 0.5 | AQ950: 0.069629997 | AR950: 0 | AS950: 0 | AT950: 0 | AU950: 0 | AV950: 0 | AW950: 60 | AX950: -1 | AY950: -1 | AZ950: -1 | BA950: -1 | BB950: -1 | BC950: -1 | BD950: -1 | BE950: -1 | BF950: -1 | BG950: -1 | BH950: -1 | BI950: -1 | BJ950: -1 | BK950: -1 | BL950: -1 | BM950: 1 | BN950: 1 | BO950: 1 | BP950: 1 | BQ950: 1 | BR950: 1 | BS950: 1 | BT950: 1 | BU950: 1 | BV950: 1 | BW950: 1 | BX950: 1 | BY950: 1 | BZ950: 1 | CA950: 1 | CB950: 1 | CC950: 3 | CD950: 63260 | CE950: 26 | CF950: 54900 | CG950: 1500 | CH950: 1500 | CI950: 1500 | CJ950: 1200 | CK950: 270 | CL950: 4 | CM950: 30 | CN950: 220 | CO950: 240 | CP950: 220 | CQ950: 5000 | CR950: 4 | CS950: 6 | CT950: 80 | CU950: 0 | CV950: 32 | CW950: 13000 | CX950: 100 | CY950: 100 | CZ950: 1 | DA950: -1 | DB950: 0 | DC950: -1 | DD950: 0 | DE950: -1 | DF950: 0 | DG950: 9 | DH950: 0.083839998 | DI950: 0 | DJ950: 1 | DK950: 20000 | DL950: 0 | DM950: 0 | DN950: 0 | DO950: 0 | DP950: 0 | DQ950: 1 | DR950: 1 | DS950: 1 | DT950: 1 | DU950: 1 | DV950: 1 | DW950: 1 | DX950: 1 | DY950: 1 | DZ950: 1 | EA950: 1 | EB950: 1 | EC950: 1 | ED950: 1 | EE950: 1 | EF950: 1 | EG950: 1 | EH950: 1 | EI950: 1 | EJ950: 1 | EK950: 0 | EL950: 7 | EM950: 1 | EN950: 1 | EO950: 0 | EP950: -1 | EQ950: -1 | ER950: 0 | ES950: -1 | ET950: -1 | EU950: 0 | EV950: -1 | EW950: -1 | EX950: 21 | EY950: 2049
A951: 16517 | B951: Endless Flame Draco | C951: 0011E | D951: 2 | E951: -1 | F951: 2 | G951: 924 | H951: 10000 | I951: 11 | J951: 50 | K951: 0 | L951: 0 | M951: 1 | N951: 500 | O951: 800 | P951: 10000 | Q951: 0 | R951: 0 | S951: 5 | T951: 10 | U951: -1 | V951: 66 | W951: 1 | X951: 59 | Y951: 1 | Z951: -1 | AA951: -1 | AB951: 274132303872 | AC951: 122391.9 | AD951: 0 | AE951: -1 | AF951: 1 | AG951: 0 | AH951: 6 | AI951: 30 | AJ951: 30 | AK951: 730 | AL951: 525 | AM951: -1 | AN951: 0 | AO951: 4792.5 | AP951: 0.5 | AQ951: 0.059409 | AR951: 0 | AS951: 0 | AT951: 80 | AU951: 70 | AV951: 70 | AW951: 70 | AX951: 00322 | AY951: 00323 | AZ951: 00303 | BA951: -1 | BB951: -1 | BC951: -1 | BD951: -1 | BE951: -1 | BF951: -1 | BG951: -1 | BH951: -1 | BI951: -1 | BJ951: -1 | BK951: -1 | BL951: -1 | BM951: 1 | BN951: 1 | BO951: 1 | BP951: 1 | BQ951: 1 | BR951: 1 | BS951: 1 | BT951: 1 | BU951: 1 | BV951: 1 | BW951: 1 | BX951: 1 | BY951: 1 | BZ951: 1 | CA951: 1 | CB951: 1 | CC951: 3 | CD951: 3029300 | CE951: 26 | CF951: 59400 | CG951: 1500 | CH951: 1500 | CI951: 1500 | CJ951: 1200 | CK951: 270 | CL951: 4 | CM951: 30 | CN951: 200 | CO951: 420 | CP951: 150 | CQ951: 5000 | CR951: 4 | CS951: 6 | CT951: 350 | CU951: 0 | CV951: 140 | CW951: 13000 | CX951: 100 | CY951: 100 | CZ951: 1 | DA951: -1 | DB951: 0 | DC951: -1 | DD951: 0 | DE951: -1 | DF951: 0 | DG951: 1 | DH951: 0 | DI951: 0 | DJ951: 1 | DK951: 5000 | DL951: 99.900002 | DM951: 60 | DN951: 45 | DO951: 0 | DP951: 0 | DQ951: 1 | DR951: 1 | DS951: 1 | DT951: 1 | DU951: 1 | DV951: 1 | DW951: 1 | DX951: 1 | DY951: 1 | DZ951: 1 | EA951: 1 | EB951: 1 | EC951: 1 | ED951: 1 | EE951: 1 | EF951: 1 | EG951: 1 | EH951: 1 | EI951: 1 | EJ951: 1 | EK951: 0 | EL951: 7 | EM951: 1 | EN951: 1 | EO951: 0 | EP951: -1 | EQ951: -1 | ER951: 0 | ES951: -1 | ET951: -1 | EU951: 0 | EV951: -1 | EW951: -1 | EX951: 14 | EY951: 2049
A952: 00E13 | B952: Queen Hive Marr | C952: 00013 | D952: 5 | E952: -1 | F952: 4 | G952: 366 | H952: 10000 | I952: 11 | J952: 50 | K952: 20 | L952: 20 | M952: 1 | N952: 0 | O952: 0 | P952: 0 | Q952: 0 | R952: 0 | S952: 5 | T952: 10 | U952: -1 | V952: 61 | W952: 0 | X952: 54 | Y952: 1 | Z952: -1 | AA952: -1 | AB952: 35798593536 | AC952: 87682.797 | AD952: 0 | AE952: -1 | AF952: 1 | AG952: 0 | AH952: 0 | AI952: 30 | AJ952: 45 | AK952: 620 | AL952: 460 | AM952: -1 | AN952: 0 | AO952: 3487.8999 | AP952: 0.5 | AQ952: 0.069629997 | AR952: 0 | AS952: 0 | AT952: 0 | AU952: 0 | AV952: 0 | AW952: 60 | AX952: 00303 | AY952: -1 | AZ952: -1 | BA952: -1 | BB952: -1 | BC952: -1 | BD952: -1 | BE952: -1 | BF952: -1 | BG952: -1 | BH952: -1 | BI952: -1 | BJ952: -1 | BK952: -1 | BL952: -1 | BM952: 1 | BN952: 1 | BO952: 1 | BP952: 1 | BQ952: 1 | BR952: 1 | BS952: 1 | BT952: 1 | BU952: 1 | BV952: 1 | BW952: 1 | BX952: 1 | BY952: 1 | BZ952: 1 | CA952: 1 | CB952: 1 | CC952: 3 | CD952: 189780 | CE952: 26 | CF952: 54900 | CG952: 2034 | CH952: 2034 | CI952: 2034 | CJ952: 736 | CK952: 270 | CL952: 4 | CM952: 30 | CN952: 150 | CO952: 45 | CP952: 100 | CQ952: 5000 | CR952: 6 | CS952: 9 | CT952: 180 | CU952: 0 | CV952: 72 | CW952: 13000 | CX952: 100 | CY952: 0 | CZ952: 1 | DA952: 00903 | DB952: 2 | DC952: 00E03 | DD952: 1 | DE952: -1 | DF952: 0 | DG952: 1 | DH952: 0 | DI952: 0 | DJ952: 1 | DK952: 20000 | DL952: 0 | DM952: 0 | DN952: 0 | DO952: 50 | DP952: 0 | DQ952: 1 | DR952: 1 | DS952: 1 | DT952: 1 | DU952: 1 | DV952: 1 | DW952: 1 | DX952: 1 | DY952: 1 | DZ952: 1 | EA952: 1 | EB952: 1 | EC952: 1 | ED952: 1 | EE952: 1 | EF952: 1 | EG952: 1 | EH952: 1 | EI952: 1 | EJ952: 1 | EK952: 0 | EL952: 7 | EM952: 1 | EN952: 1 | EO952: 0 | EP952: -1 | EQ952: -1 | ER952: 0 | ES952: -1 | ET952: -1 | EU952: 0 | EV952: -1 | EW952: -1 | EX952: 21 | EY952: 768
A953: 06A13 | B953: Ringleader RoyalGuard | C953: 000ED | D953: 5 | E953: -1 | F953: 7 | G953: 378 | H953: 10000 | I953: 11 | J953: 50 | K953: 0 | L953: 0 | M953: 1 | N953: 0 | O953: 0 | P953: 0 | Q953: 0 | R953: 0 | S953: 5 | T953: 10 | U953: -1 | V953: 61 | W953: 0 | X953: 56 | Y953: 1 | Z953: -1 | AA953: -1 | AB953: 49509990400 | AC953: 74568 | AD953: 0 | AE953: -1 | AF953: 1 | AG953: 0 | AH953: 0 | AI953: 30 | AJ953: 45 | AK953: 524 | AL953: 262 | AM953: -1 | AN953: 0 | AO953: 2454.8 | AP953: 0.5 | AQ953: 0.065008998 | AR953: 0 | AS953: 0 | AT953: 0 | AU953: 0 | AV953: 70 | AW953: 0 | AX953: 00303 | AY953: -1 | AZ953: -1 | BA953: -1 | BB953: -1 | BC953: -1 | BD953: -1 | BE953: -1 | BF953: -1 | BG953: -1 | BH953: -1 | BI953: -1 | BJ953: -1 | BK953: -1 | BL953: -1 | BM953: 1 | BN953: 1 | BO953: 1 | BP953: 1 | BQ953: 1 | BR953: 1 | BS953: 1 | BT953: 1 | BU953: 1 | BV953: 1 | BW953: 1 | BX953: 1 | BY953: 1 | BZ953: 1 | CA953: 1 | CB953: 1 | CC953: 3 | CD953: 97890 | CE953: 26 | CF953: 56700 | CG953: 2034 | CH953: 2034 | CI953: 2034 | CJ953: 1000 | CK953: 270 | CL953: 4 | CM953: 30 | CN953: 250 | CO953: 25 | CP953: 500 | CQ953: 5000 | CR953: 4 | CS953: 6 | CT953: 200 | CU953: 0 | CV953: 80 | CW953: 13000 | CX953: 100 | CY953: 100 | CZ953: 0 | DA953: -1 | DB953: 0 | DC953: -1 | DD953: 0 | DE953: -1 | DF953: 0 | DG953: 9 | DH953: 0.084518999 | DI953: 0 | DJ953: 1 | DK953: 20000 | DL953: 0 | DM953: 0 | DN953: 0 | DO953: 0 | DP953: 0 | DQ953: 1 | DR953: 1 | DS953: 1 | DT953: 1 | DU953: 1 | DV953: 1 | DW953: 1 | DX953: 1 | DY953: 1 | DZ953: 1 | EA953: 1 | EB953: 1 | EC953: 1 | ED953: 1 | EE953: 1 | EF953: 1 | EG953: 1 | EH953: 1 | EI953: 1 | EJ953: 1 | EK953: 0 | EL953: 7 | EM953: 1 | EN953: 1 | EO953: 0 | EP953: -1 | EQ953: -1 | ER953: 0 | ES953: -1 | ET953: -1 | EU953: 0 | EV953: -1 | EW953: -1 | EX953: 6 | EY953: 514
A954: 16703 | B954: Dark Clan Mercenery | C954: 000D1 | D954: 4 | E954: -1 | F954: 8 | G954: 335 | H954: 10000 | I954: 11 | J954: 50 | K954: 0 | L954: 0 | M954: 1 | N954: 0 | O954: 0 | P954: 0 | Q954: 0 | R954: 0 | S954: 5 | T954: 10 | U954: -1 | V954: 67 | W954: 0 | X954: 60 | Y954: 1 | Z954: -1 | AA954: -1 | AB954: 43144310784 | AC954: 173807 | AD954: 0 | AE954: -1 | AF954: 1 | AG954: 0 | AH954: 0 | AI954: 30 | AJ954: 45 | AK954: 332 | AL954: 166 | AM954: -1 | AN954: 0 | AO954: 3298 | AP954: 0 | AQ954: 0.057390999 | AR954: 0 | AS954: 0 | AT954: 0 | AU954: 0 | AV954: 0 | AW954: 0 | AX954: -1 | AY954: -1 | AZ954: -1 | BA954: -1 | BB954: -1 | BC954: -1 | BD954: -1 | BE954: -1 | BF954: -1 | BG954: -1 | BH954: -1 | BI954: -1 | BJ954: -1 | BK954: -1 | BL954: -1 | BM954: 1 | BN954: 1 | BO954: 1 | BP954: 1 | BQ954: 1 | BR954: 1 | BS954: 1 | BT954: 1 | BU954: 1 | BV954: 1 | BW954: 1 | BX954: 1 | BY954: 1 | BZ954: 1 | CA954: 1 | CB954: 1 | CC954: 3 | CD954: 69280 | CE954: 26 | CF954: 60300 | CG954: 2034 | CH954: 2034 | CI954: 2034 | CJ954: 1000 | CK954: 270 | CL954: 4 | CM954: 30 | CN954: 100 | CO954: 25 | CP954: 100 | CQ954: 5000 | CR954: 2 | CS954: 6 | CT954: 100 | CU954: 0 | CV954: 40 | CW954: 13000 | CX954: 0 | CY954: 0 | CZ954: 0 | DA954: -1 | DB954: 0 | DC954: -1 | DD954: 0 | DE954: -1 | DF954: 0 | DG954: 1 | DH954: 0 | DI954: 0 | DJ954: 1 | DK954: 20000 | DL954: 0 | DM954: 0 | DN954: 0 | DO954: 0 | DP954: 0 | DQ954: 1 | DR954: 1 | DS954: 1 | DT954: 1 | DU954: 1 | DV954: 1 | DW954: 1 | DX954: 1 | DY954: 1 | DZ954: 1 | EA954: 1 | EB954: 1 | EC954: 1 | ED954: 1 | EE954: 1 | EF954: 1 | EG954: 1 | EH954: 1 | EI954: 1 | EJ954: 1 | EK954: 0 | EL954: 7 | EM954: 1 | EN954: 1 | EO954: 0 | EP954: -1 | EQ954: -1 | ER954: 0 | ES954: -1 | ET954: -1 | EU954: 0 | EV954: -1 | EW954: -1 | EX954: 2 | EY954: 514
... A1452: 1E904 | B1452: Big Black Beacon | C1452: 00109 | D1452: 2 | E1452: -1 | F1452: 7 | G1452: 88 | H1452: 10000 | I1452: 11 | J1452: 50 | K1452: 30 | L1452: 100 | M1452: 1 | N1452: 500 | O1452: 800 | P1452: 60000 | Q1452: 0 | R1452: 0 | S1452: 5 | T1452: 10 | U1452: -1 | V1452: 75 | W1452: 1 | X1452: 64 | Y1452: 1 | Z1452: -1 | AA1452: -1 | AB1452: 865035747328 | AC1452: 637464 | AD1452: 0 | AE1452: -1 | AF1452: 1 | AG1452: 0 | AH1452: 6 | AI1452: 30 | AJ1452: 30 | AK1452: 942 | AL1452: 571 | AM1452: -1 | AN1452: 0 | AO1452: 11430 | AP1452: 0.5 | AQ1452: 0.050301999 | AR1452: 0 | AS1452: 0 | AT1452: 100 | AU1452: 100 | AV1452: 100 | AW1452: 100 | AX1452: 00407 | AY1452: -1 | AZ1452: -1 | BA1452: -1 | BB1452: -1 | BC1452: -1 | BD1452: -1 | BE1452: -1 | BF1452: -1 | BG1452: -1 | BH1452: -1 | BI1452: -1 | BJ1452: -1 | BK1452: -1 | BL1452: -1 | BM1452: 7 | BN1452: 1 | BO1452: 1 | BP1452: 1 | BQ1452: 1 | BR1452: 1 | BS1452: 1 | BT1452: 1 | BU1452: 1 | BV1452: 1 | BW1452: 1 | BX1452: 1 | BY1452: 1 | BZ1452: 1 | CA1452: 1 | CB1452: 1 | CC1452: 3 | CD1452: 50000000 | CE1452: 10 | CF1452: 151200 | CG1452: 2034 | CH1452: 1200 | CI1452: 1200 | CJ1452: 928 | CK1452: 270 | CL1452: 4 | CM1452: 30 | CN1452: 150 | CO1452: 0 | CP1452: 150 | CQ1452: 5000 | CR1452: 0 | CS1452: 0 | CT1452: 125 | CU1452: 0 | CV1452: 10 | CW1452: 8000 | CX1452: 100 | CY1452: 100 | CZ1452: 0 | DA1452: -1 | DB1452: 0 | DC1452: -1 | DD1452: 0 | DE1452: -1 | DF1452: 0 | DG1452: 5 | DH1452: 0 | DI1452: 0 | DJ1452: 1 | DK1452: 5000 | DL1452: 99.900002 | DM1452: 60 | DN1452: 45 | DO1452: 0 | DP1452: 0 | DQ1452: 1 | DR1452: 1 | DS1452: 1 | DT1452: 1 | DU1452: 1 | DV1452: 1 | DW1452: 1 | DX1452: 1 | DY1452: 1 | DZ1452: 1 | EA1452: 1 | EB1452: 1 | EC1452: 1 | ED1452: 1 | EE1452: 1 | EF1452: 1 | EG1452: 1 | EH1452: 1 | EI1452: 1 | EJ1452: 1 | EK1452: 0 | EL1452: 7 | EM1452: 1 | EN1452: 1 | EO1452: 0 | EP1452: -1 | EQ1452: -1 | ER1452: 0 | ES1452: -1 | ET1452: -1 | EU1452: 0 | EV1452: -1 | EW1452: -1 | EX1452: -1 | EY1452: 2560
A1453: 23301 | B1453: Dark Lord | C1453: 00200 | D1453: 2 | E1453: -1 | F1453: 5 | G1453: 994 | H1453: 10000 | I1453: 11 | J1453: 50 | K1453: 30 | L1453: 100 | M1453: 1 | N1453: 500 | O1453: 800 | P1453: 60000 | Q1453: 0 | R1453: 0 | S1453: 5 | T1453: 10 | U1453: -1 | V1453: 60 | W1453: 1 | X1453: 64 | Y1453: 1 | Z1453: -1 | AA1453: -1 | AB1453: 865035747328 | AC1453: 509971 | AD1453: 0 | AE1453: -1 | AF1453: 1 | AG1453: 0 | AH1453: 6 | AI1453: 30 | AJ1453: 30 | AK1453: 942 | AL1453: 571 | AM1453: -1 | AN1453: 0 | AO1453: 11430 | AP1453: 0.5 | AQ1453: 0.050301999 | AR1453: 0 | AS1453: 0 | AT1453: 100 | AU1453: 100 | AV1453: 100 | AW1453: 100 | AX1453: 00407 | AY1453: -1 | AZ1453: -1 | BA1453: -1 | BB1453: -1 | BC1453: -1 | BD1453: -1 | BE1453: -1 | BF1453: -1 | BG1453: -1 | BH1453: -1 | BI1453: -1 | BJ1453: -1 | BK1453: -1 | BL1453: -1 | BM1453: 7 | BN1453: 1 | BO1453: 1 | BP1453: 1 | BQ1453: 1 | BR1453: 1 | BS1453: 1 | BT1453: 1 | BU1453: 1 | BV1453: 1 | BW1453: 1 | BX1453: 1 | BY1453: 1 | BZ1453: 1 | CA1453: 1 | CB1453: 1 | CC1453: 3 | CD1453: 35000000 | CE1453: 10 | CF1453: 151200 | CG1453: 2034 | CH1453: 1200 | CI1453: 1200 | CJ1453: 928 | CK1453: 270 | CL1453: 4 | CM1453: 30 | CN1453: 150 | CO1453: 175 | CP1453: 150 | CQ1453: 5000 | CR1453: 5 | CS1453: 8 | CT1453: 300 | CU1453: 0 | CV1453: 140 | CW1453: 8000 | CX1453: 100 | CY1453: 100 | CZ1453: 0 | DA1453: -1 | DB1453: 0 | DC1453: -1 | DD1453: 0 | DE1453: -1 | DF1453: 0 | DG1453: 5 | DH1453: 0 | DI1453: 0 | DJ1453: 1 | DK1453: 5000 | DL1453: 99.900002 | DM1453: 60 | DN1453: 45 | DO1453: 0 | DP1453: 0 | DQ1453: 1 | DR1453: 1 | DS1453: 1 | DT1453: 1 | DU1453: 1 | DV1453: 1 | DW1453: 1 | DX1453: 1 | DY1453: 1 | DZ1453: 1 | EA1453: 1 | EB1453: 1 | EC1453: 1 | ED1453: 1 | EE1453: 1 | EF1453: 1 | EG1453: 1 | EH1453: 1 | EI1453: 1 | EJ1453: 1 | EK1453: 0 | EL1453: 7 | EM1453: 1 | EN1453: 1 | EO1453: 0 | EP1453: -1 | EQ1453: -1 | ER1453: 0 | ES1453: -1 | ET1453: -1 | EU1453: 0 | EV1453: -1 | EW1453: -1 | EX1453: 1 | EY1453: 514

Sheet MonsterCharacterAI
A1: string[64] | B1: dword | C1: string[64] | D1: dword | E1: float | F1: dword | G1: dword | H1: dword | I1: dword | J1: dword | K1: dword | L1: dword | M1: dword | N1: END
A2: Code | B2: SpAttType | C2: SpAttCode | D2: AttLv | E2: SpRange | F2: MotiveCond | G2: MotiveVal | H2: MotExcepCond | I2: MotExcepVal | J2: MotiveTime | K2: DstType | L2: LimitCount | M2: Probability
A3: 00000 | B3: 1 | C3: 9401 | D3: 1 | E3: -1 | F3: 0 | G3: -1 | H3: -1 | I3: -1 | J3: 10 | K3: 0 | L3: 15 | M3: 100
A4: 00001 | B4: 1 | C4: 7104 | D4: 1 | E4: -1 | F4: 1 | G4: 20 | H4: -1 | I4: -1 | J4: 20 | K4: 1 | L4: 15 | M4: 100
A5: 00002 | B5: 1 | C5: 9303 | D5: 3 | E5: -1 | F5: 0 | G5: -1 | H5: -1 | I5: -1 | J5: 10 | K5: 0 | L5: 15 | M5: 100
A6: 00003 | B6: 1 | C6: 9502 | D6: 1 | E6: -1 | F6: 1 | G6: 70 | H6: -1 | I6: -1 | J6: 10 | K6: 0 | L6: 15 | M6: 100
A7: 00004 | B7: 1 | C7: 9500 | D7: 1 | E7: -1 | F7: 1 | G7: 60 | H7: -1 | I7: -1 | J7: 4 | K7: 0 | L7: 15 | M7: 100
A8: 00005 | B8: 1 | C8: 9302 | D8: 5 | E8: -1 | F8: 0 | G8: -1 | H8: -1 | I8: -1 | J8: 10 | K8: 0 | L8: 15 | M8: 100
A9: 00006 | B9: 1 | C9: 9407 | D9: 1 | E9: -1 | F9: 0 | G9: -1 | H9: -1 | I9: -1 | J9: 10 | K9: 0 | L9: 15 | M9: 100
A10: 00007 | B10: 1 | C10: 930A | D10: 3 | E10: -1 | F10: 1 | G10: 90 | H10: -1 | I10: -1 | J10: 10 | K10: 0 | L10: 15 | M10: 100
A11: 00008 | B11: 1 | C11: 9401 | D11: 1 | E11: -1 | F11: 1 | G11: 70 | H11: -1 | I11: -1 | J11: 5 | K11: 0 | L11: 15 | M11: 100
A12: 00009 | B12: 1 | C12: 930B | D12: 4 | E12: -1 | F12: 1 | G12: 80 | H12: -1 | I12: -1 | J12: 10 | K12: 0 | L12: 15 | M12: 100
A13: 00010 | B13: 1 | C13: 9302 | D13: 1 | E13: -1 | F13: 0 | G13: -1 | H13: -1 | I13: -1 | J13: 10 | K13: 0 | L13: 15 | M13: 100
A14: 00011 | B14: 1 | C14: 9303 | D14: 4 | E14: -1 | F14: 0 | G14: -1 | H14: -1 | I14: -1 | J14: 10 | K14: 0 | L14: 15 | M14: 100
... A481: 00478 | B481: 2 | C481: 4F1F1 | D481: 1 | E481: -1 | F481: 0 | G481: -1 | H481: -1 | I481: -1 | J481: 5 | K481: 0 | L481: 15 | M481: 100

Sheet moncli
A1: xeh | B1: string[32] | C1: byte | D1: byte | E1: byte | F1: byte | G1: dword | H1: dword | I1: dword | J1: float | K1: ubyte | L1: ubyte | M1: ubyte | N1: byte | O1: float | P1: dword | Q1: dword | R1: xeh | S1: dword | T1: dword | U1: dword | V1: dword | W1: custom | X1: custom | Y1: custom | Z1: custom | AA1: custom | AB1: custom | AC1: custom | AD1: custom | AE1: custom | AF1: custom | AG1: custom | AH1: custom | AI1: custom | AJ1: custom | AK1: custom | AL1: custom | AM1: custom | AN1: custom | AO1: custom | AP1: custom | AQ1: custom | AR1: custom | AS1: custom | AT1: custom | AU1: custom | AV1: custom | AW1: custom | AX1: custom | AY1: custom | AZ1: custom | BA1: dword | BB1: dword | BC1: END
A2: =MonsterCharacter!A2 -> Code | B2: =MonsterCharacter!B2 -> Name | C2: =MonsterCharacter!E2 -> RaceCode | D2: =MonsterCharacter!D2 -> MobGrade | E2: =MonsterCharacter!V2 -> Level | F2: none | G2: =MonsterCharacter!CD2 -> MaxHP | H2: =MonsterCharacter!CG2 -> AttSpd | I2: =MonsterCharacter!AG2 -> bAttRangeType | J2: =MonsterCharacter!CO2 -> AttExt | K2: =MonsterCharacter!CR2 -> MovSpd | L2: =MonsterCharacter!CS2 -> WarMovSpd | M2: =MonsterCharacter!CV2 -> Width | N2: none | O2: =MonsterCharacter!CT2 -> ScaleRate | P2: hz | Q2: =MonsterCharacter!W2 -> bMonsterCond | R2: =MonsterCharacter!C2 -> EffectCode | S2: =MonsterCharacter!EX2 -> AttEffType | T2: =MonsterCharacter!EY2 -> DefEffType | U2: =MonsterCharacter!DH2 -> OffensiveRate | V2: fire,water,soil,wind | W2: SpAttType_1 | X2: SpAttCode_1 | Y2: SpAttType_2 | Z2: SpAttCode_2 | AA2: SpAttType_3 | AB2: SpAttCode_3 | AC2: SpAttType_4 | AD2: SpAttCode_4 | AE2: SpAttType_5 | AF2: SpAttCode_5 | AG2: SpAttType_6 | AH2: SpAttCode_6 | AI2: SpAttType_7 | AJ2: SpAttCode_7 | AK2: SpAttType_8 | AL2: SpAttCode_8 | AM2: SpAttType_9 | AN2: SpAttCode_9 | AO2: SpAttType_10 | AP2: SpAttCode_10 | AQ2: SpAttType_11 | AR2: SpAttCode_11 | AS2: SpAttType_12 | AT2: SpAttCode_12 | AU2: SpAttType_13 | AV2: SpAttCode_13 | AW2: SpAttType_14 | AX2: SpAttCode_14 | AY2: SpAttType_15 | AZ2: SpAttCode_15 | BA2: =MonsterCharacter!F2 -> MobRace | BB2: =MonsterCharacter!G2 -> KillPoint
