Workbook

Sheet Server
A1: string[64] | B1: dword | C1: string[2560] | D1: string[2560] | E1: string[2560] | F1: string[2560] | G1: string[2560] | H1: string[2560] | I1: string[2560] | J1: string[2560] | K1: string[2560] | L1: string[2560] | M1: string[2560] | N1: string[2560] | O1: string[2560] | P1: string[2560] | Q1: string[2560] | R1: string[2560] | S1: string[2560] | T1: string[2560] | U1: string[2560] | V1: string[2560] | W1: string[2560] | X1: string[2560] | Y1: string[2560] | Z1: string[2560] | AA1: string[2560] | AB1: string[2560] | AC1: string[2560] | AD1: string[2560] | AE1: string[2560] | AF1: string[2560] | AG1: string[2560] | AH1: string[2560] | AI1: string[2560] | AJ1: string[2560] | AK1: string[2560] | AL1: string[2560] | AM1: string[2560] | AN1: string[2560] | AO1: string[2560] | AP1: string[2560] | AQ1: string[2560] | AR1: string[2560] | AS1: string[2560] | AT1: string[2560] | AU1: string[2560] | AV1: string[2560] | AW1: string[2560] | AX1: string[2560] | AY1: string[2560] | AZ1: string[2560] | BA1: string[2560] | BB1: string[2560] | BC1: string[2560] | BD1: string[2560] | BE1: string[2560] | BF1: string[2560] | BG1: string[2560] | BH1: string[2560] | BI1: string[2560] | BJ1: string[2560] | BK1: string[2560] | BL1: string[2560] | BM1: string[2560] | BN1: string[2560] | BO1: string[2560] | BP1: string[2560] | BQ1: string[2560] | BR1: string[2560] | BS1: string[2560] | BT1: string[2560] | BU1: string[2560] | BV1: string[2560] | BW1: string[2560] | BX1: string[2560] | BY1: string[2560] | BZ1: string[2560] | CA1: string[2560] | CB1: string[2560] | CC1: string[2560] | CD1: string[2560] | CE1: string[2560] | CF1: string[2560] | CG1: string[2560] | CH1: string[2560] | CI1: string[2560] | CJ1: string[2560] | CK1: string[2560] | CL1: string[2560] | CM1: string[2560] | CN1: string[2560] | CO1: END
A2: Code | B2: UsingNum | C2: MobMessage_KR_1 | D2: MobMessage_KR_2 | E2: MobMessage_KR_3 | F2: MobMessage_KR_4 | G2: MobMessage_KR_5 | H2: MobMessage_KR_6 | I2: MobMessage_KR_7 | J2: MobMessage_KR_8 | K2: MobMessage_KR_9 | L2: MobMessage_KR_10 | M2: MobMessage_BR_1 | N2: MobMessage_BR_2 | O2: MobMessage_BR_3 | P2: MobMessage_BR_4 | Q2: MobMessage_BR_5 | R2: MobMessage_BR_6 | S2: MobMessage_BR_7 | T2: MobMessage_BR_8 | U2: MobMessage_BR_9 | V2: MobMessage_BR_10 | W2: MobMessage_CH_1 | X2: MobMessage_CH_2 | Y2: MobMessage_CH_3 | Z2: MobMessage_CH_4 | AA2: MobMessage_CH_5 | AB2: MobMessage_CH_6 | AC2: MobMessage_CH_7 | AD2: MobMessage_CH_8 | AE2: MobMessage_CH_9 | AF2: MobMessage_CH_10 | AG2: MobMessage_GB_1 | AH2: MobMessage_GB_2 | AI2: MobMessage_GB_3 | AJ2: MobMessage_GB_4 | AK2: MobMessage_GB_5 | AL2: MobMessage_GB_6 | AM2: MobMessage_GB_7 | AN2: MobMessage_GB_8 | AO2: MobMessage_GB_9 | AP2: MobMessage_GB_10 | AQ2: MobMessage_IN_1 | AR2: MobMessage_IN_2 | AS2: MobMessage_IN_3 | AT2: MobMessage_IN_4 | AU2: MobMessage_IN_5 | AV2: MobMessage_IN_6 | AW2: MobMessage_IN_7 | AX2: MobMessage_IN_8 | AY2: MobMessage_IN_9 | AZ2: MobMessage_IN_10 | BA2: MobMessage_JP_1 | BB2: MobMessage_JP_2 | BC2: MobMessage_JP_3 | BD2: MobMessage_JP_4 | BE2: MobMessage_JP_5 | BF2: MobMessage_JP_6 | BG2: MobMessage_JP_7 | BH2: MobMessage_JP_8 | BI2: MobMessage_JP_9 | BJ2: MobMessage_JP_10 | BK2: MobMessage_PH_1 | BL2: MobMessage_PH_2 | BM2: MobMessage_PH_3 | BN2: MobMessage_PH_4 | BO2: MobMessage_PH_5 | BP2: MobMessage_PH_6 | BQ2: MobMessage_PH_7 | BR2: MobMessage_PH_8 | BS2: MobMessage_PH_9 | BT2: MobMessage_PH_10 | BU2: MobMessage_RU_1 | BV2: MobMessage_RU_2 | BW2: MobMessage_RU_3 | BX2: MobMessage_RU_4 | BY2: MobMessage_RU_5 | BZ2: MobMessage_RU_6 | CA2: MobMessage_RU_7 | CB2: MobMessage_RU_8 | CC2: MobMessage_RU_9 | CD2: MobMessage_RU_10 | CE2: MobMessage_TP_1 | CF2: MobMessage_TP_2 | CG2: MobMessage_TP_3 | CH2: MobMessage_TP_4 | CI2: MobMessage_TP_5 | CJ2: MobMessage_TP_6 | CK2: MobMessage_TP_7 | CL2: MobMessage_TP_8 | CM2: MobMessage_TP_9 | CN2: MobMessage_TP_10 | CO2: MobMessage_GB_1 | CP2: MobMessage_GB_2 | CQ2: MobMessage_GB_3 | CR2: MobMessage_GB_4 | CS2: MobMessage_GB_5 | CT2: MobMessage_GB_6 | CU2: MobMessage_GB_7 | CV2: MobMessage_GB_8 | CW2: MobMessage_GB_9 | CX2: MobMessage_GB_10 | CY2: MobMessage_GB_1 | CZ2: MobMessage_GB_2 | DA2: MobMessage_GB_3 | DB2: MobMessage_GB_4 | DC2: MobMessage_GB_5 | DD2: MobMessage_GB_6 | DE2: MobMessage_GB_7 | DF2: MobMessage_GB_8 | DG2: MobMessage_GB_9 | DH2: MobMessage_GB_10
A3: 0 | B3: 0 | C3: _ | D3: _ | E3: _ | F3: _ | G3: _ | H3: _ | I3: _ | J3: _ | K3: _ | L3: _ | M3: _ | N3: _ | O3: _ | P3: _ | Q3: _ | R3: _ | S3: _ | T3: _ | U3: _ | V3: _ | W3: _ | X3: _ | Y3: _ | Z3: _ | AA3: _ | AB3: _ | AC3: _ | AD3: _ | AE3: _ | AF3: _ | AG3: _ | AH3: _ | AI3: _ | AJ3: _ | AK3: _ | AL3: _ | AM3: _ | AN3: _ | AO3: _ | AP3: _ | AQ3: _ | AR3: _ | AS3: _ | AT3: _ | AU3: _ | AV3: _ | AW3: _ | AX3: _ | AY3: _ | AZ3: _ | BA3: _ | BB3: _ | BC3: _ | BD3: _ | BE3: _ | BF3: _ | BG3: _ | BH3: _ | BI3: _ | BJ3: _ | BK3: _ | BL3: _ | BM3: _ | BN3: _ | BO3: _ | BP3: _ | BQ3: _ | BR3: _ | BS3: _ | BT3: _ | BU3: _ | BV3: _ | BW3: _ | BX3: _ | BY3: _ | BZ3: _ | CA3: _ | CB3: _ | CC3: _ | CD3: _ | CE3: _ | CF3: _ | CG3: _ | CH3: _ | CI3: _ | CJ3: _ | CK3: _ | CL3: _ | CM3: _ | CN3: _ | CO3: _ | CP3: _ | CQ3: _ | CR3: _ | CS3: _ | CT3: _ | CU3: _ | CV3: _ | CW3: _ | CX3: _ | CY3: _ | CZ3: _ | DA3: _ | DB3: _ | DC3: _ | DD3: _ | DE3: _ | DF3: _ | DG3: _ | DH3: _
A4: 1 | B4: 0 | C4: _ | D4: _ | E4: _ | F4: _ | G4: _ | H4: _ | I4: _ | J4: _ | K4: _ | L4: _ | M4: _ | N4: _ | O4: _ | P4: _ | Q4: _ | R4: _ | S4: _ | T4: _ | U4: _ | V4: _ | W4: _ | X4: _ | Y4: _ | Z4: _ | AA4: _ | AB4: _ | AC4: _ | AD4: _ | AE4: _ | AF4: _ | AG4: _ | AH4: _ | AI4: _ | AJ4: _ | AK4: _ | AL4: _ | AM4: _ | AN4: _ | AO4: _ | AP4: _ | AQ4: _ | AR4: _ | AS4: _ | AT4: _ | AU4: _ | AV4: _ | AW4: _ | AX4: _ | AY4: _ | AZ4: _ | BA4: _ | BB4: _ | BC4: _ | BD4: _ | BE4: _ | BF4: _ | BG4: _ | BH4: _ | BI4: _ | BJ4: _ | BK4: _ | BL4: _ | BM4: _ | BN4: _ | BO4: _ | BP4: _ | BQ4: _ | BR4: _ | BS4: _ | BT4: _ | BU4: _ | BV4: _ | BW4: _ | BX4: _ | BY4: _ | BZ4: _ | CA4: _ | CB4: _ | CC4: _ | CD4: _ | CE4: _ | CF4: _ | CG4: _ | CH4: _ | CI4: _ | CJ4: _ | CK4: _ | CL4: _ | CM4: _ | CN4: _ | CO4: _ | CP4: _ | CQ4: _ | CR4: _ | CS4: _ | CT4: _ | CU4: _ | CV4: _ | CW4: _ | CX4: _ | CY4: _ | CZ4: _ | DA4: _ | DB4: _ | DC4: _ | DD4: _ | DE4: _ | DF4: _ | DG4: _ | DH4: _
A5: 2 | B5: 0 | C5: _ | D5: _ | E5: _ | F5: _ | G5: _ | H5: _ | I5: _ | J5: _ | K5: _ | L5: _ | M5: _ | N5: _ | O5: _ | P5: _ | Q5: _ | R5: _ | S5: _ | T5: _ | U5: _ | V5: _ | W5: _ | X5: _ | Y5: _ | Z5: _ | AA5: _ | AB5: _ | AC5: _ | AD5: _ | AE5: _ | AF5: _ | AG5: _ | AH5: _ | AI5: _ | AJ5: _ | AK5: _ | AL5: _ | AM5: _ | AN5: _ | AO5: _ | AP5: _ | AQ5: _ | AR5: _ | AS5: _ | AT5: _ | AU5: _ | AV5: _ | AW5: _ | AX5: _ | AY5: _ | AZ5: _ | BA5: _ | BB5: _ | BC5: _ | BD5: _ | BE5: _ | BF5: _ | BG5: _ | BH5: _ | BI5: _ | BJ5: _ | BK5: _ | BL5: _ | BM5: _ | BN5: _ | BO5: _ | BP5: _ | BQ5: _ | BR5: _ | BS5: _ | BT5: _ | BU5: _ | BV5: _ | BW5: _ | BX5: _ | BY5: _ | BZ5: _ | CA5: _ | CB5: _ | CC5: _ | CD5: _ | CE5: _ | CF5: _ | CG5: _ | CH5: _ | CI5: _ | CJ5: _ | CK5: _ | CL5: _ | CM5: _ | CN5: _ | CO5: _ | CP5: _ | CQ5: _ | CR5: _ | CS5: _ | CT5: _ | CU5: _ | CV5: _ | CW5: _ | CX5: _ | CY5: _ | CZ5: _ | DA5: _ | DB5: _ | DC5: _ | DD5: _ | DE5: _ | DF5: _ | DG5: _ | DH5: _
A6: 3 | B6: 0 | C6: _ | D6: _ | E6: _ | F6: _ | G6: _ | H6: _ | I6: _ | J6: _ | K6: _ | L6: _ | M6: _ | N6: _ | O6: _ | P6: _ | Q6: _ | R6: _ | S6: _ | T6: _ | U6: _ | V6: _ | W6: _ | X6: _ | Y6: _ | Z6: _ | AA6: _ | AB6: _ | AC6: _ | AD6: _ | AE6: _ | AF6: _ | AG6: _ | AH6: _ | AI6: _ | AJ6: _ | AK6: _ | AL6: _ | AM6: _ | AN6: _ | AO6: _ | AP6: _ | AQ6: _ | AR6: _ | AS6: _ | AT6: _ | AU6: _ | AV6: _ | AW6: _ | AX6: _ | AY6: _ | AZ6: _ | BA6: _ | BB6: _ | BC6: _ | BD6: _ | BE6: _ | BF6: _ | BG6: _ | BH6: _ | BI6: _ | BJ6: _ | BK6: _ | BL6: _ | BM6: _ | BN6: _ | BO6: _ | BP6: _ | BQ6: _ | BR6: _ | BS6: _ | BT6: _ | BU6: _ | BV6: _ | BW6: _ | BX6: _ | BY6: _ | BZ6: _ | CA6: _ | CB6: _ | CC6: _ | CD6: _ | CE6: _ | CF6: _ | CG6: _ | CH6: _ | CI6: _ | CJ6: _ | CK6: _ | CL6: _ | CM6: _ | CN6: _ | CO6: _ | CP6: _ | CQ6: _ | CR6: _ | CS6: _ | CT6: _ | CU6: _ | CV6: _ | CW6: _ | CX6: _ | CY6: _ | CZ6: _ | DA6: _ | DB6: _ | DC6: _ | DD6: _ | DE6: _ | DF6: _ | DG6: _ | DH6: _
A7: 4 | B7: 0 | C7: _ | D7: _ | E7: _ | F7: _ | G7: _ | H7: _ | I7: _ | J7: _ | K7: _ | L7: _ | M7: _ | N7: _ | O7: _ | P7: _ | Q7: _ | R7: _ | S7: _ | T7: _ | U7: _ | V7: _ | W7: _ | X7: _ | Y7: _ | Z7: _ | AA7: _ | AB7: _ | AC7: _ | AD7: _ | AE7: _ | AF7: _ | AG7: _ | AH7: _ | AI7: _ | AJ7: _ | AK7: _ | AL7: _ | AM7: _ | AN7: _ | AO7: _ | AP7: _ | AQ7: _ | AR7: _ | AS7: _ | AT7: _ | AU7: _ | AV7: _ | AW7: _ | AX7: _ | AY7: _ | AZ7: _ | BA7: _ | BB7: _ | BC7: _ | BD7: _ | BE7: _ | BF7: _ | BG7: _ | BH7: _ | BI7: _ | BJ7: _ | BK7: _ | BL7: _ | BM7: _ | BN7: _ | BO7: _ | BP7: _ | BQ7: _ | BR7: _ | BS7: _ | BT7: _ | BU7: _ | BV7: _ | BW7: _ | BX7: _ | BY7: _ | BZ7: _ | CA7: _ | CB7: _ | CC7: _ | CD7: _ | CE7: _ | CF7: _ | CG7: _ | CH7: _ | CI7: _ | CJ7: _ | CK7: _ | CL7: _ | CM7: _ | CN7: _ | CO7: _ | CP7: _ | CQ7: _ | CR7: _ | CS7: _ | CT7: _ | CU7: _ | CV7: _ | CW7: _ | CX7: _ | CY7: _ | CZ7: _ | DA7: _ | DB7: _ | DC7: _ | DD7: _ | DE7: _ | DF7: _ | DG7: _ | DH7: _
A8: 5 | B8: 0 | C8: _ | D8: _ | E8: _ | F8: _ | G8: _ | H8: _ | I8: _ | J8: _ | K8: _ | L8: _ | M8: _ | N8: _ | O8: _ | P8: _ | Q8: _ | R8: _ | S8: _ | T8: _ | U8: _ | V8: _ | W8: _ | X8: _ | Y8: _ | Z8: _ | AA8: _ | AB8: _ | AC8: _ | AD8: _ | AE8: _ | AF8: _ | AG8: _ | AH8: _ | AI8: _ | AJ8: _ | AK8: _ | AL8: _ | AM8: _ | AN8: _ | AO8: _ | AP8: _ | AQ8: _ | AR8: _ | AS8: _ | AT8: _ | AU8: _ | AV8: _ | AW8: _ | AX8: _ | AY8: _ | AZ8: _ | BA8: _ | BB8: _ | BC8: _ | BD8: _ | BE8: _ | BF8: _ | BG8: _ | BH8: _ | BI8: _ | BJ8: _ | BK8: _ | BL8: _ | BM8: _ | BN8: _ | BO8: _ | BP8: _ | BQ8: _ | BR8: _ | BS8: _ | BT8: _ | BU8: _ | BV8: _ | BW8: _ | BX8: _ | BY8: _ | BZ8: _ | CA8: _ | CB8: _ | CC8: _ | CD8: _ | CE8: _ | CF8: _ | CG8: _ | CH8: _ | CI8: _ | CJ8: _ | CK8: _ | CL8: _ | CM8: _ | CN8: _ | CO8: _ | CP8: _ | CQ8: _ | CR8: _ | CS8: _ | CT8: _ | CU8: _ | CV8: _ | CW8: _ | CX8: _ | CY8: _ | CZ8: _ | DA8: _ | DB8: _ | DC8: _ | DD8: _ | DE8: _ | DF8: _ | DG8: _ | DH8: _
A9: 6 | B9: 0 | C9: _ | D9: _ | E9: _ | F9: _ | G9: _ | H9: _ | I9: _ | J9: _ | K9: _ | L9: _ | M9: _ | N9: _ | O9: _ | P9: _ | Q9: _ | R9: _ | S9: _ | T9: _ | U9: _ | V9: _ | W9: _ | X9: _ | Y9: _ | Z9: _ | AA9: _ | AB9: _ | AC9: _ | AD9: _ | AE9: _ | AF9: _ | AG9: _ | AH9: _ | AI9: _ | AJ9: _ | AK9: _ | AL9: _ | AM9: _ | AN9: _ | AO9: _ | AP9: _ | AQ9: _ | AR9: _ | AS9: _ | AT9: _ | AU9: _ | AV9: _ | AW9: _ | AX9: _ | AY9: _ | AZ9: _ | BA9: _ | BB9: _ | BC9: _ | BD9: _ | BE9: _ | BF9: _ | BG9: _ | BH9: _ | BI9: _ | BJ9: _ | BK9: _ | BL9: _ | BM9: _ | BN9: _ | BO9: _ | BP9: _ | BQ9: _ | BR9: _ | BS9: _ | BT9: _ | BU9: _ | BV9: _ | BW9: _ | BX9: _ | BY9: _ | BZ9: _ | CA9: _ | CB9: _ | CC9: _ | CD9: _ | CE9: _ | CF9: _ | CG9: _ | CH9: _ | CI9: _ | CJ9: _ | CK9: _ | CL9: _ | CM9: _ | CN9: _ | CO9: _ | CP9: _ | CQ9: _ | CR9: _ | CS9: _ | CT9: _ | CU9: _ | CV9: _ | CW9: _ | CX9: _ | CY9: _ | CZ9: _ | DA9: _ | DB9: _ | DC9: _ | DD9: _ | DE9: _ | DF9: _ | DG9: _ | DH9: _
A10: 7 | B10: 3 | C10: ІҐїх! ЗТДС№цё±ЕЧѕд... | D10: ѕцё¶ѕд... | E10: ѕЖѕж! їЦ¶§·Б... ! | F10: _ | G10: _ | H10: _ | I10: _ | J10: _ | K10: _ | L10: _ | M10: Krr! Eu te arranho... | N10: Ah, mamгe... | O10: Ei! Nгo bata em mim...! | P10: _ | Q10: _ | R10: _ | S10: _ | T10: _ | U10: _ | V10: _ | W10: °Ў!ТЄ№ОЖЖБЛАІ... | X10: ОТµДВиСЅЎ­ | Y10: °¦СЅ!ДгёЙВпґтОТ...! | Z10: _ | AA10: _ | AB10: _ | AC10: _ | AD10: _ | AE10: _ | AF10: _ | AG10: Krr! Scratch you... | AH10: Oh mommy... | AI10: Hey! Don't hit me... ! | AJ10: _ | AK10: _ | AL10: _ | AM10: _ | AN10: _ | AO10: _ | AP10: _ | AQ10: Krr! Scratch you... | AR10: Mamaaaaaaaaaa.... | AS10: Hei! Jangan pukul aku..! | AT10: _ | AU10: _ | AV10: _ | AW10: _ | AX10: _ | AY10: _ | AZ10: _ | BA10: ‚«‚б‚ЁЃI€ш‚Б‘~‚ў‚Д‚в‚йЃI | BB10: ‚С‚Б‚­‚и‚µ‚Ѕ... | BC10: ‚ў‚Ѕ‚БЃI‰Ѕ‚Е‰Ј‚й‚МЃI | BD10: _ | BE10: _ | BF10: _ | BG10: _ | BH10: _ | BI10: _ | BJ10: _ | BK10: Krr! Scratch you... | BL10: Oh mommy... | BM10: Hey! Don't hit me... ! | BN10: _ | BO10: _ | BP10: _ | BQ10: _ | BR10: _ | BS10: _ | BT10: _ | BU10: Гррр!!! Загрызу!!! | BV10: Ой мамочка... | BW10: Хей! Не бей меня! | BX10: _ | BY10: _ | BZ10: _ | CA10: _ | CB10: _ | CC10: _ | CD10: _ | CE10: °Ъ!­nЁнЇ}¤F°Х... | CF10: §ЪЄє¶э§r..._ | CG10: ­ь§r!§A·F№АҐґ§Ъ...! | CH10: _ | CI10: _ | CJ10: _ | CK10: _ | CL10: _ | CM10: _ | CN10: _ | CO10: Krr! Scratch you... | CP10: Oh mommy... | CQ10: Hey! Don't hit me... ! | CR10: _ | CS10: _ | CT10: _ | CU10: _ | CV10: _ | CW10: _ | CX10: _ | CY10: Krr! Scratch you... | CZ10: Oh mommy... | DA10: Hey! Don't hit me... ! | DB10: _ | DC10: _ | DD10: _ | DE10: _ | DF10: _ | DG10: _ | DH10: _
A11: 8 | B11: 3 | C11: ДЙДЙДК! їмё®ґВ ВЙ·ѕ ИС№жІЫ! ґэє­¶у ВЙ·ѕµйѕЖ! | D11: іЧірА» АвѕЖј­ ·ѕѕчА» ЗП°ЪґЩ | E11: °жЗиДЎё¦ ¶і±ЕБЦБц! Е©ЗПЗП БЧѕо¶у! | F11: _ | G11: _ | H11: _ | I11: _ | J11: _ | K11: _ | L11: _ | M11: Kkk! Nada de usar a gente para subir de nнvel! Sai pra lб! | N11: Vou pegar vocк e subir de nнvel! | O11: Vou tirar seus pontos de experiкncia! Haha, morra! | P11: _ | Q11: _ | R11: _ | S11: _ | T11: _ | U11: _ | V11: _ | W11: єИ!ХвР©»Щ°щИЛµДјТ»п!УРЦЦѕНЙПСЅ,ДгГЗХвР©јТ»п! | X11: ОТТЄЙ±БЛДгГЗАґЧчОЄОТЙэј¶µДјАЖ· | Y11: ѕ­СйЦµКЗОТµДАІ!№ю№ю!ОТТЄЙ±№вДгГЗ! | Z11: _ | AA11: _ | AB11: _ | AC11: _ | AD11: _ | AE11: _ | AF11: _ | AG11: Kkk! We are level up slanderer! Come on low levels! | AH11: I will get you and level myself up | AI11: I'll lower your Exp! haha die! | AJ11: _ | AK11: _ | AL11: _ | AM11: _ | AN11: _ | AO11: _ | AP11: _ | AQ11: Kkkk! Kami sudah level tinggi!Kesinilah kamu cupu. | AR11: Aku akan mengalahkanmu dan meningkatkan levelku. | AS11: aku akan menurunkan exp kamu! Hahaha mati kamu! | AT11: _ | AU11: _ | AV11: _ | AW11: _ | AX11: _ | AY11: _ | AZ11: _ | BA11: ‚Ї‚Ї‚ЇЃI‰ґ‚Ѕ‚ї‚НЋЧ–‚‚·‚й‚±‚Ж‚Єђ¶‚«‚Є‚ў‚И‚с‚ѕЃI‚©‚©‚Б‚Д—€‚ўЃI‚±‚МЋб‘ўЃI | BB11: ‚Ё‘O‚р“|‚µ‚ДѓЊѓxѓ‹‚рЏг‚°‚Д‚в‚йЃI | BC11: ЊoЊ±’l‚рЊё‚з‚µ‚Д‚ ‚°‚й‚жЃI“|‚к‚ї‚б‚ў‚ИЃI | BD11: _ | BE11: _ | BF11: _ | BG11: _ | BH11: _ | BI11: _ | BJ11: _ | BK11: Kkk! We are level up slanderer! Come on low levels! | BL11: I will get you and level myself up | BM11: I'll lower your Exp! haha die! | BN11: _ | BO11: _ | BP11: _ | BQ11: _ | BR11: _ | BS11: _ | BT11: _ | BU11: Хррр!!! Вы ничего не сможете с нами сделать жалкие новички!!! | BV11: Твое убийство позволит получить мне новый ранг | BW11: Ты потеряешь набранный опыт! Ха! Сдохни! | BX11: _ | BY11: _ | BZ11: _ | CA11: _ | CB11: _ | CC11: _ | CD11: _ | CE11: іЬ!іoЁЗ·ґБЅ¤HЄєіГҐл!¦ієШґN¤W§r,§A­МіoЁЗіГҐл! | CF11: §Ъ­n±ю¤F§A­МЁУ§@¬°§Ъ¤ЙЇЕЄєІЅ«~ | CG11: ёgЕз­И¬O§ЪЄє°Х!«ў«ў!§Ъ­n±юҐъ§A­М! | CH11: _ | CI11: _ | CJ11: _ | CK11: _ | CL11: _ | CM11: _ | CN11: _ | CO11: Kkk! We are level up slanderer! Come on low levels! | CP11: I will get you and level myself up | CQ11: I'll lower your Exp! haha die! | CR11: _ | CS11: _ | CT11: _ | CU11: _ | CV11: _ | CW11: _ | CX11: _ | CY11: Kkk! We are level up slanderer! Come on low levels! | CZ11: I will get you and level myself up | DA11: I'll lower your Exp! haha die! | DB11: _ | DC11: _ | DD11: _ | DE11: _ | DF11: _ | DG11: _ | DH11: _
A12: 9 | B12: 3 | C12: °ЁИч №ЩЖЫАЗ ¶ҐїЎ Д§№ьЗПґЩґП! | D12: іЧ іај® Б¤µµАЗ ИыАё·О ЗТ јц АЦґВ °НАє ѕЖ№«°Нµµ ѕшґЩ | E12: АЯ°Ф ЅдѕоБЦё¶! | F12: _ | G12: _ | H12: _ | I12: _ | J12: _ | K12: _ | L12: _ | M12: Como ousa invadir o territуrio dos Vafers!? | N12: Vocк nгo pode fazer nada aqui. | O12: Corto vocк em pedaзos! | P12: _ | Q12: _ | R12: _ | S12: _ | T12: _ | U12: _ | V12: _ | W12: ДгГЗµЁёТЗЦ·ё°Нмі¶ыµДНБµШ! | X12: ѕНЖѕДгГЗХвР©јТ»п, Г»УРУГµД! | Y12: ОТТЄФЧБЛДгГЗ! | Z12: _ | AA12: _ | AB12: _ | AC12: _ | AD12: _ | AE12: _ | AF12: _ | AG12: Dare you try Bafer Land? | AH12: There is nothing you can do here! | AI12: Cut you in pieces! | AJ12: _ | AK12: _ | AL12: _ | AM12: _ | AN12: _ | AO12: _ | AP12: _ | AQ12: Kamu sungguh berani di Tanah Bafer. | AR12: Kamu tidak dapat berbuat apa-apa disini. | AS12: aku akan memotong-motong kamu! | AT12: _ | AU12: _ | AV12: _ | AW12: _ | AX12: _ | AY12: _ | AZ12: _ | BA12: ‰Ѕ‚ѕ‚ўЃAѓoѓtѓ@‚М’n‚ЙђN‚·‚И‚с‚ДЃI | BB12: ‚Ё‘O‚М—Н‚Е‚Е‚«‚й‚М‚Н‰Ѕ‚а‚И‚ўЃB | BC12: ‚О‚з‚О‚з‚Й‚µ‚Д‚в‚йЃI | BD12: _ | BE12: _ | BF12: _ | BG12: _ | BH12: _ | BI12: _ | BJ12: _ | BK12: Dare you try Bafer Land? | BL12: There is nothing you can do here! | BM12: Cut you in pieces! | BN12: _ | BO12: _ | BP12: _ | BQ12: _ | BR12: _ | BS12: _ | BT12: _ | BU12: Слабо ступить на землю Змееголовов? | BV12: Ты ничего не должен делать здесь | BW12: Я порву тебя! | BX12: _ | BY12: _ | BZ12: _ | CA12: _ | CB12: _ | CC12: _ | CD12: _ | CE12: §A­МБxґ±«IҐЗ¤ЪґґєёЄє¤g¦a! | CF12: ґNѕМ§A­МіoЁЗіГҐл,_ЁS¦іҐОЄє! | CG12: §Ъ­n®_¤F§A­М! | CH12: _ | CI12: _ | CJ12: _ | CK12: _ | CL12: _ | CM12: _ | CN12: _ | CO12: Dare you try Bafer Land? | CP12: There is nothing you can do here! | CQ12: Cut you in pieces! | CR12: _ | CS12: _ | CT12: _ | CU12: _ | CV12: _ | CW12: _ | CX12: _ | CY12: Dare you try Bafer Land? | CZ12: There is nothing you can do here! | DA12: Cut you in pieces! | DB12: _ | DC12: _ | DD12: _ | DE12: _ | DF12: _ | DG12: _ | DH12: _
A13: 10 | B13: 3 | C13: Е©·С·ЇґВ ±аБц іфАє Аь»зАЗ єОБ·АМґЩ! | D13: Д§АФАЪґВ їлј­ЗТ јц ѕшґЩ! | E13: Е©·С·Ї їХ±№А» А§ЗПї©! | F13: _ | G13: _ | H13: _ | I13: _ | J13: _ | K13: _ | L13: _ | M13: Os Esmagadores sгo uma tribo honrada! | N13: Sem piedade para os intrusos! | O13: Pelo Reino dos Esmagadores! | P13: _ | Q13: _ | R13: _ | S13: _ | T13: _ | U13: _ | V13: _ | W13: їЛАН¶ыКЗУРёЯ¶ИИЩУюёРµДХЅКїІїЧе! | X13: ОЮ·ЁФ­БВХвР©ИлЗЦХЯ! | Y13: ОЄБЛїЛАН¶ыНх№ъ! | Z13: _ | AA13: _ | AB13: _ | AC13: _ | AD13: _ | AE13: _ | AF13: _ | AG13: We Crawlers are an honorable tribe! | AH13: Show no mercy to those intruders! | AI13: For Crawler Kingdom! | AJ13: _ | AK13: _ | AL13: _ | AM13: _ | AN13: _ | AO13: _ | AP13: _ | AQ13: Crawler adalah suku terhormat! | AR13: Tidak ada ampun bagi penyusup! | AS13: Untuk kerajaan crawler! | AT13: _ | AU13: _ | AV13: _ | AW13: _ | AX13: _ | AY13: _ | AZ13: _ | BA13: ѓNѓЌЃ[ѓ‰Ѓ[‚Нѓvѓ‰ѓCѓh‚МЌ‚‚ўђнЋm‚М•”‘°‚ѕЃI | BB13: ђN“ьЋТ‚Н‹–‚№‚И‚ўЃI | BC13: ѓNѓЌЃ[ѓ‰Ѓ[‰¤Ќ‘‚М‚Ѕ‚Я‚ЙЃI | BD13: _ | BE13: _ | BF13: _ | BG13: _ | BH13: _ | BI13: _ | BJ13: _ | BK13: We Crawlers are an honorable tribe! | BL13: Show no mercy to those intruders! | BM13: For Crawler Kingdom! | BN13: _ | BO13: _ | BP13: _ | BQ13: _ | BR13: _ | BS13: _ | BT13: _ | BU13: Мы Культисты - могучее племя! | BV13: Нет жалости захватчикам!!! | BW13: Слава Культистам! | BX13: _ | BY13: _ | BZ13: _ | CA13: _ | CB13: _ | CC13: _ | CD13: _ | CE13: §JіТєё¬O¦і°Є«ЧєaЕA·PЄєѕФ¤hіЎ±Ъ! | CF13: µLЄk­мЅМіoЁЗ¤J«IЄМ! | CG13: ¬°¤F§JіТєё¤э°к! | CH13: _ | CI13: _ | CJ13: _ | CK13: _ | CL13: _ | CM13: _ | CN13: _ | CO13: We Crawlers are an honorable tribe! | CP13: Show no mercy to those intruders! | CQ13: For Crawler Kingdom! | CR13: _ | CS13: _ | CT13: _ | CU13: _ | CV13: _ | CW13: _ | CX13: _ | CY13: We Crawlers are an honorable tribe! | CZ13: Show no mercy to those intruders! | DA13: For Crawler Kingdom! | DB13: _ | DC13: _ | DD13: _ | DE13: _ | DF13: _ | DG13: _ | DH13: _
A14: 11 | B14: 3 | C14: °ЁИч і»°Ф »уГіАФИчґЩґП! їлј­ЗТ јц ѕшґЩ! | D14: АьЕхґВ АМБ¦ ё· ЅГАЫµЗѕъА» »УАМґЩ! | E14: ѕЖБч ґэєф ИыАМ іІѕЖАЦґАіД? | F14: _ | G14: _ | H14: _ | I14: _ | J14: _ | K14: _ | L14: _ | M14: Como ousa me acertar?! Ah, nгo vai fugir, nгo! | N14: A batalha sу comeзou! | O14: Vocк ainda consegue reagir? | P14: _ | Q14: _ | R14: _ | S14: _ | T14: _ | U14: _ | V14: _ | W14: ѕ№ёТЙЛє¦ОТГЗ!ѕшІ»ИДБЛДгГЗ!_ | X14: ХЅ¶·ПЦФЪІЕТЄїЄКј! | Y14: Дг»№УРДЗёцБ¦ЖшёТёъОТГЗ¶Фї№? | Z14: _ | AA14: _ | AB14: _ | AC14: _ | AD14: _ | AE14: _ | AF14: _ | AG14: How dare you hit me? Now you cannot escape! | AH14: Now, the battle has begun! | AI14: Do you still have the strength to fight back? | AJ14: _ | AK14: _ | AL14: _ | AM14: _ | AN14: _ | AO14: _ | AP14: _ | AQ14: Kamu langcang berani memukulku! Kamu tidak bisa pergi! | AR14: Pertempuran telah dimulai! | AS14: Dapatkah kamu berdiri dibelakang perkelahian? | AT14: _ | AU14: _ | AV14: _ | AW14: _ | AX14: _ | AY14: _ | AZ14: _ | BA14: ‰Ѕ‚ѕЃI‰ґ‚ЙЏќ‚р‚В‚Ї‚й‚И‚с‚ДЃI‹–‚№‚И‚ўЃI | BB14: ђн“¬‚НЋn‚Ь‚Б‚Ѕ‚О‚©‚и‚ѕЃB | BC14: ‚Ь‚ѕ‚©‚©‚Б‚Д‚­‚й—Н‚ЄЋc‚Б‚Д‚й‚МЃH | BD14: _ | BE14: _ | BF14: _ | BG14: _ | BH14: _ | BI14: _ | BJ14: _ | BK14: How dare you hit me? Now you cannot escape! | BL14: Now, the battle has begun! | BM14: Do you still have the strength to fight back? | BN14: _ | BO14: _ | BP14: _ | BQ14: _ | BR14: _ | BS14: _ | BT14: _ | BU14: Ты посмел меня ударить?! Теперь тебе конец!!! | BV14: Битва началась! | BW14: Ты все еще способен сражаться? | BX14: _ | BY14: _ | BZ14: _ | CA14: _ | CB14: _ | CC14: _ | CD14: _ | CE14: ієґ±¶Л®`§Ъ­М!µґ¤ЈДЗ¤F§A­М!_ | CF14: ѕФ°«І{¦b¤~­n¶}©l! | CG14: §AБЩ¦іЁє­У¤O®рґ±ёт§Ъ­М№п§Ь? | CH14: _ | CI14: _ | CJ14: _ | CK14: _ | CL14: _ | CM14: _ | CN14: _ | CO14: How dare you hit me? Now you cannot escape! | CP14: Now, the battle has begun! | CQ14: Do you still have the strength to fight back? | CR14: _ | CS14: _ | CT14: _ | CU14: _ | CV14: _ | CW14: _ | CX14: _ | CY14: How dare you hit me? Now you cannot escape! | CZ14: Now, the battle has begun! | DA14: Do you still have the strength to fight back? | DB14: _ | DC14: _ | DD14: _ | DE14: _ | DF14: _ | DG14: _ | DH14: _
... A34: 31 | B34: 3 | C34: ЕЄ, Б¦№э ЗПґВ±ёіЄ. ґхґВ єББЦБц ѕК°ЪґЩ! | D34: ЕЄ, Б¦№э ЗПґВ±ёіЄ. ґхґВ єББЦБц ѕК°ЪґЩ! | E34: ЕЄ, Б¦№э ЗПґВ±ёіЄ. ґхґВ єББЦБц ѕК°ЪґЩ! | F34: _ | G34: _ | H34: _ | I34: _ | J34: _ | K34: _ | L34: _ | M34: Krrr... Nada mal. Mas chega! | N34: Krrr... Nada mal. Mas chega! | O34: Krrr... Nada mal. Mas chega! | P34: _ | Q34: _ | R34: _ | S34: _ | T34: _ | U34: _ | V34: _ | W34: єИ,І»ґнВп.І»№эОТЅУПВАґІ»»б·Е№эДгГЗ! | X34: єИ,І»ґнВп.І»№эОТЅУПВАґІ»»б·Е№эДгГЗ! | Y34: єИ,І»ґнВп.І»№эОТЅУПВАґІ»»б·Е№эДгГЗ! | Z34: _ | AA34: _ | AB34: _ | AC34: _ | AD34: _ | AE34: _ | AF34: _ | AG34: Krrr...Not bad. But, no more! | AH34: Krrr...Not bad. But, no more! | AI34: Krrr...Not bad. But, no more! | AJ34: _ | AK34: _ | AL34: _ | AM34: _ | AN34: _ | AO34: _ | AP34: _ | AQ34: Krrr... Lumayan, tapi hanya segitu saja! | AR34: Krr. Lumayan. Tapi hanya segitu saja! | AS34: Krrr...Lumayan. Tapi, hanya segitu saja! | AT34: _ | AU34: _ | AV34: _ | AW34: _ | AX34: _ | AY34: _ | AZ34: _ | BA34: ‚У‚БЃAЊ‹Ќ\‚в‚й‚ЛЃB‚±‚к€ИЏг‚Н‚в‚з‚№‚И‚ў‚жЃI | BB34: ‚У‚БЃAЊ‹Ќ\‚в‚й‚ЛЃB‚±‚к€ИЏг‚Н‚в‚з‚№‚И‚ў‚жЃI | BC34: ‚У‚БЃAЊ‹Ќ\‚в‚й‚ЛЃB‚±‚к€ИЏг‚Н‚в‚з‚№‚И‚ў‚жЃI | BD34: _ | BE34: _ | BF34: _ | BG34: _ | BH34: _ | BI34: _ | BJ34: _ | BK34: Krrr...Not bad. But, no more! | BL34: Krrr...Not bad. But, no more! | BM34: Krrr...Not bad. But, no more! | BN34: _ | BO34: _ | BP34: _ | BQ34: _ | BR34: _ | BS34: _ | BT34: _ | BU34: Хрр... Весьма неплохо, но пожалуй хватит! | BV34: Хгрр... Неплохо. Но пожалуй хватит! | BW34: Кххрр... Неплохо. Но не более того! | BX34: _ | BY34: _ | BZ34: _ | CA34: _ | CB34: _ | CC34: _ | CD34: _ | CE34: іЬ,¤Јїщ№А.¤Ј№L§Ъ±µ¤UЁУ¤Ј·|©с№L§A­М! | CF34: іЬ,¤Јїщ№А.¤Ј№L§Ъ±µ¤UЁУ¤Ј·|©с№L§A­М! | CG34: іЬ,¤Јїщ№А.¤Ј№L§Ъ±µ¤UЁУ¤Ј·|©с№L§A­М! | CH34: _ | CI34: _ | CJ34: _ | CK34: _ | CL34: _ | CM34: _ | CN34: _ | CO34: Krrr...Not bad. But, no more! | CP34: Krrr...Not bad. But, no more! | CQ34: Krrr...Not bad. But, no more! | CR34: _ | CS34: _ | CT34: _ | CU34: _ | CV34: _ | CW34: _ | CX34: _ | CY34: Krrr...Not bad. But, no more! | CZ34: Krrr...Not bad. But, no more! | DA34: Krrr...Not bad. But, no more! | DB34: _ | DC34: _ | DD34: _ | DE34: _ | DF34: _ | DG34: _ | DH34: _
A35: 32 | B35: 3 | C35: ЗмАМЗмАМЗмАМ. іЄБ» µµїНБа! | D35: ИыАМ ёрАЪ¶у... ґ©°Ў Б» µµїНБа | E35: Д§АФАЪґЩ! µїБцµйАМї©! АПѕој­¶у! | F35: _ | G35: _ | H35: _ | I35: _ | J35: _ | K35: _ | L35: _ | M35: Ai, ai, ai. Socorro!!! | N35: Nгo tenho poder suficiente... Socorro! | O35: Intruso! Levantem-se, amigos! | P35: _ | Q35: _ | R35: _ | S35: _ | T35: _ | U35: _ | V35: _ | W35: ЯА.°п°пОТ! | Y35: КЗИлЗЦХЯ!Н¬ЦѕГЗ!ЙПСЅ! | Z35: _ | AA35: _ | AB35: _ | AC35: _ | AD35: _ | AE35: _ | AF35: _ | AG35: Hey hey hey. Help!!! | AH35: Not enough power... Help! | AI35: Intruder! Stand up, buddies! | AJ35: _ | AK35: _ | AL35: _ | AM35: _ | AN35: _ | AO35: _ | AP35: _ | AQ35: Hey..Hey hey. Tolong!!! | AR35: Tidak cukup kekuatan... Tolong! | AS35: Ada pengacau! Berdiri, teman-teman! | AT35: _ | AU35: _ | AV35: _ | AW35: _ | AX35: _ | AY35: _ | AZ35: _ | BA35: Џ•‚Ї‚ДЃI | BB35: —Н‚Є‚И‚ў...ЃB’N‚©Џ•‚Ї‚ДЃB | BC35: ђN“ьЋТ‚ѕЃI“ЇЋu‚жЃI—§‚їЏг‚Є‚кЃI | BD35: _ | BE35: _ | BF35: _ | BG35: _ | BH35: _ | BI35: _ | BJ35: _ | BK35: Hey hey hey. Help!!! | BL35: Not enough power... Help! | BM35: Intruder! Stand up, buddies! | BN35: _ | BO35: _ | BP35: _ | BQ35: _ | BR35: _ | BS35: _ | BT35: _ | BU35: Хей, на помощь!!! | BV35: Недостаточно сил... На помощь! | BW35: Захватчик! К оружию! | BX35: _ | BY35: _ | BZ35: _ | CA35: _ | CB35: _ | CC35: _ | CD35: _ | CE35: §c.А°А°§Ъ! | CF35: §Ъ­М¤O¶q¤Ј°ч...¦іЅЦҐiҐHА°А°§Ъ­М.. | CG35: ¬O¤J«IЄМ!¦P§У­М!¤W§r! | CH35: _ | CI35: _ | CJ35: _ | CK35: _ | CL35: _ | CM35: _ | CN35: _ | CO35: Hey hey hey. Help!!! | CP35: Not enough power... Help! | CQ35: Intruder! Stand up, buddies! | CR35: _ | CS35: _ | CT35: _ | CU35: _ | CV35: _ | CW35: _ | CX35: _ | CY35: Hey hey hey. Help!!! | CZ35: Not enough power... Help! | DA35: Intruder! Stand up, buddies! | DB35: _ | DC35: _ | DD35: _ | DE35: _ | DF35: _ | DG35: _ | DH35: _
A36: 33 | B36: 3 | C36: АМ ѕЖё§ґЩїо ёцїЎ »уГіё¦ і»ґЩґП! №МАы °Ё°ўАМ ЗьЖнѕш±є! | D36: ±Ч·Ў. і»°Ў №Щ·О ДЪ¶у ГЦ°нАЗ №МіІАМґЩ! іЇ БъЕхЗПї© БЧАМ·Ї їВ °НАМіД? | E36: ИКИК. Иы°ъ їЬёрґВ єс·КЗПБц. і» ѕЖё§ґЩїтА» ґАіўёз БЧѕо¶у! | F36: _ | G36: _ | H36: _ | I36: _ | J36: _ | K36: _ | L36: _ | M36: Que droga de senso artнstico vocк tem! Como pode ferir meu belo corpo? | N36: Й isso aн. Sou o cara mais quente entre os Coritas! Estб com inveja? | O36: Forзa e beleza estгo diretamente relacionadas. Sinta minha beleza, e morra! | P36: _ | Q36: _ | R36: _ | S36: _ | T36: _ | U36: _ | V36: _ | W36: ѕ№ёТФЪОТГААцµДЙнЗыЙПБфПВЙЛєЫ!їґАґДгГ»УРКІГґГАёР! | X36: Г»ґн.ОТѕНКЗїЛА­ЧоЛ§µДГАДРЧУ!ДгКЗјµ¶КОТµДГАГІ¶шАґµДВр? | Y36: ЯхЯх.ОТµДБ¦БїУлНвГІјж±ё.ДгѕНёРКЬОТµДГААцєуФЩЛА°Й! | Z36: _ | AA36: _ | AB36: _ | AC36: _ | AD36: _ | AE36: _ | AF36: _ | AG36: Your artistic sense is just rubbish! How can you hurt my beautiful body! | AH36: Yes I am a Corite! Marvel at my beauty! | AI36: Strength and good looks are directly related. Stand in awe of my beauty, and die! | AJ36: _ | AK36: _ | AL36: _ | AM36: _ | AN36: _ | AO36: _ | AP36: _ | AQ36: Jiwa senimu sampah! Bagaimana kamu bisa melukai tubuh indahku ini! | AR36: Ya, Aku Pria Cora yang seksi! Apakah kamu mengagumiku? | AS36: Kekuatan dan penglihatan baik secara langsung terkait.Rasakanlah kecantikan ku, dan mati! | AT36: _ | AU36: _ | AV36: _ | AW36: _ | AX36: _ | AY36: _ | AZ36: _ | BA36: ‚±‚М”ь‚µ‚ўђg‚ЙЏќ‚р‚В‚Ї‚й‚И‚с‚Д!”ь“I‚ИЉґЉo‚Є‚Ю‚ї‚б‚­‚ї‚б‚ѕ‚Л! | BB36: ‚»‚¤ЃB‰ґ‚ЄѓRѓ‰ЌЕЌ‚‚М”ь‚µ‚«ђнЋm‚ѕЃB‚»‚к‚рЋ№“i‚µ‚Д‚«‚Ѕ‚М‚©ЃB | BC36: ‚У‚УЃA—Н‚ЖЉз‚Н”д—б‚·‚йЃB‰ґ‚М”ь‚µ‚і‚рЉґ‚¶‚И‚Є‚з‚µ‚ЛЃI | BD36: _ | BE36: _ | BF36: _ | BG36: _ | BH36: _ | BI36: _ | BJ36: _ | BK36: Your artistic sense is just rubbish! How can you hurt my beautiful body! | BL36: Yes I am a Corite! Marvel at my beauty! | BM36: Strength and good looks are directly related. Stand in awe of my beauty, and die! | BN36: _ | BO36: _ | BP36: _ | BQ36: _ | BR36: _ | BS36: _ | BT36: _ | BU36: Где ваше чувство прекрасного?? Как вы смеете прикасаться к моему совершенному телу? | BV36: Да! Я самый крутой Корит! Завидно? | BW36: Сила и внешность как правило одинаково хороши или плохи! Сдохни! | BX36: _ | BY36: _ | BZ36: _ | CA36: _ | CB36: _ | CC36: _ | CD36: _ | CE36: ієґ±¦b§Ъ¬ьДRЄєЁ­ВЯ¤WЇd¤U¶ЛІЄ!¬ЭЁУ§AЁS¦і¤°»т¬ь·P! | CF36: ЁSїщ.§ЪґN¬O§J©ФіМ«УЄє¬ьЁk¤l!§A¬O¶ъ§Є§ЪЄє¬ь»Є¦УЁУЄє¶Ь? | CG36: №Й№Й.§ЪЄє¤O¶q»PҐ~»Є­ЭіЖ.§AґN·PЁь§ЪЄє¬ьДR«б¦A¦є§a! | CH36: _ | CI36: _ | CJ36: _ | CK36: _ | CL36: _ | CM36: _ | CN36: _ | CO36: Your artistic sense is just rubbish! How can you hurt my beautiful body! | CP36: Yes I am a Corite! Marvel at my beauty! | CQ36: Strength and good looks are directly related. Stand in awe of my beauty, and die! | CR36: _ | CS36: _ | CT36: _ | CU36: _ | CV36: _ | CW36: _ | CX36: _ | CY36: Your artistic sense is just rubbish! How can you hurt my beautiful body! | CZ36: Yes I am a Corite! Marvel at my beauty! | DA36: Strength and good looks are directly related. Stand in awe of my beauty, and die! | DB36: _ | DC36: _ | DD36: _ | DE36: _ | DF36: _ | DG36: _ | DH36: _
A37: 34 | B37: 3 | C37: ЕЄ, Б¦№э ЗПґВ±ёіЄ. ґхґВ єББЦБц ѕК°ЪґЩ! | D37: БшВҐ ЅОїтАє Бц±ЭєОЕНґЩ! | E37: іЧірµйАє і» °ЛА» ілё®ґВ µµАыµйАМіД? | F37: _ | G37: _ | H37: _ | I37: _ | J37: _ | K37: _ | L37: _ | M37: Nada mal. Mas chega! | N37: A batalha sу comeзou! | O37: Quer ver o que minha espada pode fazer? | P37: _ | Q37: _ | R37: _ | S37: _ | T37: _ | U37: _ | V37: _ | W37: єИ,І»ґнВп.І»№эОТЅУПВАґІ»»б·Е№эДгГЗ! | X37: ХжХэµДХЅ¶·ПЦФЪІЕїЄКј! | Y37: ДгГЗХвР©јТ»пКЗкйкмОТ±¦ЅЈµДµБФфВр? | Z37: _ | AA37: _ | AB37: _ | AC37: _ | AD37: _ | AE37: _ | AF37: _ | AG37: Not bad! But are there more? | AH37: The Battle has just begun! | AI37: Is it my sword you seek? | AJ37: _ | AK37: _ | AL37: _ | AM37: _ | AN37: _ | AO37: _ | AP37: _ | AQ37: Lumayan, tapi yanya segitu saja! | AR37: Pertempuran baru saja dimulai! | AS37: Dapatkah kamu memperlihatkan pedang untuk aku? | AT37: _ | AU37: _ | AV37: _ | AW37: _ | AX37: _ | AY37: _ | AZ37: _ | BA37: ‚У‚БЃAЊ‹Ќ\‚в‚й‚ЛЃB‚±‚к€ИЏг‚Н‚в‚з‚№‚И‚ў‚жЃI | BB37: –{“–‚Мђн‚ў‚Н‚±‚к‚©‚з‚ѕЃI | BC37: ‚Ё‘O‚з‚Н‰ґ‚МЊ•‚р‘_‚Б‚Д‚й“D–_‚©ЃB | BD37: _ | BE37: _ | BF37: _ | BG37: _ | BH37: _ | BI37: _ | BJ37: _ | BK37: Not bad! But are there more? | BL37: The Battle has just begun! | BM37: Is it my sword you seek? | BN37: _ | BO37: _ | BP37: _ | BQ37: _ | BR37: _ | BS37: _ | BT37: _ | BU37: Неплохо. Но хорошего понемножку! | BV37: Битва началась! | BW37: Чего уставился на мой меч?! | BX37: _ | BY37: _ | BZ37: _ | CA37: _ | CB37: _ | CC37: _ | CD37: _ | CE37: іЬ,¤Јїщ№А.¤Ј№L§Ъ±µ¤UЁУ¤Ј·|©с№L§A­М! | CF37: ЇuҐїЄєѕФ°«І{¦b¤~¶}©l! | CG37: §A­МіoЁЗіГҐл¬OБ»їМ§ЪД_јCЄєµsёй¶Ь? | CH37: _ | CI37: _ | CJ37: _ | CK37: _ | CL37: _ | CM37: _ | CN37: _ | CO37: Not bad! But are there more? | CP37: The Battle has just begun! | CQ37: Is it my sword you seek? | CR37: _ | CS37: _ | CT37: _ | CU37: _ | CV37: _ | CW37: _ | CX37: _ | CY37: Not bad! But are there more? | CZ37: The Battle has just begun! | DA37: Is it my sword you seek? | DB37: _ | DC37: _ | DD37: _ | DE37: _ | DF37: _ | DG37: _ | DH37: _
A38: 35 | B38: 3 | C38: ЗПАМєк·Оѕої©! ѕој­ іЄё¦ ±ёЗШ¶у! ѕоµрАЦіЄ? Е©ѕЖѕЖѕЗ! | D38: И¦ё®ёаЕ»АЗ їµЗвёё ѕшѕъґЩёй іЧ±оБю°НµйАє »уґл°Ў ѕЖґСµҐ....... | E38: АМ·± №ъ·№µйїЎ°Ф ґзЗПґЩґП... їшЕлЗПґЩ | F38: _ | G38: _ | H38: _ | I38: _ | J38: _ | K38: _ | L38: _ | M38: Irmгos! Me ajudem! Onde vocкs foram? Ahhh! | N38: Mataria vocк facilmente se eu nгo estivesse afetado pelo Sacramental... | O38: Como й que esses ratos... | P38: _ | Q38: _ | R38: _ | S38: _ | T38: _ | U38: _ | V38: _ | W38: №юАпІјВе¶с!їмѕИѕИОТ!ДгФЪДДАпСЅ?ЯА! | X38: Ц»ТЄГ»УРКҐЅрКфµДУ°Пм,БїДгТІІ»КЗОТµД¶ФКЦ...... | Y38: ѕ№И»±»ХвР©јТ»пГЗ°µЛг...єГФ©СЅ | Z38: _ | AA38: _ | AB38: _ | AC38: _ | AD38: _ | AE38: _ | AF38: _ | AG38: Hybroers! Help me! Where are you? Ahhh | AH38: Will kill you so easily if I weren't affected by the Holy Mental....... | AI38: How can these little rats... | AJ38: _ | AK38: _ | AL38: _ | AM38: _ | AN38: _ | AO38: _ | AP38: _ | AQ38: Hybroers! Tolong aku! Kamu ada dimana? Ahhh | AR38: Akan membunuhmu dengan mudah apabila aku tidak terkena efek Holy Mental.. | AS38: Bagaimana mungkin ini sedikit omong kosong... | AT38: _ | AU38: _ | AV38: _ | AW38: _ | AX38: _ | AY38: _ | AZ38: _ | BA38: ѓnѓCѓuѓЌѓA‚жЃI‘Ѓ‚­‰ґ‚рЏ•‚Ї‚ДЃI‚З‚±‚И‚с‚ѕЃI‚­‚¦‚¦ЃI | BB38: ѓzЃ[ѓЉЃ[ѓЃѓ“ѓ^ѓ‹‚М‰e‹ї‚і‚¦‚И‚©‚Б‚Ѕ‚зЃA‚Ё‘O‚з‚И‚З“G‚Е‚Н‚И‚ў‚М‚Й......ЃB | BC38: ‚±‚с‚И’Ћ‚Й‚в‚з‚к‚й‚И‚с‚ДЃB‰ч‚µ‚ўЃI | BD38: _ | BE38: _ | BF38: _ | BG38: _ | BH38: _ | BI38: _ | BJ38: _ | BK38: Hybroers! Help me! Where are you? Ahhh | BL38: Will kill you so easily if I weren't affected by the Holy Mental....... | BM38: How can these little rats... | BN38: _ | BO38: _ | BP38: _ | BQ38: _ | BR38: _ | BS38: _ | BT38: _ | BU38: Гибриды! Ко мне! На помощь! Аааа! | BV38: Я бы сразу убил тебя, если бы не Священная сила... | BW38: Да как они посмели... | BX38: _ | BY38: _ | BZ38: _ | CA38: _ | CB38: _ | CC38: _ | CD38: _ | CE38: «ўЁЅҐ¬¬Ґґc!§Ц±П±П§Ъ!§A¦b­юёМ§r?§c! | CF38: Ґu­nЁS¦іёtЄчДЭЄєјvЕT,_¶q§A¤]¤Ј¬O§ЪЄє№п¤в...... | CG38: ієµMіQіoЁЗіГҐл­М·tєв...¦n­Ю§r | CH38: _ | CI38: _ | CJ38: _ | CK38: _ | CL38: _ | CM38: _ | CN38: _ | CO38: Hybroers! Help me! Where are you? Ahhh | CP38: Will kill you so easily if I weren't affected by the Holy Mental....... | CQ38: How can these little rats... | CR38: _ | CS38: _ | CT38: _ | CU38: _ | CV38: _ | CW38: _ | CX38: _ | CY38: Hybroers! Help me! Where are you? Ahhh | CZ38: Will kill you so easily if I weren't affected by the Holy Mental....... | DA38: How can these little rats... | DB38: _ | DC38: _ | DD38: _ | DE38: _ | DF38: _ | DG38: _ | DH38: _
A39: 36 | B39: 3 | C39: АМ °чА» ѕЛѕЖі»ґЩґП. »м·БµС јц ѕш±є. °нЕлЅє·ґ°Ф БЧї©БЦё¶! | D39: °ЁИч і» ёцїЎ јХА» ґлґЩґП! іІАЪ¶уёй БЧАМ°н ї©АЪ¶уёй №ьЗШБЦё¶! | E39: Е©ЗПЗП і» ЗЗїН »мАМ µЗ°Е¶у! | F39: _ | G39: _ | H39: _ | I39: _ | J39: _ | K39: _ | L39: _ | M39: Vocк encontrou este lugar. Nгo posso deixar vocк sair com vida. Morra! | N39: Vocк tocou em mim! Se for homem, й um homem morto. Se for mulher, vamos nos divertir! | O39: Ha ha ha! Seja minha carne e sangue! | P39: _ | Q39: _ | R39: _ | S39: _ | T39: _ | U39: _ | V39: _ | W39: ДгГЗѕУИ»µГЦЄХвёцµШ·Ѕ.ОТїЙІ»ДЬИГДгГЗ»оЧЕ»ШИҐ.ОТТЄИГДгГЗНґїаµДЛАИҐ! | X39: ѕУИ»ёТ¶ФОТ¶ЇКЦ!ДРµДОТТЄЙ±№в,Е®µДТІІ»·Е№э! | Y39: №ю№ю,ПЧЙПДгГЗµДСЄИв°Й! | Z39: _ | AA39: _ | AB39: _ | AC39: _ | AD39: _ | AE39: _ | AF39: _ | AG39: Though you have reached this place, you will not get out of here alive! | AH39: How dare you touch me?! | AI39: Hahaha Be my blood and flesh! | AJ39: _ | AK39: _ | AL39: _ | AM39: _ | AN39: _ | AO39: _ | AP39: _ | AQ39: Kamu menemukan tempat ini, Kamu tidak akan kulepaskan hidup-hidup. Matilah dalam kepedihan! | AR39: Kamu menyentuhku! Jika kamu pria, kamu akan mati. Jika wanita, kita akan bersenang-senang! | AS39: Hahaha Jadilah daging dan darah ku! | AT39: _ | AU39: _ | AV39: _ | AW39: _ | AX39: _ | AY39: _ | AZ39: _ | BA39: ‚±‚±‚Є’m‚з‚к‚й‚И‚с‚ДЃBђ¶‚©‚µ‚Д‚Н‹A‚і‚с‚јЃI | BB39: ‰ґ‚М‘М‚ЙЋи‚рЏo‚·‚И‚с‚ДЃI‚Р‚ґ‚Ь‚ё‚ЇЃI | BC39: ‚­‚Н‚НЃA‰ґ‚МЊЊ‚Ж“ч‚Й‚И‚кЃI | BD39: _ | BE39: _ | BF39: _ | BG39: _ | BH39: _ | BI39: _ | BJ39: _ | BK39: Though you have reached this place, you will not get out of here alive! | BL39: How dare you touch me?! | BM39: Hahaha Be my blood and flesh! | BN39: _ | BO39: _ | BP39: _ | BQ39: _ | BR39: _ | BS39: _ | BT39: _ | BU39: Что-ж, ты нашел это место, поздравляю. Но живым ты отсюда не выйдешь - умри!!! | BV39: Ты дотронулся до меня! Если ты мужчина - ты мертвый мужчина! Ну а если ты женщина... | BW39: Ха!ха!ха! Ты моя плоть и кровь! | BX39: _ | BY39: _ | BZ39: _ | CA39: _ | CB39: _ | CC39: _ | CD39: _ | CE39: §A­М©~µM±oЄѕіo­У¦a¤и.§ЪҐi¤ЈЇаЕэ§A­М¬ЎµЫ¦^Ґh.§Ъ­nЕэ§A­Мµh­WЄє¦єҐh! | CF39: ©~µMґ±№п§Ъ°К¤в!ЁkЄє§Ъ­n±юҐъ,_¤kЄє¤]¤Ј©с№L! | CG39: «ў«ў,Дm¤W§A­МЄє¦е¦Ч§a! | CH39: _ | CI39: _ | CJ39: _ | CK39: _ | CL39: _ | CM39: _ | CN39: _ | CO39: Though you have reached this place, you will not get out of here alive! | CP39: How dare you touch me?! | CQ39: Hahaha Be my blood and flesh! | CR39: _ | CS39: _ | CT39: _ | CU39: _ | CV39: _ | CW39: _ | CX39: _ | CY39: Though you have reached this place, you will not get out of here alive! | CZ39: How dare you touch me?! | DA39: Hahaha Be my blood and flesh! | DB39: _ | DC39: _ | DD39: _ | DE39: _ | DF39: _ | DG39: _ | DH39: _
A40: 37 | B40: 3 | C40: їлѕПїЎ ґг±ЕБЦё¶! | D40: »А±оБц ѕГѕоёФѕоБЦБц | E40: єРілё¦ «АП јц°Ў ѕшґЩ! іЧірµй ёрµОё¦ БЧАМ±в Аь±оБц °бДЪ! | F40: _ | G40: _ | H40: _ | I40: _ | J40: _ | K40: _ | L40: _ | M40: Eu jogo vocк no magma! | N40: Vou devorar seus ossos! | O40: Nгo vou controlar minha raiva atй vocк morrer! | P40: _ | Q40: _ | R40: _ | S40: _ | T40: _ | U40: _ | V40: _ | W40: ёшОТЛАФЪИЫСТАп°Й! | X40: ОТТЄїР№вДгµД№ЗН· | Y40: ОТКЗОЮ·ЁПыіэХв·ЯЕ­µД!ФЪДгГЗХвР©јТ»пЛАЗ°ѕцІ»! | Z40: _ | AA40: _ | AB40: _ | AC40: _ | AD40: _ | AE40: _ | AF40: _ | AG40: I shall put you in magma! | AH40: I will eat you up until your bones are left | AI40: The only way to ease my pain is to kill you! | AJ40: _ | AK40: _ | AL40: _ | AM40: _ | AN40: _ | AO40: _ | AP40: _ | AQ40: Membenamkanmu dalam magma! | AR40: Akan memakanmu sampai tulangmu. | AS40: Tidak bisa mengatur kemarahan ku, sampai aku membunuh kamu! | AT40: _ | AU40: _ | AV40: _ | AW40: _ | AX40: _ | AY40: _ | AZ40: _ | BA40: —oЉв‚М’†‚ЙђZ‚µ‚Д‚в‚л‚¤ЃI | BB40: Ќњ‚Ь‚ЕЉљ‚с‚Е‚в‚йЃI | BC40: “{‚и‚р—}‚¦‚з‚к‚И‚ўЃI‚Ё‘O‚з‚Є“|‚к‚й‚Ь‚Е‚НЃIЃI | BD40: _ | BE40: _ | BF40: _ | BG40: _ | BH40: _ | BI40: _ | BJ40: _ | BK40: I shall put you in magma! | BL40: I will eat you up until your bones are left | BM40: The only way to ease my pain is to kill you! | BN40: _ | BO40: _ | BP40: _ | BQ40: _ | BR40: _ | BS40: _ | BT40: _ | BU40: Гори в аду! | BV40: Обглодаю тебя до костей | BW40: Моя ярость уничтожит тебя! | BX40: _ | BY40: _ | BZ40: _ | CA40: _ | CB40: _ | CC40: _ | CD40: _ | CE40: µ№§Ъ¦є¦bєІ©ҐёМ§a! | CF40: §Ъ­n°ЩҐъ§AЄє°©АY | CG40: §Ъ¬OµLЄk®ш°Јіoј««гЄє!¦b§A­МіoЁЗіГҐл¦є«eЁM¤Ј!_ | CH40: _ | CI40: _ | CJ40: _ | CK40: _ | CL40: _ | CM40: _ | CN40: _ | CO40: I shall put you in magma! | CP40: I will eat you up until your bones are left | CQ40: The only way to ease my pain is to kill you! | CR40: _ | CS40: _ | CT40: _ | CU40: _ | CV40: _ | CW40: _ | CX40: _ | CY40: I shall put you in magma! | CZ40: I will eat you up until your bones are left | DA40: The only way to ease my pain is to kill you! | DB40: _ | DC40: _ | DD40: _ | DE40: _ | DF40: _ | DG40: _ | DH40: _
A41: 38 | B41: 3 | C41: Е©ѕЖѕЖѕЗ! °Ьїм АМ±оБю °НµйїЎ°Ф....... | D41: ЕЄ, ¶у ёёЕш¶уЅєё¦ ЗЗЗШ °ЈЅЕИч µµёБГЖґВµҐ °Ьїм АМµэ іај®µйїЎ°Ф....... | E41: АъБЦё¦ і»ё®ё¶. іКИсґВ µжЕЫЗПБц ёшЗТ °НАМґЩ! і­ ѕЖ№«°Нµµ БЦБц ѕКА» °НАМѕЯ! | F41: _ | G41: _ | H41: _ | I41: _ | J41: _ | K41: _ | L41: _ | M41: Grrr! Como eu posso... | N41: Tendo de fugir de La Mantulas, como posso... | O41: Maldito seja. Vocк nunca vai conseguir os itens! Nгo vou lhe dar nada! | P41: _ | Q41: _ | R41: _ | S41: _ | T41: _ | U41: _ | V41: _ | W41: ЯА!ѕНБ¬Хв...... | X41: ЯА,ОЄБЛ¶г±ЬА­ВьНјА­Л№¶шМУЧЯµД,ИґУЦУцµЅХвР©јТ»п...... | Y41: ОТТЄЧзЦдДгГЗ.ДгГЗДГІ»µЅ±¦ОпµД!ОТКІГґТІІ»»бёшДгГЗ! | Z41: _ | AA41: _ | AB41: _ | AC41: _ | AD41: _ | AE41: _ | AF41: _ | AG41: Grrr! How can I...... | AH41: Once I ran away from La Mantulas, how can I....... | AI41: Curse you. You'll never get the items! I will not give you anything! | AJ41: _ | AK41: _ | AL41: _ | AM41: _ | AN41: _ | AO41: _ | AP41: _ | AQ41: Grrr! Bagaimana aku bisa... | AR41: Aku pernah lari dari La Mantulas, bagaimana aku bisa.. | AS41: Kutuk kamu.kamu tidak akan pernah mendapat barang!aku tidak akan memberi kamu apa saja! | AT41: _ | AU41: _ | AV41: _ | AW41: _ | AX41: _ | AY41: _ | AZ41: _ | BA41: ѓNѓAѓAѓAѓbЃI‚±‚с‚И‚в‚В‚з‚Й‚в‚з‚к‚й‚И‚с‚Д......ЃB | BB41: ‚¤‚¤ЃAѓ‰ѓ}ѓ“ѓgѓ‰ѓX‚©‚з‚в‚Б‚Ж“¦‚°‚Ѕ‚М‚ЙЃA‚±‚с‚И‚в‚В‚з‚Й‚в‚з‚к‚й‚И‚с‚Д......ЃB | BC41: Ћф‚ў‚р‚©‚Ї‚йЃI‚Ё‘O‚з‚НѓAѓCѓeѓЂ‚рЋи‚Й“ь‚к‚з‚к‚И‚ўЃI‰ґ‚Н‰Ѕ‚а‚ ‚°‚И‚ўЃI | BD41: _ | BE41: _ | BF41: _ | BG41: _ | BH41: _ | BI41: _ | BJ41: _ | BK41: Grrr! How can I...... | BL41: Once I ran away from La Mantulas, how can I....... | BM41: Curse you. You'll never get the items! I will not give you anything! | BN41: _ | BO41: _ | BP41: _ | BQ41: _ | BR41: _ | BS41: _ | BT41: _ | BU41: Гррр! Как я могу... | BV41: Убежав однажды от Ла Манта, как я могу... | BW41: Будь ты проклят! Ты не получишь ничего! | BX41: _ | BY41: _ | BZ41: _ | CA41: _ | CB41: _ | CC41: _ | CD41: _ | CE41: §c!ґNіsіo...... | CF41: §c,¬°¤FёъБЧ©Ф°Т№П©Фґµ¦У°kЁ«Єє,«o¤S№JЁміoЁЗіГҐл...... | CG41: §Ъ­n¶A©G§A­М.§A­М®і¤ЈЁмД_Є«Єє!§Ъ¤°»т¤]¤Ј·|µ№§A­М! | CH41: _ | CI41: _ | CJ41: _ | CK41: _ | CL41: _ | CM41: _ | CN41: _ | CO41: Grrr! How can I...... | CP41: Once I ran away from La Mantulas, how can I....... | CQ41: Curse you. You'll never get the items! I will not give you anything! | CR41: _ | CS41: _ | CT41: _ | CU41: _ | CV41: _ | CW41: _ | CX41: _ | CY41: Grrr! How can I...... | CZ41: Once I ran away from La Mantulas, how can I....... | DA41: Curse you. You'll never get the items! I will not give you anything! | DB41: _ | DC41: _ | DD41: _ | DE41: _ | DF41: _ | DG41: _ | DH41: _
A42: 39 | B42: 3 | C42: °ЈАМ №и№ЫАё·О іЄїВ °НАМіД! ЗПВъАє №ъ·№µйѕЖ! | D42: °ЈАМ №и№ЫАё·О іЄїВ °НАМіД! ЗПВъАє №ъ·№µйѕЖ! | E42: °ЈАМ №и№ЫАё·О іЄїВ °НАМіД! ЗПВъАє №ъ·№µйѕЖ! | F42: _ | G42: _ | H42: _ | I42: _ | J42: _ | K42: _ | L42: _ | M42: Enlouqueceram?! Traidores! | N42: Enlouqueceram?! Traidores! | O42: Enlouqueceram?! Traidores! | P42: _ | Q42: _ | R42: _ | S42: _ | T42: _ | U42: _ | V42: _ | W42: єГґуµЁ!ДгГЗХвР©іжЧУ! | X42: єГґуµЁ!ДгГЗХвР©іжЧУ! | Y42: єГґуµЁ!ДгГЗХвР©іжЧУ! | Z42: _ | AA42: _ | AB42: _ | AC42: _ | AD42: _ | AE42: _ | AF42: _ | AG42: You are out of your mind! you little rats! | AH42: You are out of your mind! you little rats! | AI42: You are out of your mind! you little rats! | AJ42: _ | AK42: _ | AL42: _ | AM42: _ | AN42: _ | AO42: _ | AP42: _ | AQ42: Apakah kamu gila! Kamu tikus kecil! | AR42: Kamiu gila! Kamu tikus kecil! | AS42: Apakah kamu gila! Kamu tikus kecil! | AT42: _ | AU42: _ | AV42: _ | AW42: _ | AX42: _ | AY42: _ | AZ42: _ | BA42: ЉМ‘џ‚Є• ‚МЉO‚ЙЏo‚Ѕ‚М‚©ЃI‚В‚Ь‚з‚И‚ў’Ћ‚Ѕ‚ї‚жЃI | BB42: ЉМ‘џ‚Є• ‚МЉO‚ЙЏo‚Ѕ‚М‚©ЃI‚В‚Ь‚з‚И‚ў’Ћ‚Ѕ‚ї‚жЃI | BC42: ЉМ‘џ‚Є• ‚МЉO‚ЙЏo‚Ѕ‚М‚©ЃI‚В‚Ь‚з‚И‚ў’Ћ‚Ѕ‚ї‚жЃI | BD42: _ | BE42: _ | BF42: _ | BG42: _ | BH42: _ | BI42: _ | BJ42: _ | BK42: You are out of your mind! you little rats! | BL42: You are out of your mind! you little rats! | BM42: You are out of your mind! you little rats! | BN42: _ | BO42: _ | BP42: _ | BQ42: _ | BR42: _ | BS42: _ | BT42: _ | BU42: Вы сошли с ума поганые крысы!!! | BV42: Вы безумцы! Мерзкие крысы! | BW42: Да вы все полоумные идиоты! | BX42: _ | BY42: _ | BZ42: _ | CA42: _ | CB42: _ | CC42: _ | CD42: _ | CE42: ¦n¤jБx!§A­МіoЁЗВО¤l! | CF42: ¦n¤jБx!§A­МіoЁЗВО¤l! | CG42: ¦n¤jБx!§A­МіoЁЗВО¤l! | CH42: _ | CI42: _ | CJ42: _ | CK42: _ | CL42: _ | CM42: _ | CN42: _ | CO42: You are out of your mind! you little rats! | CP42: You are out of your mind! you little rats! | CQ42: You are out of your mind! you little rats! | CR42: _ | CS42: _ | CT42: _ | CU42: _ | CV42: _ | CW42: _ | CX42: _ | CY42: You are out of your mind! you little rats! | CZ42: You are out of your mind! you little rats! | DA42: You are out of your mind! you little rats! | DB42: _ | DC42: _ | DD42: _ | DE42: _ | DF42: _ | DG42: _ | DH42: _
A43: 40 | B43: 3 | C43: Д®ё®ѕЖіЄАЗ єОИпА» А§ЗШ! | D43: Д®ё®ѕЖіЄґВ ґЬБц °нЗвАё·О µ№ѕЖ°Ў°н ЅНА» »УАМґЩ! ѕоВ°Ѕб їмё®ё¦ ±«·УИчґВ °ЕБц? | E43: ... іЎ±оБц їмё®ё¦ ё»»мЅГДСѕЯёё ЗП°ЪґП? °ЎїІАє їмё® Д®ё®ѕЖіЄ єОБ·А»....... | F43: _ | G43: _ | H43: _ | I43: _ | J43: _ | K43: _ | L43: _ | M43: Em nome de Calliana! | N43: Nуs Callianas sу queremos voltar а nossa terra! Por que nos perturba? | O43: ... Vocк tem mesmo que nos aniquilar? Ah, pobre Calliana... | P43: _ | Q43: _ | R43: _ | S43: _ | T43: _ | U43: _ | V43: _ | W43: ОЄБЛїЁАц°ІДИµДёґРЛ! | X43: їЁАц°ІДИЦ»Пл»ШµЅ№КПз!ОЄКІГґАґА§ИЕОТГЗ? | Y43: ...µЅЧоєу»№ТЄХвГґ¶уЙ±ОТГЗВр?їЙБЇµДїЁАц°ІДИЧе....... | Z43: _ | AA43: _ | AB43: _ | AC43: _ | AD43: _ | AE43: _ | AF43: _ | AG43: For Caliana! | AH43: Caliana just wishes to go back to the homeland! Why are you disturbing us? | AI43: ... Do you really have to annihilate us? Poor Caliana....... | AJ43: _ | AK43: _ | AL43: _ | AM43: _ | AN43: _ | AO43: _ | AP43: _ | AQ43: Untuk Caliana! | AR43: Caliana hanya ingin kembali ke rumah asal! Kenapa kamu mengganggu kita? | AS43: Apakah kamu benar-benar mesti membinasakan kami?Poor Caliana....... | AT43: _ | AU43: _ | AV43: _ | AW43: _ | AX43: _ | AY43: _ | AZ43: _ | BA43: ѓJѓЉѓAѓi‚М•њ‹»‚М‚Ѕ‚ЯЃI | BB43: ѓJѓЉѓAѓi‚Н‚Ѕ‚ѕ‚У‚й‚і‚Ж‚Й‹A‚и‚Ѕ‚ў‚ѕ‚Ї‚ѕЃI‚З‚¤‚µ‚ДЋ„‚Ѕ‚ї‚рЋЧ–‚‚·‚й‚с‚ѕЃI | BC43: ЌЕЊг‚Ь‚ЕЋ„‚Ѕ‚ї‚МЋЧ–‚‚р‚·‚й‚М‚©ЃB‰В€¤‚»‚¤‚ИЋ„‚МѓJѓЉѓAѓi•”‘°...ЃB | BD43: _ | BE43: _ | BF43: _ | BG43: _ | BH43: _ | BI43: _ | BJ43: _ | BK43: For Caliana! | BL43: Caliana just wishes to go back to the homeland! Why are you disturbing us? | BM43: ... Do you really have to annihilate us? Poor Caliana....... | BN43: _ | BO43: _ | BP43: _ | BQ43: _ | BR43: _ | BS43: _ | BT43: _ | BU43: Отомстим за Калианцев! | BV43: Калианы лишь хотят вернуться на родину! Почему вы нам мешаете? | BW43: Ты на самом деле уничтожишь нас? Бедная Калиана... | BX43: _ | BY43: _ | BZ43: _ | CA43: _ | CB43: _ | CC43: _ | CD43: _ | CE43: ¬°¤FҐdДR¦w®RЄєґ_їі! | CF43: ҐdДR¦w®RҐu·Q¦^Ём¬G¶m!¬°¤°»тЁУ§xВZ§Ъ­М? | CG43: ..._ЁміМ«бБЩ­nіo»т§г±ю§Ъ­М¶Ь?Ґiј¦ЄєҐdДR¦w®R±Ъ....... | CH43: _ | CI43: _ | CJ43: _ | CK43: _ | CL43: _ | CM43: _ | CN43: _ | CO43: For Caliana! | CP43: Caliana just wishes to go back to the homeland! Why are you disturbing us? | CQ43: ... Do you really have to annihilate us? Poor Caliana....... | CR43: _ | CS43: _ | CT43: _ | CU43: _ | CV43: _ | CW43: _ | CX43: _ | CY43: For Caliana! | CZ43: Caliana just wishes to go back to the homeland! Why are you disturbing us? | DA43: ... Do you really have to annihilate us? Poor Caliana....... | DB43: _ | DC43: _ | DD43: _ | DE43: _ | DF43: _ | DG43: _ | DH43: _
A44: 41 | B44: 3 | C44: ёцµµ, ё¶АЅµµ ѕуѕоєЩ°Е¶у. | D44: їмё®АЗ єРіл°Ў ѕуё¶іЄ Е«Бц ґАІёєБ! | E44: АМ°НАМ Д®ё®ѕЖіЄ їХ°ЎїЎ і»·БїАґВ БшБ¤ЗС ИыАМґЩ! | F44: _ | G44: _ | H44: _ | I44: _ | J44: _ | K44: _ | L44: _ | M44: Congele o corpo e a alma. | N44: Sinta nossa raiva! | O44: Este й o verdadeiro poder do legado de Calliana. | P44: _ | Q44: _ | R44: _ | S44: _ | T44: _ | U44: _ | V44: _ | W44: ЙнМеРДБй¶јёшОТ¶іЅб°Й. | X44: ИГДгЗЖЗЖОТГЗµД·ЯЕ­! | Y44: ХвКЗїЁАц°ІДИКАґъґ«іРПВАґµДХжХэБ¦Бї! | Z44: _ | AA44: _ | AB44: _ | AC44: _ | AD44: _ | AE44: _ | AF44: _ | AG44: Freeze the body and soul. | AH44: Feel our anger! | AI44: This is the real power from Caliana legacy. | AJ44: _ | AK44: _ | AL44: _ | AM44: _ | AN44: _ | AO44: _ | AP44: _ | AQ44: Tubuh dan jiwa yang membeku. | AR44: Rasakan kemarahan kita! | AS44: Ini adalah kuasa yang nyata dari Caliana warisan. | AT44: _ | AU44: _ | AV44: _ | AW44: _ | AX44: _ | AY44: _ | AZ44: _ | BA44: ђg‚ађS‚а“Ђ‚и‚В‚ЇЃI | BB44: Ћ„‚Ѕ‚ї‚М“{‚и‚Є‚З‚с‚И‚Й‘е‚«‚ў‚©Љґ‚¶‚Д‚Э‚л‚жЃI | BC44: ‚±‚к‚ЄђМ‚©‚з‚МѓJѓЉѓAѓi‰¤‘°‚М—Н‚ѕЃI | BD44: _ | BE44: _ | BF44: _ | BG44: _ | BH44: _ | BI44: _ | BJ44: _ | BK44: Freeze the body and soul. | BL44: Feel our anger! | BM44: This is the real power from Caliana legacy. | BN44: _ | BO44: _ | BP44: _ | BQ44: _ | BR44: _ | BS44: _ | BT44: _ | BU44: Замри! | BV44: Ты утонешь в нашей ярости! | BW44: Это настоящая сила наследия расы Калиан | BX44: _ | BY44: _ | BZ44: _ | CA44: _ | CB44: _ | CC44: _ | CD44: _ | CE44: Ё­Ей¤ЯЖFіЈµ№§Ъ­бµІ§a. | CF44: Еэ§AБ@Б@§Ъ­МЄєј««г! | CG44: іo¬OҐdДR¦w®RҐ@ҐN¶З©У¤UЁУЄєЇuҐї¤O¶q! | CH44: _ | CI44: _ | CJ44: _ | CK44: _ | CL44: _ | CM44: _ | CN44: _ | CO44: Freeze the body and soul. | CP44: Feel our anger! | CQ44: This is the real power from Caliana legacy. | CR44: _ | CS44: _ | CT44: _ | CU44: _ | CV44: _ | CW44: _ | CX44: _ | CY44: Freeze the body and soul. | CZ44: Feel our anger! | DA44: This is the real power from Caliana legacy. | DB44: _ | DC44: _ | DD44: _ | DE44: _ | DF44: _ | DG44: _ | DH44: _
A45: 42 | B45: 3 | C45: і»°Ў ѕЖё§ґдґП? ёсјыА» №ЩГДµµ ББА» ёёЕ­? | D45: і» АМё§Ає їАµрѕр Д®ё®ѕЖіЄ. іКїЎ°Ф БЧАЅА» і»ё± і»ё®іл¶у | E45: ґх·Їїо Д«ёЈЕЪ¶уАЗ јъјцїЎ єьБ® АМ·± ёцАМ µЗѕъБцёё, іЧ±оБю°НµйїЎ°Ф БцБцґВ ѕКґВґЩ! | F45: _ | G45: _ | H45: _ | I45: _ | J45: _ | K45: _ | L45: _ | M45: Nгo sou linda? Vai sacrificar sua vida? | N45: Meu nome й Audion Calliana. Sentencio vocк а morte. | O45: Meu corpo foi transformado por causa da conspiraзгo suja de Cartella, mas ainda tenho forзa suficiente para matar vocк! | P45: _ | Q45: _ | R45: _ | S45: _ | T45: _ | U45: _ | V45: _ | W45: ОТєЬГА°Й?ГАµЅїЙТФИГИЛ·оПЧБй»к? | X45: ОТµДГыЧЦКЗ°ВµТ°ІїЁАц°ІДИ.°СДгГЗµДРФГьЅ»іцАґ | Y45: ЛдИ»ОТµДЙнМе±»ДЗ°№ФаµДїЁАЦчмА­КЦКхёгіЙХвСщ,µ«ѕш¶Ф»бґт°ЬДгГЗХвР©јТ»пµД! | Z45: _ | AA45: _ | AB45: _ | AC45: _ | AD45: _ | AE45: _ | AF45: _ | AG45: Am I beautiful enough for you to sacrifice your life? | AH45: My name is Audian Caliana. I will sentence you to death | AI45: My body has transformed due to dirty conspiracy of Cartellans, but I still have enough power to kill you! | AJ45: _ | AK45: _ | AL45: _ | AM45: _ | AN45: _ | AO45: _ | AP45: _ | AQ45: Apakah aku cantik? Untukmu mengorbankan nyawamu? | AR45: Namaku adalah Audian Caliana. Aku akan menghukum mati kamu. | AS45: aku memiliki kekuatan membunuh kamu! | AT45: _ | AU45: _ | AV45: _ | AW45: _ | AX45: _ | AY45: _ | AZ45: _ | BA45: Ћ„‚Є”ь‚µ‚ў‚МЃH–Ѕ‚р•щ‚°‚Д‚а—З‚ў‚­‚з‚ўЃH | BB45: Ћ„‚М–ј‘O‚НѓIѓfѓBѓAѓ“ѓJѓЉѓAѓiЃB‚Ё‘O‚Є•·‚­ЌЕЊг‚М–ј‘O‚Ж‚И‚й‚ѕ‚л‚¤ЃI | BC45: ‚ё‚й‚ўѓJѓ‹ѓeѓ‹‚МЋиЊы‚Й—Ћ‚ї‚Д‚±‚с‚И‘М‚Й‚И‚Б‚Ѕ‚Ї‚ЗЃA‚Ё‘O‚з‚И‚с‚©‚Й•‰‚Ї‚И‚ўЃI | BD45: _ | BE45: _ | BF45: _ | BG45: _ | BH45: _ | BI45: _ | BJ45: _ | BK45: Am I beautiful enough for you to sacrifice your life? | BL45: My name is Audian Caliana. I will sentence you to death | BM45: My body has transformed due to dirty conspiracy of Cartellans, but I still have enough power to kill you! | BN45: _ | BO45: _ | BP45: _ | BQ45: _ | BR45: _ | BS45: _ | BT45: _ | BU45: Красота требует жертв - умри! | BV45: Я Калиана Аудиан. И я приговариваю вас к смерти. | BW45: Я Калиана Аудиан. И я приговариваю вас к смерти. | BX45: _ | BY45: _ | BZ45: _ | CA45: _ | CB45: _ | CC45: _ | CD45: _ | CE45: §Ъ«Ь¬ь§a?¬ьЁмҐiҐHЕэ¤H©^ДmЖF»о? | CF45: §ЪЄє¦W¦r¬O¶шЁf¦wҐdДR¦w®R.§в§A­МЄє©К©RҐжҐXЁУ | CG45: БцµM§ЪЄєЁ­ЕйіQЁє»кЕјЄєҐdјЦВL©Ф¤віN·d¦ЁіoјЛ,¦эµґ№п·|Ґґ±С§A­МіoЁЗіГҐлЄє! | CH45: _ | CI45: _ | CJ45: _ | CK45: _ | CL45: _ | CM45: _ | CN45: _ | CO45: Am I beautiful enough for you to sacrifice your life? | CP45: My name is Audian Caliana. I will sentence you to death | CQ45: My body has transformed due to dirty conspiracy of Cartellans, but I still have enough power to kill you! | CR45: _ | CS45: _ | CT45: _ | CU45: _ | CV45: _ | CW45: _ | CX45: _ | CY45: Am I beautiful enough for you to sacrifice your life? | CZ45: My name is Audian Caliana. I will sentence you to death | DA45: My body has transformed due to dirty conspiracy of Cartellans, but I still have enough power to kill you! | DB45: _ | DC45: _ | DD45: _ | DE45: _ | DF45: _ | DG45: _ | DH45: _
A46: 43 | B46: 3 | C46: іЄїН °°Ає °нЕлА» ґАІёєБ! | D46: ѕоµТїЎ Аб°ЬµеґВ °нЕл... іЄїН іЄґ©ѕо БЦБц ѕКА»·Ў? | E46: АМБ¦ ѕоµТАЗ ЅГґл°Ў ЅГАЫµЙ°ЕѕЯ | F46: _ | G46: _ | H46: _ | I46: _ | J46: _ | K46: _ | L46: _ | M46: Sinta a mesma dor que a minha! | N46: A dor profunda da escuridгo... Quer dividi-la comigo? | O46: A idade das trevas estб para chegar. | P46: _ | Q46: _ | R46: _ | S46: _ | T46: _ | U46: _ | V46: _ | W46: ИГДгіўіўОТЛщФвКЬµЅµДНґїа! | X46: ЅыпАФЪєЪ°µЦРµДїаНґ...ДгІ»Аґ·ЦµЈТ»µгВр? | Y46: ПЦФЪєЪ°µµДК±ґъѕНТЄїЄКјБЛ | Z46: _ | AA46: _ | AB46: _ | AC46: _ | AD46: _ | AE46: _ | AF46: _ | AG46: Feel the same pain as I! | AH46: Deep pain of darkness... Would you share this with me? | AI46: Dark ages are about to come | AJ46: _ | AK46: _ | AL46: _ | AM46: _ | AN46: _ | AO46: _ | AP46: _ | AQ46: Rasakan sakit ini!!! | AR46: Sakit mendalam dari kegelapan. Apakah kamu mau berbagi hal ini dengaku? | AS46: Berbagai zaman gelap akan datang | AT46: _ | AU46: _ | AV46: _ | AW46: _ | AX46: _ | AY46: _ | AZ46: _ | BA46: Ћ„‚Ж“Ї‚¶‹к’Й‚р–Ў‚н‚¦ЃI | BB46: €Г€Е‚Йђх‚Э‚й‹к’ЙЃAЋ„‚Ж•Є‚ЇЌ‡‚н‚И‚ўЃH | BC46: ‚±‚к‚©‚з€Е‚МЋћ‘г‚ЄЋn‚Ь‚йЃB | BD46: _ | BE46: _ | BF46: _ | BG46: _ | BH46: _ | BI46: _ | BJ46: _ | BK46: Feel the same pain as I! | BL46: Deep pain of darkness... Would you share this with me? | BM46: Dark ages are about to come | BN46: _ | BO46: _ | BP46: _ | BQ46: _ | BR46: _ | BS46: _ | BT46: _ | BU46: Почуствуй мою боль! | BV46: Боль тьмы...Хочешь разделить ее со мной? | BW46: Время Тьмы не за горами | BX46: _ | BY46: _ | BZ46: _ | CA46: _ | CB46: _ | CC46: _ | CD46: _ | CE46: Еэ§AА|А|§Ъ©ТѕDЁьЁмЄєµh­W! | CF46: ёTАD¦b¶В·t¤¤Єє­Wµh...§A¤ЈЁУ¤Аѕб¤@ВI¶Ь? | CG46: І{¦b¶В·tЄє®ЙҐNґN­n¶}©l¤F | CH46: _ | CI46: _ | CJ46: _ | CK46: _ | CL46: _ | CM46: _ | CN46: _ | CO46: Feel the same pain as I! | CP46: Deep pain of darkness... Would you share this with me? | CQ46: Dark ages are about to come | CR46: _ | CS46: _ | CT46: _ | CU46: _ | CV46: _ | CW46: _ | CX46: _ | CY46: Feel the same pain as I! | CZ46: Deep pain of darkness... Would you share this with me? | DA46: Dark ages are about to come | DB46: _ | DC46: _ | DD46: _ | DE46: _ | DF46: _ | DG46: _ | DH46: _
A47: 44 | B47: 3 | C47: і­ ЗШГжАМ ѕЖґПѕЯ! | D47: ѕоВјёй ББѕЖ. іЇ°і°Ў ґЩ ±ё°ЬБіѕо. ѕоБ¦ ѕЦЅбј­ ґЩ·БіхѕТґВµҐ....... | E47: ѕоВ°ј­ іЇ °ш°ЭЗПґВ °ЕБц? і­ ґЩёё »м°нЅНА» »УАМѕЯ | F47: _ | G47: _ | H47: _ | I47: _ | J47: _ | K47: _ | L47: _ | M47: Nгo sou nenhum verme! | N47: O que devo fazer? Minhas asas estгo quebradas. Demorei tanto para consegui-las... | O47: Por que estб me atacando? Eu sу quero viver. | P47: _ | Q47: _ | R47: _ | S47: _ | T47: _ | U47: _ | V47: _ | W47: ОТІ»КЗє¦іж! | X47: °¦.іб°т¶јКЬЛрБЛ.ЧтМмІЕРБїаРЮёґµД....... | Y47: ОЄКІГґ№Ґ»чОТ?ОТЦ»Пл»оПВИҐ | Z47: _ | AA47: _ | AB47: _ | AC47: _ | AD47: _ | AE47: _ | AF47: _ | AG47: I am not a vermin! | AH47: What should I do. My wings are crumpled. It took me a long time to iron it....... | AI47: Why are you attacking me? I just want to live. | AJ47: _ | AK47: _ | AL47: _ | AM47: _ | AN47: _ | AO47: _ | AP47: _ | AQ47: Aku bukan makhluk hina! | AR47: Apa yang harus aku lakukan. Sayapku kusut. Perlu waktu lama untuk menyeterikanya.. | AS47: Kenapa kamu memukul aku? aku hanya ingin hidup. | AT47: _ | AU47: _ | AV47: _ | AW47: _ | AX47: _ | AY47: _ | AZ47: _ | BA47: Ћ„‚НЉQ’Ћ‚Е‚Н‚И‚ўЃI | BB47: ‚З‚¤‚µ‚ж‚¤ЃB‰H‚Є‚®‚ї‚б‚®‚ї‚б‚Й‚И‚Б‚Ѕ‚¶‚б‚сЃBЌр“ъѓAѓCѓЌѓ“‚©‚Ї‚Д‚Ё‚ў‚Ѕ‚М‚ЙЃB | BC47: ‚З‚¤‚µ‚ДЋ„‚рЌUЊ‚‚·‚й‚МЃHЋ„‚Нђ¶‚«‚Ѕ‚ў‚ѕ‚Ї‚ѕЃB | BD47: _ | BE47: _ | BF47: _ | BG47: _ | BH47: _ | BI47: _ | BJ47: _ | BK47: I am not a vermin! | BL47: What should I do. My wings are crumpled. It took me a long time to iron it....... | BM47: Why are you attacking me? I just want to live. | BN47: _ | BO47: _ | BP47: _ | BQ47: _ | BR47: _ | BS47: _ | BT47: _ | BU47: Я не хищник! | BV47: Что мне теперь делать? Мои крылья измяты, а я так долго их отращивал... | BW47: К чему все это? Я просто хочу жить! | BX47: _ | BY47: _ | BZ47: _ | CA47: _ | CB47: _ | CC47: _ | CD47: _ | CE47: §Ъ¤Ј¬O®`ВО! | CF47: ­ь.ЇН»HіЈЁь·l¤F.¬Q¤С¤~ЁЇ­W­Чґ_Єє....... | CG47: ¬°¤°»т§рА»§Ъ?§ЪҐu·Q¬Ў¤UҐh | CH47: _ | CI47: _ | CJ47: _ | CK47: _ | CL47: _ | CM47: _ | CN47: _ | CO47: I am not a vermin! | CP47: What should I do. My wings are crumpled. It took me a long time to iron it....... | CQ47: Why are you attacking me? I just want to live. | CR47: _ | CS47: _ | CT47: _ | CU47: _ | CV47: _ | CW47: _ | CX47: _ | CY47: I am not a vermin! | CZ47: What should I do. My wings are crumpled. It took me a long time to iron it....... | DA47: Why are you attacking me? I just want to live. | DB47: _ | DC47: _ | DD47: _ | DE47: _ | DF47: _ | DG47: _ | DH47: _
... A214: 211 | B214: 3 | C214: іКИсґВ ёрµО і» ѕзєРАМ µЙ °НАМґЩ! | D214: АМ°НАМ Зм·ОµрѕрАЗ ЖчЅєґЩ | E214: ѕо¶°іД? іЄАЗ єс№ьЗС ЖчЅє°Ў! БшВҐ Зм·ОµрѕрА» АМ±ж јц АЦА»°Н °°іЄ? | F214: _ | G214: _ | H214: _ | I214: _ | J214: _ | K214: _ | L214: _ | M214: Vocкs vгo virar comida! | N214: Esta й a forзa dos Herodianos! | O214: Veja minha forзa incrнvel! Acha que pode derrotar os verdadeiros Herodianos? | P214: _ | Q214: _ | R214: _ | S214: _ | T214: _ | U214: _ | V214: _ | W214: ДгГЗИ«¶ј»біЙОЄОТµДСш·Ц! | X214: ХвѕНКЗєЈВЮµТ°ІµДДЬБ¦ | Y214: ИзєО?ОТДЗ·З·ІµДДЬБ¦!ДгТФОЄДгДЬУ®µДБЛХжХэµДєЈВЮµТ°ІБ¦БїВр? | Z214: _ | AA214: _ | AB214: _ | AC214: _ | AD214: _ | AE214: _ | AF214: _ | AG214: All of you will become my nutrition! | AH214: This is the force of Herodians | AI214: How's my remarkable force! Do you think you can beat the real Herodians? | AJ214: _ | AK214: _ | AL214: _ | AM214: _ | AN214: _ | AO214: _ | AP214: _ | AQ214: Kalian semua akan menjadi nutrisiku. | AR214: Inilah kekuatan Herodians | AS214: bagaimana angkatanku yang luar biasa ! Apakah kamu pikir akan dapat mengalahkan Herodian yang sesungguhnya ? | AT214: _ | AU214: _ | AV214: _ | AW214: _ | AX214: _ | AY214: _ | AZ214: _ | BA214: ‚Ё‘O‚з‚Н‚Э‚с‚И‰ґ‚М‚¦‚і‚Й‚И‚йЃI | BB214: ‚±‚к‚ЄѓwѓЌѓfѓBѓAѓ“‚МѓtѓHЃ[ѓX‚ѕЃB | BC214: ‚З‚¤‚ѕЃH‰ґ‚М”с–}‚ИѓtѓHЃ[ѓX‚ЄЃI–{•Ё‚МѓwѓЌѓfѓBѓAѓ“‚ЙЏџ‚Д‚й‚ЖЋv‚¤‚М‚©ЃH | BD214: _ | BE214: _ | BF214: _ | BG214: _ | BH214: _ | BI214: _ | BJ214: _ | BK214: All of you will become my nutrition! | BL214: This is the force of Herodians | BM214: How's my remarkable force! Do you think you can beat the real Herodians? | BN214: _ | BO214: _ | BP214: _ | BQ214: _ | BR214: _ | BS214: _ | BT214: _ | BU214: Я сожру тебя! | BV214: Это Сила Геродиан | BW214: Ха ха ха! Жалкие потуги! Ты думаешь победить настоящих Геродиан?! | BX214: _ | BY214: _ | BZ214: _ | CA214: _ | CB214: _ | CC214: _ | CD214: _ | CE214: §A­МҐюіЈ·|¦Ё¬°§ЪЄєѕi¤А! | CF214: іoґN¬O®ьГ№Ёf¦wЄєЇа¤O | CG214: ¦p¦у?§ЪЁє«D¤ZЄєЇа¤O!§AҐH¬°§AЇаД№Єє¤FЇuҐїЄє®ьГ№Ёf¦w¤O¶q¶Ь? | CH214: _ | CI214: _ | CJ214: _ | CK214: _ | CL214: _ | CM214: _ | CN214: _ | CO214: All of you will become my nutrition! | CP214: This is the force of Herodians | CQ214: How's my remarkable force! Do you think you can beat the real Herodians? | CR214: _ | CS214: _ | CT214: _ | CU214: _ | CV214: _ | CW214: _ | CX214: _ | CY214: All of you will become my nutrition! | CZ214: This is the force of Herodians | DA214: How's my remarkable force! Do you think you can beat the real Herodians? | DB214: _ | DC214: _ | DD214: _ | DE214: _ | DF214: _ | DG214: _ | DH214: _
