Workbook

Sheet NPCharacter
A1: string[64] | B1: string[64] | C1: dword | D1: dword | E1: float | F1: float | G1: float | H1: float | I1: float | J1: float | K1: float | L1: float | M1: float | N1: float | O1: float | P1: float | Q1: float | R1: float | S1: float | T1: float | U1: float | V1: float | W1: float | X1: float | Y1: float | Z1: float | AA1: float | AB1: float | AC1: float | AD1: float | AE1: float | AF1: float | AG1: float | AH1: float | AI1: float | AJ1: float | AK1: float | AL1: float | AM1: float | AN1: float | AO1: float | AP1: float | AQ1: float | AR1: dword | AS1: float | AT1: float | AU1: dword | AV1: dword | AW1: string[64] | AX1: dword | AY1: float | AZ1: float | BA1: float | BB1: float | BC1: float | BD1: float | BE1: float | BF1: float | BG1: float | BH1: float | BI1: float | BJ1: float | BK1: float | BL1: float | BM1: float | BN1: float | BO1: float | BP1: float | BQ1: float | BR1: float | BS1: float | BT1: float | BU1: float | BV1: float | BW1: float | BX1: float | BY1: END
A2: Code | B2: strName[64] | C2: nRace | D2: bWarType | E2: fTarDecType | F2: fLevel | G2: fExt | H2: fAttFcStd | I2: fMinAFSelProb | J2: fMaxAFSelProb | K2: fAttSklUnit | L2: fDefSklUnit | M2: fWeakPart | N2: fStdDefFc | O2: fFireTol | P2: fWaterTol | Q2: fSoilTol | R2: fWindTol | S2: fAttTechID1 | T2: fAttTech1UseProb | U2: fAttTechID2 | V2: fAttTech2UseProb | W2: fAttTechID3 | X2: fAttTech3UseProb | Y2: fAttTechMinAFProb | Z2: fAttTechMinAF | AA2: fAttTechMaxAFProb | AB2: fAttTechMaxAF | AC2: fPSecTechID | AD2: fMSecTechID | AE2: fMaxHP | AF2: fHPRecDelay | AG2: fHPRecUnit | AH2: fAttSpd | AI2: fAttMoTime1 | AJ2: fAttMoTime2 | AK2: fViewExt | AL2: fAttExt | AM2: fMRefExt | AN2: fCopTime | AO2: fMovSpd | AP2: fWarMovSpd | AQ2: fScaleRate | AR2: bScaleChange | AS2: fWidth | AT2: fWaitTime | AU2: nAsitReqRate | AV2: nAsitAptRate | AW2: strChildMon[64] | AX2: nChildMonNum | AY2: fEmoType | AZ2: fDamHPStd | BA2: fEmoImpStdTime | BB2: fGoodToOrdHPPer | BC2: fOrdToBadHPPer | BD2: fBadToWorseHPPer | BE2: fEspTFProb | BF2: fTypeCompTerms | BG2: fPSecTechChat | BH2: fPAttTechChat | BI2: fEmo0Chat | BJ2: fEmo0ChatProb | BK2: fEmo1Chat | BL2: fEmo1ChatProb | BM2: fEmo2Chat | BN2: fEmo2ChatProb | BO2: fEmo3Chat | BP2: fEmo3ChatProb | BQ2: fEmo4Chat | BR2: fEmo4ChatProb | BS2: fAsitReqSteEspChat | BT2: fAsitReqSteEspChatProb | BU2: fAsitReqSteHelpChat | BV2: fAsitReqSteHelpChatProb | BW2: fAsitReqSteCopChat | BX2: fAsitReqSteCopChatProb
A3: 03000 | B3: WEAPON | C3: 0 | D3: 0 | E3: 0 | F3: 50 | G3: 3238665 | H3: 19744.236 | I3: 30 | J3: 65 | K3: 149 | L3: 149 | M3: 0 | N3: 1555 | O3: 0 | P3: 0 | Q3: 0 | R3: 0 | S3: 0 | T3: 0 | U3: 0 | V3: 0 | W3: 0 | X3: 0 | Y3: 0 | Z3: 0 | AA3: 0 | AB3: 0 | AC3: 0 | AD3: 0 | AE3: 2621 | AF3: 44 | AG3: 1310 | AH3: 2034 | AI3: 1000 | AJ3: 1000 | AK3: 300 | AL3: 25 | AM3: 300 | AN3: 5000 | AO3: 1 | AP3: 1.5 | AQ3: 100 | AR3: 0 | AS3: 20 | AT3: 3000 | AU3: 0 | AV3: 0 | AW3: 0 | AX3: 0 | AY3: 3 | AZ3: 4.1700001 | BA3: 30000 | BB3: 90 | BC3: 60 | BD3: 30 | BE3: 0 | BF3: 0 | BG3: 0 | BH3: 0 | BI3: 0 | BJ3: 0 | BK3: 0 | BL3: 0 | BM3: 0 | BN3: 0 | BO3: 0 | BP3: 0 | BQ3: 0 | BR3: 0 | BS3: 0 | BT3: 0 | BU3: 0 | BV3: 0 | BW3: 0 | BX3: 0
A4: 03001 | B4: WEAPON | C4: 0 | D4: 0 | E4: 0 | F4: 50 | G4: 3238665 | H4: 19744.236 | I4: 30 | J4: 65 | K4: 149 | L4: 149 | M4: 0 | N4: 1555 | O4: 0 | P4: 0 | Q4: 0 | R4: 0 | S4: 0 | T4: 0 | U4: 0 | V4: 0 | W4: 0 | X4: 0 | Y4: 0 | Z4: 0 | AA4: 0 | AB4: 0 | AC4: 0 | AD4: 0 | AE4: 2621 | AF4: 44 | AG4: 1310 | AH4: 2034 | AI4: 1000 | AJ4: 1000 | AK4: 300 | AL4: 25 | AM4: 300 | AN4: 5000 | AO4: 1 | AP4: 1.5 | AQ4: 100 | AR4: 0 | AS4: 20 | AT4: 3000 | AU4: 0 | AV4: 0 | AW4: 0 | AX4: 0 | AY4: 3 | AZ4: 4.1700001 | BA4: 30000 | BB4: 90 | BC4: 60 | BD4: 30 | BE4: 0 | BF4: 0 | BG4: 0 | BH4: 0 | BI4: 0 | BJ4: 0 | BK4: 0 | BL4: 0 | BM4: 0 | BN4: 0 | BO4: 0 | BP4: 0 | BQ4: 0 | BR4: 0 | BS4: 0 | BT4: 0 | BU4: 0 | BV4: 0 | BW4: 0 | BX4: 0
A5: 03002 | B5: WEAPON | C5: 0 | D5: 0 | E5: 0 | F5: 50 | G5: 3238665 | H5: 19744.236 | I5: 30 | J5: 65 | K5: 149 | L5: 149 | M5: 0 | N5: 1555 | O5: 0 | P5: 0 | Q5: 0 | R5: 0 | S5: 0 | T5: 0 | U5: 0 | V5: 0 | W5: 0 | X5: 0 | Y5: 0 | Z5: 0 | AA5: 0 | AB5: 0 | AC5: 0 | AD5: 0 | AE5: 2621 | AF5: 44 | AG5: 1310 | AH5: 2034 | AI5: 1000 | AJ5: 1000 | AK5: 300 | AL5: 25 | AM5: 300 | AN5: 5000 | AO5: 1 | AP5: 1.5 | AQ5: 100 | AR5: 0 | AS5: 20 | AT5: 3000 | AU5: 0 | AV5: 0 | AW5: 0 | AX5: 0 | AY5: 3 | AZ5: 4.1700001 | BA5: 30000 | BB5: 90 | BC5: 60 | BD5: 30 | BE5: 0 | BF5: 0 | BG5: 0 | BH5: 0 | BI5: 0 | BJ5: 0 | BK5: 0 | BL5: 0 | BM5: 0 | BN5: 0 | BO5: 0 | BP5: 0 | BQ5: 0 | BR5: 0 | BS5: 0 | BT5: 0 | BU5: 0 | BV5: 0 | BW5: 0 | BX5: 0
A6: 13060 | B6: Blueprint Vendor | C6: -1 | D6: 0 | E6: 0 | F6: 50 | G6: 3238665 | H6: 19744.236 | I6: 30 | J6: 65 | K6: 149 | L6: 149 | M6: 0 | N6: 1555 | O6: 0 | P6: 0 | Q6: 0 | R6: 0 | S6: 0 | T6: 0 | U6: 0 | V6: 0 | W6: 0 | X6: 0 | Y6: 0 | Z6: 0 | AA6: 0 | AB6: 0 | AC6: 0 | AD6: 0 | AE6: 2621 | AF6: 44 | AG6: 1310 | AH6: 2034 | AI6: 1000 | AJ6: 1000 | AK6: 300 | AL6: 25 | AM6: 300 | AN6: 5000 | AO6: 1 | AP6: 1.5 | AQ6: 100 | AR6: 0 | AS6: 20 | AT6: 3000 | AU6: 0 | AV6: 0 | AW6: 0 | AX6: 0 | AY6: 3 | AZ6: 4.1700001 | BA6: 30000 | BB6: 90 | BC6: 60 | BD6: 30 | BE6: 0 | BF6: 0 | BG6: 0 | BH6: 0 | BI6: 0 | BJ6: 0 | BK6: 0 | BL6: 0 | BM6: 0 | BN6: 0 | BO6: 0 | BP6: 0 | BQ6: 0 | BR6: 0 | BS6: 0 | BT6: 0 | BU6: 0 | BV6: 0 | BW6: 0 | BX6: 0
A7: 03011 | B7: POTION | C7: 0 | D7: 0 | E7: 0 | F7: 50 | G7: 3238665 | H7: 19744.236 | I7: 30 | J7: 65 | K7: 149 | L7: 149 | M7: 0 | N7: 1555 | O7: 0 | P7: 0 | Q7: 0 | R7: 0 | S7: 0 | T7: 0 | U7: 0 | V7: 0 | W7: 0 | X7: 0 | Y7: 0 | Z7: 0 | AA7: 0 | AB7: 0 | AC7: 0 | AD7: 0 | AE7: 2621 | AF7: 44 | AG7: 1310 | AH7: 2034 | AI7: 1000 | AJ7: 1000 | AK7: 300 | AL7: 25 | AM7: 300 | AN7: 5000 | AO7: 1 | AP7: 1.5 | AQ7: 100 | AR7: 0 | AS7: 20 | AT7: 3000 | AU7: 0 | AV7: 0 | AW7: 0 | AX7: 0 | AY7: 3 | AZ7: 4.1700001 | BA7: 30000 | BB7: 90 | BC7: 60 | BD7: 30 | BE7: 0 | BF7: 0 | BG7: 0 | BH7: 0 | BI7: 0 | BJ7: 0 | BK7: 0 | BL7: 0 | BM7: 0 | BN7: 0 | BO7: 0 | BP7: 0 | BQ7: 0 | BR7: 0 | BS7: 0 | BT7: 0 | BU7: 0 | BV7: 0 | BW7: 0 | BX7: 0
A8: 03012 | B8: POTION | C8: 0 | D8: 0 | E8: 0 | F8: 50 | G8: 3238665 | H8: 19744.236 | I8: 30 | J8: 65 | K8: 149 | L8: 149 | M8: 0 | N8: 1555 | O8: 0 | P8: 0 | Q8: 0 | R8: 0 | S8: 0 | T8: 0 | U8: 0 | V8: 0 | W8: 0 | X8: 0 | Y8: 0 | Z8: 0 | AA8: 0 | AB8: 0 | AC8: 0 | AD8: 0 | AE8: 2621 | AF8: 44 | AG8: 1310 | AH8: 2034 | AI8: 1000 | AJ8: 1000 | AK8: 300 | AL8: 25 | AM8: 300 | AN8: 5000 | AO8: 1 | AP8: 1.5 | AQ8: 100 | AR8: 0 | AS8: 20 | AT8: 3000 | AU8: 0 | AV8: 0 | AW8: 0 | AX8: 0 | AY8: 3 | AZ8: 4.1700001 | BA8: 30000 | BB8: 90 | BC8: 60 | BD8: 30 | BE8: 0 | BF8: 0 | BG8: 0 | BH8: 0 | BI8: 0 | BJ8: 0 | BK8: 0 | BL8: 0 | BM8: 0 | BN8: 0 | BO8: 0 | BP8: 0 | BQ8: 0 | BR8: 0 | BS8: 0 | BT8: 0 | BU8: 0 | BV8: 0 | BW8: 0 | BX8: 0
A9: 03020 | B9: ARMOR | C9: 0 | D9: 0 | E9: 0 | F9: 50 | G9: 3238665 | H9: 19744.236 | I9: 30 | J9: 65 | K9: 149 | L9: 149 | M9: 0 | N9: 1555 | O9: 0 | P9: 0 | Q9: 0 | R9: 0 | S9: 0 | T9: 0 | U9: 0 | V9: 0 | W9: 0 | X9: 0 | Y9: 0 | Z9: 0 | AA9: 0 | AB9: 0 | AC9: 0 | AD9: 0 | AE9: 2621 | AF9: 44 | AG9: 1310 | AH9: 2034 | AI9: 1000 | AJ9: 1000 | AK9: 300 | AL9: 25 | AM9: 300 | AN9: 5000 | AO9: 1 | AP9: 1.5 | AQ9: 100 | AR9: 0 | AS9: 20 | AT9: 3000 | AU9: 0 | AV9: 0 | AW9: 0 | AX9: 0 | AY9: 3 | AZ9: 4.1700001 | BA9: 30000 | BB9: 90 | BC9: 60 | BD9: 30 | BE9: 0 | BF9: 0 | BG9: 0 | BH9: 0 | BI9: 0 | BJ9: 0 | BK9: 0 | BL9: 0 | BM9: 0 | BN9: 0 | BO9: 0 | BP9: 0 | BQ9: 0 | BR9: 0 | BS9: 0 | BT9: 0 | BU9: 0 | BV9: 0 | BW9: 0 | BX9: 0
A10: 03021 | B10: Expensive Normal Armor Suit Vend | C10: 0 | D10: 0 | E10: 0 | F10: 50 | G10: 3238665 | H10: 19744.236 | I10: 30 | J10: 65 | K10: 149 | L10: 149 | M10: 0 | N10: 1555 | O10: 0 | P10: 0 | Q10: 0 | R10: 0 | S10: 0 | T10: 0 | U10: 0 | V10: 0 | W10: 0 | X10: 0 | Y10: 0 | Z10: 0 | AA10: 0 | AB10: 0 | AC10: 0 | AD10: 0 | AE10: 2621 | AF10: 44 | AG10: 1310 | AH10: 2034 | AI10: 1000 | AJ10: 1000 | AK10: 300 | AL10: 25 | AM10: 300 | AN10: 5000 | AO10: 1 | AP10: 1.5 | AQ10: 100 | AR10: 0 | AS10: 20 | AT10: 3000 | AU10: 0 | AV10: 0 | AW10: 0 | AX10: 0 | AY10: 3 | AZ10: 4.1700001 | BA10: 30000 | BB10: 90 | BC10: 60 | BD10: 30 | BE10: 0 | BF10: 0 | BG10: 0 | BH10: 0 | BI10: 0 | BJ10: 0 | BK10: 0 | BL10: 0 | BM10: 0 | BN10: 0 | BO10: 0 | BP10: 0 | BQ10: 0 | BR10: 0 | BS10: 0 | BT10: 0 | BU10: 0 | BV10: 0 | BW10: 0 | BX10: 0
A11: 03022 | B11: ARMOR | C11: 0 | D11: 0 | E11: 0 | F11: 50 | G11: 3238665 | H11: 19744.236 | I11: 30 | J11: 65 | K11: 149 | L11: 149 | M11: 0 | N11: 1555 | O11: 0 | P11: 0 | Q11: 0 | R11: 0 | S11: 0 | T11: 0 | U11: 0 | V11: 0 | W11: 0 | X11: 0 | Y11: 0 | Z11: 0 | AA11: 0 | AB11: 0 | AC11: 0 | AD11: 0 | AE11: 2621 | AF11: 44 | AG11: 1310 | AH11: 2034 | AI11: 1000 | AJ11: 1000 | AK11: 300 | AL11: 25 | AM11: 300 | AN11: 5000 | AO11: 1 | AP11: 1.5 | AQ11: 100 | AR11: 0 | AS11: 20 | AT11: 3000 | AU11: 0 | AV11: 0 | AW11: 0 | AX11: 0 | AY11: 3 | AZ11: 4.1700001 | BA11: 30000 | BB11: 90 | BC11: 60 | BD11: 30 | BE11: 0 | BF11: 0 | BG11: 0 | BH11: 0 | BI11: 0 | BJ11: 0 | BK11: 0 | BL11: 0 | BM11: 0 | BN11: 0 | BO11: 0 | BP11: 0 | BQ11: 0 | BR11: 0 | BS11: 0 | BT11: 0 | BU11: 0 | BV11: 0 | BW11: 0 | BX11: 0
A12: 2221E | B12: MAU | C12: 0 | D12: 0 | E12: 0 | F12: 50 | G12: 3238665 | H12: 19744.236 | I12: 30 | J12: 65 | K12: 149 | L12: 149 | M12: 0 | N12: 1555 | O12: 0 | P12: 0 | Q12: 0 | R12: 0 | S12: 0 | T12: 0 | U12: 0 | V12: 0 | W12: 0 | X12: 0 | Y12: 0 | Z12: 0 | AA12: 0 | AB12: 0 | AC12: 0 | AD12: 0 | AE12: 2621 | AF12: 44 | AG12: 1310 | AH12: 2034 | AI12: 1000 | AJ12: 1000 | AK12: 300 | AL12: 25 | AM12: 300 | AN12: 5000 | AO12: 1 | AP12: 1.5 | AQ12: 100 | AR12: 0 | AS12: 20 | AT12: 3000 | AU12: 0 | AV12: 0 | AW12: 0 | AX12: 0 | AY12: 3 | AZ12: 4.1700001 | BA12: 30000 | BB12: 90 | BC12: 60 | BD12: 30 | BE12: 0 | BF12: 0 | BG12: 0 | BH12: 0 | BI12: 0 | BJ12: 0 | BK12: 0 | BL12: 0 | BM12: 0 | BN12: 0 | BO12: 0 | BP12: 0 | BQ12: 0 | BR12: 0 | BS12: 0 | BT12: 0 | BU12: 0 | BV12: 0 | BW12: 0 | BX12: 0
A13: 03050 | B13: ORE | C13: 0 | D13: 0 | E13: 0 | F13: 50 | G13: 3238665 | H13: 19744.236 | I13: 30 | J13: 65 | K13: 149 | L13: 149 | M13: 0 | N13: 1555 | O13: 0 | P13: 0 | Q13: 0 | R13: 0 | S13: 0 | T13: 0 | U13: 0 | V13: 0 | W13: 0 | X13: 0 | Y13: 0 | Z13: 0 | AA13: 0 | AB13: 0 | AC13: 0 | AD13: 0 | AE13: 2621 | AF13: 44 | AG13: 1310 | AH13: 2034 | AI13: 1000 | AJ13: 1000 | AK13: 300 | AL13: 25 | AM13: 300 | AN13: 5000 | AO13: 1 | AP13: 1.5 | AQ13: 100 | AR13: 0 | AS13: 20 | AT13: 3000 | AU13: 0 | AV13: 0 | AW13: 0 | AX13: 0 | AY13: 3 | AZ13: 4.1700001 | BA13: 30000 | BB13: 90 | BC13: 60 | BD13: 30 | BE13: 0 | BF13: 0 | BG13: 0 | BH13: 0 | BI13: 0 | BJ13: 0 | BK13: 0 | BL13: 0 | BM13: 0 | BN13: 0 | BO13: 0 | BP13: 0 | BQ13: 0 | BR13: 0 | BS13: 0 | BT13: 0 | BU13: 0 | BV13: 0 | BW13: 0 | BX13: 0
A14: 03060 | B14: TOOL | C14: 0 | D14: 0 | E14: 0 | F14: 50 | G14: 3238665 | H14: 19744.236 | I14: 30 | J14: 65 | K14: 149 | L14: 149 | M14: 0 | N14: 1555 | O14: 0 | P14: 0 | Q14: 0 | R14: 0 | S14: 0 | T14: 0 | U14: 0 | V14: 0 | W14: 0 | X14: 0 | Y14: 0 | Z14: 0 | AA14: 0 | AB14: 0 | AC14: 0 | AD14: 0 | AE14: 2621 | AF14: 44 | AG14: 1310 | AH14: 2034 | AI14: 1000 | AJ14: 1000 | AK14: 300 | AL14: 25 | AM14: 300 | AN14: 5000 | AO14: 1 | AP14: 1.5 | AQ14: 100 | AR14: 0 | AS14: 20 | AT14: 3000 | AU14: 0 | AV14: 0 | AW14: 0 | AX14: 0 | AY14: 3 | AZ14: 4.1700001 | BA14: 30000 | BB14: 90 | BC14: 60 | BD14: 30 | BE14: 0 | BF14: 0 | BG14: 0 | BH14: 0 | BI14: 0 | BJ14: 0 | BK14: 0 | BL14: 0 | BM14: 0 | BN14: 0 | BO14: 0 | BP14: 0 | BQ14: 0 | BR14: 0 | BS14: 0 | BT14: 0 | BU14: 0 | BV14: 0 | BW14: 0 | BX14: 0
... A361: 131B0 | B361: Nexus Billboard | C361: -1 | D361: 1 | E361: 0 | F361: 50 | G361: 3238665 | H361: 19744.236 | I361: 30 | J361: 65 | K361: 149 | L361: 149 | M361: 0 | N361: 1555 | O361: 0 | P361: 0 | Q361: 0 | R361: 0 | S361: 0 | T361: 0 | U361: 0 | V361: 0 | W361: 0 | X361: 0 | Y361: 0 | Z361: 0 | AA361: 0 | AB361: 0 | AC361: 0 | AD361: 0 | AE361: 2621 | AF361: 44 | AG361: 1310 | AH361: 2034 | AI361: 1000 | AJ361: 1000 | AK361: 300 | AL361: 25 | AM361: 300 | AN361: 5000 | AO361: 1 | AP361: 1.5 | AQ361: 100 | AR361: 0 | AS361: 20 | AT361: 3000 | AU361: 0 | AV361: 0 | AW361: 0 | AX361: 0 | AY361: 3 | AZ361: 4.1700001 | BA361: 30000 | BB361: 90 | BC361: 60 | BD361: 30 | BE361: 0 | BF361: 0 | BG361: 0 | BH361: 0 | BI361: 0 | BJ361: 0 | BK361: 0 | BL361: 0 | BM361: 0 | BN361: 0 | BO361: 0 | BP361: 0 | BQ361: 0 | BR361: 0 | BS361: 0 | BT361: 0 | BU361: 0 | BV361: 0 | BW361: 0 | BX361: 0

Sheet StoreList
A1: string[64] | B1: string[64] | C1: string[64] | D1: string[64] | E1: string[64] | F1: dword | G1: dword | H1: dword | I1: dword | J1: dword | K1: dword | L1: dword | M1: dword | N1: dword | O1: dword | P1: dword | Q1: dword | R1: dword | S1: dword | T1: dword | U1: dword | V1: dword | W1: xeh | X1: string[64] | Y1: string[64] | Z1: string[64] | AA1: string[64] | AB1: string[64] | AC1: string[64] | AD1: string[64] | AE1: string[64] | AF1: string[64] | AG1: string[64] | AH1: string[64] | AI1: string[64] | AJ1: string[64] | AK1: string[64] | AL1: string[64] | AM1: string[64] | AN1: string[64] | AO1: string[64] | AP1: string[64] | AQ1: string[64] | AR1: string[64] | AS1: string[64] | AT1: string[64] | AU1: string[64] | AV1: string[64] | AW1: string[64] | AX1: string[64] | AY1: string[64] | AZ1: string[64] | BA1: string[64] | BB1: string[64] | BC1: string[64] | BD1: string[64] | BE1: string[64] | BF1: string[64] | BG1: string[64] | BH1: string[64] | BI1: string[64] | BJ1: string[64] | BK1: string[64] | BL1: string[64] | BM1: string[64] | BN1: string[64] | BO1: string[64] | BP1: string[64] | BQ1: string[64] | BR1: string[64] | BS1: string[64] | BT1: string[64] | BU1: string[64] | BV1: string[64] | BW1: string[64] | BX1: string[64] | BY1: string[64] | BZ1: string[64] | CA1: string[64] | CB1: string[64] | CC1: string[64] | CD1: string[64] | CE1: string[64] | CF1: string[64] | CG1: string[64] | CH1: string[64] | CI1: string[64] | CJ1: string[64] | CK1: string[64] | CL1: string[64] | CM1: string[64] | CN1: string[64] | CO1: string[64] | CP1: string[64] | CQ1: string[64] | CR1: string[64] | CS1: string[64] | CT1: string[64] | CU1: string[64] | CV1: string[64] | CW1: string[64] | CX1: string[64] | CY1: string[64] | CZ1: string[64] | DA1: string[64] | DB1: string[64] | DC1: string[64] | DD1: string[64] | DE1: string[64] | DF1: string[64] | DG1: string[64] | DH1: string[64] | DI1: string[64] | DJ1: string[64] | DK1: string[64] | DL1: string[64] | DM1: string[64] | DN1: string[64] | DO1: string[64] | DP1: string[64] | DQ1: string[64] | DR1: string[64] | DS1: string[64] | DT1: string[64] | DU1: string[64] | DV1: string[64] | DW1: string[64] | DX1: string[64] | DY1: string[64] | DZ1: string[64] | EA1: string[64] | EB1: string[64] | EC1: string[64] | ED1: string[64] | EE1: string[64] | EF1: string[64] | EG1: string[64] | EH1: string[64] | EI1: string[64] | EJ1: string[64] | EK1: string[64] | EL1: string[64] | EM1: string[64] | EN1: string[64] | EO1: string[64] | EP1: string[64] | EQ1: string[64] | ER1: string[64] | ES1: string[64] | ET1: string[64] | EU1: string[64] | EV1: string[64] | EW1: string[64] | EX1: string[64] | EY1: string[64] | EZ1: string[64] | FA1: string[64] | FB1: string[64] | FC1: string[64] | FD1: string[64] | FE1: string[64] | FF1: string[64] | FG1: string[64] | FH1: string[64] | FI1: string[64] | FJ1: string[64] | FK1: string[64] | FL1: string[64] | FM1: string[64] | FN1: string[64] | FO1: string[64] | FP1: string[64] | FQ1: string[64] | FR1: string[64] | FS1: string[64] | FT1: string[64] | FU1: string[64] | FV1: string[64] | FW1: string[64] | FX1: string[64] | FY1: string[64] | FZ1: string[64] | GA1: string[64] | GB1: string[64] | GC1: string[64] | GD1: string[64] | GE1: string[64] | GF1: string[64] | GG1: string[64] | GH1: string[64] | GI1: string[64] | GJ1: string[64] | GK1: string[64] | GL1: string[64] | GM1: string[64] | GN1: string[64] | GO1: string[64] | GP1: string[64] | GQ1: string[64] | GR1: string[64] | GS1: string[64] | GT1: string[64] | GU1: string[64] | GV1: string[64] | GW1: string[64] | GX1: string[64] | GY1: string[64] | GZ1: string[64] | HA1: string[64] | HB1: string[64] | HC1: string[64] | HD1: string[64] | HE1: string[64] | HF1: string[64] | HG1: string[64] | HH1: string[64] | HI1: string[64] | HJ1: string[64] | HK1: string[64] | HL1: string[64] | HM1: string[64] | HN1: string[64] | HO1: string[64] | HP1: string[64] | HQ1: dword | HR1: string[64] | HS1: dword | HT1: string[64] | HU1: dword | HV1: string[64] | HW1: dword | HX1: string[64] | HY1: dword | HZ1: string[64] | IA1: dword | IB1: string[64] | IC1: dword | ID1: string[64] | IE1: dword | IF1: string[64] | IG1: dword | IH1: string[64] | II1: dword | IJ1: string[64] | IK1: dword | IL1: string[64] | IM1: dword | IN1: string[64] | IO1: dword | IP1: string[64] | IQ1: dword | IR1: string[64] | IS1: dword | IT1: string[64] | IU1: dword | IV1: END
A2: Code | B2: BindDummy | C2: =NPCharacter!A2 -> Code | D2: NPCName | E2: MAPCode | F2: Store_trade | G2: IsSet_NPCangle | H2: Store_NPCangle | I2: NPCClass1 | J2: NPCClass2 | K2: NPCClass3 | L2: NPCClass4 | M2: NPCClass5 | N2: NPCClass6 | O2: NPCClass7 | P2: NPCClass8 | Q2: NPCClass9 | R2: NPCClass10 | S2: ListCount | T2: LimListCount | U2: LimItemInitTime | V2: PriceSet | W2: ItemUpCode | X2: Item1 | Y2: Item2 | Z2: Item3 | AA2: Item4 | AB2: Item5 | AC2: Item6 | AD2: Item7 | AE2: Item8 | AF2: Item9 | AG2: Item10 | AH2: Item11 | AI2: Item12 | AJ2: Item13 | AK2: Item14 | AL2: Item15 | AM2: Item16 | AN2: Item17 | AO2: Item18 | AP2: Item19 | AQ2: Item20 | AR2: Item21 | AS2: Item22 | AT2: Item23 | AU2: Item24 | AV2: Item25 | AW2: Item26 | AX2: Item27 | AY2: Item28 | AZ2: Item29 | BA2: Item30 | BB2: Item31 | BC2: Item32 | BD2: Item33 | BE2: Item34 | BF2: Item35 | BG2: Item36 | BH2: Item37 | BI2: Item38 | BJ2: Item39 | BK2: Item40 | BL2: Item41 | BM2: Item42 | BN2: Item43 | BO2: Item44 | BP2: Item45 | BQ2: Item46 | BR2: Item47 | BS2: Item48 | BT2: Item49 | BU2: Item50 | BV2: Item51 | BW2: Item52 | BX2: Item53 | BY2: Item54 | BZ2: Item55 | CA2: Item56 | CB2: Item57 | CC2: Item58 | CD2: Item59 | CE2: Item60 | CF2: Item61 | CG2: Item62 | CH2: Item63 | CI2: Item64 | CJ2: Item65 | CK2: Item66 | CL2: Item67 | CM2: Item68 | CN2: Item69 | CO2: Item70 | CP2: Item71 | CQ2: Item72 | CR2: Item73 | CS2: Item74 | CT2: Item75 | CU2: Item76 | CV2: Item77 | CW2: Item78 | CX2: Item79 | CY2: Item80 | CZ2: Item81 | DA2: Item82 | DB2: Item83 | DC2: Item84 | DD2: Item85 | DE2: Item86 | DF2: Item87 | DG2: Item88 | DH2: Item89 | DI2: Item90 | DJ2: Item91 | DK2: Item92 | DL2: Item93 | DM2: Item94 | DN2: Item95 | DO2: Item96 | DP2: Item97 | DQ2: Item98 | DR2: Item99 | DS2: Item100 | DT2: Item101 | DU2: Item102 | DV2: Item103 | DW2: Item104 | DX2: Item105 | DY2: Item106 | DZ2: Item107 | EA2: Item108 | EB2: Item109 | EC2: Item110 | ED2: Item111 | EE2: Item112 | EF2: Item113 | EG2: Item114 | EH2: Item115 | EI2: Item116 | EJ2: Item117 | EK2: Item118 | EL2: Item119 | EM2: Item120 | EN2: Item121 | EO2: Item122 | EP2: Item123 | EQ2: Item124 | ER2: Item125 | ES2: Item126 | ET2: Item127 | EU2: Item128 | EV2: Item129 | EW2: Item130 | EX2: Item131 | EY2: Item132 | EZ2: Item133 | FA2: Item134 | FB2: Item135 | FC2: Item136 | FD2: Item137 | FE2: Item138 | FF2: Item139 | FG2: Item140 | FH2: Item141 | FI2: Item142 | FJ2: Item143 | FK2: Item144 | FL2: Item145 | FM2: Item146 | FN2: Item147 | FO2: Item148 | FP2: Item149 | FQ2: Item150 | FR2: Item151 | FS2: Item152 | FT2: Item153 | FU2: Item154 | FV2: Item155 | FW2: Item156 | FX2: Item157 | FY2: Item158 | FZ2: Item159 | GA2: Item160 | GB2: Item161 | GC2: Item162 | GD2: Item163 | GE2: Item164 | GF2: Item165 | GG2: Item166 | GH2: Item167 | GI2: Item168 | GJ2: Item169 | GK2: Item170 | GL2: Item171 | GM2: Item172 | GN2: Item173 | GO2: Item174 | GP2: Item175 | GQ2: Item176 | GR2: Item177 | GS2: Item178 | GT2: Item179 | GU2: Item180 | GV2: Item181 | GW2: Item182 | GX2: Item183 | GY2: Item184 | GZ2: Item185 | HA2: Item186 | HB2: Item187 | HC2: Item188 | HD2: Item189 | HE2: Item190 | HF2: Item191 | HG2: Item192 | HH2: Item193 | HI2: Item194 | HJ2: Item195 | HK2: Item196 | HL2: Item197 | HM2: Item198 | HN2: Item199 | HO2: Item200 | HP2: tmp1 | HQ2: tempnum1 | HR2: tmp2 | HS2: tempnum2 | HT2: tmp3 | HU2: tempnum3 | HV2: tmp4 | HW2: tempnum4 | HX2: tmp5 | HY2: tempnum5 | HZ2: tmp6 | IA2: tempnum6 | IB2: tmp7 | IC2: tempnum7 | ID2: tmp8 | IE2: tempnum8 | IF2: tmp9 | IG2: tempnum9 | IH2: tmp10 | II2: tempnum10 | IJ2: tmp11 | IK2: tempnum11 | IL2: tmp12 | IM2: tempnum12 | IN2: tmp13 | IO2: tempnum13 | IP2: tmp14 | IQ2: tempnum14 | IR2: tmp15 | IS2: tempnum15 | IT2: tmp16 | IU2: tempnum16
A3: sd03000 | B3: bd03000 | C3: =NPCharacter!A3 -> 03000 | D3: Green Eye | E3: NeutralB | F3: 0 | G3: 0 | H3: 0 | I3: 1 | J3: 13 | K3: 2 | L3: 53 | M3: 0 | N3: 0 | O3: 0 | P3: 0 | Q3: 0 | R3: 0 | S3: 62 | T3: 0 | U3: 0 | V3: 1 | W3: -1 | X3: iwkna03 | Y3: iwkna05 | Z3: iwkna07 | AA3: iwkna10 | AB3: iwkna12 | AC3: iwkna15 | AD3: iwswa03 | AE3: iwswa05 | AF3: iwswa07 | AG3: iwswa10 | AH3: iwswa12 | AI3: iwswa15 | AJ3: iwaxa03 | AK3: iwaxa05 | AL3: iwaxa07 | AM3: iwaxa10 | AN3: iwaxa12 | AO3: iwaxa15 | AP3: iwmaa03 | AQ3: iwmaa05 | AR3: iwmaa07 | AS3: iwmaa10 | AT3: iwmaa12 | AU3: iwmaa15 | AV3: iwsta03 | AW3: iwsta05 | AX3: iwsta07 | AY3: iwsta10 | AZ3: iwsta12 | BA3: iwsta15 | BB3: iwspa03 | BC3: iwspa05 | BD3: iwspa07 | BE3: iwspa10 | BF3: iwspa12 | BG3: iwspa15 | BH3: iwboa03 | BI3: iwboa05 | BJ3: iwboa07 | BK3: iwboa10 | BL3: iwboa12 | BM3: iwboa15 | BN3: iwfia03 | BO3: iwfia05 | BP3: iwfia07 | BQ3: iwfia10 | BR3: iwfia12 | BS3: iwfia15 | BT3: iwdka05 | BU3: iwdka10 | BV3: iwdka15 | BW3: idbca04 | BX3: idbca07 | BY3: idbca10 | BZ3: idbca13 | CA3: idbca16 | CB3: ibbow01 | CC3: ibbow08 | CD3: ibbow15 | CE3: ibfir01 | CF3: ibfir04 | CG3: ibfir05 | CH3: 0 | CI3: 0 | CJ3: 0 | CK3: 0 | CL3: 0 | CM3: 0 | CN3: 0 | CO3: 0 | CP3: 0 | CQ3: 0 | CR3: 0 | CS3: 0 | CT3: 0 | CU3: 0 | CV3: 0 | CW3: 0 | CX3: 0 | CY3: 0 | CZ3: 0 | DA3: 0 | DB3: 0 | DC3: 0 | DD3: 0 | DE3: 0 | DF3: 0 | DG3: 0 | DH3: 0 | DI3: 0 | DJ3: 0 | DK3: 0 | DL3: 0 | DM3: 0 | DN3: 0 | DO3: 0 | DP3: 0 | DQ3: 0 | DR3: 0 | DS3: 0 | DT3: 0 | DU3: 0 | DV3: 0 | DW3: 0 | DX3: 0 | DY3: 0 | DZ3: 0 | EA3: 0 | EB3: 0 | EC3: 0 | ED3: 0 | EE3: 0 | EF3: 0 | EG3: 0 | EH3: 0 | EI3: 0 | EJ3: 0 | EK3: 0 | EL3: 0 | EM3: 0 | EN3: 0 | EO3: 0 | EP3: 0 | EQ3: 0 | ER3: 0 | ES3: 0 | ET3: 0 | EU3: 0 | EV3: 0 | EW3: 0 | EX3: 0 | EY3: 0 | EZ3: 0 | FA3: 0 | FB3: 0 | FC3: 0 | FD3: 0 | FE3: 0 | FF3: 0 | FG3: 0 | FH3: 0 | FI3: 0 | FJ3: 0 | FK3: 0 | FL3: 0 | FM3: 0 | FN3: 0 | FO3: 0 | FP3: 0 | FQ3: 0 | FR3: 0 | FS3: 0 | FT3: 0 | FU3: 0 | FV3: 0 | FW3: 0 | FX3: 0 | FY3: 0 | FZ3: 0 | GA3: 0 | GB3: 0 | GC3: 0 | GD3: 0 | GE3: 0 | GF3: 0 | GG3: 0 | GH3: 0 | GI3: 0 | GJ3: 0 | GK3: 0 | GL3: 0 | GM3: 0 | GN3: 0 | GO3: 0 | GP3: 0 | GQ3: 0 | GR3: 0 | GS3: 0 | GT3: 0 | GU3: 0 | GV3: 0 | GW3: 0 | GX3: 0 | GY3: 0 | GZ3: 0 | HA3: 0 | HB3: 0 | HC3: 0 | HD3: 0 | HE3: 0 | HF3: 0 | HG3: 0 | HH3: 0 | HI3: 0 | HJ3: 0 | HK3: 0 | HL3: 0 | HM3: 0 | HN3: 0 | HO3: 0 | HP3: 0 | HQ3: 0 | HR3: 0 | HS3: 0 | HT3: 0 | HU3: 0 | HV3: 0 | HW3: 0 | HX3: 0 | HY3: 0 | HZ3: 0 | IA3: 0 | IB3: 0 | IC3: 0 | ID3: 0 | IE3: 0 | IF3: 0 | IG3: 0 | IH3: 0 | II3: 0 | IJ3: 0 | IK3: 0 | IL3: 0 | IM3: 0 | IN3: 0 | IO3: 0 | IP3: 0 | IQ3: 0 | IR3: 0 | IS3: 0 | IT3: 0 | IU3: 0
A4: sd03001 | B4: bd03001 | C4: =NPCharacter!A4 -> 03001 | D4: Madison | E4: NeutralB | F4: 0 | G4: 0 | H4: 0 | I4: 1 | J4: 13 | K4: 2 | L4: 0 | M4: 0 | N4: 0 | O4: 0 | P4: 0 | Q4: 0 | R4: 0 | S4: 62 | T4: 0 | U4: 0 | V4: 1 | W4: -1 | X4: iwkna03 | Y4: iwkna05 | Z4: iwkna07 | AA4: iwkna10 | AB4: iwkna12 | AC4: iwkna15 | AD4: iwswa03 | AE4: iwswa05 | AF4: iwswa07 | AG4: iwswa10 | AH4: iwswa12 | AI4: iwswa15 | AJ4: iwaxa03 | AK4: iwaxa05 | AL4: iwaxa07 | AM4: iwaxa10 | AN4: iwaxa12 | AO4: iwaxa15 | AP4: iwmaa03 | AQ4: iwmaa05 | AR4: iwmaa07 | AS4: iwmaa10 | AT4: iwmaa12 | AU4: iwmaa15 | AV4: iwsta03 | AW4: iwsta05 | AX4: iwsta07 | AY4: iwsta10 | AZ4: iwsta12 | BA4: iwsta15 | BB4: iwspa03 | BC4: iwspa05 | BD4: iwspa07 | BE4: iwspa10 | BF4: iwspa12 | BG4: iwspa15 | BH4: iwboa03 | BI4: iwboa05 | BJ4: iwboa07 | BK4: iwboa10 | BL4: iwboa12 | BM4: iwboa15 | BN4: iwfia03 | BO4: iwfia05 | BP4: iwfia07 | BQ4: iwfia10 | BR4: iwfia12 | BS4: iwfia15 | BT4: iwdka05 | BU4: iwdka10 | BV4: iwdka15 | BW4: idbca04 | BX4: idbca07 | BY4: idbca10 | BZ4: idbca13 | CA4: idbca16 | CB4: ibbow01 | CC4: ibbow08 | CD4: ibbow15 | CE4: ibfir01 | CF4: ibfir04 | CG4: ibfir05 | CH4: 0 | CI4: 0 | CJ4: 0 | CK4: 0 | CL4: 0 | CM4: 0 | CN4: 0 | CO4: 0 | CP4: 0 | CQ4: 0 | CR4: 0 | CS4: 0 | CT4: 0 | CU4: 0 | CV4: 0 | CW4: 0 | CX4: 0 | CY4: 0 | CZ4: 0 | DA4: 0 | DB4: 0 | DC4: 0 | DD4: 0 | DE4: 0 | DF4: 0 | DG4: 0 | DH4: 0 | DI4: 0 | DJ4: 0 | DK4: 0 | DL4: 0 | DM4: 0 | DN4: 0 | DO4: 0 | DP4: 0 | DQ4: 0 | DR4: 0 | DS4: 0 | DT4: 0 | DU4: 0 | DV4: 0 | DW4: 0 | DX4: 0 | DY4: 0 | DZ4: 0 | EA4: 0 | EB4: 0 | EC4: 0 | ED4: 0 | EE4: 0 | EF4: 0 | EG4: 0 | EH4: 0 | EI4: 0 | EJ4: 0 | EK4: 0 | EL4: 0 | EM4: 0 | EN4: 0 | EO4: 0 | EP4: 0 | EQ4: 0 | ER4: 0 | ES4: 0 | ET4: 0 | EU4: 0 | EV4: 0 | EW4: 0 | EX4: 0 | EY4: 0 | EZ4: 0 | FA4: 0 | FB4: 0 | FC4: 0 | FD4: 0 | FE4: 0 | FF4: 0 | FG4: 0 | FH4: 0 | FI4: 0 | FJ4: 0 | FK4: 0 | FL4: 0 | FM4: 0 | FN4: 0 | FO4: 0 | FP4: 0 | FQ4: 0 | FR4: 0 | FS4: 0 | FT4: 0 | FU4: 0 | FV4: 0 | FW4: 0 | FX4: 0 | FY4: 0 | FZ4: 0 | GA4: 0 | GB4: 0 | GC4: 0 | GD4: 0 | GE4: 0 | GF4: 0 | GG4: 0 | GH4: 0 | GI4: 0 | GJ4: 0 | GK4: 0 | GL4: 0 | GM4: 0 | GN4: 0 | GO4: 0 | GP4: 0 | GQ4: 0 | GR4: 0 | GS4: 0 | GT4: 0 | GU4: 0 | GV4: 0 | GW4: 0 | GX4: 0 | GY4: 0 | GZ4: 0 | HA4: 0 | HB4: 0 | HC4: 0 | HD4: 0 | HE4: 0 | HF4: 0 | HG4: 0 | HH4: 0 | HI4: 0 | HJ4: 0 | HK4: 0 | HL4: 0 | HM4: 0 | HN4: 0 | HO4: 0 | HP4: 0 | HQ4: 0 | HR4: 0 | HS4: 0 | HT4: 0 | HU4: 0 | HV4: 0 | HW4: 0 | HX4: 0 | HY4: 0 | HZ4: 0 | IA4: 0 | IB4: 0 | IC4: 0 | ID4: 0 | IE4: 0 | IF4: 0 | IG4: 0 | IH4: 0 | II4: 0 | IJ4: 0 | IK4: 0 | IL4: 0 | IM4: 0 | IN4: 0 | IO4: 0 | IP4: 0 | IQ4: 0 | IR4: 0 | IS4: 0 | IT4: 0 | IU4: 0
A5: sd03002 | B5: bd03002 | C5: =NPCharacter!A5 -> 03002 | D5: Cecil Atkin | E5: NeutralB | F5: 0 | G5: 0 | H5: 0 | I5: 1 | J5: 13 | K5: 0 | L5: 0 | M5: 0 | N5: 0 | O5: 0 | P5: 0 | Q5: 0 | R5: 0 | S5: 81 | T5: 0 | U5: 0 | V5: 1 | W5: -1 | X5: iwkna12 | Y5: iwkna15 | Z5: iwkna18 | AA5: iwkna20 | AB5: iwkna22 | AC5: iwkna25 | AD5: iwkna28 | AE5: iwkna30 | AF5: iwswa12 | AG5: iwswa15 | AH5: iwswa18 | AI5: iwswa20 | AJ5: iwswa22 | AK5: iwswa25 | AL5: iwswa28 | AM5: iwswa30 | AN5: iwaxa12 | AO5: iwaxa15 | AP5: iwaxa18 | AQ5: iwaxa20 | AR5: iwaxa22 | AS5: iwaxa25 | AT5: iwaxa28 | AU5: iwaxa30 | AV5: iwmaa12 | AW5: iwmaa15 | AX5: iwmaa18 | AY5: iwmaa20 | AZ5: iwmaa22 | BA5: iwmaa25 | BB5: iwmaa28 | BC5: iwmaa30 | BD5: iwsta12 | BE5: iwsta15 | BF5: iwsta18 | BG5: iwsta20 | BH5: iwsta22 | BI5: iwsta25 | BJ5: iwsta28 | BK5: iwsta30 | BL5: iwspa12 | BM5: iwspa15 | BN5: iwspa18 | BO5: iwspa20 | BP5: iwspa22 | BQ5: iwspa25 | BR5: iwspa28 | BS5: iwspa30 | BT5: iwboa12 | BU5: iwboa15 | BV5: iwboa18 | BW5: iwboa20 | BX5: iwboa22 | BY5: iwboa25 | BZ5: iwboa28 | CA5: iwboa30 | CB5: iwfia12 | CC5: iwfia15 | CD5: iwfia18 | CE5: iwfia20 | CF5: iwfia22 | CG5: iwfia25 | CH5: iwfia28 | CI5: iwfia30 | CJ5: iwdka20 | CK5: iwdka25 | CL5: iwdka30 | CM5: idbca19 | CN5: idbca21 | CO5: idbca23 | CP5: idbca25 | CQ5: idbca27 | CR5: idbca29 | CS5: idbca31 | CT5: idbca33 | CU5: ibbow01 | CV5: ibbow08 | CW5: ibbow15 | CX5: ibfir01 | CY5: ibfir04 | CZ5: ibfir05 | DA5: 0 | DB5: 0 | DC5: 0 | DD5: 0 | DE5: 0 | DF5: 0 | DG5: 0 | DH5: 0 | DI5: 0 | DJ5: 0 | DK5: 0 | DL5: 0 | DM5: 0 | DN5: 0 | DO5: 0 | DP5: 0 | DQ5: 0 | DR5: 0 | DS5: 0 | DT5: 0 | DU5: 0 | DV5: 0 | DW5: 0 | DX5: 0 | DY5: 0 | DZ5: 0 | EA5: 0 | EB5: 0 | EC5: 0 | ED5: 0 | EE5: 0 | EF5: 0 | EG5: 0 | EH5: 0 | EI5: 0 | EJ5: 0 | EK5: 0 | EL5: 0 | EM5: 0 | EN5: 0 | EO5: 0 | EP5: 0 | EQ5: 0 | ER5: 0 | ES5: 0 | ET5: 0 | EU5: 0 | EV5: 0 | EW5: 0 | EX5: 0 | EY5: 0 | EZ5: 0 | FA5: 0 | FB5: 0 | FC5: 0 | FD5: 0 | FE5: 0 | FF5: 0 | FG5: 0 | FH5: 0 | FI5: 0 | FJ5: 0 | FK5: 0 | FL5: 0 | FM5: 0 | FN5: 0 | FO5: 0 | FP5: 0 | FQ5: 0 | FR5: 0 | FS5: 0 | FT5: 0 | FU5: 0 | FV5: 0 | FW5: 0 | FX5: 0 | FY5: 0 | FZ5: 0 | GA5: 0 | GB5: 0 | GC5: 0 | GD5: 0 | GE5: 0 | GF5: 0 | GG5: 0 | GH5: 0 | GI5: 0 | GJ5: 0 | GK5: 0 | GL5: 0 | GM5: 0 | GN5: 0 | GO5: 0 | GP5: 0 | GQ5: 0 | GR5: 0 | GS5: 0 | GT5: 0 | GU5: 0 | GV5: 0 | GW5: 0 | GX5: 0 | GY5: 0 | GZ5: 0 | HA5: 0 | HB5: 0 | HC5: 0 | HD5: 0 | HE5: 0 | HF5: 0 | HG5: 0 | HH5: 0 | HI5: 0 | HJ5: 0 | HK5: 0 | HL5: 0 | HM5: 0 | HN5: 0 | HO5: 0 | HP5: 0 | HQ5: 0 | HR5: 0 | HS5: 0 | HT5: 0 | HU5: 0 | HV5: 0 | HW5: 0 | HX5: 0 | HY5: 0 | HZ5: 0 | IA5: 0 | IB5: 0 | IC5: 0 | ID5: 0 | IE5: 0 | IF5: 0 | IG5: 0 | IH5: 0 | II5: 0 | IJ5: 0 | IK5: 0 | IL5: 0 | IM5: 0 | IN5: 0 | IO5: 0 | IP5: 0 | IQ5: 0 | IR5: 0 | IS5: 0 | IT5: 0 | IU5: 0
A6: sd03010 | B6: bd03010 | C6: =NPCharacter!A6 -> 13060 | D6: omae wa mou shindeiru? | E6: NeutralB | F6: 23 | G6: 0 | H6: 0 | I6: 1 | J6: 0 | K6: 0 | L6: 0 | M6: 0 | N6: 0 | O6: 0 | P6: 0 | Q6: 0 | R6: 0 | S6: 38 | T6: 0 | U6: 0 | V6: 1 | W6: -1 | X6: 0 | Y6: 0 | Z6: 0 | AA6: 0 | AB6: 0 | AC6: 0 | AD6: 0 | AE6: 0 | AF6: 0 | AG6: 0 | AH6: 0 | AI6: 0 | AJ6: 0 | AK6: 0 | AL6: 0 | AM6: 0 | AN6: 0 | AO6: 0 | AP6: 0 | AQ6: 0 | AR6: 0 | AS6: 0 | AT6: 0 | AU6: 0 | AV6: 0 | AW6: 0 | AX6: 0 | AY6: 0 | AZ6: 0 | BA6: 0 | BB6: 0 | BC6: 0 | BD6: 0 | BE6: 0 | BF6: 0 | BG6: 0 | BH6: 0 | BI6: 0 | BJ6: 0 | BK6: 0 | BL6: 0 | BM6: 0 | BN6: 0 | BO6: 0 | BP6: 0 | BQ6: 0 | BR6: 0 | BS6: 0 | BT6: 0 | BU6: 0 | BV6: 0 | BW6: 0 | BX6: 0 | BY6: 0 | BZ6: 0 | CA6: 0 | CB6: 0 | CC6: 0 | CD6: 0 | CE6: 0 | CF6: 0 | CG6: 0 | CH6: 0 | CI6: 0 | CJ6: 0 | CK6: 0 | CL6: 0 | CM6: 0 | CN6: 0 | CO6: 0 | CP6: 0 | CQ6: 0 | CR6: 0 | CS6: 0 | CT6: 0 | CU6: 0 | CV6: 0 | CW6: 0 | CX6: 0 | CY6: 0 | CZ6: 0 | DA6: 0 | DB6: 0 | DC6: 0 | DD6: 0 | DE6: 0 | DF6: 0 | DG6: 0 | DH6: 0 | DI6: 0 | DJ6: 0 | DK6: 0 | DL6: 0 | DM6: 0 | DN6: 0 | DO6: 0 | DP6: 0 | DQ6: 0 | DR6: 0 | DS6: 0 | DT6: 0 | DU6: 0 | DV6: 0 | DW6: 0 | DX6: 0 | DY6: 0 | DZ6: 0 | EA6: 0 | EB6: 0 | EC6: 0 | ED6: 0 | EE6: 0 | EF6: 0 | EG6: 0 | EH6: 0 | EI6: 0 | EJ6: 0 | EK6: 0 | EL6: 0 | EM6: 0 | EN6: 0 | EO6: 0 | EP6: 0 | EQ6: 0 | ER6: 0 | ES6: 0 | ET6: 0 | EU6: 0 | EV6: 0 | EW6: 0 | EX6: 0 | EY6: 0 | EZ6: 0 | FA6: 0 | FB6: 0 | FC6: 0 | FD6: 0 | FE6: 0 | FF6: 0 | FG6: 0 | FH6: 0 | FI6: 0 | FJ6: 0 | FK6: 0 | FL6: 0 | FM6: 0 | FN6: 0 | FO6: 0 | FP6: 0 | FQ6: 0 | FR6: 0 | FS6: 0 | FT6: 0 | FU6: 0 | FV6: 0 | FW6: 0 | FX6: 0 | FY6: 0 | FZ6: 0 | GA6: 0 | GB6: 0 | GC6: 0 | GD6: 0 | GE6: 0 | GF6: 0 | GG6: 0 | GH6: 0 | GI6: 0 | GJ6: 0 | GK6: 0 | GL6: 0 | GM6: 0 | GN6: 0 | GO6: 0 | GP6: 0 | GQ6: 0 | GR6: 0 | GS6: 0 | GT6: 0 | GU6: 0 | GV6: 0 | GW6: 0 | GX6: 0 | GY6: 0 | GZ6: 0 | HA6: 0 | HB6: 0 | HC6: 0 | HD6: 0 | HE6: 0 | HF6: 0 | HG6: 0 | HH6: 0 | HI6: 0 | HJ6: 0 | HK6: 0 | HL6: 0 | HM6: 0 | HN6: 0 | HO6: 0 | HP6: 0 | HQ6: 0 | HR6: 0 | HS6: 0 | HT6: 0 | HU6: 0 | HV6: 0 | HW6: 0 | HX6: 0 | HY6: 0 | HZ6: 0 | IA6: 0 | IB6: 0 | IC6: 0 | ID6: 0 | IE6: 0 | IF6: 0 | IG6: 0 | IH6: 0 | II6: 0 | IJ6: 0 | IK6: 0 | IL6: 0 | IM6: 0 | IN6: 0 | IO6: 0 | IP6: 0 | IQ6: 0 | IR6: 0 | IS6: 0 | IT6: 0 | IU6: 0
A7: sd03011 | B7: bd03011 | C7: =NPCharacter!A7 -> 03011 | D7: Charlie | E7: NeutralB | F7: 1 | G7: 0 | H7: 0 | I7: 1 | J7: 13 | K7: 0 | L7: 0 | M7: 0 | N7: 0 | O7: 0 | P7: 0 | Q7: 0 | R7: 0 | S7: 14 | T7: 0 | U7: 0 | V7: 1 | W7: -1 | X7: ipbcu00 | Y7: ipbhp06 | Z7: ipbfp08 | AA7: ipbsp04 | AB7: 0 | AC7: 0 | AD7: 0 | AE7: 0 | AF7: 0 | AG7: 0 | AH7: 0 | AI7: 0 | AJ7: 0 | AK7: 0 | AL7: 0 | AM7: 0 | AN7: 0 | AO7: 0 | AP7: 0 | AQ7: 0 | AR7: 0 | AS7: 0 | AT7: 0 | AU7: 0 | AV7: 0 | AW7: 0 | AX7: 0 | AY7: 0 | AZ7: 0 | BA7: 0 | BB7: 0 | BC7: 0 | BD7: 0 | BE7: 0 | BF7: 0 | BG7: 0 | BH7: 0 | BI7: 0 | BJ7: 0 | BK7: 0 | BL7: 0 | BM7: 0 | BN7: 0 | BO7: 0 | BP7: 0 | BQ7: 0 | BR7: 0 | BS7: 0 | BT7: 0 | BU7: 0 | BV7: 0 | BW7: 0 | BX7: 0 | BY7: 0 | BZ7: 0 | CA7: 0 | CB7: 0 | CC7: 0 | CD7: 0 | CE7: 0 | CF7: 0 | CG7: 0 | CH7: 0 | CI7: 0 | CJ7: 0 | CK7: 0 | CL7: 0 | CM7: 0 | CN7: 0 | CO7: 0 | CP7: 0 | CQ7: 0 | CR7: 0 | CS7: 0 | CT7: 0 | CU7: 0 | CV7: 0 | CW7: 0 | CX7: 0 | CY7: 0 | CZ7: 0 | DA7: 0 | DB7: 0 | DC7: 0 | DD7: 0 | DE7: 0 | DF7: 0 | DG7: 0 | DH7: 0 | DI7: 0 | DJ7: 0 | DK7: 0 | DL7: 0 | DM7: 0 | DN7: 0 | DO7: 0 | DP7: 0 | DQ7: 0 | DR7: 0 | DS7: 0 | DT7: 0 | DU7: 0 | DV7: 0 | DW7: 0 | DX7: 0 | DY7: 0 | DZ7: 0 | EA7: 0 | EB7: 0 | EC7: 0 | ED7: 0 | EE7: 0 | EF7: 0 | EG7: 0 | EH7: 0 | EI7: 0 | EJ7: 0 | EK7: 0 | EL7: 0 | EM7: 0 | EN7: 0 | EO7: 0 | EP7: 0 | EQ7: 0 | ER7: 0 | ES7: 0 | ET7: 0 | EU7: 0 | EV7: 0 | EW7: 0 | EX7: 0 | EY7: 0 | EZ7: 0 | FA7: 0 | FB7: 0 | FC7: 0 | FD7: 0 | FE7: 0 | FF7: 0 | FG7: 0 | FH7: 0 | FI7: 0 | FJ7: 0 | FK7: 0 | FL7: 0 | FM7: 0 | FN7: 0 | FO7: 0 | FP7: 0 | FQ7: 0 | FR7: 0 | FS7: 0 | FT7: 0 | FU7: 0 | FV7: 0 | FW7: 0 | FX7: 0 | FY7: 0 | FZ7: 0 | GA7: 0 | GB7: 0 | GC7: 0 | GD7: 0 | GE7: 0 | GF7: 0 | GG7: 0 | GH7: 0 | GI7: 0 | GJ7: 0 | GK7: 0 | GL7: 0 | GM7: 0 | GN7: 0 | GO7: 0 | GP7: 0 | GQ7: 0 | GR7: 0 | GS7: 0 | GT7: 0 | GU7: 0 | GV7: 0 | GW7: 0 | GX7: 0 | GY7: 0 | GZ7: 0 | HA7: 0 | HB7: 0 | HC7: 0 | HD7: 0 | HE7: 0 | HF7: 0 | HG7: 0 | HH7: 0 | HI7: 0 | HJ7: 0 | HK7: 0 | HL7: 0 | HM7: 0 | HN7: 0 | HO7: 0 | HP7: 0 | HQ7: 0 | HR7: 0 | HS7: 0 | HT7: 0 | HU7: 0 | HV7: 0 | HW7: 0 | HX7: 0 | HY7: 0 | HZ7: 0 | IA7: 0 | IB7: 0 | IC7: 0 | ID7: 0 | IE7: 0 | IF7: 0 | IG7: 0 | IH7: 0 | II7: 0 | IJ7: 0 | IK7: 0 | IL7: 0 | IM7: 0 | IN7: 0 | IO7: 0 | IP7: 0 | IQ7: 0 | IR7: 0 | IS7: 0 | IT7: 0 | IU7: 0
A8: sd03012 | B8: bd03012 | C8: =NPCharacter!A8 -> 03012 | D8: Taha Azlani | E8: NeutralB | F8: 1 | G8: 0 | H8: 0 | I8: 1 | J8: 13 | K8: 0 | L8: 0 | M8: 0 | N8: 0 | O8: 0 | P8: 0 | Q8: 0 | R8: 0 | S8: 8 | T8: 0 | U8: 0 | V8: 1 | W8: -1 | X8: ipbcu00 | Y8: ipbhp06 | Z8: ipbfp08 | AA8: ipbsp04 | AB8: 0 | AC8: 0 | AD8: 0 | AE8: 0 | AF8: 0 | AG8: 0 | AH8: 0 | AI8: 0 | AJ8: 0 | AK8: 0 | AL8: 0 | AM8: 0 | AN8: 0 | AO8: 0 | AP8: 0 | AQ8: 0 | AR8: 0 | AS8: 0 | AT8: 0 | AU8: 0 | AV8: 0 | AW8: 0 | AX8: 0 | AY8: 0 | AZ8: 0 | BA8: 0 | BB8: 0 | BC8: 0 | BD8: 0 | BE8: 0 | BF8: 0 | BG8: 0 | BH8: 0 | BI8: 0 | BJ8: 0 | BK8: 0 | BL8: 0 | BM8: 0 | BN8: 0 | BO8: 0 | BP8: 0 | BQ8: 0 | BR8: 0 | BS8: 0 | BT8: 0 | BU8: 0 | BV8: 0 | BW8: 0 | BX8: 0 | BY8: 0 | BZ8: 0 | CA8: 0 | CB8: 0 | CC8: 0 | CD8: 0 | CE8: 0 | CF8: 0 | CG8: 0 | CH8: 0 | CI8: 0 | CJ8: 0 | CK8: 0 | CL8: 0 | CM8: 0 | CN8: 0 | CO8: 0 | CP8: 0 | CQ8: 0 | CR8: 0 | CS8: 0 | CT8: 0 | CU8: 0 | CV8: 0 | CW8: 0 | CX8: 0 | CY8: 0 | CZ8: 0 | DA8: 0 | DB8: 0 | DC8: 0 | DD8: 0 | DE8: 0 | DF8: 0 | DG8: 0 | DH8: 0 | DI8: 0 | DJ8: 0 | DK8: 0 | DL8: 0 | DM8: 0 | DN8: 0 | DO8: 0 | DP8: 0 | DQ8: 0 | DR8: 0 | DS8: 0 | DT8: 0 | DU8: 0 | DV8: 0 | DW8: 0 | DX8: 0 | DY8: 0 | DZ8: 0 | EA8: 0 | EB8: 0 | EC8: 0 | ED8: 0 | EE8: 0 | EF8: 0 | EG8: 0 | EH8: 0 | EI8: 0 | EJ8: 0 | EK8: 0 | EL8: 0 | EM8: 0 | EN8: 0 | EO8: 0 | EP8: 0 | EQ8: 0 | ER8: 0 | ES8: 0 | ET8: 0 | EU8: 0 | EV8: 0 | EW8: 0 | EX8: 0 | EY8: 0 | EZ8: 0 | FA8: 0 | FB8: 0 | FC8: 0 | FD8: 0 | FE8: 0 | FF8: 0 | FG8: 0 | FH8: 0 | FI8: 0 | FJ8: 0 | FK8: 0 | FL8: 0 | FM8: 0 | FN8: 0 | FO8: 0 | FP8: 0 | FQ8: 0 | FR8: 0 | FS8: 0 | FT8: 0 | FU8: 0 | FV8: 0 | FW8: 0 | FX8: 0 | FY8: 0 | FZ8: 0 | GA8: 0 | GB8: 0 | GC8: 0 | GD8: 0 | GE8: 0 | GF8: 0 | GG8: 0 | GH8: 0 | GI8: 0 | GJ8: 0 | GK8: 0 | GL8: 0 | GM8: 0 | GN8: 0 | GO8: 0 | GP8: 0 | GQ8: 0 | GR8: 0 | GS8: 0 | GT8: 0 | GU8: 0 | GV8: 0 | GW8: 0 | GX8: 0 | GY8: 0 | GZ8: 0 | HA8: 0 | HB8: 0 | HC8: 0 | HD8: 0 | HE8: 0 | HF8: 0 | HG8: 0 | HH8: 0 | HI8: 0 | HJ8: 0 | HK8: 0 | HL8: 0 | HM8: 0 | HN8: 0 | HO8: 0 | HP8: 0 | HQ8: 0 | HR8: 0 | HS8: 0 | HT8: 0 | HU8: 0 | HV8: 0 | HW8: 0 | HX8: 0 | HY8: 0 | HZ8: 0 | IA8: 0 | IB8: 0 | IC8: 0 | ID8: 0 | IE8: 0 | IF8: 0 | IG8: 0 | IH8: 0 | II8: 0 | IJ8: 0 | IK8: 0 | IL8: 0 | IM8: 0 | IN8: 0 | IO8: 0 | IP8: 0 | IQ8: 0 | IR8: 0 | IS8: 0 | IT8: 0 | IU8: 0
A9: sd03020 | B9: bd03020 | C9: =NPCharacter!A9 -> 03020 | D9: Monk | E9: NeutralB | F9: 2 | G9: 0 | H9: 0 | I9: 1 | J9: 13 | K9: 2 | L9: 53 | M9: 0 | N9: 0 | O9: 0 | P9: 0 | Q9: 0 | R9: 0 | S9: 45 | T9: 0 | U9: 0 | V9: 1 | W9: -1 | X9: ihbwa04 | Y9: iubwa04 | Z9: ilbwa04 | AA9: igbwa04 | AB9: isbwa04 | AC9: ihbwa07 | AD9: iubwa07 | AE9: ilbwa07 | AF9: igbwa07 | AG9: isbwa07 | AH9: ihbwa10 | AI9: iubwa10 | AJ9: ilbwa10 | AK9: igbwa10 | AL9: isbwa10 | AM9: ihbwa13 | AN9: iubwa13 | AO9: ilbwa13 | AP9: igbwa13 | AQ9: isbwa13 | AR9: ihbwa16 | AS9: iubwa16 | AT9: ilbwa16 | AU9: igbwa16 | AV9: isbwa16 | AW9: ihbra13 | AX9: iubra13 | AY9: ilbra13 | AZ9: igbra13 | BA9: isbra13 | BB9: ihbra16 | BC9: iubra16 | BD9: ilbra16 | BE9: igbra16 | BF9: isbra16 | BG9: ihbfa13 | BH9: iubfa13 | BI9: ilbfa13 | BJ9: igbfa13 | BK9: isbfa13 | BL9: ihbfa16 | BM9: iubfa16 | BN9: ilbfa16 | BO9: igbfa16 | BP9: isbfa16 | BQ9: 0 | BR9: 0 | BS9: 0 | BT9: 0 | BU9: 0 | BV9: 0 | BW9: 0 | BX9: 0 | BY9: 0 | BZ9: 0 | CA9: 0 | CB9: 0 | CC9: 0 | CD9: 0 | CE9: 0 | CF9: 0 | CG9: 0 | CH9: 0 | CI9: 0 | CJ9: 0 | CK9: 0 | CL9: 0 | CM9: 0 | CN9: 0 | CO9: 0 | CP9: 0 | CQ9: 0 | CR9: 0 | CS9: 0 | CT9: 0 | CU9: 0 | CV9: 0 | CW9: 0 | CX9: 0 | CY9: 0 | CZ9: 0 | DA9: 0 | DB9: 0 | DC9: 0 | DD9: 0 | DE9: 0 | DF9: 0 | DG9: 0 | DH9: 0 | DI9: 0 | DJ9: 0 | DK9: 0 | DL9: 0 | DM9: 0 | DN9: 0 | DO9: 0 | DP9: 0 | DQ9: 0 | DR9: 0 | DS9: 0 | DT9: 0 | DU9: 0 | DV9: 0 | DW9: 0 | DX9: 0 | DY9: 0 | DZ9: 0 | EA9: 0 | EB9: 0 | EC9: 0 | ED9: 0 | EE9: 0 | EF9: 0 | EG9: 0 | EH9: 0 | EI9: 0 | EJ9: 0 | EK9: 0 | EL9: 0 | EM9: 0 | EN9: 0 | EO9: 0 | EP9: 0 | EQ9: 0 | ER9: 0 | ES9: 0 | ET9: 0 | EU9: 0 | EV9: 0 | EW9: 0 | EX9: 0 | EY9: 0 | EZ9: 0 | FA9: 0 | FB9: 0 | FC9: 0 | FD9: 0 | FE9: 0 | FF9: 0 | FG9: 0 | FH9: 0 | FI9: 0 | FJ9: 0 | FK9: 0 | FL9: 0 | FM9: 0 | FN9: 0 | FO9: 0 | FP9: 0 | FQ9: 0 | FR9: 0 | FS9: 0 | FT9: 0 | FU9: 0 | FV9: 0 | FW9: 0 | FX9: 0 | FY9: 0 | FZ9: 0 | GA9: 0 | GB9: 0 | GC9: 0 | GD9: 0 | GE9: 0 | GF9: 0 | GG9: 0 | GH9: 0 | GI9: 0 | GJ9: 0 | GK9: 0 | GL9: 0 | GM9: 0 | GN9: 0 | GO9: 0 | GP9: 0 | GQ9: 0 | GR9: 0 | GS9: 0 | GT9: 0 | GU9: 0 | GV9: 0 | GW9: 0 | GX9: 0 | GY9: 0 | GZ9: 0 | HA9: 0 | HB9: 0 | HC9: 0 | HD9: 0 | HE9: 0 | HF9: 0 | HG9: 0 | HH9: 0 | HI9: 0 | HJ9: 0 | HK9: 0 | HL9: 0 | HM9: 0 | HN9: 0 | HO9: 0 | HP9: 0 | HQ9: 0 | HR9: 0 | HS9: 0 | HT9: 0 | HU9: 0 | HV9: 0 | HW9: 0 | HX9: 0 | HY9: 0 | HZ9: 0 | IA9: 0 | IB9: 0 | IC9: 0 | ID9: 0 | IE9: 0 | IF9: 0 | IG9: 0 | IH9: 0 | II9: 0 | IJ9: 0 | IK9: 0 | IL9: 0 | IM9: 0 | IN9: 0 | IO9: 0 | IP9: 0 | IQ9: 0 | IR9: 0 | IS9: 0 | IT9: 0 | IU9: 0
A10: sd03021 | B10: bd03021 | C10: =NPCharacter!A10 -> 03021 | D10: Jaden | E10: NeutralB | F10: 2 | G10: 0 | H10: 0 | I10: 1 | J10: 13 | K10: 53 | L10: 0 | M10: 0 | N10: 0 | O10: 0 | P10: 0 | Q10: 0 | R10: 0 | S10: 120 | T10: 0 | U10: 0 | V10: 30 | W10: 7FFFFFFF | X10: ihbwa35 | Y10: iubwa35 | Z10: ilbwa35 | AA10: igbwa35 | AB10: isbwa35 | AC10: ihbwa37 | AD10: iubwa37 | AE10: ilbwa37 | AF10: igbwa37 | AG10: isbwa37 | AH10: ihbwa39 | AI10: iubwa39 | AJ10: ilbwa39 | AK10: igbwa39 | AL10: isbwa39 | AM10: ihbwa41 | AN10: iubwa41 | AO10: ilbwa41 | AP10: igbwa41 | AQ10: isbwa41 | AR10: ihbwa43 | AS10: iubwa43 | AT10: ilbwa43 | AU10: igbwa43 | AV10: isbwa43 | AW10: ihbwa45 | AX10: iubwa45 | AY10: ilbwa45 | AZ10: igbwa45 | BA10: isbwa45 | BB10: ihbwa47 | BC10: iubwa47 | BD10: ilbwa47 | BE10: igbwa47 | BF10: isbwa47 | BG10: ihbra35 | BH10: iubra35 | BI10: ilbra35 | BJ10: igbra35 | BK10: isbra35 | BL10: ihbra37 | BM10: iubra37 | BN10: ilbra37 | BO10: igbra37 | BP10: isbra37 | BQ10: ihbra39 | BR10: iubra39 | BS10: ilbra39 | BT10: igbra39 | BU10: isbra39 | BV10: ihbra41 | BW10: iubra41 | BX10: ilbra41 | BY10: igbra41 | BZ10: isbra41 | CA10: ihbra43 | CB10: iubra43 | CC10: ilbra43 | CD10: igbra43 | CE10: isbra43 | CF10: ihbra45 | CG10: iubra45 | CH10: ilbra45 | CI10: igbra45 | CJ10: isbra45 | CK10: ihbra47 | CL10: iubra47 | CM10: ilbra47 | CN10: igbra47 | CO10: isbra47 | CP10: ihbfa35 | CQ10: iubfa35 | CR10: ilbfa35 | CS10: igbfa35 | CT10: isbfa35 | CU10: ihbfa37 | CV10: iubfa37 | CW10: ilbfa37 | CX10: igbfa37 | CY10: isbfa37 | CZ10: ihbfa39 | DA10: iubfa39 | DB10: ilbfa39 | DC10: igbfa39 | DD10: isbfa39 | DE10: ihbfa41 | DF10: iubfa41 | DG10: ilbfa41 | DH10: igbfa41 | DI10: isbfa41 | DJ10: ihbfa43 | DK10: iubfa43 | DL10: ilbfa43 | DM10: igbfa43 | DN10: isbfa43 | DO10: ihbfa45 | DP10: iubfa45 | DQ10: ilbfa45 | DR10: igbfa45 | DS10: isbfa45 | DT10: ihbfa47 | DU10: iubfa47 | DV10: ilbfa47 | DW10: igbfa47 | DX10: isbfa47 | DY10: 0 | DZ10: 0 | EA10: 0 | EB10: 0 | EC10: 0 | ED10: 0 | EE10: 0 | EF10: 0 | EG10: 0 | EH10: 0 | EI10: 0 | EJ10: 0 | EK10: 0 | EL10: 0 | EM10: 0 | EN10: 0 | EO10: 0 | EP10: 0 | EQ10: 0 | ER10: 0 | ES10: 0 | ET10: 0 | EU10: 0 | EV10: 0 | EW10: 0 | EX10: 0 | EY10: 0 | EZ10: 0 | FA10: 0 | FB10: 0 | FC10: 0 | FD10: 0 | FE10: 0 | FF10: 0 | FG10: 0 | FH10: 0 | FI10: 0 | FJ10: 0 | FK10: 0 | FL10: 0 | FM10: 0 | FN10: 0 | FO10: 0 | FP10: 0 | FQ10: 0 | FR10: 0 | FS10: 0 | FT10: 0 | FU10: 0 | FV10: 0 | FW10: 0 | FX10: 0 | FY10: 0 | FZ10: 0 | GA10: 0 | GB10: 0 | GC10: 0 | GD10: 0 | GE10: 0 | GF10: 0 | GG10: 0 | GH10: 0 | GI10: 0 | GJ10: 0 | GK10: 0 | GL10: 0 | GM10: 0 | GN10: 0 | GO10: 0 | GP10: 0 | GQ10: 0 | GR10: 0 | GS10: 0 | GT10: 0 | GU10: 0 | GV10: 0 | GW10: 0 | GX10: 0 | GY10: 0 | GZ10: 0 | HA10: 0 | HB10: 0 | HC10: 0 | HD10: 0 | HE10: 0 | HF10: 0 | HG10: 0 | HH10: 0 | HI10: 0 | HJ10: 0 | HK10: 0 | HL10: 0 | HM10: 0 | HN10: 0 | HO10: 0 | HP10: 0 | HQ10: 0 | HR10: 0 | HS10: 0 | HT10: 0 | HU10: 0 | HV10: 0 | HW10: 0 | HX10: 0 | HY10: 0 | HZ10: 0 | IA10: 0 | IB10: 0 | IC10: 0 | ID10: 0 | IE10: 0 | IF10: 0 | IG10: 0 | IH10: 0 | II10: 0 | IJ10: 0 | IK10: 0 | IL10: 0 | IM10: 0 | IN10: 0 | IO10: 0 | IP10: 0 | IQ10: 0 | IR10: 0 | IS10: 0 | IT10: 0 | IU10: 0
A11: sd03022 | B11: bd03022 | C11: =NPCharacter!A11 -> 03022 | D11: Jules | E11: NeutralB | F11: 2 | G11: 0 | H11: 0 | I11: 1 | J11: 13 | K11: 53 | L11: 0 | M11: 0 | N11: 0 | O11: 0 | P11: 0 | Q11: 0 | R11: 0 | S11: 150 | T11: 0 | U11: 0 | V11: 1 | W11: -1 | X11: ihbwa13 | Y11: iubwa13 | Z11: ilbwa13 | AA11: igbwa13 | AB11: isbwa13 | AC11: ihbwa16 | AD11: iubwa16 | AE11: ilbwa16 | AF11: igbwa16 | AG11: isbwa16 | AH11: ihbwa19 | AI11: iubwa19 | AJ11: ilbwa19 | AK11: igbwa19 | AL11: isbwa19 | AM11: ihbwa21 | AN11: iubwa21 | AO11: ilbwa21 | AP11: igbwa21 | AQ11: isbwa21 | AR11: ihbwa23 | AS11: iubwa23 | AT11: ilbwa23 | AU11: igbwa23 | AV11: isbwa23 | AW11: ihbwa25 | AX11: iubwa25 | AY11: ilbwa25 | AZ11: igbwa25 | BA11: isbwa25 | BB11: ihbwa27 | BC11: iubwa27 | BD11: ilbwa27 | BE11: igbwa27 | BF11: isbwa27 | BG11: ihbwa29 | BH11: iubwa29 | BI11: ilbwa29 | BJ11: igbwa29 | BK11: isbwa29 | BL11: ihbwa31 | BM11: iubwa31 | BN11: ilbwa31 | BO11: igbwa31 | BP11: isbwa31 | BQ11: ihbwa33 | BR11: iubwa33 | BS11: ilbwa33 | BT11: igbwa33 | BU11: isbwa33 | BV11: ihbra13 | BW11: iubra13 | BX11: ilbra13 | BY11: igbra13 | BZ11: isbra13 | CA11: ihbra16 | CB11: iubra16 | CC11: ilbra16 | CD11: igbra16 | CE11: isbra16 | CF11: ihbra19 | CG11: iubra19 | CH11: ilbra19 | CI11: igbra19 | CJ11: isbra19 | CK11: ihbra21 | CL11: iubra21 | CM11: ilbra21 | CN11: igbra21 | CO11: isbra21 | CP11: ihbra23 | CQ11: iubra23 | CR11: ilbra23 | CS11: igbra23 | CT11: isbra23 | CU11: ihbra25 | CV11: iubra25 | CW11: ilbra25 | CX11: igbra25 | CY11: isbra25 | CZ11: ihbra27 | DA11: iubra27 | DB11: ilbra27 | DC11: igbra27 | DD11: isbra27 | DE11: ihbra29 | DF11: iubra29 | DG11: ilbra29 | DH11: igbra29 | DI11: isbra29 | DJ11: ihbra31 | DK11: iubra31 | DL11: ilbra31 | DM11: igbra31 | DN11: isbra31 | DO11: ihbra33 | DP11: iubra33 | DQ11: ilbra33 | DR11: igbra33 | DS11: isbra33 | DT11: ihbfa13 | DU11: iubfa13 | DV11: ilbfa13 | DW11: igbfa13 | DX11: isbfa13 | DY11: ihbfa16 | DZ11: iubfa16 | EA11: ilbfa16 | EB11: igbfa16 | EC11: isbfa16 | ED11: ihbfa19 | EE11: iubfa19 | EF11: ilbfa19 | EG11: igbfa19 | EH11: isbfa19 | EI11: ihbfa21 | EJ11: iubfa21 | EK11: ilbfa21 | EL11: igbfa21 | EM11: isbfa21 | EN11: ihbfa23 | EO11: iubfa23 | EP11: ilbfa23 | EQ11: igbfa23 | ER11: isbfa23 | ES11: ihbfa25 | ET11: iubfa25 | EU11: ilbfa25 | EV11: igbfa25 | EW11: isbfa25 | EX11: ihbfa27 | EY11: iubfa27 | EZ11: ilbfa27 | FA11: igbfa27 | FB11: isbfa27 | FC11: ihbfa29 | FD11: iubfa29 | FE11: ilbfa29 | FF11: igbfa29 | FG11: isbfa29 | FH11: ihbfa31 | FI11: iubfa31 | FJ11: ilbfa31 | FK11: igbfa31 | FL11: isbfa31 | FM11: ihbfa33 | FN11: iubfa33 | FO11: ilbfa33 | FP11: igbfa33 | FQ11: isbfa33 | FR11: 0 | FS11: 0 | FT11: 0 | FU11: 0 | FV11: 0 | FW11: 0 | FX11: 0 | FY11: 0 | FZ11: 0 | GA11: 0 | GB11: 0 | GC11: 0 | GD11: 0 | GE11: 0 | GF11: 0 | GG11: 0 | GH11: 0 | GI11: 0 | GJ11: 0 | GK11: 0 | GL11: 0 | GM11: 0 | GN11: 0 | GO11: 0 | GP11: 0 | GQ11: 0 | GR11: 0 | GS11: 0 | GT11: 0 | GU11: 0 | GV11: 0 | GW11: 0 | GX11: 0 | GY11: 0 | GZ11: 0 | HA11: 0 | HB11: 0 | HC11: 0 | HD11: 0 | HE11: 0 | HF11: 0 | HG11: 0 | HH11: 0 | HI11: 0 | HJ11: 0 | HK11: 0 | HL11: 0 | HM11: 0 | HN11: 0 | HO11: 0 | HP11: 0 | HQ11: 0 | HR11: 0 | HS11: 0 | HT11: 0 | HU11: 0 | HV11: 0 | HW11: 0 | HX11: 0 | HY11: 0 | HZ11: 0 | IA11: 0 | IB11: 0 | IC11: 0 | ID11: 0 | IE11: 0 | IF11: 0 | IG11: 0 | IH11: 0 | II11: 0 | IJ11: 0 | IK11: 0 | IL11: 0 | IM11: 0 | IN11: 0 | IO11: 0 | IP11: 0 | IQ11: 0 | IR11: 0 | IS11: 0 | IT11: 0 | IU11: 0
A12: sd03040 | B12: bd03040 | C12: =NPCharacter!A12 -> 2221E | D12: Ashton Shar | E12: NeutralB | F12: 4 | G12: 1 | H12: 30 | I12: 1 | J12: 10 | K12: 11 | L12: 13 | M12: 2 | N12: 53 | O12: 0 | P12: 0 | Q12: 0 | R12: 0 | S12: 2 | T12: 0 | U12: 0 | V12: 1 | W12: -1 | X12: inbbb01 | Y12: inbbb02 | Z12: 0 | AA12: 0 | AB12: 0 | AC12: 0 | AD12: 0 | AE12: 0 | AF12: 0 | AG12: 0 | AH12: 0 | AI12: 0 | AJ12: 0 | AK12: 0 | AL12: 0 | AM12: 0 | AN12: 0 | AO12: 0 | AP12: 0 | AQ12: 0 | AR12: 0 | AS12: 0 | AT12: 0 | AU12: 0 | AV12: 0 | AW12: 0 | AX12: 0 | AY12: 0 | AZ12: 0 | BA12: 0 | BB12: 0 | BC12: 0 | BD12: 0 | BE12: 0 | BF12: 0 | BG12: 0 | BH12: 0 | BI12: 0 | BJ12: 0 | BK12: 0 | BL12: 0 | BM12: 0 | BN12: 0 | BO12: 0 | BP12: 0 | BQ12: 0 | BR12: 0 | BS12: 0 | BT12: 0 | BU12: 0 | BV12: 0 | BW12: 0 | BX12: 0 | BY12: 0 | BZ12: 0 | CA12: 0 | CB12: 0 | CC12: 0 | CD12: 0 | CE12: 0 | CF12: 0 | CG12: 0 | CH12: 0 | CI12: 0 | CJ12: 0 | CK12: 0 | CL12: 0 | CM12: 0 | CN12: 0 | CO12: 0 | CP12: 0 | CQ12: 0 | CR12: 0 | CS12: 0 | CT12: 0 | CU12: 0 | CV12: 0 | CW12: 0 | CX12: 0 | CY12: 0 | CZ12: 0 | DA12: 0 | DB12: 0 | DC12: 0 | DD12: 0 | DE12: 0 | DF12: 0 | DG12: 0 | DH12: 0 | DI12: 0 | DJ12: 0 | DK12: 0 | DL12: 0 | DM12: 0 | DN12: 0 | DO12: 0 | DP12: 0 | DQ12: 0 | DR12: 0 | DS12: 0 | DT12: 0 | DU12: 0 | DV12: 0 | DW12: 0 | DX12: 0 | DY12: 0 | DZ12: 0 | EA12: 0 | EB12: 0 | EC12: 0 | ED12: 0 | EE12: 0 | EF12: 0 | EG12: 0 | EH12: 0 | EI12: 0 | EJ12: 0 | EK12: 0 | EL12: 0 | EM12: 0 | EN12: 0 | EO12: 0 | EP12: 0 | EQ12: 0 | ER12: 0 | ES12: 0 | ET12: 0 | EU12: 0 | EV12: 0 | EW12: 0 | EX12: 0 | EY12: 0 | EZ12: 0 | FA12: 0 | FB12: 0 | FC12: 0 | FD12: 0 | FE12: 0 | FF12: 0 | FG12: 0 | FH12: 0 | FI12: 0 | FJ12: 0 | FK12: 0 | FL12: 0 | FM12: 0 | FN12: 0 | FO12: 0 | FP12: 0 | FQ12: 0 | FR12: 0 | FS12: 0 | FT12: 0 | FU12: 0 | FV12: 0 | FW12: 0 | FX12: 0 | FY12: 0 | FZ12: 0 | GA12: 0 | GB12: 0 | GC12: 0 | GD12: 0 | GE12: 0 | GF12: 0 | GG12: 0 | GH12: 0 | GI12: 0 | GJ12: 0 | GK12: 0 | GL12: 0 | GM12: 0 | GN12: 0 | GO12: 0 | GP12: 0 | GQ12: 0 | GR12: 0 | GS12: 0 | GT12: 0 | GU12: 0 | GV12: 0 | GW12: 0 | GX12: 0 | GY12: 0 | GZ12: 0 | HA12: 0 | HB12: 0 | HC12: 0 | HD12: 0 | HE12: 0 | HF12: 0 | HG12: 0 | HH12: 0 | HI12: 0 | HJ12: 0 | HK12: 0 | HL12: 0 | HM12: 0 | HN12: 0 | HO12: 0 | HP12: 0 | HQ12: 0 | HR12: 0 | HS12: 0 | HT12: 0 | HU12: 0 | HV12: 0 | HW12: 0 | HX12: 0 | HY12: 0 | HZ12: 0 | IA12: 0 | IB12: 0 | IC12: 0 | ID12: 0 | IE12: 0 | IF12: 0 | IG12: 0 | IH12: 0 | II12: 0 | IJ12: 0 | IK12: 0 | IL12: 0 | IM12: 0 | IN12: 0 | IO12: 0 | IP12: 0 | IQ12: 0 | IR12: 0 | IS12: 0 | IT12: 0 | IU12: 0
A13: sd03050 | B13: bd03050 | C13: =NPCharacter!A13 -> 03050 | D13: Durba | E13: NeutralB | F13: 5 | G13: 0 | H13: 0 | I13: 1 | J13: 5 | K13: 36 | L13: 38 | M13: 39 | N13: 40 | O13: 13 | P13: 2 | Q13: 53 | R13: 0 | S13: 4 | T13: 0 | U13: 0 | V13: 1000 | W13: -1 | X13: iwmtb01 | Y13: itttt01 | Z13: itttt02 | AA13: itttt03 | AB13: 0 | AC13: 0 | AD13: 0 | AE13: 0 | AF13: 0 | AG13: 0 | AH13: 0 | AI13: 0 | AJ13: 0 | AK13: 0 | AL13: 0 | AM13: 0 | AN13: 0 | AO13: 0 | AP13: 0 | AQ13: 0 | AR13: 0 | AS13: 0 | AT13: 0 | AU13: 0 | AV13: 0 | AW13: 0 | AX13: 0 | AY13: 0 | AZ13: 0 | BA13: 0 | BB13: 0 | BC13: 0 | BD13: 0 | BE13: 0 | BF13: 0 | BG13: 0 | BH13: 0 | BI13: 0 | BJ13: 0 | BK13: 0 | BL13: 0 | BM13: 0 | BN13: 0 | BO13: 0 | BP13: 0 | BQ13: 0 | BR13: 0 | BS13: 0 | BT13: 0 | BU13: 0 | BV13: 0 | BW13: 0 | BX13: 0 | BY13: 0 | BZ13: 0 | CA13: 0 | CB13: 0 | CC13: 0 | CD13: 0 | CE13: 0 | CF13: 0 | CG13: 0 | CH13: 0 | CI13: 0 | CJ13: 0 | CK13: 0 | CL13: 0 | CM13: 0 | CN13: 0 | CO13: 0 | CP13: 0 | CQ13: 0 | CR13: 0 | CS13: 0 | CT13: 0 | CU13: 0 | CV13: 0 | CW13: 0 | CX13: 0 | CY13: 0 | CZ13: 0 | DA13: 0 | DB13: 0 | DC13: 0 | DD13: 0 | DE13: 0 | DF13: 0 | DG13: 0 | DH13: 0 | DI13: 0 | DJ13: 0 | DK13: 0 | DL13: 0 | DM13: 0 | DN13: 0 | DO13: 0 | DP13: 0 | DQ13: 0 | DR13: 0 | DS13: 0 | DT13: 0 | DU13: 0 | DV13: 0 | DW13: 0 | DX13: 0 | DY13: 0 | DZ13: 0 | EA13: 0 | EB13: 0 | EC13: 0 | ED13: 0 | EE13: 0 | EF13: 0 | EG13: 0 | EH13: 0 | EI13: 0 | EJ13: 0 | EK13: 0 | EL13: 0 | EM13: 0 | EN13: 0 | EO13: 0 | EP13: 0 | EQ13: 0 | ER13: 0 | ES13: 0 | ET13: 0 | EU13: 0 | EV13: 0 | EW13: 0 | EX13: 0 | EY13: 0 | EZ13: 0 | FA13: 0 | FB13: 0 | FC13: 0 | FD13: 0 | FE13: 0 | FF13: 0 | FG13: 0 | FH13: 0 | FI13: 0 | FJ13: 0 | FK13: 0 | FL13: 0 | FM13: 0 | FN13: 0 | FO13: 0 | FP13: 0 | FQ13: 0 | FR13: 0 | FS13: 0 | FT13: 0 | FU13: 0 | FV13: 0 | FW13: 0 | FX13: 0 | FY13: 0 | FZ13: 0 | GA13: 0 | GB13: 0 | GC13: 0 | GD13: 0 | GE13: 0 | GF13: 0 | GG13: 0 | GH13: 0 | GI13: 0 | GJ13: 0 | GK13: 0 | GL13: 0 | GM13: 0 | GN13: 0 | GO13: 0 | GP13: 0 | GQ13: 0 | GR13: 0 | GS13: 0 | GT13: 0 | GU13: 0 | GV13: 0 | GW13: 0 | GX13: 0 | GY13: 0 | GZ13: 0 | HA13: 0 | HB13: 0 | HC13: 0 | HD13: 0 | HE13: 0 | HF13: 0 | HG13: 0 | HH13: 0 | HI13: 0 | HJ13: 0 | HK13: 0 | HL13: 0 | HM13: 0 | HN13: 0 | HO13: 0 | HP13: 0 | HQ13: 0 | HR13: 0 | HS13: 0 | HT13: 0 | HU13: 0 | HV13: 0 | HW13: 0 | HX13: 0 | HY13: 0 | HZ13: 0 | IA13: 0 | IB13: 0 | IC13: 0 | ID13: 0 | IE13: 0 | IF13: 0 | IG13: 0 | IH13: 0 | II13: 0 | IJ13: 0 | IK13: 0 | IL13: 0 | IM13: 0 | IN13: 0 | IO13: 0 | IP13: 0 | IQ13: 0 | IR13: 0 | IS13: 0 | IT13: 0 | IU13: 0
A14: sd03060 | B14: bd03060 | C14: =NPCharacter!A14 -> 03060 | D14: Jun | E14: NeutralB | F14: 6 | G14: 0 | H14: 0 | I14: 1 | J14: 13 | K14: 2 | L14: 53 | M14: 0 | N14: 0 | O14: 0 | P14: 0 | Q14: 0 | R14: 0 | S14: 24 | T14: 0 | U14: 0 | V14: 1 | W14: -1 | X14: fibbb01 | Y14: fibbb02 | Z14: fibbb03 | AA14: fibbb04 | AB14: immmm01 | AC14: immmm03 | AD14: immmm02 | AE14: iebbb00 | AF14: izbbb01 | AG14: izree01 | AH14: iqbbb01 | AI14: iqbbb02 | AJ14: gtbb001 | AK14: tr00001 | AL14: iyyyy25 | AM14: iyyyy26 | AN14: iycra01 | AO14: iyext01 | AP14: iymer01 | AQ14: iymer02 | AR14: skbal01 | AS14: lknpc00 | AT14: lknpc12 | AU14: ipgag01 | AV14: 0 | AW14: 0 | AX14: 0 | AY14: 0 | AZ14: 0 | BA14: 0 | BB14: 0 | BC14: 0 | BD14: 0 | BE14: 0 | BF14: 0 | BG14: 0 | BH14: 0 | BI14: 0 | BJ14: 0 | BK14: 0 | BL14: 0 | BM14: 0 | BN14: 0 | BO14: 0 | BP14: 0 | BQ14: 0 | BR14: 0 | BS14: 0 | BT14: 0 | BU14: 0 | BV14: 0 | BW14: 0 | BX14: 0 | BY14: 0 | BZ14: 0 | CA14: 0 | CB14: 0 | CC14: 0 | CD14: 0 | CE14: 0 | CF14: 0 | CG14: 0 | CH14: 0 | CI14: 0 | CJ14: 0 | CK14: 0 | CL14: 0 | CM14: 0 | CN14: 0 | CO14: 0 | CP14: 0 | CQ14: 0 | CR14: 0 | CS14: 0 | CT14: 0 | CU14: 0 | CV14: 0 | CW14: 0 | CX14: 0 | CY14: 0 | CZ14: 0 | DA14: 0 | DB14: 0 | DC14: 0 | DD14: 0 | DE14: 0 | DF14: 0 | DG14: 0 | DH14: 0 | DI14: 0 | DJ14: 0 | DK14: 0 | DL14: 0 | DM14: 0 | DN14: 0 | DO14: 0 | DP14: 0 | DQ14: 0 | DR14: 0 | DS14: 0 | DT14: 0 | DU14: 0 | DV14: 0 | DW14: 0 | DX14: 0 | DY14: 0 | DZ14: 0 | EA14: 0 | EB14: 0 | EC14: 0 | ED14: 0 | EE14: 0 | EF14: 0 | EG14: 0 | EH14: 0 | EI14: 0 | EJ14: 0 | EK14: 0 | EL14: 0 | EM14: 0 | EN14: 0 | EO14: 0 | EP14: 0 | EQ14: 0 | ER14: 0 | ES14: 0 | ET14: 0 | EU14: 0 | EV14: 0 | EW14: 0 | EX14: 0 | EY14: 0 | EZ14: 0 | FA14: 0 | FB14: 0 | FC14: 0 | FD14: 0 | FE14: 0 | FF14: 0 | FG14: 0 | FH14: 0 | FI14: 0 | FJ14: 0 | FK14: 0 | FL14: 0 | FM14: 0 | FN14: 0 | FO14: 0 | FP14: 0 | FQ14: 0 | FR14: 0 | FS14: 0 | FT14: 0 | FU14: 0 | FV14: 0 | FW14: 0 | FX14: 0 | FY14: 0 | FZ14: 0 | GA14: 0 | GB14: 0 | GC14: 0 | GD14: 0 | GE14: 0 | GF14: 0 | GG14: 0 | GH14: 0 | GI14: 0 | GJ14: 0 | GK14: 0 | GL14: 0 | GM14: 0 | GN14: 0 | GO14: 0 | GP14: 0 | GQ14: 0 | GR14: 0 | GS14: 0 | GT14: 0 | GU14: 0 | GV14: 0 | GW14: 0 | GX14: 0 | GY14: 0 | GZ14: 0 | HA14: 0 | HB14: 0 | HC14: 0 | HD14: 0 | HE14: 0 | HF14: 0 | HG14: 0 | HH14: 0 | HI14: 0 | HJ14: 0 | HK14: 0 | HL14: 0 | HM14: 0 | HN14: 0 | HO14: 0 | HP14: 0 | HQ14: 0 | HR14: 0 | HS14: 0 | HT14: 0 | HU14: 0 | HV14: 0 | HW14: 0 | HX14: 0 | HY14: 0 | HZ14: 0 | IA14: 0 | IB14: 0 | IC14: 0 | ID14: 0 | IE14: 0 | IF14: 0 | IG14: 0 | IH14: 0 | II14: 0 | IJ14: 0 | IK14: 0 | IL14: 0 | IM14: 0 | IN14: 0 | IO14: 0 | IP14: 0 | IQ14: 0 | IR14: 0 | IS14: 0 | IT14: 0 | IU14: 0
... A113: sd05172 | B113: bd05172 | C113: =NPCharacter!A113 -> 05172 | D113: AR33-32-1173 | E113: NeutralA | F113: 23 | G113: 0 | H113: 0 | I113: 1 | J113: 13 | K113: 0 | L113: 0 | M113: 0 | N113: 0 | O113: 0 | P113: 0 | Q113: 0 | R113: 0 | S113: 192 | T113: 0 | U113: 0 | V113: 60 | W113: 7FFFFFFF | X113: iwkha35 | Y113: iwkhb35 | Z113: iwkhc35 | AA113: iwkhd35 | AB113: iwkhe35 | AC113: iwkhf35 | AD113: iwkhg35 | AE113: iwkhh35 | AF113: iwkhi35 | AG113: iwkhj35 | AH113: iwkhk35 | AI113: iwkhl35 | AJ113: iwsha35 | AK113: iwshb35 | AL113: iwshc35 | AM113: iwshd35 | AN113: iwshe35 | AO113: iwshf35 | AP113: iwshg35 | AQ113: iwshh35 | AR113: iwshi35 | AS113: iwshj35 | AT113: iwshk35 | AU113: iwshl35 | AV113: iwxha35 | AW113: iwxhb35 | AX113: iwxhc35 | AY113: iwxhd35 | AZ113: iwxhe35 | BA113: iwxhf35 | BB113: iwxhg35 | BC113: iwxhh35 | BD113: iwxhi35 | BE113: iwxhj35 | BF113: iwxhk35 | BG113: iwxhl35 | BH113: iwmha35 | BI113: iwmhb35 | BJ113: iwmhc35 | BK113: iwmhd35 | BL113: iwmhe35 | BM113: iwmhf35 | BN113: iwmhg35 | BO113: iwmhh35 | BP113: iwmhi35 | BQ113: iwmhj35 | BR113: iwmhk35 | BS113: iwmhl35 | BT113: iwpha35 | BU113: iwphb35 | BV113: iwphc35 | BW113: iwphd35 | BX113: iwphe35 | BY113: iwphf35 | BZ113: iwphg35 | CA113: iwphh35 | CB113: iwphi35 | CC113: iwphj35 | CD113: iwphk35 | CE113: iwphl35 | CF113: iwfha35 | CG113: iwfhb35 | CH113: iwfhc35 | CI113: iwfhd35 | CJ113: iwfhe35 | CK113: iwfhf35 | CL113: iwfhg35 | CM113: iwfhh35 | CN113: iwfhi35 | CO113: iwfhj35 | CP113: iwfhk35 | CQ113: iwfhl35 | CR113: iwbha35 | CS113: iwbhb35 | CT113: iwbhc35 | CU113: iwbhd35 | CV113: iwbhe35 | CW113: iwbhf35 | CX113: iwbhg35 | CY113: iwbhh35 | CZ113: iwbhi35 | DA113: iwbhj35 | DB113: iwbhk35 | DC113: iwbhl35 | DD113: iwuha35 | DE113: iwuhb35 | DF113: iwuhc35 | DG113: iwuhd35 | DH113: iwuhe35 | DI113: iwuhf35 | DJ113: iwuhg35 | DK113: iwuhh35 | DL113: iwuhi35 | DM113: iwuhj35 | DN113: iwuhk35 | DO113: iwuhl35 | DP113: iwkha40 | DQ113: iwkhb40 | DR113: iwkhc40 | DS113: iwkhd40 | DT113: iwkhe40 | DU113: iwkhf40 | DV113: iwkhg40 | DW113: iwkhh40 | DX113: iwkhi40 | DY113: iwkhj40 | DZ113: iwkhk40 | EA113: iwkhl40 | EB113: iwsha40 | EC113: iwshb40 | ED113: iwshc40 | EE113: iwshd40 | EF113: iwshe40 | EG113: iwshf40 | EH113: iwshg40 | EI113: iwshh40 | EJ113: iwshi40 | EK113: iwshj40 | EL113: iwshk40 | EM113: iwshl40 | EN113: iwxha40 | EO113: iwxhb40 | EP113: iwxhc40 | EQ113: iwxhd40 | ER113: iwxhe40 | ES113: iwxhf40 | ET113: iwxhg40 | EU113: iwxhh40 | EV113: iwxhi40 | EW113: iwxhj40 | EX113: iwxhk40 | EY113: iwxhl40 | EZ113: iwmha40 | FA113: iwmhb40 | FB113: iwmhc40 | FC113: iwmhd40 | FD113: iwmhe40 | FE113: iwmhf40 | FF113: iwmhg40 | FG113: iwmhh40 | FH113: iwmhi40 | FI113: iwmhj40 | FJ113: iwmhk40 | FK113: iwmhl40 | FL113: iwpha40 | FM113: iwphb40 | FN113: iwphc40 | FO113: iwphd40 | FP113: iwphe40 | FQ113: iwphf40 | FR113: iwphg40 | FS113: iwphh40 | FT113: iwphi40 | FU113: iwphj40 | FV113: iwphk40 | FW113: iwphl40 | FX113: iwfha40 | FY113: iwfhb40 | FZ113: iwfhc40 | GA113: iwfhd40 | GB113: iwfhe40 | GC113: iwfhf40 | GD113: iwfhg40 | GE113: iwfhh40 | GF113: iwfhi40 | GG113: iwfhj40 | GH113: iwfhk40 | GI113: iwfhl40 | GJ113: iwbha40 | GK113: iwbhb40 | GL113: iwbhc40 | GM113: iwbhd40 | GN113: iwbhe40 | GO113: iwbhf40 | GP113: iwbhg40 | GQ113: iwbhh40 | GR113: iwbhi40 | GS113: iwbhj40 | GT113: iwbhk40 | GU113: iwbhl40 | GV113: iwlha40 | GW113: iwlhb40 | GX113: iwlhc40 | GY113: iwlhd40 | GZ113: iwlhe40 | HA113: iwlhf40 | HB113: iwlhg40 | HC113: iwlhh40 | HD113: iwlhi40 | HE113: iwlhj40 | HF113: iwlhk40 | HG113: iwlhl40 | HH113: 0 | HI113: 0 | HJ113: 0 | HK113: 0 | HL113: 0 | HM113: 0 | HN113: 0 | HO113: 0 | HP113: 0 | HQ113: 0 | HR113: 0 | HS113: 0 | HT113: 0 | HU113: 0 | HV113: 0 | HW113: 0 | HX113: 0 | HY113: 0 | HZ113: 0 | IA113: 0 | IB113: 0 | IC113: 0 | ID113: 0 | IE113: 0 | IF113: 0 | IG113: 0 | IH113: 0 | II113: 0 | IJ113: 0 | IK113: 0 | IL113: 0 | IM113: 0 | IN113: 0 | IO113: 0 | IP113: 0 | IQ113: 0 | IR113: 0 | IS113: 0 | IT113: 0 | IU113: 0
