Workbook

Sheet ItemCombine
A1: string[64] | B1: dword | C1: dword | D1: string[64] | E1: dword | F1: dword | G1: string[8] | H1: dword | I1: string[8] | J1: dword | K1: string[8] | L1: dword | M1: string[8] | N1: dword | O1: string[8] | P1: dword | Q1: END
A2: Code | B2: CombineIdx | C2: dwFee | D2: Civil | E2: TradeValue | F2: dwTradeMoney | G2: Mat1 | H2: Dur1 | I2: Mat2 | J2: Dur2 | K2: Mat3 | L2: Dur3 | M2: Mat4 | N2: Dur4 | O2: Mat5 | P2: Dur5
A3: bxlow01 | B3: 0 | C3: 543 | D3: 11111000 | E3: -1 | F3: -1 | G3: iytwe01 | H3: 7 | I3: iytwe02 | J3: 7 | K3: -1 | L3: -1 | M3: -1 | N3: -1 | O3: -1 | P3: -1
A4: bxchr01 | B4: 1 | C4: 50000 | D4: 11111000 | E4: -1 | F4: -1 | G4: iyxma01 | H4: 5 | I4: -1 | J4: -1 | K4: -1 | L4: -1 | M4: -1 | N4: -1 | O4: -1 | P4: -1
A5: bxchr02 | B5: 2 | C5: 200000 | D5: 11111000 | E5: -1 | F5: -1 | G5: bxchr01 | H5: 5 | I5: -1 | J5: -1 | K5: -1 | L5: -1 | M5: -1 | N5: -1 | O5: -1 | P5: -1
A6: bxchr03 | B6: 3 | C6: 400000 | D6: 11111000 | E6: -1 | F6: -1 | G6: bxchr02 | H6: 5 | I6: -1 | J6: -1 | K6: -1 | L6: -1 | M6: -1 | N6: -1 | O6: -1 | P6: -1
A7: iygem02 | B7: 4 | C7: 10000 | D7: 11111000 | E7: -1 | F7: -1 | G7: iygem01 | H7: 5 | I7: -1 | J7: -1 | K7: -1 | L7: -1 | M7: -1 | N7: -1 | O7: -1 | P7: -1
A8: iygem03 | B8: 5 | C8: 20000 | D8: 11111000 | E8: -1 | F8: -1 | G8: iygem02 | H8: 5 | I8: -1 | J8: -1 | K8: -1 | L8: -1 | M8: -1 | N8: -1 | O8: -1 | P8: -1
A9: iygem04 | B9: 6 | C9: 150000 | D9: 11111000 | E9: -1 | F9: -1 | G9: iygem03 | H9: 5 | I9: -1 | J9: -1 | K9: -1 | L9: -1 | M9: -1 | N9: -1 | O9: -1 | P9: -1
A10: bxgem01 | B10: 7 | C10: 10000 | D10: 11111000 | E10: -1 | F10: -1 | G10: iygem02 | H10: 1 | I10: -1 | J10: -1 | K10: -1 | L10: -1 | M10: -1 | N10: -1 | O10: -1 | P10: -1
A11: bxgem02 | B11: 8 | C11: 10000 | D11: 11111000 | E11: -1 | F11: -1 | G11: iygem03 | H11: 1 | I11: -1 | J11: -1 | K11: -1 | L11: -1 | M11: -1 | N11: -1 | O11: -1 | P11: -1
A12: bxgem03 | B12: 9 | C12: 10000 | D12: 11111000 | E12: -1 | F12: -1 | G12: iygem04 | H12: 1 | I12: -1 | J12: -1 | K12: -1 | L12: -1 | M12: -1 | N12: -1 | O12: -1 | P12: -1
A13: bxgem04 | B13: 10 | C13: 10000 | D13: 11111000 | E13: -1 | F13: -1 | G13: iybox03 | H13: 50 | I13: -1 | J13: -1 | K13: -1 | L13: -1 | M13: -1 | N13: -1 | O13: -1 | P13: -1
A14: ipexp03 | B14: 11 | C14: 10000 | D14: 11111000 | E14: -1 | F14: -1 | G14: irwav01 | H14: 1 | I14: -1 | J14: -1 | K14: -1 | L14: -1 | M14: -1 | N14: -1 | O14: -1 | P14: -1
... A105: bxafc65 | B105: 102 | C105: 150000000 | D105: 00001000 | E105: -1 | F105: -1 | G105: ircry03 | H105: 50 | I105: -1 | J105: -1 | K105: -1 | L105: -1 | M105: -1 | N105: -1 | O105: -1 | P105: -1

Sheet 45decrypt
A1: dword | B1: custom | C1: dword | D1: stb | E1: byte | F1: dword | G1: custom | H1: dword | I1: custom | J1: dword | K1: custom | L1: dword | M1: custom | N1: dword | O1: custom | P1: dword | Q1: END
A2: =ItemCombine!B2 -> CombineIdx | B2: =ItemCombine!A2 -> Code | C2: =ItemCombine!C2 -> dwFee | D2: =ItemCombine!D2 -> Civil | E2: =ItemCombine!E2 -> TradeValue | F2: =ItemCombine!F2 -> dwTradeMoney | G2: =ItemCombine!G2 -> Mat1 | H2: =ItemCombine!H2 -> Dur1 | I2: =ItemCombine!I2 -> Mat2 | J2: =ItemCombine!J2 -> Dur2 | ... P2: =ItemCombine!P2 -> Dur5
A3: =ItemCombine!B3 -> 0 | B3: =ItemCombine!A3 -> bxlow01 | C3: =ItemCombine!C3 -> 543 | D3: =ItemCombine!D3 -> 11111000 | E3: =ItemCombine!E3 -> -1 | F3: =ItemCombine!F3 -> -1 | G3: =ItemCombine!G3 -> iytwe01 | H3: =ItemCombine!H3 -> 7 | I3: =ItemCombine!I3 -> iytwe02 | J3: =ItemCombine!J3 -> 7 | ... P3: =ItemCombine!P3 -> -1
A4: =ItemCombine!B4 -> 1 | B4: =ItemCombine!A4 -> bxchr01 | C4: =ItemCombine!C4 -> 50000 | D4: =ItemCombine!D4 -> 11111000 | E4: =ItemCombine!E4 -> -1 | F4: =ItemCombine!F4 -> -1 | G4: =ItemCombine!G4 -> iyxma01 | H4: =ItemCombine!H4 -> 5 | I4: =ItemCombine!I4 -> -1 | J4: =ItemCombine!J4 -> -1 | ... P4: =ItemCombine!P4 -> -1
A5: =ItemCombine!B5 -> 2 | B5: =ItemCombine!A5 -> bxchr02 | C5: =ItemCombine!C5 -> 200000 | D5: =ItemCombine!D5 -> 11111000 | E5: =ItemCombine!E5 -> -1 | F5: =ItemCombine!F5 -> -1 | G5: =ItemCombine!G5 -> bxchr01 | H5: =ItemCombine!H5 -> 5 | I5: =ItemCombine!I5 -> -1 | J5: =ItemCombine!J5 -> -1 | ... P5: =ItemCombine!P5 -> -1
A6: =ItemCombine!B6 -> 3 | B6: =ItemCombine!A6 -> bxchr03 | C6: =ItemCombine!C6 -> 400000 | D6: =ItemCombine!D6 -> 11111000 | E6: =ItemCombine!E6 -> -1 | F6: =ItemCombine!F6 -> -1 | G6: =ItemCombine!G6 -> bxchr02 | H6: =ItemCombine!H6 -> 5 | I6: =ItemCombine!I6 -> -1 | J6: =ItemCombine!J6 -> -1 | ... P6: =ItemCombine!P6 -> -1
A7: =ItemCombine!B7 -> 4 | B7: =ItemCombine!A7 -> iygem02 | C7: =ItemCombine!C7 -> 10000 | D7: =ItemCombine!D7 -> 11111000 | E7: =ItemCombine!E7 -> -1 | F7: =ItemCombine!F7 -> -1 | G7: =ItemCombine!G7 -> iygem01 | H7: =ItemCombine!H7 -> 5 | I7: =ItemCombine!I7 -> -1 | J7: =ItemCombine!J7 -> -1 | ... P7: =ItemCombine!P7 -> -1
A8: =ItemCombine!B8 -> 5 | B8: =ItemCombine!A8 -> iygem03 | C8: =ItemCombine!C8 -> 20000 | D8: =ItemCombine!D8 -> 11111000 | E8: =ItemCombine!E8 -> -1 | F8: =ItemCombine!F8 -> -1 | G8: =ItemCombine!G8 -> iygem02 | H8: =ItemCombine!H8 -> 5 | I8: =ItemCombine!I8 -> -1 | J8: =ItemCombine!J8 -> -1 | ... P8: =ItemCombine!P8 -> -1
A9: =ItemCombine!B9 -> 6 | B9: =ItemCombine!A9 -> iygem04 | C9: =ItemCombine!C9 -> 150000 | D9: =ItemCombine!D9 -> 11111000 | E9: =ItemCombine!E9 -> -1 | F9: =ItemCombine!F9 -> -1 | G9: =ItemCombine!G9 -> iygem03 | H9: =ItemCombine!H9 -> 5 | I9: =ItemCombine!I9 -> -1 | J9: =ItemCombine!J9 -> -1 | ... P9: =ItemCombine!P9 -> -1
A10: =ItemCombine!B10 -> 7 | B10: =ItemCombine!A10 -> bxgem01 | C10: =ItemCombine!C10 -> 10000 | D10: =ItemCombine!D10 -> 11111000 | E10: =ItemCombine!E10 -> -1 | F10: =ItemCombine!F10 -> -1 | G10: =ItemCombine!G10 -> iygem02 | H10: =ItemCombine!H10 -> 1 | I10: =ItemCombine!I10 -> -1 | J10: =ItemCombine!J10 -> -1 | ... P10: =ItemCombine!P10 -> -1
A11: =ItemCombine!B11 -> 8 | B11: =ItemCombine!A11 -> bxgem02 | C11: =ItemCombine!C11 -> 10000 | D11: =ItemCombine!D11 -> 11111000 | E11: =ItemCombine!E11 -> -1 | F11: =ItemCombine!F11 -> -1 | G11: =ItemCombine!G11 -> iygem03 | H11: =ItemCombine!H11 -> 1 | I11: =ItemCombine!I11 -> -1 | J11: =ItemCombine!J11 -> -1 | ... P11: =ItemCombine!P11 -> -1
A12: =ItemCombine!B12 -> 9 | B12: =ItemCombine!A12 -> bxgem03 | C12: =ItemCombine!C12 -> 10000 | D12: =ItemCombine!D12 -> 11111000 | E12: =ItemCombine!E12 -> -1 | F12: =ItemCombine!F12 -> -1 | G12: =ItemCombine!G12 -> iygem04 | H12: =ItemCombine!H12 -> 1 | I12: =ItemCombine!I12 -> -1 | J12: =ItemCombine!J12 -> -1 | ... P12: =ItemCombine!P12 -> -1
A13: =ItemCombine!B13 -> 10 | B13: =ItemCombine!A13 -> bxgem04 | C13: =ItemCombine!C13 -> 10000 | D13: =ItemCombine!D13 -> 11111000 | E13: =ItemCombine!E13 -> -1 | F13: =ItemCombine!F13 -> -1 | G13: =ItemCombine!G13 -> iybox03 | H13: =ItemCombine!H13 -> 50 | I13: =ItemCombine!I13 -> -1 | J13: =ItemCombine!J13 -> -1 | ... P13: =ItemCombine!P13 -> -1
... A105: =ItemCombine!B105 -> 102 | B105: =ItemCombine!A105 -> bxafc65 | C105: =ItemCombine!C105 -> 150000000 | D105: =ItemCombine!D105 -> 00001000 | E105: =ItemCombine!E105 -> -1 | F105: =ItemCombine!F105 -> -1 | G105: =ItemCombine!G105 -> ircry03 | H105: =ItemCombine!H105 -> 50 | I105: =ItemCombine!I105 -> -1 | J105: =ItemCombine!J105 -> -1 | ... P105: =ItemCombine!P105 -> -1

Sheet 45desc
A1: dword | B1: text | C1: END
A2: Count | B2: desc

Sheet ButtonIds
A1: TranslationID | B1: ExchangeID | C1: ButtonID | D1: Text
A2: 0x67 | C2: 0 | D2: No
A3: 0x3AF | C3: 1 | D3: Buy / Sell
A4: 0x2D1 | C4: 2 | D4: Exercise
A5: 0x3B0 | C5: 3 | D5: Confirm the economic indicator
A6: 0x3A6 | C6: 4 | D6: Exchange
A7: 0x3B1 | C7: 5 | D7: Cleaning
A8: 0x72D | C8: 6 | D8: Buy Storage
A9: 0x3B3 | C9: 7 | D9: Management
A10: 0x3B4 | C10: 8 | D10: Enter
A11: 0x3B5 | C11: 9 | D11: Exchange PvP points
A12: 0x3B6 | C12: 10 | D12: Gain MAU
A13: 0x3B7 | C13: 11 | D13: Delivery MAU
... A29: 0x947 | C29: 27 | D29: Guild Tournaments
A30: 0x67 | B30: 0 | C30: 28 | D30: No
A31: 0x948 | B31: 1 | C31: 29 | D31: Small Gift Box Exchange
A32: 0x949 | B32: 2 | C32: 30 | D32: Gift Box Exchange
A33: 0x94A | B33: 3 | C33: 31 | D33: Large Gift Box Exchange
A34: 0x9F0 | C34: 32 | D34: Generate territory
A35: 0x9F1 | C35: 33 | D35: ABU setup
A36: 0xA20 | C36: 34 | D36: Tax rate
A37: 0xA21 | C37: 35 | D37: Vulcan Cauldron Territory
A38: 0xA72 | C38: 36 | D38: Composition of ABU
A39: 0xB9A | C39: 37 | D39: Territorial
A40: 0xB9B | B40: 4 | C40: 38 | D40: Rough Crystal
A41: 0xB9C | B41: 5 | C41: 39 | D41: Polished crystal
A42: 0xB9D | B42: 6 | C42: 40 | D42: Faceted crystal
A43: 0xB9E | B43: 7 | C43: 41 | D43: Small Box
A44: 0xB9F | B44: 8 | C44: 42 | D44: Medium Box
A45: 0xBA0 | B45: 9 | C45: 43 | D45: Big Box
A46: 0xBA1 | C46: 44 | D46: Guild Hall
A47: 0xBA2 | C47: 45 | D47: List of prices
A48: 0xBA3 | C48: 46 | D48: Procedural information
A49: 0xBA4 | C49: 47 | D49: Squeeze tightly
A50: 0xBA5 | B50: 10 | C50: 48 | D50: Clear exchange box
A51: 0xD09 | C51: 49 | D51: Passage through Elan
A52: 0xD0A | C52: 50 | D52: Trade ads
A53: 0xD0B | B53: 11 | C53: 51 | D53: Pass the petal
A54: 0xD0C | B54: 12 | C54: 52 | D54: Exchange of Buddha giving wealth
A55: 0xD0D | C55: 53 | D55: Dialogue
...
