Workbook

Sheet PotionItem
A1: string[64] | B1: dword | C1: string[64] | D1: dword | E1: string[64] | F1: dword | G1: dword | H1: string[64] | I1: string[64] | J1: dword | K1: dword | L1: string[64] | M1: float | N1: dword | O1: dword | P1: dword | Q1: dword | R1: dword | S1: dword | T1: dword | U1: dword | V1: dword | W1: dword | X1: dword | Y1: dword | Z1: dword | AA1: dword | AB1: dword | AC1: dword | AD1: dword | AE1: dword | AF1: float | AG1: string[64] | AH1: dword | AI1: dword | AJ1: dword | AK1: dword | AL1: dword | AM1: dword | AN1: dword | AO1: dword | AP1: string[64] | AQ1: dword | AR1: dword | AS1: dword | AT1: END
A2: Code | B2: IsExist | C2: Model | D2: IconID | E2: Name | F2: KindClt | G2: FixPart | H2: Civil | I2: ActTarget | J2: PotionCheck | K2: UseState | L2: TargetEff | M2: ActDelay | N2: DelayType | O2: UseRange | P2: LevelLim | Q2: UpLevelLim | R2: PotionLim | S2: MapCode1 | T2: MapCode2 | U2: MapCode3 | V2: MapCode4 | W2: MapCode5 | X2: Money | Y2: StdPrice | Z2: StdPoint | AA2: GoldPoint | AB2: KillPoint | AC2: ProcPoint | AD2: StorePrice | AE2: IsAbr | AF2: EquipSpeed | AG2: EffCode | AH2: EffArea | AI2: EffAreaVal | AJ2: IsSell | AK2: IsExchange | AL2: IsGround | AM2: IsStore | AN2: IsNormAcc | AO2: IsUpgrade | AP2: ToolTip | AQ2: IsCash | AR2: UsePCCash | AS2: IsTime
A3: ipbhp01 | B3: 1 | C3: 720000 | D3: 1 | E3: Bless HP Potion 100 | F3: 200 | G3: 250 | H3: 11000000 | I3: 10000000 | J3: -1 | K3: 0 | L3: -1 | M3: 1600 | N3: 0 | O3: 0 | P3: 1 | Q3: -1 | R3: -1 | S3: -1 | T3: -1 | U3: -1 | V3: -1 | W3: -1 | X3: 0 | Y3: 40 | Z3: 0 | AA3: 0 | AB3: 0 | AC3: 0 | AD3: 4 | AE3: 1 | AF3: 1 | AG3: 1 | AH3: 0 | AI3: 0 | AJ3: 1 | AK3: 1 | AL3: 1 | AM3: 1 | AN3: 1 | AO3: 0 | AP3: ="t"&A3 -> tipbhp01 | AQ3: 0 | AR3: 0 | AS3: 0
A4: ipbhp02 | B4: 1 | C4: 720001 | D4: 2 | E4: Bless HP Potion 250 | F4: 200 | G4: 250 | H4: 11000000 | I4: 10000000 | J4: -1 | K4: 0 | L4: -1 | M4: 1600 | N4: 0 | O4: 0 | P4: 1 | Q4: -1 | R4: -1 | S4: -1 | T4: -1 | U4: -1 | V4: -1 | W4: -1 | X4: 0 | Y4: 100 | Z4: 0 | AA4: 0 | AB4: 0 | AC4: 0 | AD4: 10 | AE4: 1 | AF4: 1 | AG4: 2 | AH4: 0 | AI4: 0 | AJ4: 1 | AK4: 1 | AL4: 1 | AM4: 1 | AN4: 1 | AO4: 0 | AP4: ="t"&A4 -> tipbhp02 | AQ4: 0 | AR4: 0 | AS4: 0
A5: ipbhp03 | B5: 1 | C5: 720002 | D5: 3 | E5: Bless HP Potion 500 | F5: 200 | G5: 250 | H5: 11000000 | I5: 10000000 | J5: -1 | K5: 0 | L5: -1 | M5: 1600 | N5: 0 | O5: 0 | P5: 1 | Q5: -1 | R5: -1 | S5: -1 | T5: -1 | U5: -1 | V5: -1 | W5: -1 | X5: 0 | Y5: 220 | Z5: 0 | AA5: 0 | AB5: 0 | AC5: 0 | AD5: 22 | AE5: 1 | AF5: 1 | AG5: 3 | AH5: 0 | AI5: 0 | AJ5: 1 | AK5: 1 | AL5: 1 | AM5: 1 | AN5: 1 | AO5: 0 | AP5: ="t"&A5 -> tipbhp03 | AQ5: 0 | AR5: 0 | AS5: 0
A6: ipbhp04 | B6: 1 | C6: 720003 | D6: 4 | E6: Bless HP Potion 1000 | F6: 200 | G6: 250 | H6: 11000000 | I6: 10000000 | J6: -1 | K6: 0 | L6: -1 | M6: 1800 | N6: 0 | O6: 0 | P6: 1 | Q6: -1 | R6: -1 | S6: -1 | T6: -1 | U6: -1 | V6: -1 | W6: -1 | X6: 0 | Y6: 500 | Z6: 0 | AA6: 0 | AB6: 0 | AC6: 0 | AD6: 50 | AE6: 1 | AF6: 1 | AG6: 4 | AH6: 0 | AI6: 0 | AJ6: 1 | AK6: 1 | AL6: 1 | AM6: 1 | AN6: 1 | AO6: 0 | AP6: ="t"&A6 -> tipbhp04 | AQ6: 0 | AR6: 0 | AS6: 0
A7: ipbhp05 | B7: 1 | C7: 720004 | D7: 5 | E7: Bless HP Potion 2000 | F7: 200 | G7: 250 | H7: 11000000 | I7: 10000000 | J7: -1 | K7: 0 | L7: -1 | M7: 2200 | N7: 0 | O7: 0 | P7: 1 | Q7: -1 | R7: -1 | S7: -1 | T7: -1 | U7: -1 | V7: -1 | W7: -1 | X7: 0 | Y7: 1200 | Z7: 0 | AA7: 0 | AB7: 0 | AC7: 0 | AD7: 120 | AE7: 1 | AF7: 1 | AG7: 5 | AH7: 0 | AI7: 0 | AJ7: 1 | AK7: 1 | AL7: 1 | AM7: 1 | AN7: 1 | AO7: 0 | AP7: ="t"&A7 -> tipbhp05 | AQ7: 0 | AR7: 0 | AS7: 0
A8: ipbhp06 | B8: 1 | C8: 720005 | D8: 6 | E8: Bless HP Potion 3000 | F8: 200 | G8: 250 | H8: 11000000 | I8: 10000000 | J8: -1 | K8: 0 | L8: -1 | M8: 2500 | N8: 0 | O8: 0 | P8: 1 | Q8: -1 | R8: -1 | S8: -1 | T8: -1 | U8: -1 | V8: -1 | W8: -1 | X8: 0 | Y8: 3637 | Z8: 0 | AA8: 0 | AB8: 0 | AC8: 0 | AD8: 225 | AE8: 1 | AF8: 1 | AG8: 6 | AH8: 0 | AI8: 0 | AJ8: 1 | AK8: 1 | AL8: 1 | AM8: 1 | AN8: 1 | AO8: 0 | AP8: ="t"&A8 -> tipbhp06 | AQ8: 0 | AR8: 0 | AS8: 0
A9: ipbhp07 | B9: 1 | C9: 720006 | D9: 7 | E9: Bless HP Potion 4000 | F9: 200 | G9: 250 | H9: 11000000 | I9: 10000000 | J9: -1 | K9: 0 | L9: -1 | M9: 2500 | N9: 0 | O9: 0 | P9: 1 | Q9: -1 | R9: -1 | S9: -1 | T9: -1 | U9: -1 | V9: -1 | W9: -1 | X9: 0 | Y9: 5250 | Z9: 0 | AA9: 0 | AB9: 0 | AC9: 0 | AD9: 525 | AE9: 1 | AF9: 1 | AG9: 7 | AH9: 0 | AI9: 0 | AJ9: 1 | AK9: 1 | AL9: 1 | AM9: 1 | AN9: 1 | AO9: 0 | AP9: ="t"&A9 -> tipbhp07 | AQ9: 0 | AR9: 0 | AS9: 0
A10: ipbhp08 | B10: 1 | C10: 720007 | D10: 8 | E10: Bless HP Potion 5000 | F10: 200 | G10: 250 | H10: 11000000 | I10: 10000000 | J10: -1 | K10: 0 | L10: -1 | M10: 2500 | N10: 0 | O10: 0 | P10: 1 | Q10: -1 | R10: -1 | S10: -1 | T10: -1 | U10: -1 | V10: -1 | W10: -1 | X10: 0 | Y10: 11257 | Z10: 0 | AA10: 0 | AB10: 0 | AC10: 0 | AD10: 1126 | AE10: 1 | AF10: 1 | AG10: 8 | AH10: 0 | AI10: 0 | AJ10: 1 | AK10: 1 | AL10: 1 | AM10: 1 | AN10: 1 | AO10: 0 | AP10: ="t"&A10 -> tipbhp08 | AQ10: 0 | AR10: 0 | AS10: 0
A11: ipchp01 | B11: 1 | C11: 820008 | D11: 9 | E11: Pope HP Potion 100 | F11: 200 | G11: 250 | H11: 00110000 | I11: 10000000 | J11: -1 | K11: 0 | L11: -1 | M11: 1600 | N11: 0 | O11: 0 | P11: 1 | Q11: -1 | R11: -1 | S11: -1 | T11: -1 | U11: -1 | V11: -1 | W11: -1 | X11: 0 | Y11: 40 | Z11: 0 | AA11: 0 | AB11: 0 | AC11: 0 | AD11: 4 | AE11: 1 | AF11: 1 | AG11: 9 | AH11: 0 | AI11: 0 | AJ11: 1 | AK11: 1 | AL11: 1 | AM11: 1 | AN11: 1 | AO11: 0 | AP11: ="t"&A11 -> tipchp01 | AQ11: 0 | AR11: 0 | AS11: 0
A12: ipchp02 | B12: 1 | C12: 820009 | D12: 10 | E12: Pope HP Potion 250 | F12: 200 | G12: 250 | H12: 00110000 | I12: 10000000 | J12: -1 | K12: 0 | L12: -1 | M12: 1600 | N12: 0 | O12: 0 | P12: 1 | Q12: -1 | R12: -1 | S12: -1 | T12: -1 | U12: -1 | V12: -1 | W12: -1 | X12: 0 | Y12: 100 | Z12: 0 | AA12: 0 | AB12: 0 | AC12: 0 | AD12: 10 | AE12: 1 | AF12: 1 | AG12: A | AH12: 0 | AI12: 0 | AJ12: 1 | AK12: 1 | AL12: 1 | AM12: 1 | AN12: 1 | AO12: 0 | AP12: ="t"&A12 -> tipchp02 | AQ12: 0 | AR12: 0 | AS12: 0
A13: ipchp03 | B13: 1 | C13: 82000A | D13: 11 | E13: Pope HP Potion 500 | F13: 200 | G13: 250 | H13: 00110000 | I13: 10000000 | J13: -1 | K13: 0 | L13: -1 | M13: 1600 | N13: 0 | O13: 0 | P13: 1 | Q13: -1 | R13: -1 | S13: -1 | T13: -1 | U13: -1 | V13: -1 | W13: -1 | X13: 0 | Y13: 220 | Z13: 0 | AA13: 0 | AB13: 0 | AC13: 0 | AD13: 22 | AE13: 1 | AF13: 1 | AG13: B | AH13: 0 | AI13: 0 | AJ13: 1 | AK13: 1 | AL13: 1 | AM13: 1 | AN13: 1 | AO13: 0 | AP13: ="t"&A13 -> tipchp03 | AQ13: 0 | AR13: 0 | AS13: 0
A14: ipchp04 | B14: 1 | C14: 82000B | D14: 12 | E14: Pope HP Potion 1000 | F14: 200 | G14: 250 | H14: 00110000 | I14: 10000000 | J14: -1 | K14: 0 | L14: -1 | M14: 1800 | N14: 0 | O14: 0 | P14: 1 | Q14: -1 | R14: -1 | S14: -1 | T14: -1 | U14: -1 | V14: -1 | W14: -1 | X14: 0 | Y14: 500 | Z14: 0 | AA14: 0 | AB14: 0 | AC14: 0 | AD14: 50 | AE14: 1 | AF14: 1 | AG14: C | AH14: 0 | AI14: 0 | AJ14: 1 | AK14: 1 | AL14: 1 | AM14: 1 | AN14: 1 | AO14: 0 | AP14: ="t"&A14 -> tipchp04 | AQ14: 0 | AR14: 0 | AS14: 0
... A399: ipgld20 | B399: 1 | C399: A2056F | D399: 404 | E399: Gold Capsule+20 | F399: 205 | G399: 250 | H399: 11111000 | I399: 10000000 | J399: -1 | K399: 0 | L399: -1 | M399: 0 | N399: 28 | O399: 0 | P399: 1 | Q399: -1 | R399: -1 | S399: -1 | T399: -1 | U399: -1 | V399: -1 | W399: -1 | X399: 0 | Y399: 1 | Z399: 0 | AA399: 0 | AB399: 0 | AC399: 0 | AD399: 1 | AE399: 1 | AF399: 1 | AG399: 18E | AH399: 0 | AI399: 0 | AJ399: 1 | AK399: 1 | AL399: 1 | AM399: 1 | AN399: 1 | AO399: 0 | AP399: ="t"&A399 -> tipgld20 | AQ399: 0 | AR399: 0 | AS399: 0
A400: ipgld21 | B400: 1 | C400: A2056F | D400: 406 | E400: Cash Capsule+1 | F400: 205 | G400: 250 | H400: 11111000 | I400: 10000000 | J400: -1 | K400: 0 | L400: -1 | M400: 0 | N400: 28 | O400: 0 | P400: 1 | Q400: -1 | R400: -1 | S400: -1 | T400: -1 | U400: -1 | V400: -1 | W400: -1 | X400: 0 | Y400: 1 | Z400: 0 | AA400: 0 | AB400: 0 | AC400: 0 | AD400: 1 | AE400: 1 | AF400: 1 | AG400: 253 | AH400: 0 | AI400: 0 | AJ400: 1 | AK400: 1 | AL400: 1 | AM400: 1 | AN400: 1 | AO400: 0 | AP400: ="t"&A400 -> tipgld21 | AQ400: 0 | AR400: 0 | AS400: 0
A401: ipgld22 | B401: 1 | C401: A2056F | D401: 407 | E401: Cash Capsule+5 | F401: 205 | G401: 250 | H401: 11111000 | I401: 10000000 | J401: -1 | K401: 0 | L401: -1 | M401: 0 | N401: 28 | O401: 0 | P401: 1 | Q401: -1 | R401: -1 | S401: -1 | T401: -1 | U401: -1 | V401: -1 | W401: -1 | X401: 0 | Y401: 1 | Z401: 0 | AA401: 0 | AB401: 0 | AC401: 0 | AD401: 1 | AE401: 1 | AF401: 1 | AG401: 254 | AH401: 0 | AI401: 0 | AJ401: 1 | AK401: 1 | AL401: 1 | AM401: 1 | AN401: 1 | AO401: 0 | AP401: ="t"&A401 -> tipgld22 | AQ401: 0 | AR401: 0 | AS401: 0
A402: ipgld23 | B402: 1 | C402: A2056F | D402: 408 | E402: Cash Capsule+20 | F402: 205 | G402: 250 | H402: 11111000 | I402: 10000000 | J402: -1 | K402: 0 | L402: -1 | M402: 0 | N402: 28 | O402: 0 | P402: 1 | Q402: -1 | R402: -1 | S402: -1 | T402: -1 | U402: -1 | V402: -1 | W402: -1 | X402: 0 | Y402: 1 | Z402: 0 | AA402: 0 | AB402: 0 | AC402: 0 | AD402: 1 | AE402: 1 | AF402: 1 | AG402: 255 | AH402: 0 | AI402: 0 | AJ402: 1 | AK402: 1 | AL402: 1 | AM402: 1 | AN402: 1 | AO402: 0 | AP402: ="t"&A402 -> tipgld23 | AQ402: 0 | AR402: 0 | AS402: 0
A403: ipgld24 | B403: 1 | C403: A2056F | D403: 409 | E403: Cash Capsule+100 | F403: 205 | G403: 250 | H403: 11111000 | I403: 10000000 | J403: -1 | K403: 0 | L403: -1 | M403: 0 | N403: 28 | O403: 0 | P403: 1 | Q403: -1 | R403: -1 | S403: -1 | T403: -1 | U403: -1 | V403: -1 | W403: -1 | X403: 0 | Y403: 1 | Z403: 0 | AA403: 0 | AB403: 0 | AC403: 0 | AD403: 1 | AE403: 1 | AF403: 1 | AG403: 256 | AH403: 0 | AI403: 0 | AJ403: 1 | AK403: 1 | AL403: 1 | AM403: 1 | AN403: 1 | AO403: 0 | AP403: ="t"&A403 -> tipgld24 | AQ403: 0 | AR403: 0 | AS403: 0
A404: ipgld25 | B404: 1 | C404: A2056F | D404: 410 | E404: Cash Capsule+300 | F404: 205 | G404: 250 | H404: 11111000 | I404: 10000000 | J404: -1 | K404: 0 | L404: -1 | M404: 0 | N404: 28 | O404: 0 | P404: 1 | Q404: -1 | R404: -1 | S404: -1 | T404: -1 | U404: -1 | V404: -1 | W404: -1 | X404: 0 | Y404: 1 | Z404: 0 | AA404: 0 | AB404: 0 | AC404: 0 | AD404: 1 | AE404: 1 | AF404: 1 | AG404: 257 | AH404: 0 | AI404: 0 | AJ404: 1 | AK404: 1 | AL404: 1 | AM404: 1 | AN404: 1 | AO404: 0 | AP404: ="t"&A404 -> tipgld25 | AQ404: 0 | AR404: 0 | AS404: 0
A405: ipgld26 | B405: 1 | C405: A2056F | D405: 411 | E405: Cash Capsule+500 | F405: 205 | G405: 250 | H405: 11111000 | I405: 10000000 | J405: -1 | K405: 0 | L405: -1 | M405: 0 | N405: 28 | O405: 0 | P405: 1 | Q405: -1 | R405: -1 | S405: -1 | T405: -1 | U405: -1 | V405: -1 | W405: -1 | X405: 0 | Y405: 1 | Z405: 0 | AA405: 0 | AB405: 0 | AC405: 0 | AD405: 1 | AE405: 1 | AF405: 1 | AG405: 258 | AH405: 0 | AI405: 0 | AJ405: 1 | AK405: 1 | AL405: 1 | AM405: 1 | AN405: 1 | AO405: 0 | AP405: ="t"&A405 -> tipgld26 | AQ405: 0 | AR405: 0 | AS405: 0
A406: ipgld27 | B406: 1 | C406: A2056F | D406: 412 | E406: Cash Capsule+1000 | F406: 205 | G406: 250 | H406: 11111000 | I406: 10000000 | J406: -1 | K406: 0 | L406: -1 | M406: 0 | N406: 28 | O406: 0 | P406: 1 | Q406: -1 | R406: -1 | S406: -1 | T406: -1 | U406: -1 | V406: -1 | W406: -1 | X406: 0 | Y406: 1 | Z406: 0 | AA406: 0 | AB406: 0 | AC406: 0 | AD406: 1 | AE406: 1 | AF406: 1 | AG406: 259 | AH406: 0 | AI406: 0 | AJ406: 1 | AK406: 1 | AL406: 1 | AM406: 1 | AN406: 1 | AO406: 0 | AP406: ="t"&A406 -> tipgld27 | AQ406: 0 | AR406: 0 | AS406: 0
A407: ipgld28 | B407: 1 | C407: A2056F | D407: 413 | E407: Cash Capsule+10000 | F407: 205 | G407: 250 | H407: 11111000 | I407: 10000000 | J407: -1 | K407: 0 | L407: -1 | M407: 0 | N407: 28 | O407: 0 | P407: 1 | Q407: -1 | R407: -1 | S407: -1 | T407: -1 | U407: -1 | V407: -1 | W407: -1 | X407: 0 | Y407: 1 | Z407: 0 | AA407: 0 | AB407: 0 | AC407: 0 | AD407: 1 | AE407: 1 | AF407: 1 | AG407: 260 | AH407: 0 | AI407: 0 | AJ407: 1 | AK407: 1 | AL407: 1 | AM407: 1 | AN407: 1 | AO407: 0 | AP407: ="t"&A407 -> tipgld28 | AQ407: 0 | AR407: 0 | AS407: 0
A408: ipgld29 | B408: 1 | C408: A2056F | D408: 459 | E408: Premium Service [1 day] | F408: 205 | G408: 250 | H408: 11111000 | I408: 10000000 | J408: -1 | K408: 0 | L408: -1 | M408: 0 | N408: 28 | O408: 0 | P408: 1 | Q408: -1 | R408: -1 | S408: -1 | T408: -1 | U408: -1 | V408: -1 | W408: -1 | X408: 0 | Y408: 1 | Z408: 0 | AA408: 0 | AB408: 0 | AC408: 0 | AD408: 1 | AE408: 1 | AF408: 1 | AG408: 261 | AH408: 0 | AI408: 0 | AJ408: 1 | AK408: 1 | AL408: 1 | AM408: 1 | AN408: 1 | AO408: 0 | AP408: ="t"&A408 -> tipgld29 | AQ408: 0 | AR408: 0 | AS408: 0
A409: ipgld30 | B409: 1 | C409: A2056F | D409: 416 | E409: Gold Capsule+4000 | F409: 205 | G409: 250 | H409: 11111000 | I409: 10000000 | J409: -1 | K409: 0 | L409: -1 | M409: 0 | N409: 28 | O409: 0 | P409: 1 | Q409: -1 | R409: -1 | S409: -1 | T409: -1 | U409: -1 | V409: -1 | W409: -1 | X409: 0 | Y409: 1 | Z409: 0 | AA409: 0 | AB409: 0 | AC409: 0 | AD409: 1 | AE409: 1 | AF409: 1 | AG409: 198 | AH409: 0 | AI409: 0 | AJ409: 1 | AK409: 1 | AL409: 1 | AM409: 1 | AN409: 1 | AO409: 0 | AP409: ="t"&A409 -> tipgld30 | AQ409: 0 | AR409: 0 | AS409: 0
A410: ipgld31 | B410: 1 | C410: A2056F | D410: 425 | E410: Gold Capsule+4500 | F410: 205 | G410: 250 | H410: 11111000 | I410: 10000000 | J410: -1 | K410: 0 | L410: -1 | M410: 0 | N410: 28 | O410: 0 | P410: 1 | Q410: -1 | R410: -1 | S410: -1 | T410: -1 | U410: -1 | V410: -1 | W410: -1 | X410: 0 | Y410: 1 | Z410: 0 | AA410: 0 | AB410: 0 | AC410: 0 | AD410: 1 | AE410: 1 | AF410: 1 | AG410: 199 | AH410: 0 | AI410: 0 | AJ410: 1 | AK410: 1 | AL410: 1 | AM410: 1 | AN410: 1 | AO410: 0 | AP410: ="t"&A410 -> tipgld31 | AQ410: 0 | AR410: 0 | AS410: 0
A411: ipgld32 | B411: 1 | C411: A2056F | D411: 417 | E411: Gold Capsule+5000 | F411: 205 | G411: 250 | H411: 11111000 | I411: 10000000 | J411: -1 | K411: 0 | L411: -1 | M411: 0 | N411: 28 | O411: 0 | P411: 1 | Q411: -1 | R411: -1 | S411: -1 | T411: -1 | U411: -1 | V411: -1 | W411: -1 | X411: 0 | Y411: 1 | Z411: 0 | AA411: 0 | AB411: 0 | AC411: 0 | AD411: 1 | AE411: 1 | AF411: 1 | AG411: 19A | AH411: 0 | AI411: 0 | AJ411: 1 | AK411: 1 | AL411: 1 | AM411: 1 | AN411: 1 | AO411: 0 | AP411: ="t"&A411 -> tipgld32 | AQ411: 0 | AR411: 0 | AS411: 0
A412: ipgld33 | B412: 1 | C412: A2056F | D412: 426 | E412: Gold Capsule+5500 | F412: 205 | G412: 250 | H412: 11111000 | I412: 10000000 | J412: -1 | K412: 0 | L412: -1 | M412: 0 | N412: 28 | O412: 0 | P412: 1 | Q412: -1 | R412: -1 | S412: -1 | T412: -1 | U412: -1 | V412: -1 | W412: -1 | X412: 0 | Y412: 1 | Z412: 0 | AA412: 0 | AB412: 0 | AC412: 0 | AD412: 1 | AE412: 1 | AF412: 1 | AG412: 19B | AH412: 0 | AI412: 0 | AJ412: 1 | AK412: 1 | AL412: 1 | AM412: 1 | AN412: 1 | AO412: 0 | AP412: ="t"&A412 -> tipgld33 | AQ412: 0 | AR412: 0 | AS412: 0
A413: ipgld34 | B413: 1 | C413: A2056F | D413: 418 | E413: Gold Capsule+6000 | F413: 205 | G413: 250 | H413: 11111000 | I413: 10000000 | J413: -1 | K413: 0 | L413: -1 | M413: 0 | N413: 28 | O413: 0 | P413: 1 | Q413: -1 | R413: -1 | S413: -1 | T413: -1 | U413: -1 | V413: -1 | W413: -1 | X413: 0 | Y413: 1 | Z413: 0 | AA413: 0 | AB413: 0 | AC413: 0 | AD413: 1 | AE413: 1 | AF413: 1 | AG413: 19C | AH413: 0 | AI413: 0 | AJ413: 1 | AK413: 1 | AL413: 1 | AM413: 1 | AN413: 1 | AO413: 0 | AP413: ="t"&A413 -> tipgld34 | AQ413: 0 | AR413: 0 | AS413: 0
A414: ipgld35 | B414: 1 | C414: A2056F | D414: 419 | E414: Gold Capsule+6500 | F414: 205 | G414: 250 | H414: 11111000 | I414: 10000000 | J414: -1 | K414: 0 | L414: -1 | M414: 0 | N414: 28 | O414: 0 | P414: 1 | Q414: -1 | R414: -1 | S414: -1 | T414: -1 | U414: -1 | V414: -1 | W414: -1 | X414: 0 | Y414: 1 | Z414: 0 | AA414: 0 | AB414: 0 | AC414: 0 | AD414: 1 | AE414: 1 | AF414: 1 | AG414: 19D | AH414: 0 | AI414: 0 | AJ414: 1 | AK414: 1 | AL414: 1 | AM414: 1 | AN414: 1 | AO414: 0 | AP414: ="t"&A414 -> tipgld35 | AQ414: 0 | AR414: 0 | AS414: 0
A415: ipgld36 | B415: 1 | C415: A2056F | D415: 420 | E415: Gold Capsule+7000 | F415: 205 | G415: 250 | H415: 11111000 | I415: 10000000 | J415: -1 | K415: 0 | L415: -1 | M415: 0 | N415: 28 | O415: 0 | P415: 1 | Q415: -1 | R415: -1 | S415: -1 | T415: -1 | U415: -1 | V415: -1 | W415: -1 | X415: 0 | Y415: 1 | Z415: 0 | AA415: 0 | AB415: 0 | AC415: 0 | AD415: 1 | AE415: 1 | AF415: 1 | AG415: 19E | AH415: 0 | AI415: 0 | AJ415: 1 | AK415: 1 | AL415: 1 | AM415: 1 | AN415: 1 | AO415: 0 | AP415: ="t"&A415 -> tipgld36 | AQ415: 0 | AR415: 0 | AS415: 0
A416: ipgld37 | B416: 1 | C416: A2056F | D416: 427 | E416: Gold Capsule+7500 | F416: 205 | G416: 250 | H416: 11111000 | I416: 10000000 | J416: -1 | K416: 0 | L416: -1 | M416: 0 | N416: 28 | O416: 0 | P416: 1 | Q416: -1 | R416: -1 | S416: -1 | T416: -1 | U416: -1 | V416: -1 | W416: -1 | X416: 0 | Y416: 1 | Z416: 0 | AA416: 0 | AB416: 0 | AC416: 0 | AD416: 1 | AE416: 1 | AF416: 1 | AG416: 19F | AH416: 0 | AI416: 0 | AJ416: 1 | AK416: 1 | AL416: 1 | AM416: 1 | AN416: 1 | AO416: 0 | AP416: ="t"&A416 -> tipgld37 | AQ416: 0 | AR416: 0 | AS416: 0
A417: ipgld38 | B417: 1 | C417: A2056F | D417: 428 | E417: Gold Capsule+10000 | F417: 205 | G417: 250 | H417: 11111000 | I417: 10000000 | J417: -1 | K417: 0 | L417: -1 | M417: 0 | N417: 28 | O417: 0 | P417: 1 | Q417: -1 | R417: -1 | S417: -1 | T417: -1 | U417: -1 | V417: -1 | W417: -1 | X417: 0 | Y417: 1 | Z417: 0 | AA417: 0 | AB417: 0 | AC417: 0 | AD417: 1 | AE417: 1 | AF417: 1 | AG417: 201 | AH417: 0 | AI417: 0 | AJ417: 1 | AK417: 1 | AL417: 1 | AM417: 1 | AN417: 1 | AO417: 0 | AP417: ="t"&A417 -> tipgld38 | AQ417: 0 | AR417: 0 | AS417: 0
A418: ipgld39 | B418: 1 | C418: A2056F | D418: 429 | E418: Gold Capsule+12500 | F418: 205 | G418: 250 | H418: 11111000 | I418: 10000000 | J418: -1 | K418: 0 | L418: -1 | M418: 0 | N418: 28 | O418: 0 | P418: 1 | Q418: -1 | R418: -1 | S418: -1 | T418: -1 | U418: -1 | V418: -1 | W418: -1 | X418: 0 | Y418: 1 | Z418: 0 | AA418: 0 | AB418: 0 | AC418: 0 | AD418: 1 | AE418: 1 | AF418: 1 | AG418: 202 | AH418: 0 | AI418: 0 | AJ418: 1 | AK418: 1 | AL418: 1 | AM418: 1 | AN418: 1 | AO418: 0 | AP418: ="t"&A418 -> tipgld39 | AQ418: 0 | AR418: 0 | AS418: 0
A419: ipgld40 | B419: 1 | C419: A2056F | D419: 430 | E419: Gold Capsule+15000 | F419: 205 | G419: 250 | H419: 11111000 | I419: 10000000 | J419: -1 | K419: 0 | L419: -1 | M419: 0 | N419: 28 | O419: 0 | P419: 1 | Q419: -1 | R419: -1 | S419: -1 | T419: -1 | U419: -1 | V419: -1 | W419: -1 | X419: 0 | Y419: 1 | Z419: 0 | AA419: 0 | AB419: 0 | AC419: 0 | AD419: 1 | AE419: 1 | AF419: 1 | AG419: 203 | AH419: 0 | AI419: 0 | AJ419: 1 | AK419: 1 | AL419: 1 | AM419: 1 | AN419: 1 | AO419: 0 | AP419: ="t"&A419 -> tipgld40 | AQ419: 0 | AR419: 0 | AS419: 0
A420: ipgld41 | B420: 1 | C420: A2056F | D420: 431 | E420: Gold Capsule+17500 | F420: 205 | G420: 250 | H420: 11111000 | I420: 10000000 | J420: -1 | K420: 0 | L420: -1 | M420: 0 | N420: 28 | O420: 0 | P420: 1 | Q420: -1 | R420: -1 | S420: -1 | T420: -1 | U420: -1 | V420: -1 | W420: -1 | X420: 0 | Y420: 1 | Z420: 0 | AA420: 0 | AB420: 0 | AC420: 0 | AD420: 1 | AE420: 1 | AF420: 1 | AG420: 204 | AH420: 0 | AI420: 0 | AJ420: 1 | AK420: 1 | AL420: 1 | AM420: 1 | AN420: 1 | AO420: 0 | AP420: ="t"&A420 -> tipgld41 | AQ420: 0 | AR420: 0 | AS420: 0
... A461: ipmas09 | B461: 1 | C461: A2056F | D461: 540 | E461: Gold Capsule +1000000 | F461: 201 | G461: 250 | H461: 11111000 | I461: 10000000 | J461: -1 | K461: 0 | L461: -1 | M461: 0 | N461: 28 | O461: 0 | P461: 100 | Q461: -1 | R461: 0 | S461: -1 | T461: -1 | U461: -1 | V461: -1 | W461: -1 | X461: 6 | Y461: 1 | Z461: 0 | AA461: 0 | AB461: 0 | AC461: 0 | AD461: 1 | AE461: 1 | AF461: 1 | AG461: 252 | AH461: 0 | AI461: 0 | AJ461: 1 | AK461: 1 | AL461: 1 | AM461: 1 | AN461: 1 | AO461: 0 | AP461: ="t"&A461 -> tipmas09 | AQ461: 0 | AR461: 0 | AS461: 0
A462: ippms01 | B462: 1 | C462: A2056F | D462: 574 | E462: Premium Service [1 day] | F462: 205 | G462: 250 | H462: 11111000 | I462: 10000000 | J462: -1 | K462: 0 | L462: -1 | M462: 0 | N462: 28 | O462: 0 | P462: 1 | Q462: -1 | R462: -1 | S462: -1 | T462: -1 | U462: -1 | V462: -1 | W462: -1 | X462: 0 | Y462: 1 | Z462: 0 | AA462: 0 | AB462: 0 | AC462: 0 | AD462: 1 | AE462: 1 | AF462: 1 | AG462: 263 | AH462: 0 | AI462: 0 | AJ462: 1 | AK462: 1 | AL462: 1 | AM462: 1 | AN462: 1 | AO462: 0 | AP462: ="t"&A462 -> tippms01 | AQ462: 0 | AR462: 0 | AS462: 0
A463: ippms02 | B463: 1 | C463: A2056F | D463: 574 | E463: Premium Service [3 day] | F463: 205 | G463: 250 | H463: 11111000 | I463: 10000000 | J463: -1 | K463: 0 | L463: -1 | M463: 0 | N463: 28 | O463: 0 | P463: 1 | Q463: -1 | R463: -1 | S463: -1 | T463: -1 | U463: -1 | V463: -1 | W463: -1 | X463: 0 | Y463: 1 | Z463: 0 | AA463: 0 | AB463: 0 | AC463: 0 | AD463: 1 | AE463: 1 | AF463: 1 | AG463: 264 | AH463: 0 | AI463: 0 | AJ463: 1 | AK463: 1 | AL463: 1 | AM463: 1 | AN463: 1 | AO463: 0 | AP463: ="t"&A463 -> tippms02 | AQ463: 1 | AR463: 0 | AS463: 0
A464: ippms03 | B464: 1 | C464: A2056F | D464: 574 | E464: Premium Service [7 day] | F464: 205 | G464: 250 | H464: 11111000 | I464: 10000000 | J464: -1 | K464: 0 | L464: -1 | M464: 0 | N464: 28 | O464: 0 | P464: 1 | Q464: -1 | R464: -1 | S464: -1 | T464: -1 | U464: -1 | V464: -1 | W464: -1 | X464: 0 | Y464: 1 | Z464: 0 | AA464: 0 | AB464: 0 | AC464: 0 | AD464: 1 | AE464: 1 | AF464: 1 | AG464: 265 | AH464: 0 | AI464: 0 | AJ464: 1 | AK464: 1 | AL464: 1 | AM464: 1 | AN464: 1 | AO464: 0 | AP464: ="t"&A464 -> tippms03 | AQ464: 1 | AR464: 0 | AS464: 0
...

Sheet 13decrypt
A1: clcode | B1: string[64] | C1: xeh | D1: dword | E1: stb | F1: byte | G1: byte | H1: word | I1: dword | J1: dword | K1: dword | L1: dword | M1: dword | N1: dword | O1: dword | P1: dword | Q1: dword | R1: dword | S1: dword | T1: dword | U1: dword | V1: dword | W1: long | X1: dword | Y1: dword | Z1: dword | AA1: stb | AB1: dword | AC1: dword | AD1: dword | AE1: xeh | AF1: dword | AG1: dword | AH1: dword | AI1: dword | AJ1: END
A2: =PotionItem!A2 -> Code | B2: =PotionItem!E2 -> Name | C2: =PotionItem!C2 -> Model | D2: =PotionItem!D2 -> IconID | E2: =PotionItem!H2 -> Civil | F2: ListID | G2: =PotionItem!X2 -> Money | H2: none | I2: =PotionItem!Y2 -> StdPrice | J2: =PotionItem!Z2 -> StdPoint | K2: =PotionItem!AA2 -> GoldPoint | L2: =PotionItem!AC2 -> ProcPoint | M2: =PotionItem!AB2 -> KillPoint | N2: =PotionItem!AD2 -> StorePrice | O2: =PotionItem!AK2 -> IsExchange | P2: =PotionItem!AJ2 -> IsSell | Q2: =PotionItem!AL2 -> IsGround | R2: =PotionItem!AM2 -> IsStore | S2: Descripton | T2: =PotionItem!B2 -> IsExist | U2: =PotionItem!AQ2 -> IsCash | V2: =PotionItem!AS2 -> IsTime | W2: =PotionItem!Q2 -> UpLevelLim | X2: =PotionItem!P2 -> LevelLim | Y2: =PotionItem!M2 -> ActDelay | Z2: =PotionItem!K2 -> UseState | AA2: =PotionItem!I2 -> ActTarget | AB2: =PotionItem!L2 -> TargetEff | AC2: =PotionItem!N2 -> DelayType | AD2: =PotionItem!O2 -> UseRange | AE2: =PotionItem!AG2 -> EffCode | AF2: =PotionItem!AH2 -> EffArea | AG2: =PotionItem!AI2 -> EffAreaVal | AH2: =PotionItem!AR2 -> UsePCCash | AI2: unkn
A3: =PotionItem!A3 -> ipbhp01 | B3: =PotionItem!E3 -> Bless HP Potion 100 | C3: =PotionItem!C3 -> 720000 | D3: =PotionItem!D3 -> 1 | E3: =PotionItem!H3 -> 11000000 | F3: 13 | G3: =PotionItem!X3 -> 0 | H3: 0 | I3: =PotionItem!Y3 -> 40 | J3: =PotionItem!Z3 -> 0 | K3: =PotionItem!AA3 -> 0 | L3: =PotionItem!AC3 -> 0 | M3: =PotionItem!AB3 -> 0 | N3: =PotionItem!AD3 -> 4 | O3: =PotionItem!AK3 -> 1 | P3: =PotionItem!AJ3 -> 1 | Q3: =PotionItem!AL3 -> 1 | R3: =PotionItem!AM3 -> 1 | S3: 0 | T3: =PotionItem!B3 -> 1 | U3: =PotionItem!AQ3 -> 0 | V3: =PotionItem!AS3 -> 0 | W3: =PotionItem!Q3 -> -1 | X3: =PotionItem!P3 -> 1 | Y3: =PotionItem!M3 -> 1600 | Z3: =PotionItem!K3 -> 0 | AA3: =PotionItem!I3 -> 10000000 | AB3: =PotionItem!L3 -> -1 | AC3: =PotionItem!N3 -> 0 | AD3: =PotionItem!O3 -> 0 | AE3: =PotionItem!AG3 -> 1 | AF3: =PotionItem!AH3 -> 0 | AG3: =PotionItem!AI3 -> 0 | AH3: =PotionItem!AR3 -> 0 | AI3: 0
A4: =PotionItem!A4 -> ipbhp02 | B4: =PotionItem!E4 -> Bless HP Potion 250 | C4: =PotionItem!C4 -> 720001 | D4: =PotionItem!D4 -> 2 | E4: =PotionItem!H4 -> 11000000 | F4: 13 | G4: =PotionItem!X4 -> 0 | H4: 0 | I4: =PotionItem!Y4 -> 100 | J4: =PotionItem!Z4 -> 0 | K4: =PotionItem!AA4 -> 0 | L4: =PotionItem!AC4 -> 0 | M4: =PotionItem!AB4 -> 0 | N4: =PotionItem!AD4 -> 10 | O4: =PotionItem!AK4 -> 1 | P4: =PotionItem!AJ4 -> 1 | Q4: =PotionItem!AL4 -> 1 | R4: =PotionItem!AM4 -> 1 | S4: 1 | T4: =PotionItem!B4 -> 1 | U4: =PotionItem!AQ4 -> 0 | V4: =PotionItem!AS4 -> 0 | W4: =PotionItem!Q4 -> -1 | X4: =PotionItem!P4 -> 1 | Y4: =PotionItem!M4 -> 1600 | Z4: =PotionItem!K4 -> 0 | AA4: =PotionItem!I4 -> 10000000 | AB4: =PotionItem!L4 -> -1 | AC4: =PotionItem!N4 -> 0 | AD4: =PotionItem!O4 -> 0 | AE4: =PotionItem!AG4 -> 2 | AF4: =PotionItem!AH4 -> 0 | AG4: =PotionItem!AI4 -> 0 | AH4: =PotionItem!AR4 -> 0 | AI4: 0
A5: =PotionItem!A5 -> ipbhp03 | B5: =PotionItem!E5 -> Bless HP Potion 500 | C5: =PotionItem!C5 -> 720002 | D5: =PotionItem!D5 -> 3 | E5: =PotionItem!H5 -> 11000000 | F5: 13 | G5: =PotionItem!X5 -> 0 | H5: 0 | I5: =PotionItem!Y5 -> 220 | J5: =PotionItem!Z5 -> 0 | K5: =PotionItem!AA5 -> 0 | L5: =PotionItem!AC5 -> 0 | M5: =PotionItem!AB5 -> 0 | N5: =PotionItem!AD5 -> 22 | O5: =PotionItem!AK5 -> 1 | P5: =PotionItem!AJ5 -> 1 | Q5: =PotionItem!AL5 -> 1 | R5: =PotionItem!AM5 -> 1 | S5: 2 | T5: =PotionItem!B5 -> 1 | U5: =PotionItem!AQ5 -> 0 | V5: =PotionItem!AS5 -> 0 | W5: =PotionItem!Q5 -> -1 | X5: =PotionItem!P5 -> 1 | Y5: =PotionItem!M5 -> 1600 | Z5: =PotionItem!K5 -> 0 | AA5: =PotionItem!I5 -> 10000000 | AB5: =PotionItem!L5 -> -1 | AC5: =PotionItem!N5 -> 0 | AD5: =PotionItem!O5 -> 0 | AE5: =PotionItem!AG5 -> 3 | AF5: =PotionItem!AH5 -> 0 | AG5: =PotionItem!AI5 -> 0 | AH5: =PotionItem!AR5 -> 0 | AI5: 0
A6: =PotionItem!A6 -> ipbhp04 | B6: =PotionItem!E6 -> Bless HP Potion 1000 | C6: =PotionItem!C6 -> 720003 | D6: =PotionItem!D6 -> 4 | E6: =PotionItem!H6 -> 11000000 | F6: 13 | G6: =PotionItem!X6 -> 0 | H6: 0 | I6: =PotionItem!Y6 -> 500 | J6: =PotionItem!Z6 -> 0 | K6: =PotionItem!AA6 -> 0 | L6: =PotionItem!AC6 -> 0 | M6: =PotionItem!AB6 -> 0 | N6: =PotionItem!AD6 -> 50 | O6: =PotionItem!AK6 -> 1 | P6: =PotionItem!AJ6 -> 1 | Q6: =PotionItem!AL6 -> 1 | R6: =PotionItem!AM6 -> 1 | S6: 3 | T6: =PotionItem!B6 -> 1 | U6: =PotionItem!AQ6 -> 0 | V6: =PotionItem!AS6 -> 0 | W6: =PotionItem!Q6 -> -1 | X6: =PotionItem!P6 -> 1 | Y6: =PotionItem!M6 -> 1800 | Z6: =PotionItem!K6 -> 0 | AA6: =PotionItem!I6 -> 10000000 | AB6: =PotionItem!L6 -> -1 | AC6: =PotionItem!N6 -> 0 | AD6: =PotionItem!O6 -> 0 | AE6: =PotionItem!AG6 -> 4 | AF6: =PotionItem!AH6 -> 0 | AG6: =PotionItem!AI6 -> 0 | AH6: =PotionItem!AR6 -> 0 | AI6: 0
A7: =PotionItem!A7 -> ipbhp05 | B7: =PotionItem!E7 -> Bless HP Potion 2000 | C7: =PotionItem!C7 -> 720004 | D7: =PotionItem!D7 -> 5 | E7: =PotionItem!H7 -> 11000000 | F7: 13 | G7: =PotionItem!X7 -> 0 | H7: 0 | I7: =PotionItem!Y7 -> 1200 | J7: =PotionItem!Z7 -> 0 | K7: =PotionItem!AA7 -> 0 | L7: =PotionItem!AC7 -> 0 | M7: =PotionItem!AB7 -> 0 | N7: =PotionItem!AD7 -> 120 | O7: =PotionItem!AK7 -> 1 | P7: =PotionItem!AJ7 -> 1 | Q7: =PotionItem!AL7 -> 1 | R7: =PotionItem!AM7 -> 1 | S7: 4 | T7: =PotionItem!B7 -> 1 | U7: =PotionItem!AQ7 -> 0 | V7: =PotionItem!AS7 -> 0 | W7: =PotionItem!Q7 -> -1 | X7: =PotionItem!P7 -> 1 | Y7: =PotionItem!M7 -> 2200 | Z7: =PotionItem!K7 -> 0 | AA7: =PotionItem!I7 -> 10000000 | AB7: =PotionItem!L7 -> -1 | AC7: =PotionItem!N7 -> 0 | AD7: =PotionItem!O7 -> 0 | AE7: =PotionItem!AG7 -> 5 | AF7: =PotionItem!AH7 -> 0 | AG7: =PotionItem!AI7 -> 0 | AH7: =PotionItem!AR7 -> 0 | AI7: 0
A8: =PotionItem!A8 -> ipbhp06 | B8: =PotionItem!E8 -> Bless HP Potion 3000 | C8: =PotionItem!C8 -> 720005 | D8: =PotionItem!D8 -> 6 | E8: =PotionItem!H8 -> 11000000 | F8: 13 | G8: =PotionItem!X8 -> 0 | H8: 0 | I8: =PotionItem!Y8 -> 3637 | J8: =PotionItem!Z8 -> 0 | K8: =PotionItem!AA8 -> 0 | L8: =PotionItem!AC8 -> 0 | M8: =PotionItem!AB8 -> 0 | N8: =PotionItem!AD8 -> 225 | O8: =PotionItem!AK8 -> 1 | P8: =PotionItem!AJ8 -> 1 | Q8: =PotionItem!AL8 -> 1 | R8: =PotionItem!AM8 -> 1 | S8: 5 | T8: =PotionItem!B8 -> 1 | U8: =PotionItem!AQ8 -> 0 | V8: =PotionItem!AS8 -> 0 | W8: =PotionItem!Q8 -> -1 | X8: =PotionItem!P8 -> 1 | Y8: =PotionItem!M8 -> 2500 | Z8: =PotionItem!K8 -> 0 | AA8: =PotionItem!I8 -> 10000000 | AB8: =PotionItem!L8 -> -1 | AC8: =PotionItem!N8 -> 0 | AD8: =PotionItem!O8 -> 0 | AE8: =PotionItem!AG8 -> 6 | AF8: =PotionItem!AH8 -> 0 | AG8: =PotionItem!AI8 -> 0 | AH8: =PotionItem!AR8 -> 0 | AI8: 0
A9: =PotionItem!A9 -> ipbhp07 | B9: =PotionItem!E9 -> Bless HP Potion 4000 | C9: =PotionItem!C9 -> 720006 | D9: =PotionItem!D9 -> 7 | E9: =PotionItem!H9 -> 11000000 | F9: 13 | G9: =PotionItem!X9 -> 0 | H9: 0 | I9: =PotionItem!Y9 -> 5250 | J9: =PotionItem!Z9 -> 0 | K9: =PotionItem!AA9 -> 0 | L9: =PotionItem!AC9 -> 0 | M9: =PotionItem!AB9 -> 0 | N9: =PotionItem!AD9 -> 525 | O9: =PotionItem!AK9 -> 1 | P9: =PotionItem!AJ9 -> 1 | Q9: =PotionItem!AL9 -> 1 | R9: =PotionItem!AM9 -> 1 | S9: 6 | T9: =PotionItem!B9 -> 1 | U9: =PotionItem!AQ9 -> 0 | V9: =PotionItem!AS9 -> 0 | W9: =PotionItem!Q9 -> -1 | X9: =PotionItem!P9 -> 1 | Y9: =PotionItem!M9 -> 2500 | Z9: =PotionItem!K9 -> 0 | AA9: =PotionItem!I9 -> 10000000 | AB9: =PotionItem!L9 -> -1 | AC9: =PotionItem!N9 -> 0 | AD9: =PotionItem!O9 -> 0 | AE9: =PotionItem!AG9 -> 7 | AF9: =PotionItem!AH9 -> 0 | AG9: =PotionItem!AI9 -> 0 | AH9: =PotionItem!AR9 -> 0 | AI9: 0
A10: =PotionItem!A10 -> ipbhp08 | B10: =PotionItem!E10 -> Bless HP Potion 5000 | C10: =PotionItem!C10 -> 720007 | D10: =PotionItem!D10 -> 8 | E10: =PotionItem!H10 -> 11000000 | F10: 13 | G10: =PotionItem!X10 -> 0 | H10: 0 | I10: =PotionItem!Y10 -> 11257 | J10: =PotionItem!Z10 -> 0 | K10: =PotionItem!AA10 -> 0 | L10: =PotionItem!AC10 -> 0 | M10: =PotionItem!AB10 -> 0 | N10: =PotionItem!AD10 -> 1126 | O10: =PotionItem!AK10 -> 1 | P10: =PotionItem!AJ10 -> 1 | Q10: =PotionItem!AL10 -> 1 | R10: =PotionItem!AM10 -> 1 | S10: 7 | T10: =PotionItem!B10 -> 1 | U10: =PotionItem!AQ10 -> 0 | V10: =PotionItem!AS10 -> 0 | W10: =PotionItem!Q10 -> -1 | X10: =PotionItem!P10 -> 1 | Y10: =PotionItem!M10 -> 2500 | Z10: =PotionItem!K10 -> 0 | AA10: =PotionItem!I10 -> 10000000 | AB10: =PotionItem!L10 -> -1 | AC10: =PotionItem!N10 -> 0 | AD10: =PotionItem!O10 -> 0 | AE10: =PotionItem!AG10 -> 8 | AF10: =PotionItem!AH10 -> 0 | AG10: =PotionItem!AI10 -> 0 | AH10: =PotionItem!AR10 -> 0 | AI10: 0
A11: =PotionItem!A11 -> ipchp01 | B11: =PotionItem!E11 -> Pope HP Potion 100 | C11: =PotionItem!C11 -> 820008 | D11: =PotionItem!D11 -> 9 | E11: =PotionItem!H11 -> 00110000 | F11: 13 | G11: =PotionItem!X11 -> 0 | H11: 0 | I11: =PotionItem!Y11 -> 40 | J11: =PotionItem!Z11 -> 0 | K11: =PotionItem!AA11 -> 0 | L11: =PotionItem!AC11 -> 0 | M11: =PotionItem!AB11 -> 0 | N11: =PotionItem!AD11 -> 4 | O11: =PotionItem!AK11 -> 1 | P11: =PotionItem!AJ11 -> 1 | Q11: =PotionItem!AL11 -> 1 | R11: =PotionItem!AM11 -> 1 | S11: 8 | T11: =PotionItem!B11 -> 1 | U11: =PotionItem!AQ11 -> 0 | V11: =PotionItem!AS11 -> 0 | W11: =PotionItem!Q11 -> -1 | X11: =PotionItem!P11 -> 1 | Y11: =PotionItem!M11 -> 1600 | Z11: =PotionItem!K11 -> 0 | AA11: =PotionItem!I11 -> 10000000 | AB11: =PotionItem!L11 -> -1 | AC11: =PotionItem!N11 -> 0 | AD11: =PotionItem!O11 -> 0 | AE11: =PotionItem!AG11 -> 9 | AF11: =PotionItem!AH11 -> 0 | AG11: =PotionItem!AI11 -> 0 | AH11: =PotionItem!AR11 -> 0 | AI11: 0
A12: =PotionItem!A12 -> ipchp02 | B12: =PotionItem!E12 -> Pope HP Potion 250 | C12: =PotionItem!C12 -> 820009 | D12: =PotionItem!D12 -> 10 | E12: =PotionItem!H12 -> 00110000 | F12: 13 | G12: =PotionItem!X12 -> 0 | H12: 0 | I12: =PotionItem!Y12 -> 100 | J12: =PotionItem!Z12 -> 0 | K12: =PotionItem!AA12 -> 0 | L12: =PotionItem!AC12 -> 0 | M12: =PotionItem!AB12 -> 0 | N12: =PotionItem!AD12 -> 10 | O12: =PotionItem!AK12 -> 1 | P12: =PotionItem!AJ12 -> 1 | Q12: =PotionItem!AL12 -> 1 | R12: =PotionItem!AM12 -> 1 | S12: 9 | T12: =PotionItem!B12 -> 1 | U12: =PotionItem!AQ12 -> 0 | V12: =PotionItem!AS12 -> 0 | W12: =PotionItem!Q12 -> -1 | X12: =PotionItem!P12 -> 1 | Y12: =PotionItem!M12 -> 1600 | Z12: =PotionItem!K12 -> 0 | AA12: =PotionItem!I12 -> 10000000 | AB12: =PotionItem!L12 -> -1 | AC12: =PotionItem!N12 -> 0 | AD12: =PotionItem!O12 -> 0 | AE12: =PotionItem!AG12 -> A | AF12: =PotionItem!AH12 -> 0 | AG12: =PotionItem!AI12 -> 0 | AH12: =PotionItem!AR12 -> 0 | AI12: 0
A13: =PotionItem!A13 -> ipchp03 | B13: =PotionItem!E13 -> Pope HP Potion 500 | C13: =PotionItem!C13 -> 82000A | D13: =PotionItem!D13 -> 11 | E13: =PotionItem!H13 -> 00110000 | F13: 13 | G13: =PotionItem!X13 -> 0 | H13: 0 | I13: =PotionItem!Y13 -> 220 | J13: =PotionItem!Z13 -> 0 | K13: =PotionItem!AA13 -> 0 | L13: =PotionItem!AC13 -> 0 | M13: =PotionItem!AB13 -> 0 | N13: =PotionItem!AD13 -> 22 | O13: =PotionItem!AK13 -> 1 | P13: =PotionItem!AJ13 -> 1 | Q13: =PotionItem!AL13 -> 1 | R13: =PotionItem!AM13 -> 1 | S13: 10 | T13: =PotionItem!B13 -> 1 | U13: =PotionItem!AQ13 -> 0 | V13: =PotionItem!AS13 -> 0 | W13: =PotionItem!Q13 -> -1 | X13: =PotionItem!P13 -> 1 | Y13: =PotionItem!M13 -> 1600 | Z13: =PotionItem!K13 -> 0 | AA13: =PotionItem!I13 -> 10000000 | AB13: =PotionItem!L13 -> -1 | AC13: =PotionItem!N13 -> 0 | AD13: =PotionItem!O13 -> 0 | AE13: =PotionItem!AG13 -> B | AF13: =PotionItem!AH13 -> 0 | AG13: =PotionItem!AI13 -> 0 | AH13: =PotionItem!AR13 -> 0 | AI13: 0
A14: =PotionItem!A14 -> ipchp04 | B14: =PotionItem!E14 -> Pope HP Potion 1000 | C14: =PotionItem!C14 -> 82000B | D14: =PotionItem!D14 -> 12 | E14: =PotionItem!H14 -> 00110000 | F14: 13 | G14: =PotionItem!X14 -> 0 | H14: 0 | I14: =PotionItem!Y14 -> 500 | J14: =PotionItem!Z14 -> 0 | K14: =PotionItem!AA14 -> 0 | L14: =PotionItem!AC14 -> 0 | M14: =PotionItem!AB14 -> 0 | N14: =PotionItem!AD14 -> 50 | O14: =PotionItem!AK14 -> 1 | P14: =PotionItem!AJ14 -> 1 | Q14: =PotionItem!AL14 -> 1 | R14: =PotionItem!AM14 -> 1 | S14: 11 | T14: =PotionItem!B14 -> 1 | U14: =PotionItem!AQ14 -> 0 | V14: =PotionItem!AS14 -> 0 | W14: =PotionItem!Q14 -> -1 | X14: =PotionItem!P14 -> 1 | Y14: =PotionItem!M14 -> 1800 | Z14: =PotionItem!K14 -> 0 | AA14: =PotionItem!I14 -> 10000000 | AB14: =PotionItem!L14 -> -1 | AC14: =PotionItem!N14 -> 0 | AD14: =PotionItem!O14 -> 0 | AE14: =PotionItem!AG14 -> C | AF14: =PotionItem!AH14 -> 0 | AG14: =PotionItem!AI14 -> 0 | AH14: =PotionItem!AR14 -> 0 | AI14: 0
... A495: =PotionItem!A495 -> ippvp18 | B495: =PotionItem!E495 -> Defense Charger [pvp points] | C495: =PotionItem!C495 -> 42053E | D495: =PotionItem!D495 -> 139 | E495: =PotionItem!H495 -> 00001000 | F495: 13 | G495: =PotionItem!X495 -> 2 | H495: 0 | I495: =PotionItem!Y495 -> 46 | J495: =PotionItem!Z495 -> 46 | K495: =PotionItem!AA495 -> 46 | L495: =PotionItem!AC495 -> 46 | M495: =PotionItem!AB495 -> 46 | N495: =PotionItem!AD495 -> 1 | O495: =PotionItem!AK495 -> 1 | P495: =PotionItem!AJ495 -> 1 | Q495: =PotionItem!AL495 -> 1 | R495: =PotionItem!AM495 -> 1 | S495: 195 | T495: =PotionItem!B495 -> 1 | U495: =PotionItem!AQ495 -> 1 | V495: =PotionItem!AS495 -> 0 | W495: =PotionItem!Q495 -> -1 | X495: =PotionItem!P495 -> 1 | Y495: =PotionItem!M495 -> 10000 | Z495: =PotionItem!K495 -> 0 | AA495: =PotionItem!I495 -> 10000000 | AB495: =PotionItem!L495 -> -1 | AC495: =PotionItem!N495 -> 4 | AD495: =PotionItem!O495 -> 0 | AE495: =PotionItem!AG495 -> AB | AF495: =PotionItem!AH495 -> 0 | AG495: =PotionItem!AI495 -> 0 | AH495: =PotionItem!AR495 -> 0 | AI495: 0

Sheet 13desc
A1: dword | B1: text | C1: END
A2: Count | B2: desc
A3: 0 | B3: Potion exclusive for Bellato
A4: 1 | B4: Potion exclusive for Bellato
A5: 2 | B5: Potion exclusive for Bellato
A6: 3 | B6: Potion exclusive for Bellato
A7: 4 | B7: Potion exclusive for Bellato
A8: 5 | B8: Potion exclusive for Bellato
A9: 6 | B9: Potion exclusive for Bellato
A10: 7 | B10: Potion exclusive for Bellato
A11: 8 | B11: Potion exclusive for Cora
A12: 9 | B12: Potion exclusive for Cora
A13: 10 | B13: Potion exclusive for Cora
A14: 11 | B14: Potion exclusive for Cora
... A598: 595 | B598: <font color='05f9ff'>[A Mysterious Serum that will increase your level upon use.]</font>
