Workbook

Sheet bootYItem
A1: string[64] | B1: dword | C1: string[64] | D1: dword | E1: string[64] | F1: dword | G1: dword | H1: string[64] | I1: dword | J1: dword | K1: dword | L1: dword | M1: dword | N1: dword | O1: dword | P1: dword | Q1: dword | R1: dword | S1: dword | T1: dword | U1: string[64] | V1: dword | W1: dword | X1: END
A2: Code | B2: IsExist | C2: Model | D2: Icon | E2: Name | F2: KindClt | G2: FixPart | H2: Civil | I2: Money | J2: StdPrice | K2: StdPoint | L2: GoldPoint | M2: KillPoint | N2: ProcPoint | O2: StorePrice | P2: IsSell | Q2: IsExchange | R2: IsGround | S2: IsStore | T2: IsNormAcc | U2: ToolTip | V2: IsCash | W2: IsTime
A3: iyyyy01 | B3: 1 | C3: A30200 | D3: 1 | E3: Cling | F3: 302 | G3: 300 | H3: 11111000 | I3: 0 | J3: 90 | K3: 0 | L3: 0 | M3: 0 | N3: 0 | O3: 1 | P3: 1 | Q3: 1 | R3: 1 | S3: 1 | T3: 1 | U3: ="t"&A3 -> tiyyyy01 | V3: 0 | W3: 0
A4: iyyyy02 | B4: 1 | C4: A30201 | D4: 2 | E4: Haren | F4: 302 | G4: 300 | H4: 11111000 | I4: 0 | J4: 400 | K4: 0 | L4: 0 | M4: 0 | N4: 0 | O4: 4 | P4: 1 | Q4: 1 | R4: 1 | S4: 1 | T4: 1 | U4: ="t"&A4 -> tiyyyy02 | V4: 0 | W4: 0
A5: iyyyy03 | B5: 1 | C5: A30202 | D5: 3 | E5: Greaf | F5: 302 | G5: 300 | H5: 11111000 | I5: 0 | J5: 1880 | K5: 0 | L5: 0 | M5: 0 | N5: 0 | O5: 17 | P5: 1 | Q5: 1 | R5: 1 | S5: 1 | T5: 1 | U5: ="t"&A5 -> tiyyyy03 | V5: 0 | W5: 0
A6: iyyyy04 | B6: 1 | C6: A30203 | D6: 4 | E6: Rian | F6: 302 | G6: 300 | H6: 11111000 | I6: 0 | J6: 11223 | K6: 0 | L6: 0 | M6: 0 | N6: 0 | O6: 87 | P6: 1 | Q6: 1 | R6: 1 | S6: 1 | T6: 1 | U6: ="t"&A6 -> tiyyyy04 | V6: 0 | W6: 0
A7: iyyyy05 | B7: 1 | C7: A30204 | D7: 5 | E7: Mika | F7: 302 | G7: 300 | H7: 11111000 | I7: 0 | J7: 100 | K7: 0 | L7: 0 | M7: 0 | N7: 0 | O7: 1 | P7: 1 | Q7: 1 | R7: 1 | S7: 1 | T7: 1 | U7: ="t"&A7 -> tiyyyy05 | V7: 0 | W7: 0
A8: iyyyy06 | B8: 1 | C8: A30205 | D8: 6 | E8: Louis Mika | F8: 302 | G8: 300 | H8: 11111000 | I8: 0 | J8: 480 | K8: 0 | L8: 0 | M8: 0 | N8: 0 | O8: 4 | P8: 1 | Q8: 1 | R8: 1 | S8: 1 | T8: 1 | U8: ="t"&A8 -> tiyyyy06 | V8: 0 | W8: 0
A9: iyyyy07 | B9: 1 | C9: A30206 | D9: 7 | E9: Mid Mika | F9: 302 | G9: 300 | H9: 11111000 | I9: 0 | J9: 2260 | K9: 0 | L9: 0 | M9: 0 | N9: 0 | O9: 22 | P9: 1 | Q9: 1 | R9: 1 | S9: 1 | T9: 1 | U9: ="t"&A9 -> tiyyyy07 | V9: 0 | W9: 0
A10: iyyyy08 | B10: 1 | C10: A30207 | D10: 8 | E10: Wief | F10: 302 | G10: 300 | H10: 11111000 | I10: 0 | J10: 50 | K10: 0 | L10: 0 | M10: 0 | N10: 0 | O10: 1 | P10: 1 | Q10: 1 | R10: 1 | S10: 1 | T10: 1 | U10: ="t"&A10 -> tiyyyy08 | V10: 0 | W10: 0
A11: iyyyy09 | B11: 1 | C11: A30208 | D11: 9 | E11: Cell Wief | F11: 302 | G11: 300 | H11: 11111000 | I11: 0 | J11: 270 | K11: 0 | L11: 0 | M11: 0 | N11: 0 | O11: 2 | P11: 1 | Q11: 1 | R11: 1 | S11: 1 | T11: 1 | U11: ="t"&A11 -> tiyyyy09 | V11: 0 | W11: 0
A12: iyyyy10 | B12: 1 | C12: A30209 | D12: 10 | E12: Ward Wief | F12: 302 | G12: 300 | H12: 11111000 | I12: 0 | J12: 870 | K12: 0 | L12: 0 | M12: 0 | N12: 0 | O12: 8 | P12: 1 | Q12: 1 | R12: 1 | S12: 1 | T12: 1 | U12: ="t"&A12 -> tiyyyy10 | V12: 0 | W12: 0
A13: iyyyy11 | B13: 1 | C13: A3020A | D13: 11 | E13: Lake | F13: 302 | G13: 300 | H13: 11111000 | I13: 0 | J13: 4870 | K13: 0 | L13: 0 | M13: 0 | N13: 0 | O13: 48 | P13: 1 | Q13: 1 | R13: 1 | S13: 1 | T13: 1 | U13: ="t"&A13 -> tiyyyy11 | V13: 0 | W13: 0
A14: iyyyy12 | B14: 1 | C14: A3020B | D14: 12 | E14: Riar | F14: 302 | G14: 300 | H14: 11111000 | I14: 0 | J14: 40 | K14: 0 | L14: 0 | M14: 0 | N14: 0 | O14: 1 | P14: 1 | Q14: 1 | R14: 1 | S14: 1 | T14: 1 | U14: ="t"&A14 -> tiyyyy12 | V14: 0 | W14: 1
... A2636: iybrd01 | B2636: 1 | C2636: A30213 | D2636: 1017 | E2636: Broadcast | F2636: 302 | G2636: 300 | H2636: 11111000 | I2636: 0 | J2636: 120 | K2636: 0 | L2636: 0 | M2636: 0 | N2636: 0 | O2636: 1 | P2636: 1 | Q2636: 1 | R2636: 1 | S2636: 1 | T2636: 1 | U2636: ="t"&A2636 -> tiybrd01 | V2636: 1 | W2636: 0

Sheet 20decrypt
A1: clcode | B1: string[64] | C1: xeh | D1: dword | E1: stb | F1: byte | G1: byte | H1: word | I1: dword | J1: dword | K1: dword | L1: dword | M1: dword | N1: dword | O1: dword | P1: dword | Q1: dword | R1: dword | S1: dword | T1: dword | U1: dword | V1: dword | W1: long | X1: dword | Y1: END
A2: =bootYItem!A2 -> Code | B2: =bootYItem!E2 -> Name | C2: =bootYItem!C2 -> Model | D2: =bootYItem!D2 -> Icon | E2: =bootYItem!H2 -> Civil | F2: ListID | G2: =bootYItem!I2 -> Money | H2: none | I2: =bootYItem!J2 -> StdPrice | J2: =bootYItem!K2 -> StdPoint | K2: =bootYItem!L2 -> GoldPoint | L2: =bootYItem!N2 -> ProcPoint | M2: =bootYItem!M2 -> KillPoint | N2: =bootYItem!O2 -> StorePrice | O2: =bootYItem!Q2 -> IsExchange | P2: =bootYItem!P2 -> IsSell | Q2: =bootYItem!R2 -> IsGround | R2: =bootYItem!S2 -> IsStore | S2: Dwscrypt | T2: =bootYItem!B2 -> IsExist | U2: =bootYItem!V2 -> IsCash | V2: =bootYItem!W2 -> IsTime | W2: UpLvLim | X2: hz
A3: =bootYItem!A3 -> iyyyy01 | B3: =bootYItem!E3 -> Cling | C3: =bootYItem!C3 -> A30200 | D3: =bootYItem!D3 -> 1 | E3: =bootYItem!H3 -> 11111000 | F3: 20 | G3: =bootYItem!I3 -> 0 | H3: 0 | I3: =bootYItem!J3 -> 90 | J3: =bootYItem!K3 -> 0 | K3: =bootYItem!L3 -> 0 | L3: =bootYItem!N3 -> 0 | M3: =bootYItem!M3 -> 0 | N3: =bootYItem!O3 -> 1 | O3: =bootYItem!Q3 -> 1 | P3: =bootYItem!P3 -> 1 | Q3: =bootYItem!R3 -> 1 | R3: =bootYItem!S3 -> 1 | S3: 0 | T3: =bootYItem!B3 -> 1 | U3: =bootYItem!V3 -> 0 | V3: =bootYItem!W3 -> 0 | W3: 0 | X3: 0
A4: =bootYItem!A4 -> iyyyy02 | B4: =bootYItem!E4 -> Haren | C4: =bootYItem!C4 -> A30201 | D4: =bootYItem!D4 -> 2 | E4: =bootYItem!H4 -> 11111000 | F4: 20 | G4: =bootYItem!I4 -> 0 | H4: 0 | I4: =bootYItem!J4 -> 400 | J4: =bootYItem!K4 -> 0 | K4: =bootYItem!L4 -> 0 | L4: =bootYItem!N4 -> 0 | M4: =bootYItem!M4 -> 0 | N4: =bootYItem!O4 -> 4 | O4: =bootYItem!Q4 -> 1 | P4: =bootYItem!P4 -> 1 | Q4: =bootYItem!R4 -> 1 | R4: =bootYItem!S4 -> 1 | S4: 1 | T4: =bootYItem!B4 -> 1 | U4: =bootYItem!V4 -> 0 | V4: =bootYItem!W4 -> 0 | W4: 0 | X4: 0
A5: =bootYItem!A5 -> iyyyy03 | B5: =bootYItem!E5 -> Greaf | C5: =bootYItem!C5 -> A30202 | D5: =bootYItem!D5 -> 3 | E5: =bootYItem!H5 -> 11111000 | F5: 20 | G5: =bootYItem!I5 -> 0 | H5: 0 | I5: =bootYItem!J5 -> 1880 | J5: =bootYItem!K5 -> 0 | K5: =bootYItem!L5 -> 0 | L5: =bootYItem!N5 -> 0 | M5: =bootYItem!M5 -> 0 | N5: =bootYItem!O5 -> 17 | O5: =bootYItem!Q5 -> 1 | P5: =bootYItem!P5 -> 1 | Q5: =bootYItem!R5 -> 1 | R5: =bootYItem!S5 -> 1 | S5: 2 | T5: =bootYItem!B5 -> 1 | U5: =bootYItem!V5 -> 0 | V5: =bootYItem!W5 -> 0 | W5: 0 | X5: 0
A6: =bootYItem!A6 -> iyyyy04 | B6: =bootYItem!E6 -> Rian | C6: =bootYItem!C6 -> A30203 | D6: =bootYItem!D6 -> 4 | E6: =bootYItem!H6 -> 11111000 | F6: 20 | G6: =bootYItem!I6 -> 0 | H6: 0 | I6: =bootYItem!J6 -> 11223 | J6: =bootYItem!K6 -> 0 | K6: =bootYItem!L6 -> 0 | L6: =bootYItem!N6 -> 0 | M6: =bootYItem!M6 -> 0 | N6: =bootYItem!O6 -> 87 | O6: =bootYItem!Q6 -> 1 | P6: =bootYItem!P6 -> 1 | Q6: =bootYItem!R6 -> 1 | R6: =bootYItem!S6 -> 1 | S6: 3 | T6: =bootYItem!B6 -> 1 | U6: =bootYItem!V6 -> 0 | V6: =bootYItem!W6 -> 0 | W6: 0 | X6: 0
A7: =bootYItem!A7 -> iyyyy05 | B7: =bootYItem!E7 -> Mika | C7: =bootYItem!C7 -> A30204 | D7: =bootYItem!D7 -> 5 | E7: =bootYItem!H7 -> 11111000 | F7: 20 | G7: =bootYItem!I7 -> 0 | H7: 0 | I7: =bootYItem!J7 -> 100 | J7: =bootYItem!K7 -> 0 | K7: =bootYItem!L7 -> 0 | L7: =bootYItem!N7 -> 0 | M7: =bootYItem!M7 -> 0 | N7: =bootYItem!O7 -> 1 | O7: =bootYItem!Q7 -> 1 | P7: =bootYItem!P7 -> 1 | Q7: =bootYItem!R7 -> 1 | R7: =bootYItem!S7 -> 1 | S7: 4 | T7: =bootYItem!B7 -> 1 | U7: =bootYItem!V7 -> 0 | V7: =bootYItem!W7 -> 0 | W7: 0 | X7: 0
A8: =bootYItem!A8 -> iyyyy06 | B8: =bootYItem!E8 -> Louis Mika | C8: =bootYItem!C8 -> A30205 | D8: =bootYItem!D8 -> 6 | E8: =bootYItem!H8 -> 11111000 | F8: 20 | G8: =bootYItem!I8 -> 0 | H8: 0 | I8: =bootYItem!J8 -> 480 | J8: =bootYItem!K8 -> 0 | K8: =bootYItem!L8 -> 0 | L8: =bootYItem!N8 -> 0 | M8: =bootYItem!M8 -> 0 | N8: =bootYItem!O8 -> 4 | O8: =bootYItem!Q8 -> 1 | P8: =bootYItem!P8 -> 1 | Q8: =bootYItem!R8 -> 1 | R8: =bootYItem!S8 -> 1 | S8: 5 | T8: =bootYItem!B8 -> 1 | U8: =bootYItem!V8 -> 0 | V8: =bootYItem!W8 -> 0 | W8: 0 | X8: 0
A9: =bootYItem!A9 -> iyyyy07 | B9: =bootYItem!E9 -> Mid Mika | C9: =bootYItem!C9 -> A30206 | D9: =bootYItem!D9 -> 7 | E9: =bootYItem!H9 -> 11111000 | F9: 20 | G9: =bootYItem!I9 -> 0 | H9: 0 | I9: =bootYItem!J9 -> 2260 | J9: =bootYItem!K9 -> 0 | K9: =bootYItem!L9 -> 0 | L9: =bootYItem!N9 -> 0 | M9: =bootYItem!M9 -> 0 | N9: =bootYItem!O9 -> 22 | O9: =bootYItem!Q9 -> 1 | P9: =bootYItem!P9 -> 1 | Q9: =bootYItem!R9 -> 1 | R9: =bootYItem!S9 -> 1 | S9: 6 | T9: =bootYItem!B9 -> 1 | U9: =bootYItem!V9 -> 0 | V9: =bootYItem!W9 -> 0 | W9: 0 | X9: 0
A10: =bootYItem!A10 -> iyyyy08 | B10: =bootYItem!E10 -> Wief | C10: =bootYItem!C10 -> A30207 | D10: =bootYItem!D10 -> 8 | E10: =bootYItem!H10 -> 11111000 | F10: 20 | G10: =bootYItem!I10 -> 0 | H10: 0 | I10: =bootYItem!J10 -> 50 | J10: =bootYItem!K10 -> 0 | K10: =bootYItem!L10 -> 0 | L10: =bootYItem!N10 -> 0 | M10: =bootYItem!M10 -> 0 | N10: =bootYItem!O10 -> 1 | O10: =bootYItem!Q10 -> 1 | P10: =bootYItem!P10 -> 1 | Q10: =bootYItem!R10 -> 1 | R10: =bootYItem!S10 -> 1 | S10: 7 | T10: =bootYItem!B10 -> 1 | U10: =bootYItem!V10 -> 0 | V10: =bootYItem!W10 -> 0 | W10: 0 | X10: 0
A11: =bootYItem!A11 -> iyyyy09 | B11: =bootYItem!E11 -> Cell Wief | C11: =bootYItem!C11 -> A30208 | D11: =bootYItem!D11 -> 9 | E11: =bootYItem!H11 -> 11111000 | F11: 20 | G11: =bootYItem!I11 -> 0 | H11: 0 | I11: =bootYItem!J11 -> 270 | J11: =bootYItem!K11 -> 0 | K11: =bootYItem!L11 -> 0 | L11: =bootYItem!N11 -> 0 | M11: =bootYItem!M11 -> 0 | N11: =bootYItem!O11 -> 2 | O11: =bootYItem!Q11 -> 1 | P11: =bootYItem!P11 -> 1 | Q11: =bootYItem!R11 -> 1 | R11: =bootYItem!S11 -> 1 | S11: 8 | T11: =bootYItem!B11 -> 1 | U11: =bootYItem!V11 -> 0 | V11: =bootYItem!W11 -> 0 | W11: 0 | X11: 0
A12: =bootYItem!A12 -> iyyyy10 | B12: =bootYItem!E12 -> Ward Wief | C12: =bootYItem!C12 -> A30209 | D12: =bootYItem!D12 -> 10 | E12: =bootYItem!H12 -> 11111000 | F12: 20 | G12: =bootYItem!I12 -> 0 | H12: 0 | I12: =bootYItem!J12 -> 870 | J12: =bootYItem!K12 -> 0 | K12: =bootYItem!L12 -> 0 | L12: =bootYItem!N12 -> 0 | M12: =bootYItem!M12 -> 0 | N12: =bootYItem!O12 -> 8 | O12: =bootYItem!Q12 -> 1 | P12: =bootYItem!P12 -> 1 | Q12: =bootYItem!R12 -> 1 | R12: =bootYItem!S12 -> 1 | S12: 9 | T12: =bootYItem!B12 -> 1 | U12: =bootYItem!V12 -> 0 | V12: =bootYItem!W12 -> 0 | W12: 0 | X12: 0
A13: =bootYItem!A13 -> iyyyy11 | B13: =bootYItem!E13 -> Lake | C13: =bootYItem!C13 -> A3020A | D13: =bootYItem!D13 -> 11 | E13: =bootYItem!H13 -> 11111000 | F13: 20 | G13: =bootYItem!I13 -> 0 | H13: 0 | I13: =bootYItem!J13 -> 4870 | J13: =bootYItem!K13 -> 0 | K13: =bootYItem!L13 -> 0 | L13: =bootYItem!N13 -> 0 | M13: =bootYItem!M13 -> 0 | N13: =bootYItem!O13 -> 48 | O13: =bootYItem!Q13 -> 1 | P13: =bootYItem!P13 -> 1 | Q13: =bootYItem!R13 -> 1 | R13: =bootYItem!S13 -> 1 | S13: 10 | T13: =bootYItem!B13 -> 1 | U13: =bootYItem!V13 -> 0 | V13: =bootYItem!W13 -> 0 | W13: 0 | X13: 0
A14: =bootYItem!A14 -> iyyyy12 | B14: =bootYItem!E14 -> Riar | C14: =bootYItem!C14 -> A3020B | D14: =bootYItem!D14 -> 12 | E14: =bootYItem!H14 -> 11111000 | F14: 20 | G14: =bootYItem!I14 -> 0 | H14: 0 | I14: =bootYItem!J14 -> 40 | J14: =bootYItem!K14 -> 0 | K14: =bootYItem!L14 -> 0 | L14: =bootYItem!N14 -> 0 | M14: =bootYItem!M14 -> 0 | N14: =bootYItem!O14 -> 1 | O14: =bootYItem!Q14 -> 1 | P14: =bootYItem!P14 -> 1 | Q14: =bootYItem!R14 -> 1 | R14: =bootYItem!S14 -> 1 | S14: 11 | T14: =bootYItem!B14 -> 1 | U14: =bootYItem!V14 -> 0 | V14: =bootYItem!W14 -> 1 | W14: 0 | X14: 0
... A2636: =bootYItem!A2636 -> iybrd01 | B2636: =bootYItem!E2636 -> Broadcast | C2636: =bootYItem!C2636 -> A30213 | D2636: =bootYItem!D2636 -> 1017 | E2636: =bootYItem!H2636 -> 11111000 | F2636: 20 | G2636: =bootYItem!I2636 -> 0 | H2636: 0 | I2636: =bootYItem!J2636 -> 120 | J2636: =bootYItem!K2636 -> 0 | K2636: =bootYItem!L2636 -> 0 | L2636: =bootYItem!N2636 -> 0 | M2636: =bootYItem!M2636 -> 0 | N2636: =bootYItem!O2636 -> 1 | O2636: =bootYItem!Q2636 -> 1 | P2636: =bootYItem!P2636 -> 1 | Q2636: =bootYItem!R2636 -> 1 | R2636: =bootYItem!S2636 -> 1 | S2636: 2181 | T2636: =bootYItem!B2636 -> 1 | U2636: =bootYItem!V2636 -> 1 | V2636: =bootYItem!W2636 -> 0 | W2636: 0 | X2636: 0

Sheet 20desc
A1: dword | B1: text | C1: END
A2: Count | B2: Desc
A3: 0 | B3: Hunting items are acquired from hunting and are used in item production.
A4: 1 | B4: Hunting items are acquired from hunting and are used in item production.
A5: 2 | B5: Hunting items are acquired from hunting and are used in item production.
A6: 3 | B6: Hunting items are acquired from hunting and are used in item production.
A7: 4 | B7: Hunting items are acquired from hunting and are used in item production.
A8: 5 | B8: Hunting items are acquired from hunting and are used in item production.
A9: 6 | B9: Hunting items are acquired from hunting and are used in item production.
A10: 7 | B10: Hunting items are acquired from hunting and are used in item production.
A11: 8 | B11: Hunting items are acquired from hunting and are used in item production.
A12: 9 | B12: Hunting items are acquired from hunting and are used in item production.
A13: 10 | B13: Hunting items are acquired from hunting and are used in item production.
A14: 11 | B14: Hunting items are acquired from hunting and are used in item production.
... A683: 680 | B683: GoldenPig
A684: 681
A685: 682
A686: 683
A687: 684
A688: 685 | B688: Dark hall ruler's tormented spirit is trapped in the two transparent holes stuck on each side
A689: 686 | B689: Large solid canine tooth with blood
A690: 687 | B690: Large sharp claw with the prey's chop
A691: 688 | B691: Piece of a tongue with sticky liquid. Still wriggling
A692: 689 | B692: Living body pocket filled with poison
A693: 690 | B693: Damaged shell which feels very solid and elastic
A694: 691 | B694: Dreadful slayer's shoulder strap
A695: 692 | B695: Ruler's snapped head which was believed to have never surrendered.
A696: 693 | B696: Crawler race's nose pendant which is the symbol of indomitability.
A697: 694 | B697: Crawler archon's head still staring with intimidating look at it's enemies
A698: 695 | B698: Pursuer's eyeball which was pulled out so that one cannot give chase anymore
A699: 696 | B699: Vafer archon's head which is a symbol of a warrior who has overcome their cowardice.
... A1440: 1437 | B1440: Rake Draco King's rake sampl
A1441: 1438
A1442: 1439
A1443: 1440
A1444: 1441
A1445: 1442
A1446: 1443
A1447: 1444
A1448: 1445
...
